fill ~224 ~48 ~64 ~255 ~63 ~95 minecraft:air strict
fill ~224 ~32 ~64 ~255 ~47 ~95 minecraft:air strict
fill ~224 ~16 ~64 ~255 ~31 ~95 minecraft:air strict
fill ~224 ~0 ~64 ~255 ~15 ~95 minecraft:air strict
fill ~224 ~80 ~96 ~255 ~95 ~127 minecraft:air strict
fill ~224 ~64 ~96 ~255 ~79 ~127 minecraft:air strict
fill ~224 ~48 ~96 ~255 ~63 ~127 minecraft:air strict
fill ~224 ~32 ~96 ~255 ~47 ~127 minecraft:air strict
fill ~224 ~16 ~96 ~255 ~31 ~127 minecraft:air strict
fill ~224 ~0 ~96 ~255 ~15 ~127 minecraft:air strict
fill ~224 ~80 ~128 ~255 ~95 ~159 minecraft:air strict
fill ~224 ~64 ~128 ~255 ~79 ~159 minecraft:air strict
fill ~224 ~48 ~128 ~255 ~63 ~159 minecraft:air strict
fill ~224 ~32 ~128 ~255 ~47 ~159 minecraft:air strict
fill ~224 ~16 ~128 ~255 ~31 ~159 minecraft:air strict
fill ~224 ~0 ~128 ~255 ~15 ~159 minecraft:air strict
fill ~224 ~80 ~160 ~255 ~95 ~191 minecraft:air strict
fill ~224 ~64 ~160 ~255 ~79 ~191 minecraft:air strict
fill ~224 ~48 ~160 ~255 ~63 ~191 minecraft:air strict
fill ~224 ~32 ~160 ~255 ~47 ~191 minecraft:air strict
fill ~224 ~16 ~160 ~255 ~31 ~191 minecraft:air strict
fill ~224 ~0 ~160 ~255 ~15 ~191 minecraft:air strict
fill ~224 ~80 ~192 ~255 ~95 ~223 minecraft:air strict
fill ~224 ~64 ~192 ~255 ~79 ~223 minecraft:air strict
fill ~224 ~48 ~192 ~255 ~63 ~223 minecraft:air strict
fill ~224 ~32 ~192 ~255 ~47 ~223 minecraft:air strict
fill ~224 ~16 ~192 ~255 ~31 ~223 minecraft:air strict
fill ~224 ~0 ~192 ~255 ~15 ~223 minecraft:air strict
fill ~224 ~80 ~224 ~255 ~95 ~255 minecraft:air strict
fill ~224 ~64 ~224 ~255 ~79 ~255 minecraft:air strict
fill ~224 ~48 ~224 ~255 ~63 ~255 minecraft:air strict
fill ~224 ~32 ~224 ~255 ~47 ~255 minecraft:air strict
fill ~224 ~16 ~224 ~255 ~31 ~255 minecraft:air strict
fill ~224 ~0 ~224 ~255 ~15 ~255 minecraft:air strict
fill ~63 ~10 ~173 ~64 ~11 ~174 minecraft:smooth_basalt strict
fill ~61 ~10 ~174 ~62 ~11 ~178 minecraft:smooth_basalt strict
fill ~59 ~10 ~175 ~60 ~11 ~176 minecraft:smooth_basalt strict
fill ~63 ~10 ~175 ~63 ~11 ~176 minecraft:smooth_basalt strict
fill ~60 ~10 ~177 ~60 ~11 ~178 minecraft:smooth_basalt strict
fill ~61 ~10 ~179 ~61 ~11 ~179 minecraft:smooth_basalt strict
fill ~79 ~10 ~182 ~80 ~13 ~185 minecraft:blackstone strict
fill ~78 ~10 ~183 ~78 ~13 ~184 minecraft:blackstone strict
fill ~53 ~10 ~185 ~56 ~10 ~192 minecraft:smooth_basalt strict
fill ~78 ~10 ~185 ~78 ~12 ~186 minecraft:basalt[axis=y] strict
fill ~79 ~10 ~186 ~79 ~11 ~186 minecraft:basalt[axis=y] strict
fill ~80 ~10 ~186 ~80 ~11 ~186 minecraft:blackstone strict
fill ~57 ~10 ~187 ~57 ~10 ~192 minecraft:smooth_basalt strict
fill ~58 ~10 ~191 ~58 ~10 ~192 minecraft:smooth_basalt strict
setblock ~59 ~10 ~192 minecraft:smooth_basalt strict
fill ~54 ~10 ~193 ~56 ~10 ~193 minecraft:smooth_basalt strict
fill ~64 ~10 ~198 ~64 ~11 ~201 minecraft:basalt[axis=y] strict
fill ~65 ~10 ~199 ~65 ~13 ~203 minecraft:basalt[axis=y] strict
fill ~63 ~10 ~200 ~63 ~13 ~202 minecraft:blackstone strict
fill ~66 ~10 ~200 ~68 ~13 ~203 minecraft:basalt[axis=y] strict
fill ~62 ~10 ~201 ~62 ~13 ~201 minecraft:blackstone strict
fill ~69 ~10 ~201 ~69 ~13 ~202 minecraft:basalt[axis=y] strict
fill ~64 ~10 ~202 ~64 ~10 ~203 minecraft:blackstone strict
fill ~71 ~11 ~171 ~72 ~14 ~173 minecraft:basalt[axis=y] strict
fill ~66 ~11 ~172 ~70 ~12 ~178 minecraft:blackstone strict
fill ~73 ~11 ~172 ~75 ~15 ~173 minecraft:basalt[axis=y] strict
fill ~65 ~11 ~173 ~65 ~14 ~181 minecraft:blackstone strict
fill ~76 ~11 ~173 ~76 ~12 ~181 minecraft:blackstone strict
fill ~71 ~11 ~174 ~71 ~12 ~178 minecraft:blackstone strict
setblock ~72 ~11 ~174 minecraft:basalt[axis=y] strict
fill ~73 ~11 ~174 ~73 ~11 ~180 minecraft:blackstone strict
setblock ~74 ~11 ~174 minecraft:basalt[axis=y] strict
fill ~75 ~11 ~174 ~75 ~14 ~180 minecraft:blackstone strict
fill ~64 ~11 ~175 ~64 ~11 ~181 minecraft:smooth_basalt strict
fill ~72 ~11 ~175 ~72 ~14 ~179 minecraft:blackstone strict
fill ~74 ~11 ~175 ~74 ~14 ~180 minecraft:blackstone strict
fill ~77 ~11 ~175 ~77 ~14 ~182 minecraft:blackstone strict
fill ~57 ~11 ~176 ~58 ~11 ~190 minecraft:smooth_basalt strict
fill ~78 ~11 ~176 ~78 ~14 ~182 minecraft:blackstone strict
fill ~55 ~11 ~177 ~56 ~11 ~191 minecraft:smooth_basalt strict
fill ~59 ~11 ~177 ~59 ~11 ~189 minecraft:smooth_basalt strict
fill ~63 ~11 ~177 ~63 ~11 ~181 minecraft:smooth_basalt strict
fill ~79 ~11 ~177 ~79 ~14 ~181 minecraft:blackstone strict
fill ~54 ~11 ~178 ~54 ~11 ~191 minecraft:smooth_basalt strict
fill ~80 ~11 ~178 ~80 ~11 ~181 minecraft:blackstone strict
fill ~60 ~11 ~179 ~60 ~11 ~182 minecraft:smooth_basalt strict
fill ~62 ~11 ~179 ~62 ~11 ~181 minecraft:smooth_basalt strict
fill ~66 ~11 ~179 ~69 ~14 ~179 minecraft:blackstone strict
fill ~81 ~11 ~179 ~81 ~14 ~179 minecraft:basalt[axis=y] strict
fill ~53 ~11 ~180 ~53 ~11 ~191 minecraft:smooth_basalt strict
fill ~61 ~11 ~180 ~61 ~11 ~181 minecraft:smooth_basalt strict
fill ~66 ~11 ~180 ~68 ~14 ~180 minecraft:blackstone strict
fill ~81 ~11 ~180 ~81 ~12 ~186 minecraft:blackstone strict
fill ~82 ~11 ~180 ~82 ~14 ~196 minecraft:basalt[axis=y] strict
fill ~66 ~11 ~181 ~67 ~14 ~181 minecraft:blackstone strict
fill ~73 ~11 ~181 ~75 ~12 ~181 minecraft:basalt[axis=y] strict
fill ~74 ~11 ~182 ~76 ~14 ~182 minecraft:basalt[axis=y] strict
fill ~83 ~11 ~182 ~83 ~12 ~195 minecraft:basalt[axis=y] strict
fill ~75 ~11 ~183 ~77 ~14 ~183 minecraft:basalt[axis=y] strict
fill ~76 ~11 ~184 ~77 ~14 ~186 minecraft:basalt[axis=y] strict
fill ~84 ~11 ~184 ~84 ~11 ~188 minecraft:basalt[axis=y] strict
fill ~60 ~11 ~185 ~60 ~11 ~189 minecraft:smooth_basalt strict
fill ~61 ~11 ~187 ~61 ~11 ~188 minecraft:smooth_basalt strict
fill ~77 ~11 ~187 ~81 ~12 ~197 minecraft:basalt[axis=y] strict
fill ~85 ~11 ~187 ~85 ~15 ~187 minecraft:basalt[axis=y] strict
fill ~52 ~11 ~188 ~52 ~11 ~191 minecraft:smooth_basalt strict
fill ~85 ~11 ~188 ~85 ~14 ~192 minecraft:blackstone strict
fill ~84 ~11 ~189 ~84 ~14 ~192 minecraft:blackstone strict
fill ~59 ~11 ~190 ~59 ~13 ~197 minecraft:basalt[axis=y] strict
fill ~60 ~11 ~190 ~60 ~15 ~190 minecraft:blackstone strict
fill ~76 ~11 ~190 ~76 ~14 ~199 minecraft:basalt[axis=y] strict
fill ~57 ~11 ~191 ~58 ~11 ~195 minecraft:basalt[axis=y] strict
fill ~60 ~11 ~191 ~60 ~14 ~198 minecraft:basalt[axis=y] strict
fill ~74 ~11 ~191 ~75 ~14 ~200 minecraft:basalt[axis=y] strict
fill ~52 ~11 ~192 ~56 ~13 ~192 minecraft:basalt[axis=y] strict
fill ~52 ~11 ~193 ~53 ~14 ~193 minecraft:blackstone strict
fill ~54 ~11 ~193 ~56 ~13 ~193 minecraft:basalt[axis=y] strict
setblock ~84 ~11 ~193 minecraft:basalt[axis=y] strict
fill ~53 ~11 ~194 ~56 ~12 ~195 minecraft:blackstone strict
fill ~61 ~11 ~194 ~61 ~14 ~198 minecraft:basalt[axis=y] strict
fill ~73 ~11 ~194 ~73 ~14 ~203 minecraft:basalt[axis=y] strict
fill ~72 ~11 ~195 ~72 ~14 ~203 minecraft:basalt[axis=y] strict
fill ~54 ~11 ~196 ~57 ~14 ~197 minecraft:blackstone strict
fill ~58 ~11 ~196 ~58 ~15 ~196 minecraft:basalt[axis=y] strict
fill ~62 ~11 ~196 ~66 ~14 ~197 minecraft:basalt[axis=y] strict
fill ~71 ~11 ~196 ~71 ~14 ~204 minecraft:basalt[axis=y] strict
fill ~58 ~11 ~197 ~58 ~14 ~201 minecraft:blackstone strict
fill ~67 ~11 ~197 ~67 ~11 ~199 minecraft:basalt[axis=y] strict
fill ~70 ~11 ~197 ~70 ~12 ~204 minecraft:basalt[axis=y] strict
fill ~55 ~11 ~198 ~57 ~14 ~198 minecraft:blackstone strict
fill ~59 ~11 ~198 ~59 ~14 ~202 minecraft:blackstone strict
fill ~62 ~11 ~198 ~63 ~14 ~199 minecraft:basalt[axis=y] strict
fill ~65 ~11 ~198 ~66 ~14 ~198 minecraft:basalt[axis=y] strict
fill ~68 ~11 ~198 ~69 ~14 ~199 minecraft:basalt[axis=y] strict
fill ~77 ~11 ~198 ~80 ~14 ~198 minecraft:basalt[axis=y] strict
fill ~56 ~11 ~199 ~57 ~14 ~200 minecraft:blackstone strict
fill ~60 ~11 ~199 ~61 ~14 ~202 minecraft:blackstone strict
fill ~66 ~11 ~199 ~66 ~15 ~199 minecraft:basalt[axis=y] strict
fill ~77 ~11 ~199 ~79 ~11 ~199 minecraft:basalt[axis=y] strict
setblock ~80 ~11 ~199 minecraft:blackstone strict
fill ~62 ~11 ~200 ~62 ~14 ~200 minecraft:blackstone strict
fill ~69 ~11 ~200 ~69 ~14 ~200 minecraft:basalt[axis=y] strict
fill ~76 ~11 ~200 ~79 ~12 ~200 minecraft:blackstone strict
fill ~74 ~11 ~201 ~74 ~13 ~202 minecraft:basalt[axis=y] strict
fill ~75 ~11 ~201 ~78 ~11 ~201 minecraft:blackstone strict
fill ~62 ~11 ~202 ~62 ~14 ~203 minecraft:blackstone strict
fill ~64 ~11 ~202 ~64 ~11 ~203 minecraft:basalt[axis=y] strict
fill ~75 ~11 ~202 ~75 ~14 ~202 minecraft:blackstone strict
fill ~63 ~11 ~203 ~63 ~14 ~203 minecraft:blackstone strict
fill ~69 ~11 ~203 ~69 ~14 ~205 minecraft:basalt[axis=y] strict
fill ~65 ~11 ~204 ~68 ~14 ~204 minecraft:basalt[axis=y] strict
fill ~67 ~11 ~205 ~68 ~15 ~205 minecraft:basalt[axis=y] strict
fill ~63 ~12 ~173 ~64 ~13 ~181 minecraft:blackstone strict
fill ~61 ~12 ~174 ~62 ~13 ~181 minecraft:blackstone strict
fill ~72 ~12 ~174 ~72 ~13 ~174 minecraft:blackstone strict
setblock ~73 ~12 ~174 minecraft:basalt[axis=y] strict
fill ~74 ~12 ~174 ~74 ~15 ~174 minecraft:blackstone strict
fill ~59 ~12 ~175 ~60 ~14 ~182 minecraft:blackstone strict
fill ~73 ~12 ~175 ~73 ~14 ~180 minecraft:blackstone strict
fill ~57 ~12 ~176 ~58 ~13 ~185 minecraft:blackstone strict
setblock ~55 ~12 ~177 minecraft:basalt[axis=y] strict
fill ~56 ~12 ~177 ~56 ~14 ~184 minecraft:blackstone strict
fill ~54 ~12 ~178 ~54 ~14 ~178 minecraft:basalt[axis=y] strict
fill ~55 ~12 ~178 ~55 ~14 ~184 minecraft:blackstone strict
setblock ~80 ~12 ~178 minecraft:basalt[axis=y] strict
fill ~54 ~12 ~179 ~54 ~12 ~185 minecraft:blackstone strict
fill ~80 ~12 ~179 ~80 ~14 ~181 minecraft:blackstone strict
fill ~53 ~12 ~180 ~53 ~13 ~185 minecraft:blackstone strict
fill ~59 ~12 ~183 ~59 ~14 ~189 minecraft:blackstone strict
fill ~84 ~12 ~184 ~84 ~14 ~187 minecraft:basalt[axis=y] strict
fill ~55 ~12 ~185 ~56 ~13 ~191 minecraft:basalt[axis=y] strict
fill ~60 ~12 ~185 ~60 ~14 ~189 minecraft:blackstone strict
fill ~53 ~12 ~186 ~54 ~14 ~191 minecraft:basalt[axis=y] strict
fill ~57 ~12 ~186 ~57 ~13 ~194 minecraft:basalt[axis=y] strict
fill ~58 ~12 ~186 ~58 ~15 ~186 minecraft:blackstone strict
setblock ~79 ~12 ~186 minecraft:blackstone strict
setblock ~80 ~12 ~186 minecraft:basalt[axis=y] strict
fill ~58 ~12 ~187 ~58 ~12 ~195 minecraft:basalt[axis=y] strict
fill ~61 ~12 ~187 ~61 ~14 ~188 minecraft:blackstone strict
fill ~52 ~12 ~188 ~52 ~14 ~191 minecraft:basalt[axis=y] strict
setblock ~84 ~12 ~188 minecraft:blackstone strict
fill ~84 ~12 ~193 ~84 ~14 ~193 minecraft:blackstone strict
fill ~57 ~12 ~195 ~57 ~13 ~195 minecraft:blackstone strict
fill ~67 ~12 ~197 ~67 ~13 ~197 minecraft:blackstone strict
fill ~64 ~12 ~198 ~64 ~14 ~200 minecraft:basalt[axis=y] strict
fill ~67 ~12 ~198 ~67 ~14 ~199 minecraft:basalt[axis=y] strict
fill ~77 ~12 ~199 ~78 ~12 ~199 minecraft:basalt[axis=y] strict
setblock ~79 ~12 ~199 minecraft:blackstone strict
setblock ~80 ~12 ~199 minecraft:basalt[axis=y] strict
fill ~64 ~12 ~201 ~64 ~12 ~203 minecraft:blackstone strict
setblock ~75 ~12 ~201 minecraft:basalt[axis=y] strict
fill ~76 ~12 ~201 ~78 ~14 ~201 minecraft:blackstone strict
fill ~62 ~13 ~172 ~70 ~14 ~172 minecraft:blackstone strict
fill ~60 ~13 ~173 ~62 ~17 ~173 minecraft:blackstone strict
fill ~66 ~13 ~173 ~70 ~14 ~174 minecraft:blackstone strict
setblock ~76 ~13 ~173 minecraft:basalt[axis=y] strict
fill ~58 ~13 ~174 ~60 ~17 ~174 minecraft:blackstone strict
setblock ~71 ~13 ~174 minecraft:basalt[axis=y] strict
fill ~73 ~13 ~174 ~73 ~14 ~174 minecraft:blackstone strict
fill ~76 ~13 ~174 ~76 ~14 ~181 minecraft:blackstone strict
fill ~58 ~13 ~175 ~58 ~17 ~175 minecraft:blackstone strict
fill ~66 ~13 ~175 ~68 ~28 ~175 minecraft:cracked_polished_blackstone_bricks strict
fill ~69 ~13 ~175 ~70 ~28 ~175 minecraft:polished_blackstone_bricks strict
fill ~71 ~13 ~175 ~71 ~14 ~178 minecraft:blackstone strict
fill ~66 ~13 ~176 ~66 ~28 ~176 minecraft:cracked_polished_blackstone_bricks strict
fill ~67 ~13 ~176 ~69 ~28 ~176 minecraft:polished_blackstone_bricks strict
fill ~70 ~13 ~176 ~70 ~28 ~177 minecraft:cracked_polished_blackstone_bricks strict
fill ~55 ~13 ~177 ~55 ~14 ~177 minecraft:blackstone strict
fill ~66 ~13 ~177 ~67 ~28 ~177 minecraft:polished_blackstone_bricks strict
fill ~68 ~13 ~177 ~68 ~28 ~177 minecraft:cracked_polished_blackstone_bricks strict
fill ~69 ~13 ~177 ~69 ~28 ~177 minecraft:polished_blackstone_bricks strict
fill ~66 ~13 ~178 ~70 ~14 ~178 minecraft:blackstone strict
setblock ~80 ~13 ~178 minecraft:blackstone strict
fill ~54 ~13 ~179 ~54 ~14 ~184 minecraft:blackstone strict
setblock ~81 ~13 ~180 minecraft:basalt[axis=y] strict
fill ~73 ~13 ~181 ~74 ~15 ~181 minecraft:basalt[axis=y] strict
setblock ~75 ~13 ~181 minecraft:blackstone strict
fill ~81 ~13 ~181 ~81 ~14 ~185 minecraft:blackstone strict
fill ~83 ~13 ~182 ~83 ~14 ~188 minecraft:basalt[axis=y] strict
fill ~52 ~13 ~184 ~52 ~13 ~186 minecraft:blackstone strict
fill ~54 ~13 ~185 ~54 ~14 ~185 minecraft:basalt[axis=y] strict
setblock ~78 ~13 ~185 minecraft:blackstone strict
fill ~78 ~13 ~186 ~78 ~13 ~197 minecraft:basalt[axis=y] strict
fill ~79 ~13 ~186 ~80 ~28 ~187 minecraft:polished_blackstone_bricks strict
fill ~81 ~13 ~186 ~81 ~28 ~186 minecraft:cracked_polished_blackstone_bricks strict
fill ~52 ~13 ~187 ~52 ~23 ~187 minecraft:basalt[axis=y] strict
setblock ~58 ~13 ~187 minecraft:blackstone strict
fill ~77 ~13 ~187 ~77 ~14 ~197 minecraft:basalt[axis=y] strict
fill ~81 ~13 ~187 ~81 ~29 ~188 minecraft:polished_blackstone_bricks strict
fill ~58 ~13 ~188 ~58 ~14 ~195 minecraft:basalt[axis=y] strict
fill ~79 ~13 ~188 ~79 ~28 ~188 minecraft:polished_blackstone_bricks strict
fill ~80 ~13 ~188 ~80 ~29 ~188 minecraft:cracked_polished_blackstone_bricks strict
setblock ~84 ~13 ~188 minecraft:basalt[axis=y] strict
fill ~79 ~13 ~189 ~79 ~28 ~190 minecraft:cracked_polished_blackstone_bricks strict
fill ~80 ~13 ~189 ~80 ~28 ~189 minecraft:polished_blackstone_bricks strict
fill ~81 ~13 ~189 ~81 ~28 ~190 minecraft:cracked_polished_blackstone_bricks strict
fill ~83 ~13 ~189 ~83 ~13 ~190 minecraft:blackstone strict
fill ~80 ~13 ~190 ~80 ~28 ~190 minecraft:cracked_polished_blackstone_bricks strict
fill ~79 ~13 ~191 ~81 ~14 ~197 minecraft:basalt[axis=y] strict
fill ~83 ~13 ~191 ~83 ~14 ~195 minecraft:basalt[axis=y] strict
fill ~53 ~13 ~194 ~55 ~14 ~195 minecraft:blackstone strict
setblock ~56 ~13 ~194 minecraft:basalt[axis=y] strict
fill ~56 ~13 ~195 ~56 ~15 ~195 minecraft:blackstone strict
setblock ~70 ~13 ~197 minecraft:blackstone strict
fill ~70 ~13 ~198 ~70 ~14 ~204 minecraft:basalt[axis=y] strict
fill ~77 ~13 ~199 ~77 ~15 ~199 minecraft:basalt[axis=y] strict
fill ~78 ~13 ~199 ~78 ~13 ~200 minecraft:blackstone strict
setblock ~79 ~13 ~199 minecraft:basalt[axis=y] strict
fill ~80 ~13 ~199 ~80 ~14 ~199 minecraft:blackstone strict
setblock ~76 ~13 ~200 minecraft:basalt[axis=y] strict
fill ~77 ~13 ~200 ~77 ~15 ~200 minecraft:blackstone strict
fill ~79 ~13 ~200 ~79 ~14 ~200 minecraft:blackstone strict
fill ~64 ~13 ~201 ~64 ~13 ~204 minecraft:basalt[axis=y] strict
fill ~75 ~13 ~201 ~75 ~15 ~201 minecraft:blackstone strict
fill ~63 ~13 ~204 ~63 ~14 ~204 minecraft:blackstone strict
fill ~59 ~14 ~69 ~63 ~15 ~75 minecraft:blackstone strict
fill ~58 ~14 ~70 ~58 ~16 ~75 minecraft:blackstone strict
fill ~64 ~14 ~70 ~64 ~16 ~78 minecraft:blackstone strict
fill ~57 ~14 ~71 ~57 ~16 ~76 minecraft:blackstone strict
fill ~65 ~14 ~71 ~65 ~16 ~77 minecraft:blackstone strict
fill ~56 ~14 ~72 ~56 ~17 ~76 minecraft:blackstone strict
fill ~66 ~14 ~72 ~66 ~16 ~76 minecraft:blackstone strict
fill ~58 ~14 ~76 ~60 ~14 ~78 minecraft:basalt[axis=y] strict
fill ~61 ~14 ~76 ~63 ~16 ~76 minecraft:blackstone strict
setblock ~57 ~14 ~77 minecraft:basalt[axis=y] strict
fill ~61 ~14 ~77 ~62 ~14 ~79 minecraft:basalt[axis=y] strict
fill ~63 ~14 ~77 ~63 ~16 ~79 minecraft:blackstone strict
fill ~59 ~14 ~79 ~60 ~14 ~79 minecraft:basalt[axis=y] strict
fill ~70 ~14 ~170 ~71 ~15 ~170 minecraft:blackstone strict
fill ~72 ~14 ~170 ~73 ~21 ~170 minecraft:basalt[axis=y] strict
fill ~65 ~14 ~171 ~70 ~16 ~171 minecraft:blackstone strict
fill ~73 ~14 ~171 ~75 ~21 ~171 minecraft:basalt[axis=y] strict
setblock ~76 ~14 ~171 minecraft:blackstone strict
fill ~76 ~14 ~172 ~76 ~20 ~172 minecraft:basalt[axis=y] strict
fill ~77 ~14 ~172 ~77 ~15 ~174 minecraft:blackstone strict
fill ~63 ~14 ~173 ~64 ~14 ~173 minecraft:gravel strict
setblock ~76 ~14 ~173 minecraft:blackstone strict
setblock ~61 ~14 ~174 minecraft:blackstone strict
fill ~62 ~14 ~174 ~62 ~14 ~175 minecraft:gravel strict
fill ~63 ~14 ~174 ~64 ~14 ~174 minecraft:blackstone strict
fill ~71 ~14 ~174 ~71 ~15 ~174 minecraft:blackstone strict
setblock ~72 ~14 ~174 minecraft:basalt[axis=y] strict
fill ~78 ~14 ~174 ~78 ~14 ~175 minecraft:blackstone strict
fill ~56 ~14 ~175 ~57 ~14 ~176 minecraft:blackstone strict
fill ~61 ~14 ~175 ~61 ~14 ~177 minecraft:basalt[axis=y] strict
fill ~63 ~14 ~175 ~63 ~14 ~176 minecraft:gravel strict
fill ~64 ~14 ~175 ~64 ~14 ~182 minecraft:blackstone strict
fill ~79 ~14 ~175 ~79 ~14 ~176 minecraft:blackstone strict
fill ~54 ~14 ~176 ~55 ~14 ~176 minecraft:basalt[axis=y] strict
fill ~58 ~14 ~176 ~58 ~14 ~185 minecraft:blackstone strict
setblock ~62 ~14 ~176 minecraft:blackstone strict
setblock ~80 ~14 ~176 minecraft:blackstone strict
fill ~53 ~14 ~177 ~54 ~23 ~177 minecraft:basalt[axis=y] strict
fill ~57 ~14 ~177 ~57 ~14 ~184 minecraft:blackstone strict
fill ~62 ~14 ~177 ~62 ~14 ~178 minecraft:basalt[axis=y] strict
fill ~63 ~14 ~177 ~63 ~14 ~182 minecraft:blackstone strict
fill ~80 ~14 ~177 ~81 ~14 ~178 minecraft:basalt[axis=y] strict
fill ~53 ~14 ~178 ~53 ~23 ~179 minecraft:basalt[axis=y] strict
setblock ~61 ~14 ~178 minecraft:gravel strict
fill ~82 ~14 ~178 ~82 ~20 ~179 minecraft:basalt[axis=y] strict
fill ~52 ~14 ~179 ~52 ~14 ~180 minecraft:basalt[axis=y] strict
setblock ~61 ~14 ~179 minecraft:basalt[axis=y] strict
fill ~62 ~14 ~179 ~62 ~14 ~182 minecraft:blackstone strict
fill ~70 ~14 ~179 ~71 ~15 ~180 minecraft:blackstone strict
fill ~83 ~14 ~179 ~83 ~20 ~181 minecraft:basalt[axis=y] strict
fill ~53 ~14 ~180 ~53 ~14 ~184 minecraft:blackstone strict
fill ~61 ~14 ~180 ~61 ~14 ~186 minecraft:blackstone strict
fill ~69 ~14 ~180 ~69 ~16 ~181 minecraft:blackstone strict
fill ~72 ~14 ~180 ~72 ~15 ~180 minecraft:blackstone strict
setblock ~81 ~14 ~180 minecraft:blackstone strict
fill ~52 ~14 ~181 ~52 ~17 ~185 minecraft:blackstone strict
fill ~68 ~14 ~181 ~68 ~16 ~182 minecraft:blackstone strict
fill ~72 ~14 ~181 ~72 ~14 ~182 minecraft:basalt[axis=y] strict
setblock ~75 ~14 ~181 minecraft:basalt[axis=y] strict
fill ~84 ~14 ~181 ~84 ~20 ~183 minecraft:basalt[axis=y] strict
fill ~65 ~14 ~182 ~67 ~16 ~182 minecraft:blackstone strict
fill ~73 ~14 ~182 ~73 ~21 ~183 minecraft:basalt[axis=y] strict
fill ~79 ~14 ~182 ~79 ~14 ~183 minecraft:basalt[axis=y] strict
fill ~80 ~14 ~182 ~80 ~14 ~185 minecraft:gravel strict
fill ~60 ~14 ~183 ~60 ~17 ~184 minecraft:blackstone strict
fill ~74 ~14 ~183 ~74 ~20 ~184 minecraft:basalt[axis=y] strict
fill ~78 ~14 ~183 ~78 ~14 ~184 minecraft:gravel strict
fill ~85 ~14 ~183 ~85 ~20 ~186 minecraft:basalt[axis=y] strict
fill ~75 ~14 ~184 ~75 ~20 ~187 minecraft:basalt[axis=y] strict
setblock ~79 ~14 ~184 minecraft:gravel strict
setblock ~53 ~14 ~185 minecraft:gravel strict
fill ~55 ~14 ~185 ~56 ~14 ~185 minecraft:gravel strict
fill ~57 ~14 ~185 ~57 ~14 ~188 minecraft:basalt[axis=y] strict
setblock ~78 ~14 ~185 minecraft:basalt[axis=y] strict
setblock ~79 ~14 ~185 minecraft:blackstone strict
setblock ~52 ~14 ~186 minecraft:basalt[axis=y] strict
fill ~55 ~14 ~186 ~56 ~14 ~186 minecraft:basalt[axis=y] strict
fill ~62 ~14 ~186 ~62 ~16 ~189 minecraft:blackstone strict
setblock ~78 ~14 ~186 minecraft:gravel strict
fill ~86 ~14 ~186 ~86 ~20 ~187 minecraft:basalt[axis=y] strict
fill ~51 ~14 ~187 ~51 ~17 ~187 minecraft:blackstone strict
setblock ~55 ~14 ~187 minecraft:gravel strict
setblock ~56 ~14 ~187 minecraft:basalt[axis=y] strict
fill ~58 ~14 ~187 ~58 ~15 ~187 minecraft:basalt[axis=y] strict
fill ~76 ~14 ~187 ~76 ~20 ~189 minecraft:basalt[axis=y] strict
fill ~78 ~14 ~187 ~78 ~14 ~197 minecraft:basalt[axis=y] strict
fill ~51 ~14 ~188 ~51 ~18 ~191 minecraft:basalt[axis=y] strict
setblock ~55 ~14 ~188 minecraft:basalt[axis=y] strict
setblock ~56 ~14 ~188 minecraft:gravel strict
setblock ~84 ~14 ~188 minecraft:blackstone strict
fill ~86 ~14 ~188 ~86 ~14 ~193 minecraft:blackstone strict
fill ~55 ~14 ~189 ~55 ~14 ~192 minecraft:gravel strict
setblock ~56 ~14 ~189 minecraft:basalt[axis=y] strict
fill ~57 ~14 ~189 ~57 ~14 ~190 minecraft:gravel strict
fill ~61 ~14 ~189 ~61 ~16 ~190 minecraft:blackstone strict
fill ~75 ~14 ~189 ~75 ~20 ~190 minecraft:basalt[axis=y] strict
fill ~83 ~14 ~189 ~83 ~14 ~190 minecraft:basalt[axis=y] strict
fill ~56 ~14 ~190 ~56 ~14 ~191 minecraft:gravel strict
setblock ~59 ~14 ~190 minecraft:blackstone strict
fill ~73 ~14 ~190 ~74 ~21 ~190 minecraft:basalt[axis=y] strict
setblock ~57 ~14 ~191 minecraft:basalt[axis=y] strict
