fill ~11 ~58 ~202 ~13 ~63 ~202 minecraft:basalt[axis=y] strict
fill ~253 ~58 ~202 ~253 ~58 ~203 minecraft:basalt[axis=y] strict
setblock ~255 ~58 ~202 minecraft:magma_block strict
fill ~5 ~58 ~203 ~5 ~59 ~203 minecraft:polished_deepslate strict
fill ~11 ~58 ~203 ~12 ~59 ~203 minecraft:polished_deepslate strict
setblock ~255 ~58 ~203 minecraft:smooth_basalt strict
fill ~7 ~58 ~205 ~8 ~58 ~206 minecraft:blackstone strict
fill ~1 ~58 ~206 ~1 ~58 ~212 minecraft:basalt[axis=y] strict
fill ~3 ~58 ~206 ~6 ~59 ~206 minecraft:blackstone strict
fill ~9 ~58 ~206 ~10 ~59 ~206 minecraft:blackstone strict
fill ~0 ~58 ~207 ~0 ~58 ~211 minecraft:basalt[axis=y] strict
fill ~2 ~58 ~208 ~9 ~61 ~208 minecraft:basalt[axis=y] strict
fill ~2 ~58 ~209 ~8 ~59 ~210 minecraft:blackstone strict
fill ~2 ~58 ~211 ~2 ~60 ~213 minecraft:basalt[axis=y] strict
fill ~3 ~58 ~211 ~6 ~59 ~211 minecraft:blackstone strict
fill ~7 ~58 ~211 ~7 ~59 ~211 minecraft:basalt[axis=y] strict
setblock ~248 ~58 ~211 minecraft:nether_wart_block strict
fill ~3 ~58 ~212 ~4 ~59 ~214 minecraft:basalt[axis=y] strict
setblock ~251 ~58 ~212 minecraft:nether_wart_block strict
setblock ~246 ~58 ~213 minecraft:nether_wart_block strict
setblock ~252 ~58 ~214 minecraft:nether_wart_block strict
setblock ~4 ~58 ~215 minecraft:basalt[axis=y] strict
setblock ~246 ~58 ~215 minecraft:nether_wart_block strict
setblock ~6 ~58 ~216 minecraft:magma_block strict
setblock ~251 ~58 ~216 minecraft:nether_wart_block strict
setblock ~248 ~58 ~217 minecraft:nether_wart_block strict
setblock ~202 ~58 ~233 minecraft:nether_wart_block strict
setblock ~199 ~58 ~234 minecraft:nether_wart_block strict
setblock ~205 ~58 ~235 minecraft:nether_wart_block strict
fill ~202 ~58 ~237 ~202 ~59 ~237 minecraft:crimson_stem[axis=y] strict
setblock ~198 ~58 ~238 minecraft:nether_wart_block strict
setblock ~206 ~58 ~238 minecraft:nether_wart_block strict
fill ~200 ~58 ~240 ~200 ~59 ~240 minecraft:nether_wart_block strict
fill ~216 ~58 ~251 ~216 ~60 ~251 minecraft:crimson_stem[axis=y] strict
fill ~100 ~58 ~254 ~100 ~58 ~255 minecraft:blackstone strict
setblock ~101 ~58 ~254 minecraft:basalt[axis=y] strict
setblock ~102 ~58 ~254 minecraft:smooth_basalt strict
fill ~98 ~58 ~255 ~99 ~58 ~255 minecraft:smooth_basalt strict
setblock ~101 ~58 ~255 minecraft:blackstone strict
fill ~104 ~58 ~255 ~105 ~58 ~255 minecraft:magma_block strict
setblock ~106 ~58 ~255 minecraft:tuff strict
fill ~35 ~59 ~0 ~38 ~59 ~1 minecraft:smooth_basalt strict
fill ~181 ~59 ~0 ~187 ~59 ~1 minecraft:smooth_basalt strict
fill ~188 ~59 ~0 ~188 ~59 ~3 minecraft:crimson_nylium strict
setblock ~34 ~59 ~1 minecraft:smooth_basalt strict
fill ~45 ~59 ~1 ~46 ~59 ~1 minecraft:basalt[axis=y] strict
fill ~189 ~59 ~1 ~189 ~59 ~3 minecraft:crimson_nylium strict
fill ~30 ~59 ~2 ~31 ~59 ~2 minecraft:blackstone strict
fill ~32 ~59 ~2 ~33 ~59 ~3 minecraft:smooth_basalt strict
setblock ~34 ~59 ~2 minecraft:magma_block strict
fill ~35 ~59 ~2 ~36 ~59 ~2 minecraft:blackstone strict
fill ~38 ~59 ~2 ~38 ~59 ~3 minecraft:smooth_basalt strict
fill ~43 ~59 ~2 ~44 ~59 ~2 minecraft:basalt[axis=y] strict
fill ~45 ~59 ~2 ~45 ~61 ~2 minecraft:blackstone strict
fill ~180 ~59 ~2 ~185 ~59 ~2 minecraft:smooth_basalt strict
fill ~186 ~59 ~2 ~187 ~59 ~2 minecraft:magma_block strict
fill ~190 ~59 ~2 ~191 ~59 ~2 minecraft:crimson_nylium strict
fill ~24 ~59 ~3 ~25 ~59 ~3 minecraft:basalt[axis=y] strict
setblock ~34 ~59 ~3 minecraft:smooth_basalt strict
setblock ~35 ~59 ~3 minecraft:magma_block strict
setblock ~36 ~59 ~3 minecraft:blackstone strict
fill ~42 ~59 ~3 ~43 ~59 ~3 minecraft:basalt[axis=y] strict
fill ~46 ~59 ~3 ~46 ~59 ~6 minecraft:blackstone strict
fill ~47 ~59 ~3 ~50 ~61 ~9 minecraft:basalt[axis=y] strict
setblock ~187 ~59 ~3 minecraft:smooth_basalt strict
setblock ~190 ~59 ~3 minecraft:crimson_nylium strict
setblock ~191 ~59 ~3 minecraft:basalt[axis=y] strict
fill ~45 ~59 ~4 ~45 ~61 ~7 minecraft:blackstone strict
fill ~51 ~59 ~4 ~51 ~61 ~11 minecraft:basalt[axis=y] strict
fill ~42 ~59 ~5 ~42 ~61 ~5 minecraft:blackstone strict
fill ~44 ~59 ~5 ~44 ~61 ~11 minecraft:blackstone strict
fill ~52 ~59 ~5 ~52 ~61 ~11 minecraft:basalt[axis=y] strict
fill ~43 ~59 ~6 ~43 ~61 ~10 minecraft:blackstone strict
fill ~53 ~59 ~6 ~53 ~61 ~10 minecraft:basalt[axis=y] strict
fill ~46 ~59 ~7 ~46 ~61 ~8 minecraft:basalt[axis=y] strict
fill ~45 ~59 ~8 ~45 ~61 ~8 minecraft:basalt[axis=y] strict
fill ~45 ~59 ~9 ~46 ~61 ~12 minecraft:blackstone strict
fill ~47 ~59 ~10 ~48 ~61 ~13 minecraft:blackstone strict
fill ~49 ~59 ~10 ~50 ~61 ~10 minecraft:basalt[axis=y] strict
fill ~41 ~59 ~11 ~42 ~61 ~11 minecraft:blackstone strict
fill ~49 ~59 ~11 ~49 ~61 ~13 minecraft:blackstone strict
fill ~50 ~59 ~11 ~50 ~61 ~11 minecraft:basalt[axis=y] strict
fill ~42 ~59 ~12 ~42 ~61 ~13 minecraft:blackstone strict
fill ~50 ~59 ~12 ~51 ~61 ~12 minecraft:blackstone strict
fill ~43 ~59 ~13 ~43 ~61 ~14 minecraft:blackstone strict
fill ~46 ~59 ~13 ~46 ~61 ~13 minecraft:blackstone strict
fill ~50 ~59 ~13 ~50 ~61 ~13 minecraft:blackstone strict
fill ~54 ~59 ~13 ~54 ~60 ~13 minecraft:blackstone strict
fill ~44 ~59 ~14 ~45 ~61 ~14 minecraft:blackstone strict
fill ~51 ~59 ~14 ~52 ~61 ~14 minecraft:blackstone strict
fill ~45 ~59 ~15 ~51 ~61 ~15 minecraft:blackstone strict
setblock ~112 ~59 ~17 minecraft:red_wool strict
fill ~113 ~59 ~18 ~114 ~59 ~18 minecraft:red_wool strict
fill ~248 ~59 ~41 ~250 ~61 ~41 minecraft:basalt[axis=y] strict
fill ~250 ~59 ~42 ~252 ~61 ~42 minecraft:basalt[axis=y] strict
fill ~252 ~59 ~43 ~252 ~61 ~43 minecraft:basalt[axis=y] strict
fill ~252 ~59 ~53 ~252 ~61 ~54 minecraft:basalt[axis=y] strict
fill ~243 ~59 ~54 ~244 ~60 ~54 minecraft:basalt[axis=y] strict
fill ~250 ~59 ~54 ~251 ~61 ~54 minecraft:basalt[axis=y] strict
fill ~244 ~59 ~55 ~244 ~60 ~55 minecraft:basalt[axis=y] strict
fill ~248 ~59 ~55 ~250 ~61 ~55 minecraft:basalt[axis=y] strict
setblock ~239 ~59 ~112 minecraft:blue_wool strict
fill ~238 ~59 ~113 ~238 ~59 ~114 minecraft:blue_wool strict
setblock ~255 ~59 ~139 minecraft:netherrack strict
fill ~255 ~59 ~140 ~255 ~59 ~142 minecraft:tuff strict
fill ~18 ~59 ~142 ~18 ~59 ~143 minecraft:yellow_wool strict
setblock ~17 ~59 ~144 minecraft:yellow_wool strict
fill ~0 ~59 ~159 ~1 ~59 ~159 minecraft:tuff strict
fill ~0 ~59 ~160 ~2 ~59 ~160 minecraft:magma_block strict
fill ~0 ~59 ~161 ~1 ~59 ~161 minecraft:blackstone strict
setblock ~2 ~59 ~161 minecraft:smooth_basalt strict
fill ~2 ~59 ~162 ~2 ~60 ~164 minecraft:basalt[axis=y] strict
setblock ~7 ~59 ~200 minecraft:magma_block strict
setblock ~8 ~59 ~200 minecraft:basalt[axis=y] strict
fill ~4 ~59 ~205 ~5 ~63 ~205 minecraft:basalt[axis=y] strict
setblock ~6 ~59 ~205 minecraft:blackstone strict
fill ~7 ~59 ~205 ~7 ~61 ~205 minecraft:basalt[axis=y] strict
fill ~8 ~59 ~205 ~8 ~59 ~206 minecraft:blackstone strict
fill ~1 ~59 ~206 ~1 ~60 ~211 minecraft:basalt[axis=y] strict
setblock ~7 ~59 ~206 minecraft:blackstone strict
fill ~0 ~59 ~207 ~0 ~59 ~210 minecraft:basalt[axis=y] strict
fill ~249 ~59 ~212 ~250 ~59 ~216 minecraft:nether_wart_block strict
setblock ~247 ~59 ~213 minecraft:nether_wart_block strict
setblock ~248 ~59 ~214 minecraft:nether_wart_block strict
setblock ~251 ~59 ~214 minecraft:nether_wart_block strict
setblock ~247 ~59 ~215 minecraft:nether_wart_block strict
setblock ~202 ~59 ~234 minecraft:nether_wart_block strict
setblock ~200 ~59 ~235 minecraft:nether_wart_block strict
setblock ~204 ~59 ~235 minecraft:nether_wart_block strict
setblock ~199 ~59 ~237 minecraft:nether_wart_block strict
fill ~142 ~59 ~238 ~143 ~59 ~238 minecraft:lime_wool strict
setblock ~205 ~59 ~238 minecraft:nether_wart_block strict
setblock ~144 ~59 ~239 minecraft:lime_wool strict
setblock ~203 ~59 ~240 minecraft:nether_wart_block strict
fill ~206 ~59 ~242 ~210 ~61 ~244 minecraft:red_sandstone strict
fill ~205 ~59 ~243 ~205 ~61 ~244 minecraft:red_sandstone strict
fill ~211 ~59 ~243 ~211 ~61 ~247 minecraft:red_sandstone strict
fill ~204 ~59 ~244 ~204 ~61 ~250 minecraft:basalt[axis=y] strict
fill ~212 ~59 ~244 ~212 ~61 ~248 minecraft:red_sandstone strict
fill ~203 ~59 ~245 ~203 ~61 ~249 minecraft:basalt[axis=y] strict
fill ~205 ~59 ~245 ~205 ~59 ~246 minecraft:basalt[axis=y] strict
fill ~206 ~59 ~245 ~206 ~61 ~252 minecraft:blackstone strict
fill ~207 ~59 ~245 ~210 ~61 ~245 minecraft:red_sandstone strict
fill ~213 ~59 ~245 ~213 ~62 ~248 minecraft:red_sandstone strict
fill ~207 ~59 ~246 ~207 ~61 ~252 minecraft:blackstone strict
fill ~208 ~59 ~246 ~210 ~61 ~246 minecraft:red_sandstone strict
fill ~205 ~59 ~247 ~205 ~61 ~251 minecraft:blackstone strict
fill ~208 ~59 ~247 ~209 ~61 ~252 minecraft:blackstone strict
fill ~210 ~59 ~247 ~210 ~61 ~247 minecraft:red_sandstone strict
fill ~210 ~59 ~248 ~211 ~61 ~251 minecraft:blackstone strict
fill ~212 ~59 ~249 ~212 ~61 ~250 minecraft:blackstone strict
setblock ~213 ~59 ~249 minecraft:basalt[axis=y] strict
fill ~210 ~59 ~252 ~210 ~61 ~252 minecraft:blackstone strict
fill ~205 ~59 ~253 ~205 ~61 ~253 minecraft:blackstone strict
fill ~211 ~59 ~253 ~212 ~61 ~253 minecraft:blackstone strict
setblock ~205 ~59 ~254 minecraft:basalt[axis=y] strict
fill ~206 ~59 ~254 ~211 ~61 ~254 minecraft:blackstone strict
fill ~100 ~59 ~255 ~102 ~59 ~255 minecraft:smooth_basalt strict
setblock ~103 ~59 ~255 minecraft:magma_block strict
fill ~45 ~60 ~1 ~46 ~62 ~1 minecraft:blackstone strict
fill ~35 ~60 ~2 ~37 ~60 ~2 minecraft:smooth_basalt strict
fill ~43 ~60 ~2 ~44 ~62 ~2 minecraft:blackstone strict
fill ~36 ~60 ~3 ~37 ~60 ~3 minecraft:smooth_basalt strict
fill ~42 ~60 ~3 ~43 ~62 ~3 minecraft:blackstone strict
fill ~46 ~60 ~3 ~46 ~61 ~5 minecraft:blackstone strict
fill ~42 ~60 ~4 ~42 ~62 ~4 minecraft:blackstone strict
fill ~41 ~60 ~5 ~41 ~62 ~6 minecraft:blackstone strict
setblock ~46 ~60 ~6 minecraft:basalt[axis=y] strict
setblock ~55 ~60 ~11 minecraft:blackstone strict
fill ~242 ~60 ~42 ~243 ~62 ~42 minecraft:smooth_basalt strict
fill ~241 ~60 ~43 ~242 ~62 ~43 minecraft:smooth_basalt strict
fill ~253 ~60 ~43 ~253 ~62 ~45 minecraft:basalt[axis=y] strict
fill ~241 ~60 ~44 ~241 ~62 ~45 minecraft:smooth_basalt strict
fill ~240 ~60 ~45 ~240 ~62 ~51 minecraft:smooth_basalt strict
fill ~254 ~60 ~45 ~254 ~62 ~51 minecraft:basalt[axis=y] strict
fill ~241 ~60 ~51 ~241 ~62 ~53 minecraft:smooth_basalt strict
fill ~253 ~60 ~51 ~253 ~62 ~53 minecraft:basalt[axis=y] strict
fill ~242 ~60 ~53 ~242 ~62 ~53 minecraft:smooth_basalt strict
fill ~242 ~60 ~54 ~242 ~62 ~54 minecraft:blackstone strict
fill ~0 ~60 ~161 ~1 ~60 ~162 minecraft:smooth_basalt strict
fill ~0 ~60 ~163 ~1 ~60 ~165 minecraft:blackstone strict
fill ~6 ~60 ~202 ~10 ~63 ~203 minecraft:basalt[axis=y] strict
fill ~5 ~60 ~203 ~5 ~65 ~203 minecraft:basalt[axis=y] strict
fill ~11 ~60 ~203 ~12 ~65 ~203 minecraft:basalt[axis=y] strict
fill ~6 ~60 ~205 ~6 ~61 ~206 minecraft:basalt[axis=y] strict
fill ~8 ~60 ~205 ~11 ~61 ~205 minecraft:basalt[axis=y] strict
fill ~3 ~60 ~206 ~5 ~61 ~206 minecraft:basalt[axis=y] strict
fill ~7 ~60 ~206 ~10 ~61 ~206 minecraft:basalt[axis=y] strict
fill ~2 ~60 ~209 ~8 ~61 ~210 minecraft:basalt[axis=y] strict
fill ~3 ~60 ~211 ~7 ~61 ~212 minecraft:polished_deepslate strict
fill ~3 ~60 ~213 ~3 ~60 ~214 minecraft:basalt[axis=y] strict
fill ~4 ~60 ~213 ~6 ~61 ~213 minecraft:polished_deepslate strict
fill ~4 ~60 ~214 ~5 ~63 ~214 minecraft:basalt[axis=y] strict
fill ~6 ~60 ~214 ~6 ~61 ~214 minecraft:polished_deepslate strict
fill ~5 ~60 ~215 ~6 ~62 ~215 minecraft:basalt[axis=y] strict
fill ~202 ~60 ~235 ~202 ~60 ~238 minecraft:nether_wart_block strict
fill ~201 ~60 ~236 ~201 ~60 ~239 minecraft:nether_wart_block strict
fill ~203 ~60 ~236 ~204 ~60 ~236 minecraft:nether_wart_block strict
setblock ~200 ~60 ~237 minecraft:nether_wart_block strict
setblock ~203 ~60 ~237 minecraft:nether_wart_block strict
setblock ~204 ~60 ~238 minecraft:nether_wart_block strict
setblock ~203 ~60 ~239 minecraft:nether_wart_block strict
fill ~205 ~60 ~245 ~205 ~61 ~245 minecraft:basalt[axis=y] strict
fill ~205 ~60 ~246 ~205 ~61 ~246 minecraft:blackstone strict
setblock ~214 ~60 ~246 minecraft:nether_wart_block strict
setblock ~218 ~60 ~247 minecraft:nether_wart_block strict
fill ~213 ~60 ~249 ~213 ~62 ~249 minecraft:blackstone strict
fill ~214 ~60 ~250 ~215 ~60 ~250 minecraft:blackstone strict
setblock ~219 ~60 ~250 minecraft:nether_wart_block strict
fill ~214 ~60 ~251 ~214 ~62 ~252 minecraft:blackstone strict
setblock ~211 ~60 ~252 minecraft:nether_wart_block strict
fill ~213 ~60 ~252 ~213 ~62 ~253 minecraft:blackstone strict
setblock ~217 ~60 ~253 minecraft:nether_wart_block strict
fill ~205 ~60 ~254 ~205 ~61 ~254 minecraft:blackstone strict
setblock ~214 ~60 ~254 minecraft:nether_wart_block strict
setblock ~46 ~61 ~6 minecraft:blackstone strict
setblock ~55 ~61 ~11 minecraft:basalt[axis=y] strict
setblock ~54 ~61 ~13 minecraft:basalt[axis=y] strict
setblock ~117 ~61 ~17 minecraft:gold_block strict
fill ~244 ~61 ~41 ~247 ~63 ~41 minecraft:smooth_basalt strict
fill ~244 ~61 ~42 ~244 ~63 ~42 minecraft:smooth_basalt strict
fill ~243 ~61 ~54 ~244 ~63 ~54 minecraft:blackstone strict
fill ~244 ~61 ~55 ~247 ~63 ~55 minecraft:blackstone strict
setblock ~239 ~61 ~117 minecraft:gold_block strict
setblock ~17 ~61 ~139 minecraft:gold_block strict
fill ~5 ~61 ~201 ~9 ~61 ~201 minecraft:deepslate[axis=y] strict
fill ~1 ~61 ~206 ~1 ~63 ~211 minecraft:blackstone strict
fill ~2 ~61 ~211 ~2 ~63 ~213 minecraft:blackstone strict
fill ~3 ~61 ~213 ~3 ~63 ~214 minecraft:blackstone strict
setblock ~139 ~61 ~239 minecraft:gold_block strict
setblock ~214 ~61 ~247 minecraft:nether_wart_block strict
setblock ~217 ~61 ~248 minecraft:nether_wart_block strict
fill ~214 ~61 ~250 ~214 ~62 ~250 minecraft:blackstone strict
setblock ~215 ~61 ~250 minecraft:crimson_stem[axis=y] strict
setblock ~218 ~61 ~250 minecraft:nether_wart_block strict
setblock ~212 ~61 ~251 minecraft:nether_wart_block strict
setblock ~217 ~61 ~252 minecraft:nether_wart_block strict
setblock ~214 ~61 ~253 minecraft:nether_wart_block strict
fill ~47 ~62 ~1 ~51 ~62 ~9 minecraft:smooth_basalt strict
fill ~45 ~62 ~2 ~46 ~62 ~8 minecraft:smooth_basalt strict
fill ~52 ~62 ~2 ~53 ~62 ~12 minecraft:smooth_basalt strict
fill ~44 ~62 ~3 ~44 ~62 ~7 minecraft:smooth_basalt strict
fill ~54 ~62 ~3 ~54 ~64 ~13 minecraft:smooth_basalt strict
fill ~43 ~62 ~4 ~43 ~62 ~7 minecraft:smooth_basalt strict
fill ~42 ~62 ~5 ~42 ~64 ~7 minecraft:smooth_basalt strict
fill ~55 ~62 ~5 ~55 ~64 ~11 minecraft:smooth_basalt strict
fill ~42 ~62 ~8 ~44 ~62 ~8 minecraft:blackstone strict
fill ~42 ~62 ~9 ~42 ~62 ~10 minecraft:blackstone strict
fill ~43 ~62 ~9 ~46 ~62 ~14 minecraft:basalt[axis=y] strict
fill ~47 ~62 ~10 ~48 ~62 ~15 minecraft:basalt[axis=y] strict
fill ~49 ~62 ~10 ~51 ~62 ~10 minecraft:smooth_basalt strict
fill ~41 ~62 ~11 ~42 ~66 ~11 minecraft:basalt[axis=y] strict
fill ~49 ~62 ~11 ~49 ~62 ~15 minecraft:basalt[axis=y] strict
fill ~50 ~62 ~11 ~51 ~62 ~11 minecraft:smooth_basalt strict
fill ~42 ~62 ~12 ~42 ~66 ~13 minecraft:basalt[axis=y] strict
fill ~50 ~62 ~12 ~51 ~62 ~15 minecraft:basalt[axis=y] strict
fill ~52 ~62 ~13 ~52 ~66 ~14 minecraft:basalt[axis=y] strict
fill ~53 ~62 ~13 ~53 ~64 ~13 minecraft:smooth_basalt strict
setblock ~53 ~62 ~14 minecraft:basalt[axis=y] strict
fill ~45 ~62 ~15 ~46 ~66 ~15 minecraft:basalt[axis=y] strict
fill ~248 ~62 ~41 ~249 ~64 ~41 minecraft:smooth_basalt strict
fill ~250 ~62 ~41 ~250 ~64 ~42 minecraft:blackstone strict
fill ~251 ~62 ~42 ~252 ~64 ~42 minecraft:blackstone strict
fill ~252 ~62 ~43 ~252 ~64 ~43 minecraft:blackstone strict
fill ~252 ~62 ~53 ~252 ~64 ~54 minecraft:blackstone strict
fill ~250 ~62 ~54 ~251 ~64 ~54 minecraft:blackstone strict
fill ~248 ~62 ~55 ~250 ~64 ~55 minecraft:blackstone strict
fill ~5 ~62 ~201 ~8 ~63 ~201 minecraft:deepslate[axis=y] strict
setblock ~9 ~62 ~201 minecraft:basalt[axis=y] strict
fill ~6 ~62 ~205 ~6 ~63 ~205 minecraft:basalt[axis=y] strict
fill ~7 ~62 ~205 ~11 ~63 ~205 minecraft:blackstone strict
fill ~3 ~62 ~206 ~10 ~63 ~206 minecraft:blackstone strict
fill ~3 ~62 ~207 ~9 ~62 ~208 minecraft:polished_deepslate strict
fill ~2 ~62 ~208 ~2 ~63 ~208 minecraft:polished_deepslate strict
fill ~2 ~62 ~209 ~8 ~63 ~210 minecraft:blackstone strict
fill ~3 ~62 ~211 ~7 ~62 ~211 minecraft:blackstone strict
fill ~3 ~62 ~212 ~4 ~65 ~212 minecraft:blackstone strict
fill ~5 ~62 ~212 ~7 ~62 ~212 minecraft:basalt[axis=y] strict
setblock ~4 ~62 ~213 minecraft:blackstone strict
fill ~5 ~62 ~213 ~6 ~63 ~213 minecraft:basalt[axis=y] strict
fill ~6 ~62 ~214 ~6 ~65 ~214 minecraft:basalt[axis=y] strict
fill ~205 ~62 ~240 ~211 ~62 ~244 minecraft:smooth_red_sandstone strict
fill ~203 ~62 ~241 ~204 ~64 ~242 minecraft:smooth_red_sandstone strict
fill ~202 ~62 ~242 ~202 ~64 ~252 minecraft:smooth_basalt strict
setblock ~212 ~62 ~242 minecraft:red_sandstone strict
fill ~203 ~62 ~243 ~203 ~62 ~253 minecraft:smooth_basalt strict
fill ~204 ~62 ~243 ~204 ~64 ~243 minecraft:smooth_red_sandstone strict
fill ~212 ~62 ~243 ~212 ~62 ~248 minecraft:smooth_red_sandstone strict
fill ~213 ~62 ~243 ~213 ~62 ~244 minecraft:red_sandstone strict
fill ~201 ~62 ~244 ~201 ~64 ~250 minecraft:smooth_basalt strict
fill ~204 ~62 ~244 ~204 ~62 ~253 minecraft:smooth_basalt strict
fill ~205 ~62 ~245 ~206 ~62 ~254 minecraft:smooth_basalt strict
fill ~207 ~62 ~245 ~211 ~62 ~245 minecraft:smooth_red_sandstone strict
fill ~214 ~62 ~245 ~214 ~62 ~248 minecraft:red_sandstone strict
fill ~207 ~62 ~246 ~207 ~62 ~254 minecraft:smooth_basalt strict
fill ~208 ~62 ~246 ~211 ~62 ~246 minecraft:smooth_red_sandstone strict
fill ~208 ~62 ~247 ~209 ~62 ~254 minecraft:smooth_basalt strict
fill ~210 ~62 ~247 ~211 ~62 ~247 minecraft:smooth_red_sandstone strict
fill ~210 ~62 ~248 ~211 ~62 ~254 minecraft:smooth_basalt strict
fill ~216 ~62 ~248 ~216 ~62 ~252 minecraft:nether_wart_block strict
fill ~212 ~62 ~249 ~212 ~62 ~253 minecraft:smooth_basalt strict
setblock ~214 ~62 ~249 minecraft:blackstone strict
fill ~213 ~62 ~250 ~213 ~62 ~251 minecraft:blackstone strict
fill ~215 ~62 ~250 ~215 ~62 ~252 minecraft:nether_wart_block strict
setblock ~217 ~62 ~250 minecraft:nether_wart_block strict
fill ~45 ~63 ~1 ~51 ~64 ~2 minecraft:smooth_basalt strict
fill ~43 ~63 ~2 ~44 ~64 ~4 minecraft:smooth_basalt strict
fill ~52 ~63 ~2 ~53 ~64 ~4 minecraft:smooth_basalt strict
fill ~42 ~63 ~3 ~42 ~65 ~4 minecraft:smooth_basalt strict
fill ~45 ~63 ~3 ~45 ~64 ~3 minecraft:smooth_basalt strict
setblock ~46 ~63 ~3 minecraft:red_sand strict
setblock ~47 ~63 ~3 minecraft:magma_block strict
fill ~48 ~63 ~3 ~48 ~63 ~4 minecraft:gravel strict
fill ~49 ~63 ~3 ~50 ~63 ~4 minecraft:red_sand strict
fill ~51 ~63 ~3 ~51 ~64 ~3 minecraft:smooth_basalt strict
fill ~45 ~63 ~4 ~46 ~63 ~4 minecraft:gravel strict
setblock ~47 ~63 ~4 minecraft:blackstone strict
setblock ~51 ~63 ~4 minecraft:blackstone strict
fill ~41 ~63 ~5 ~41 ~65 ~6 minecraft:smooth_basalt strict
fill ~43 ~63 ~5 ~43 ~64 ~5 minecraft:smooth_basalt strict
setblock ~44 ~63 ~5 minecraft:red_sand strict
fill ~45 ~63 ~5 ~45 ~63 ~6 minecraft:magma_block strict
setblock ~46 ~63 ~5 minecraft:blackstone strict
setblock ~47 ~63 ~5 minecraft:red_sand strict
fill ~48 ~63 ~5 ~49 ~63 ~5 minecraft:magma_block strict
fill ~50 ~63 ~5 ~52 ~63 ~5 minecraft:red_sand strict
fill ~53 ~63 ~5 ~53 ~64 ~5 minecraft:smooth_basalt strict
setblock ~43 ~63 ~6 minecraft:gravel strict
setblock ~44 ~63 ~6 minecraft:magma_block strict
setblock ~46 ~63 ~6 minecraft:magma_block strict
fill ~47 ~63 ~6 ~48 ~63 ~6 minecraft:blackstone strict
fill ~49 ~63 ~6 ~50 ~63 ~6 minecraft:red_sand strict
fill ~51 ~63 ~6 ~52 ~63 ~6 minecraft:gravel strict
fill ~53 ~63 ~6 ~53 ~63 ~7 minecraft:red_sand strict
fill ~43 ~63 ~7 ~44 ~63 ~7 minecraft:red_sand strict
setblock ~45 ~63 ~7 minecraft:gravel strict
setblock ~46 ~63 ~7 minecraft:red_sand strict
fill ~47 ~63 ~7 ~48 ~63 ~7 minecraft:gravel strict
setblock ~49 ~63 ~7 minecraft:magma_block strict
fill ~50 ~63 ~7 ~51 ~63 ~7 minecraft:blackstone strict
fill ~52 ~63 ~7 ~52 ~63 ~8 minecraft:red_sand strict
fill ~42 ~63 ~8 ~42 ~64 ~9 minecraft:blackstone strict
fill ~43 ~63 ~8 ~43 ~63 ~10 minecraft:gravel strict
fill ~44 ~63 ~8 ~45 ~63 ~8 minecraft:blackstone strict
setblock ~46 ~63 ~8 minecraft:magma_block strict
setblock ~47 ~63 ~8 minecraft:blackstone strict
fill ~48 ~63 ~8 ~48 ~63 ~9 minecraft:gravel strict
setblock ~49 ~63 ~8 minecraft:red_sand strict
setblock ~50 ~63 ~8 minecraft:blackstone strict
setblock ~51 ~63 ~8 minecraft:gravel strict
