setblock ~53 ~63 ~8 minecraft:gravel strict
setblock ~44 ~63 ~9 minecraft:blackstone strict
setblock ~45 ~63 ~9 minecraft:magma_block strict
setblock ~46 ~63 ~9 minecraft:blackstone strict
setblock ~47 ~63 ~9 minecraft:gravel strict
setblock ~49 ~63 ~9 minecraft:gravel strict
setblock ~50 ~63 ~9 minecraft:magma_block strict
setblock ~51 ~63 ~9 minecraft:blackstone strict
fill ~52 ~63 ~9 ~53 ~63 ~9 minecraft:magma_block strict
fill ~42 ~63 ~10 ~42 ~66 ~10 minecraft:basalt[axis=y] strict
fill ~44 ~63 ~10 ~45 ~63 ~10 minecraft:gravel strict
fill ~46 ~63 ~10 ~46 ~63 ~13 minecraft:red_sand strict
setblock ~47 ~63 ~10 minecraft:blackstone strict
fill ~48 ~63 ~10 ~48 ~63 ~11 minecraft:red_sand strict
setblock ~49 ~63 ~10 minecraft:blackstone strict
setblock ~50 ~63 ~10 minecraft:red_sand strict
fill ~51 ~63 ~10 ~51 ~63 ~11 minecraft:gravel strict
fill ~52 ~63 ~10 ~53 ~63 ~10 minecraft:blackstone strict
fill ~43 ~63 ~11 ~43 ~66 ~14 minecraft:basalt[axis=y] strict
setblock ~44 ~63 ~11 minecraft:gravel strict
setblock ~45 ~63 ~11 minecraft:magma_block strict
setblock ~47 ~63 ~11 minecraft:gravel strict
fill ~49 ~63 ~11 ~50 ~63 ~11 minecraft:magma_block strict
setblock ~52 ~63 ~11 minecraft:blackstone strict
fill ~53 ~63 ~11 ~53 ~64 ~12 minecraft:smooth_basalt strict
fill ~44 ~63 ~12 ~44 ~66 ~14 minecraft:basalt[axis=y] strict
setblock ~45 ~63 ~12 minecraft:red_sand strict
fill ~47 ~63 ~12 ~47 ~63 ~13 minecraft:red_sand strict
setblock ~48 ~63 ~12 minecraft:blackstone strict
setblock ~49 ~63 ~12 minecraft:gravel strict
fill ~50 ~63 ~12 ~51 ~63 ~12 minecraft:red_sand strict
fill ~52 ~63 ~12 ~52 ~64 ~12 minecraft:smooth_basalt strict
fill ~45 ~63 ~13 ~45 ~66 ~14 minecraft:basalt[axis=y] strict
fill ~48 ~63 ~13 ~49 ~63 ~13 minecraft:red_sand strict
setblock ~50 ~63 ~13 minecraft:magma_block strict
fill ~51 ~63 ~13 ~51 ~66 ~15 minecraft:basalt[axis=y] strict
fill ~46 ~63 ~14 ~50 ~66 ~14 minecraft:basalt[axis=y] strict
fill ~53 ~63 ~14 ~53 ~64 ~14 minecraft:blackstone strict
fill ~47 ~63 ~15 ~50 ~66 ~15 minecraft:basalt[axis=y] strict
fill ~242 ~63 ~42 ~243 ~65 ~42 minecraft:blackstone strict
fill ~241 ~63 ~43 ~242 ~65 ~43 minecraft:blackstone strict
fill ~245 ~63 ~43 ~248 ~63 ~44 minecraft:smooth_basalt strict
fill ~249 ~63 ~43 ~249 ~64 ~53 minecraft:blackstone strict
fill ~253 ~63 ~43 ~253 ~65 ~45 minecraft:blackstone strict
fill ~241 ~63 ~44 ~241 ~65 ~45 minecraft:blackstone strict
fill ~244 ~63 ~44 ~244 ~63 ~51 minecraft:smooth_basalt strict
fill ~250 ~63 ~44 ~250 ~64 ~52 minecraft:blackstone strict
fill ~240 ~63 ~45 ~240 ~65 ~51 minecraft:blackstone strict
fill ~243 ~63 ~45 ~243 ~65 ~50 minecraft:blackstone strict
fill ~245 ~63 ~45 ~247 ~63 ~46 minecraft:smooth_basalt strict
fill ~248 ~63 ~45 ~248 ~64 ~53 minecraft:blackstone strict
fill ~251 ~63 ~45 ~251 ~64 ~51 minecraft:blackstone strict
fill ~254 ~63 ~45 ~254 ~65 ~51 minecraft:blackstone strict
fill ~242 ~63 ~46 ~242 ~65 ~50 minecraft:blackstone strict
fill ~252 ~63 ~46 ~252 ~64 ~50 minecraft:blackstone strict
fill ~245 ~63 ~47 ~246 ~63 ~48 minecraft:smooth_basalt strict
fill ~247 ~63 ~47 ~247 ~63 ~53 minecraft:blackstone strict
setblock ~245 ~63 ~49 minecraft:smooth_basalt strict
fill ~246 ~63 ~49 ~246 ~63 ~51 minecraft:basalt[axis=y] strict
fill ~245 ~63 ~50 ~245 ~63 ~52 minecraft:basalt[axis=y] strict
fill ~241 ~63 ~51 ~241 ~65 ~53 minecraft:blackstone strict
setblock ~243 ~63 ~51 minecraft:smooth_basalt strict
fill ~253 ~63 ~51 ~253 ~65 ~53 minecraft:blackstone strict
setblock ~244 ~63 ~52 minecraft:basalt[axis=y] strict
fill ~246 ~63 ~52 ~246 ~63 ~53 minecraft:blackstone strict
fill ~242 ~63 ~53 ~242 ~65 ~53 minecraft:blackstone strict
setblock ~245 ~63 ~53 minecraft:blackstone strict
fill ~242 ~63 ~54 ~242 ~65 ~54 minecraft:smooth_basalt strict
setblock ~9 ~63 ~201 minecraft:deepslate[axis=y] strict
fill ~3 ~63 ~207 ~9 ~63 ~208 minecraft:blackstone strict
fill ~3 ~63 ~211 ~6 ~63 ~211 minecraft:blackstone strict
fill ~7 ~63 ~211 ~7 ~63 ~212 minecraft:basalt[axis=y] strict
setblock ~5 ~63 ~212 minecraft:blackstone strict
setblock ~6 ~63 ~212 minecraft:basalt[axis=y] strict
setblock ~4 ~63 ~213 minecraft:basalt[axis=y] strict
fill ~5 ~63 ~215 ~6 ~65 ~215 minecraft:smooth_basalt strict
fill ~205 ~63 ~240 ~211 ~64 ~241 minecraft:smooth_red_sandstone strict
fill ~212 ~63 ~241 ~213 ~64 ~243 minecraft:smooth_red_sandstone strict
fill ~205 ~63 ~242 ~205 ~64 ~242 minecraft:smooth_red_sandstone strict
fill ~206 ~63 ~242 ~206 ~63 ~244 minecraft:gravel strict
fill ~207 ~63 ~242 ~207 ~63 ~244 minecraft:blackstone strict
setblock ~208 ~63 ~242 minecraft:magma_block strict
setblock ~209 ~63 ~242 minecraft:red_sand strict
setblock ~210 ~63 ~242 minecraft:gravel strict
fill ~211 ~63 ~242 ~211 ~64 ~242 minecraft:smooth_red_sandstone strict
fill ~214 ~63 ~242 ~214 ~65 ~248 minecraft:smooth_red_sandstone strict
fill ~203 ~63 ~243 ~203 ~64 ~244 minecraft:smooth_basalt strict
setblock ~205 ~63 ~243 minecraft:gravel strict
fill ~208 ~63 ~243 ~209 ~63 ~243 minecraft:gravel strict
setblock ~210 ~63 ~243 minecraft:red_sand strict
setblock ~211 ~63 ~243 minecraft:blackstone strict
setblock ~204 ~63 ~244 minecraft:red_sand strict
setblock ~205 ~63 ~244 minecraft:blackstone strict
setblock ~208 ~63 ~244 minecraft:magma_block strict
fill ~209 ~63 ~244 ~209 ~63 ~245 minecraft:blackstone strict
fill ~210 ~63 ~244 ~211 ~63 ~245 minecraft:gravel strict
setblock ~212 ~63 ~244 minecraft:red_sand strict
fill ~213 ~63 ~244 ~213 ~65 ~244 minecraft:smooth_red_sandstone strict
fill ~215 ~63 ~244 ~215 ~65 ~249 minecraft:smooth_red_sandstone strict
setblock ~203 ~63 ~245 minecraft:red_sand strict
fill ~204 ~63 ~245 ~205 ~63 ~245 minecraft:magma_block strict
fill ~206 ~63 ~245 ~206 ~63 ~246 minecraft:red_sand strict
setblock ~207 ~63 ~245 minecraft:magma_block strict
fill ~208 ~63 ~245 ~208 ~63 ~246 minecraft:blackstone strict
setblock ~212 ~63 ~245 minecraft:magma_block strict
setblock ~213 ~63 ~245 minecraft:red_sand strict
setblock ~203 ~63 ~246 minecraft:magma_block strict
fill ~204 ~63 ~246 ~204 ~63 ~248 minecraft:gravel strict
setblock ~205 ~63 ~246 minecraft:magma_block strict
fill ~207 ~63 ~246 ~207 ~63 ~247 minecraft:red_sand strict
setblock ~209 ~63 ~246 minecraft:magma_block strict
setblock ~210 ~63 ~246 minecraft:gravel strict
setblock ~211 ~63 ~246 minecraft:magma_block strict
setblock ~212 ~63 ~246 minecraft:red_sand strict
fill ~213 ~63 ~246 ~213 ~63 ~247 minecraft:gravel strict
setblock ~203 ~63 ~247 minecraft:blackstone strict
setblock ~205 ~63 ~247 minecraft:gravel strict
fill ~206 ~63 ~247 ~206 ~63 ~248 minecraft:blackstone strict
fill ~208 ~63 ~247 ~210 ~63 ~247 minecraft:red_sand strict
setblock ~211 ~63 ~247 minecraft:blackstone strict
setblock ~212 ~63 ~247 minecraft:magma_block strict
setblock ~203 ~63 ~248 minecraft:red_sand strict
fill ~205 ~63 ~248 ~205 ~63 ~249 minecraft:red_sand strict
fill ~207 ~63 ~248 ~207 ~63 ~249 minecraft:gravel strict
fill ~208 ~63 ~248 ~208 ~63 ~249 minecraft:red_sand strict
setblock ~209 ~63 ~248 minecraft:blackstone strict
setblock ~210 ~63 ~248 minecraft:red_sand strict
setblock ~211 ~63 ~248 minecraft:gravel strict
setblock ~212 ~63 ~248 minecraft:red_sand strict
setblock ~213 ~63 ~248 minecraft:blackstone strict
setblock ~203 ~63 ~249 minecraft:gravel strict
setblock ~204 ~63 ~249 minecraft:blackstone strict
setblock ~206 ~63 ~249 minecraft:gravel strict
fill ~209 ~63 ~249 ~210 ~63 ~249 minecraft:magma_block strict
setblock ~211 ~63 ~249 minecraft:red_sand strict
fill ~212 ~63 ~249 ~213 ~63 ~249 minecraft:gravel strict
fill ~214 ~63 ~249 ~214 ~65 ~252 minecraft:smooth_basalt strict
fill ~203 ~63 ~250 ~203 ~64 ~253 minecraft:smooth_basalt strict
setblock ~204 ~63 ~250 minecraft:gravel strict
setblock ~205 ~63 ~250 minecraft:blackstone strict
fill ~206 ~63 ~250 ~206 ~63 ~251 minecraft:magma_block strict
setblock ~207 ~63 ~250 minecraft:red_sand strict
fill ~208 ~63 ~250 ~209 ~63 ~251 minecraft:magma_block strict
setblock ~210 ~63 ~250 minecraft:red_sand strict
setblock ~211 ~63 ~250 minecraft:magma_block strict
setblock ~212 ~63 ~250 minecraft:gravel strict
fill ~213 ~63 ~250 ~213 ~65 ~253 minecraft:smooth_basalt strict
fill ~215 ~63 ~250 ~215 ~65 ~250 minecraft:smooth_basalt strict
fill ~204 ~63 ~251 ~204 ~64 ~253 minecraft:smooth_basalt strict
setblock ~205 ~63 ~251 minecraft:gravel strict
setblock ~207 ~63 ~251 minecraft:blackstone strict
fill ~210 ~63 ~251 ~211 ~63 ~251 minecraft:gravel strict
fill ~212 ~63 ~251 ~212 ~64 ~253 minecraft:smooth_basalt strict
fill ~205 ~63 ~252 ~205 ~64 ~254 minecraft:smooth_basalt strict
fill ~206 ~63 ~252 ~208 ~63 ~252 minecraft:red_sand strict
setblock ~209 ~63 ~252 minecraft:gravel strict
setblock ~210 ~63 ~252 minecraft:red_sand strict
fill ~211 ~63 ~252 ~211 ~64 ~254 minecraft:smooth_basalt strict
fill ~206 ~63 ~253 ~210 ~64 ~254 minecraft:smooth_basalt strict
fill ~46 ~64 ~3 ~50 ~65 ~8 minecraft:lava strict
fill ~45 ~64 ~4 ~45 ~65 ~8 minecraft:lava strict
fill ~51 ~64 ~4 ~51 ~65 ~11 minecraft:lava strict
fill ~44 ~64 ~5 ~44 ~65 ~7 minecraft:lava strict
fill ~52 ~64 ~5 ~52 ~65 ~11 minecraft:lava strict
fill ~43 ~64 ~6 ~43 ~65 ~7 minecraft:lava strict
fill ~53 ~64 ~6 ~53 ~65 ~10 minecraft:lava strict
fill ~43 ~64 ~8 ~44 ~65 ~10 minecraft:water strict
fill ~45 ~64 ~9 ~46 ~65 ~12 minecraft:water strict
fill ~47 ~64 ~9 ~50 ~65 ~9 minecraft:lava strict
fill ~47 ~64 ~10 ~48 ~65 ~13 minecraft:water strict
fill ~49 ~64 ~10 ~50 ~65 ~10 minecraft:lava strict
fill ~44 ~64 ~11 ~44 ~65 ~11 minecraft:water strict
fill ~49 ~64 ~11 ~49 ~65 ~13 minecraft:water strict
fill ~50 ~64 ~11 ~50 ~65 ~11 minecraft:lava strict
fill ~50 ~64 ~12 ~51 ~65 ~12 minecraft:water strict
fill ~46 ~64 ~13 ~46 ~65 ~13 minecraft:water strict
fill ~50 ~64 ~13 ~50 ~65 ~13 minecraft:water strict
fill ~244 ~64 ~41 ~247 ~66 ~41 minecraft:blackstone strict
fill ~244 ~64 ~42 ~244 ~66 ~42 minecraft:blackstone strict
fill ~245 ~64 ~43 ~247 ~66 ~46 minecraft:blackstone strict
fill ~248 ~64 ~43 ~248 ~64 ~44 minecraft:smooth_basalt strict
fill ~244 ~64 ~44 ~244 ~66 ~51 minecraft:blackstone strict
fill ~245 ~64 ~47 ~246 ~66 ~48 minecraft:blackstone strict
fill ~247 ~64 ~47 ~247 ~66 ~53 minecraft:smooth_basalt strict
fill ~245 ~64 ~49 ~245 ~66 ~49 minecraft:blackstone strict
fill ~246 ~64 ~49 ~246 ~66 ~53 minecraft:smooth_basalt strict
fill ~245 ~64 ~50 ~245 ~66 ~53 minecraft:smooth_basalt strict
fill ~243 ~64 ~51 ~243 ~66 ~51 minecraft:blackstone strict
fill ~244 ~64 ~52 ~244 ~66 ~52 minecraft:smooth_basalt strict
fill ~243 ~64 ~54 ~244 ~66 ~54 minecraft:smooth_basalt strict
fill ~244 ~64 ~55 ~247 ~66 ~55 minecraft:smooth_basalt strict
fill ~5 ~64 ~201 ~11 ~66 ~201 minecraft:smooth_basalt strict
fill ~3 ~64 ~202 ~5 ~66 ~202 minecraft:smooth_basalt strict
fill ~6 ~64 ~202 ~10 ~65 ~202 minecraft:basalt[axis=y] strict
fill ~11 ~64 ~202 ~12 ~66 ~202 minecraft:smooth_basalt strict
setblock ~13 ~64 ~202 minecraft:basalt[axis=y] strict
fill ~2 ~64 ~203 ~3 ~66 ~203 minecraft:smooth_basalt strict
fill ~6 ~64 ~203 ~10 ~66 ~206 minecraft:smooth_basalt strict
fill ~2 ~64 ~204 ~2 ~66 ~205 minecraft:smooth_basalt strict
fill ~4 ~64 ~204 ~4 ~65 ~204 minecraft:basalt[axis=y] strict
fill ~5 ~64 ~204 ~5 ~66 ~212 minecraft:smooth_basalt strict
fill ~11 ~64 ~204 ~11 ~66 ~205 minecraft:smooth_basalt strict
fill ~1 ~64 ~205 ~1 ~66 ~211 minecraft:smooth_basalt strict
fill ~4 ~64 ~205 ~4 ~66 ~211 minecraft:smooth_basalt strict
fill ~3 ~64 ~206 ~3 ~66 ~210 minecraft:smooth_basalt strict
fill ~6 ~64 ~207 ~9 ~66 ~208 minecraft:smooth_basalt strict
fill ~2 ~64 ~208 ~2 ~66 ~213 minecraft:smooth_basalt strict
fill ~6 ~64 ~209 ~8 ~66 ~210 minecraft:smooth_basalt strict
fill ~3 ~64 ~211 ~3 ~65 ~211 minecraft:blackstone strict
fill ~6 ~64 ~211 ~7 ~66 ~212 minecraft:smooth_basalt strict
fill ~3 ~64 ~213 ~3 ~66 ~214 minecraft:smooth_basalt strict
setblock ~4 ~64 ~213 minecraft:blackstone strict
fill ~5 ~64 ~213 ~5 ~65 ~213 minecraft:basalt[axis=y] strict
fill ~6 ~64 ~213 ~6 ~66 ~213 minecraft:smooth_basalt strict
fill ~4 ~64 ~214 ~5 ~66 ~214 minecraft:smooth_basalt strict
fill ~206 ~64 ~242 ~210 ~65 ~244 minecraft:water strict
fill ~205 ~64 ~243 ~205 ~65 ~244 minecraft:water strict
fill ~211 ~64 ~243 ~211 ~65 ~247 minecraft:water strict
fill ~204 ~64 ~244 ~204 ~65 ~250 minecraft:lava strict
fill ~212 ~64 ~244 ~212 ~65 ~248 minecraft:water strict
fill ~203 ~64 ~245 ~203 ~65 ~249 minecraft:lava strict
fill ~205 ~64 ~245 ~206 ~65 ~251 minecraft:lava strict
fill ~207 ~64 ~245 ~210 ~65 ~245 minecraft:water strict
fill ~213 ~64 ~245 ~213 ~65 ~248 minecraft:water strict
fill ~207 ~64 ~246 ~207 ~65 ~252 minecraft:lava strict
fill ~208 ~64 ~246 ~210 ~65 ~246 minecraft:water strict
fill ~208 ~64 ~247 ~209 ~65 ~252 minecraft:lava strict
fill ~210 ~64 ~247 ~210 ~65 ~247 minecraft:water strict
fill ~210 ~64 ~248 ~211 ~65 ~251 minecraft:lava strict
fill ~212 ~64 ~249 ~213 ~65 ~249 minecraft:lava strict
fill ~212 ~64 ~250 ~212 ~65 ~250 minecraft:lava strict
fill ~206 ~64 ~252 ~206 ~65 ~252 minecraft:lava strict
fill ~210 ~64 ~252 ~210 ~65 ~252 minecraft:lava strict
fill ~45 ~65 ~1 ~46 ~65 ~1 minecraft:smooth_basalt strict
fill ~47 ~65 ~1 ~51 ~66 ~2 minecraft:basalt[axis=y] strict
fill ~43 ~65 ~2 ~44 ~65 ~2 minecraft:smooth_basalt strict
fill ~45 ~65 ~2 ~46 ~66 ~2 minecraft:blackstone strict
fill ~52 ~65 ~2 ~53 ~66 ~4 minecraft:basalt[axis=y] strict
setblock ~43 ~65 ~3 minecraft:smooth_basalt strict
fill ~44 ~65 ~3 ~45 ~66 ~3 minecraft:blackstone strict
fill ~51 ~65 ~3 ~51 ~66 ~3 minecraft:basalt[axis=y] strict
fill ~54 ~65 ~3 ~54 ~65 ~12 minecraft:basalt[axis=y] strict
fill ~43 ~65 ~4 ~44 ~66 ~4 minecraft:blackstone strict
fill ~42 ~65 ~5 ~43 ~66 ~5 minecraft:blackstone strict
fill ~53 ~65 ~5 ~53 ~66 ~5 minecraft:basalt[axis=y] strict
fill ~55 ~65 ~5 ~55 ~66 ~10 minecraft:basalt[axis=y] strict
fill ~42 ~65 ~6 ~42 ~66 ~7 minecraft:blackstone strict
fill ~41 ~65 ~7 ~41 ~66 ~10 minecraft:basalt[axis=y] strict
fill ~42 ~65 ~8 ~42 ~66 ~9 minecraft:basalt[axis=y] strict
fill ~53 ~65 ~11 ~53 ~66 ~14 minecraft:basalt[axis=y] strict
setblock ~55 ~65 ~11 minecraft:blackstone strict
fill ~52 ~65 ~12 ~52 ~66 ~12 minecraft:basalt[axis=y] strict
setblock ~54 ~65 ~13 minecraft:blackstone strict
fill ~248 ~65 ~41 ~249 ~67 ~41 minecraft:blackstone strict
fill ~250 ~65 ~41 ~250 ~67 ~42 minecraft:smooth_basalt strict
fill ~251 ~65 ~42 ~252 ~67 ~42 minecraft:smooth_basalt strict
fill ~248 ~65 ~43 ~248 ~66 ~44 minecraft:blackstone strict
fill ~249 ~65 ~43 ~249 ~66 ~53 minecraft:smooth_basalt strict
fill ~252 ~65 ~43 ~252 ~67 ~43 minecraft:smooth_basalt strict
fill ~250 ~65 ~44 ~250 ~66 ~52 minecraft:smooth_basalt strict
fill ~248 ~65 ~45 ~248 ~66 ~53 minecraft:smooth_basalt strict
fill ~251 ~65 ~45 ~251 ~66 ~51 minecraft:smooth_basalt strict
fill ~252 ~65 ~46 ~252 ~65 ~48 minecraft:blackstone strict
fill ~252 ~65 ~49 ~252 ~66 ~50 minecraft:smooth_basalt strict
fill ~252 ~65 ~53 ~252 ~67 ~54 minecraft:smooth_basalt strict
fill ~250 ~65 ~54 ~251 ~67 ~54 minecraft:smooth_basalt strict
fill ~248 ~65 ~55 ~250 ~67 ~55 minecraft:smooth_basalt strict
fill ~13 ~65 ~202 ~13 ~67 ~202 minecraft:smooth_basalt strict
setblock ~4 ~65 ~213 minecraft:basalt[axis=y] strict
fill ~205 ~65 ~240 ~211 ~66 ~241 minecraft:red_sandstone strict
fill ~203 ~65 ~241 ~204 ~66 ~242 minecraft:red_sandstone strict
fill ~212 ~65 ~241 ~213 ~65 ~242 minecraft:smooth_red_sandstone strict
fill ~202 ~65 ~242 ~202 ~65 ~252 minecraft:basalt[axis=y] strict
fill ~205 ~65 ~242 ~205 ~66 ~242 minecraft:red_sandstone strict
fill ~211 ~65 ~242 ~211 ~66 ~242 minecraft:red_sandstone strict
fill ~203 ~65 ~243 ~203 ~66 ~244 minecraft:basalt[axis=y] strict
fill ~204 ~65 ~243 ~204 ~66 ~243 minecraft:red_sandstone strict
fill ~212 ~65 ~243 ~212 ~66 ~243 minecraft:red_sandstone strict
setblock ~213 ~65 ~243 minecraft:smooth_red_sandstone strict
fill ~201 ~65 ~244 ~201 ~66 ~250 minecraft:basalt[axis=y] strict
fill ~203 ~65 ~250 ~203 ~66 ~253 minecraft:basalt[axis=y] strict
fill ~204 ~65 ~251 ~204 ~66 ~253 minecraft:basalt[axis=y] strict
fill ~212 ~65 ~251 ~212 ~66 ~253 minecraft:blackstone strict
fill ~205 ~65 ~252 ~205 ~66 ~254 minecraft:blackstone strict
fill ~211 ~65 ~252 ~211 ~66 ~254 minecraft:blackstone strict
fill ~206 ~65 ~253 ~210 ~66 ~254 minecraft:blackstone strict
fill ~45 ~66 ~1 ~46 ~66 ~1 minecraft:blackstone strict
fill ~43 ~66 ~2 ~44 ~66 ~2 minecraft:blackstone strict
fill ~42 ~66 ~3 ~43 ~66 ~3 minecraft:blackstone strict
fill ~54 ~66 ~3 ~54 ~66 ~4 minecraft:basalt[axis=y] strict
setblock ~42 ~66 ~4 minecraft:blackstone strict
fill ~41 ~66 ~5 ~41 ~66 ~6 minecraft:blackstone strict
fill ~54 ~66 ~5 ~54 ~66 ~6 minecraft:magma_block strict
fill ~54 ~66 ~7 ~54 ~66 ~13 minecraft:basalt[axis=y] strict
setblock ~55 ~66 ~11 minecraft:basalt[axis=y] strict
fill ~242 ~66 ~42 ~243 ~66 ~50 minecraft:deepslate[axis=y] strict
fill ~245 ~66 ~42 ~248 ~66 ~42 minecraft:blackstone strict
fill ~249 ~66 ~42 ~249 ~67 ~42 minecraft:smooth_basalt strict
fill ~241 ~66 ~43 ~241 ~68 ~53 minecraft:deepslate[axis=y] strict
setblock ~244 ~66 ~43 minecraft:blackstone strict
fill ~250 ~66 ~43 ~251 ~67 ~43 minecraft:smooth_basalt strict
fill ~253 ~66 ~43 ~253 ~68 ~53 minecraft:smooth_basalt strict
fill ~251 ~66 ~44 ~252 ~67 ~44 minecraft:smooth_basalt strict
fill ~240 ~66 ~45 ~240 ~68 ~51 minecraft:deepslate[axis=y] strict
fill ~252 ~66 ~45 ~252 ~66 ~48 minecraft:smooth_basalt strict
fill ~254 ~66 ~45 ~254 ~68 ~51 minecraft:smooth_basalt strict
fill ~242 ~66 ~51 ~242 ~68 ~53 minecraft:deepslate[axis=y] strict
fill ~252 ~66 ~51 ~252 ~67 ~52 minecraft:smooth_basalt strict
setblock ~243 ~66 ~52 minecraft:blackstone strict
fill ~251 ~66 ~52 ~251 ~67 ~53 minecraft:smooth_basalt strict
fill ~243 ~66 ~53 ~244 ~66 ~53 minecraft:smooth_basalt strict
fill ~250 ~66 ~53 ~250 ~67 ~53 minecraft:smooth_basalt strict
fill ~242 ~66 ~54 ~242 ~70 ~54 minecraft:blackstone strict
fill ~245 ~66 ~54 ~249 ~66 ~54 minecraft:smooth_basalt strict
fill ~6 ~66 ~202 ~10 ~66 ~202 minecraft:smooth_basalt strict
fill ~4 ~66 ~203 ~5 ~66 ~203 minecraft:smooth_basalt strict
fill ~11 ~66 ~203 ~12 ~66 ~203 minecraft:smooth_basalt strict
fill ~3 ~66 ~204 ~4 ~66 ~204 minecraft:smooth_basalt strict
setblock ~3 ~66 ~205 minecraft:smooth_basalt strict
fill ~2 ~66 ~206 ~2 ~66 ~207 minecraft:smooth_basalt strict
fill ~3 ~66 ~211 ~3 ~66 ~212 minecraft:smooth_basalt strict
fill ~4 ~66 ~212 ~4 ~66 ~213 minecraft:smooth_basalt strict
setblock ~5 ~66 ~213 minecraft:smooth_basalt strict
setblock ~6 ~66 ~214 minecraft:smooth_basalt strict
fill ~5 ~66 ~215 ~6 ~69 ~215 minecraft:basalt[axis=y] strict
fill ~212 ~66 ~241 ~213 ~66 ~242 minecraft:red_sandstone strict
fill ~202 ~66 ~242 ~202 ~66 ~243 minecraft:basalt[axis=y] strict
fill ~214 ~66 ~242 ~214 ~66 ~248 minecraft:red_sandstone strict
fill ~213 ~66 ~243 ~213 ~66 ~244 minecraft:red_sandstone strict
setblock ~202 ~66 ~244 minecraft:magma_block strict
fill ~215 ~66 ~244 ~215 ~66 ~249 minecraft:red_sandstone strict
fill ~202 ~66 ~245 ~202 ~66 ~252 minecraft:basalt[axis=y] strict
fill ~214 ~66 ~249 ~214 ~66 ~252 minecraft:blackstone strict
fill ~213 ~66 ~250 ~213 ~66 ~253 minecraft:blackstone strict
setblock ~215 ~66 ~250 minecraft:blackstone strict
fill ~244 ~67 ~41 ~247 ~69 ~42 minecraft:deepslate[axis=y] strict
fill ~242 ~67 ~42 ~243 ~68 ~44 minecraft:deepslate[axis=y] strict
fill ~248 ~67 ~42 ~248 ~67 ~43 minecraft:blackstone strict
fill ~244 ~67 ~43 ~244 ~69 ~43 minecraft:deepslate[axis=y] strict
setblock ~245 ~67 ~43 minecraft:magma_block strict
fill ~246 ~67 ~43 ~247 ~67 ~44 minecraft:red_sand strict
setblock ~249 ~67 ~43 minecraft:red_sand strict
setblock ~244 ~67 ~44 minecraft:gravel strict
setblock ~245 ~67 ~44 minecraft:red_sand strict
fill ~248 ~67 ~44 ~249 ~67 ~44 minecraft:gravel strict
setblock ~250 ~67 ~44 minecraft:blackstone strict
fill ~242 ~67 ~45 ~242 ~68 ~45 minecraft:deepslate[axis=y] strict
fill ~243 ~67 ~45 ~244 ~67 ~45 minecraft:red_sand strict
setblock ~245 ~67 ~45 minecraft:magma_block strict
setblock ~246 ~67 ~45 minecraft:red_sand strict
