fill ~218 ~69 ~156 ~220 ~69 ~255 minecraft:barrier strict
fill ~221 ~69 ~156 ~235 ~69 ~156 minecraft:barrier[waterlogged=false] strict
fill ~236 ~69 ~156 ~238 ~69 ~255 minecraft:barrier strict
fill ~21 ~69 ~157 ~27 ~69 ~255 minecraft:barrier strict
setblock ~28 ~69 ~157 minecraft:barrier[waterlogged=false] strict
fill ~29 ~69 ~157 ~35 ~69 ~255 minecraft:barrier strict
fill ~221 ~69 ~157 ~227 ~69 ~255 minecraft:barrier strict
setblock ~228 ~69 ~157 minecraft:barrier[waterlogged=false] strict
fill ~229 ~69 ~157 ~235 ~69 ~255 minecraft:barrier strict
fill ~28 ~69 ~158 ~28 ~69 ~255 minecraft:barrier strict
fill ~228 ~69 ~158 ~228 ~69 ~255 minecraft:barrier strict
fill ~128 ~69 ~199 ~128 ~69 ~203 minecraft:barrier[waterlogged=false] strict
fill ~121 ~69 ~200 ~127 ~69 ~203 minecraft:barrier[waterlogged=false] strict
fill ~129 ~69 ~200 ~135 ~69 ~203 minecraft:barrier[waterlogged=false] strict
fill ~3 ~69 ~201 ~4 ~69 ~201 minecraft:barrier strict
setblock ~9 ~69 ~201 minecraft:basalt[axis=y] strict
fill ~12 ~69 ~201 ~13 ~69 ~201 minecraft:barrier strict
fill ~118 ~69 ~201 ~120 ~69 ~203 minecraft:barrier[waterlogged=false] strict
fill ~136 ~69 ~201 ~138 ~69 ~203 minecraft:barrier[waterlogged=false] strict
fill ~116 ~69 ~202 ~117 ~69 ~203 minecraft:barrier[waterlogged=false] strict
fill ~139 ~69 ~202 ~140 ~69 ~203 minecraft:barrier[waterlogged=false] strict
fill ~13 ~69 ~203 ~13 ~69 ~255 minecraft:barrier strict
fill ~114 ~69 ~203 ~115 ~69 ~203 minecraft:barrier[waterlogged=false] strict
fill ~141 ~69 ~203 ~142 ~69 ~203 minecraft:barrier[waterlogged=false] strict
fill ~12 ~69 ~204 ~12 ~69 ~255 minecraft:barrier strict
fill ~11 ~69 ~206 ~11 ~69 ~255 minecraft:barrier strict
fill ~10 ~69 ~207 ~10 ~69 ~255 minecraft:barrier strict
fill ~9 ~69 ~209 ~9 ~69 ~255 minecraft:barrier strict
fill ~8 ~69 ~211 ~8 ~69 ~255 minecraft:barrier strict
fill ~1 ~69 ~212 ~1 ~69 ~255 minecraft:barrier strict
fill ~4 ~69 ~213 ~4 ~69 ~214 minecraft:blackstone strict
fill ~7 ~69 ~213 ~7 ~69 ~255 minecraft:barrier strict
fill ~2 ~69 ~214 ~2 ~69 ~255 minecraft:barrier strict
fill ~103 ~69 ~214 ~103 ~69 ~242 minecraft:barrier[waterlogged=false] strict
fill ~153 ~69 ~214 ~153 ~69 ~242 minecraft:barrier[waterlogged=false] strict
fill ~3 ~69 ~215 ~4 ~69 ~255 minecraft:barrier strict
fill ~5 ~69 ~216 ~6 ~69 ~255 minecraft:barrier strict
fill ~102 ~69 ~216 ~102 ~69 ~240 minecraft:barrier[waterlogged=false] strict
fill ~154 ~69 ~216 ~154 ~69 ~240 minecraft:barrier[waterlogged=false] strict
fill ~101 ~69 ~218 ~101 ~69 ~238 minecraft:barrier[waterlogged=false] strict
fill ~155 ~69 ~218 ~155 ~69 ~238 minecraft:barrier[waterlogged=false] strict
fill ~100 ~69 ~221 ~100 ~69 ~235 minecraft:barrier[waterlogged=false] strict
fill ~156 ~69 ~221 ~156 ~69 ~235 minecraft:barrier[waterlogged=false] strict
setblock ~99 ~69 ~228 minecraft:barrier[waterlogged=false] strict
setblock ~157 ~69 ~228 minecraft:barrier[waterlogged=false] strict
fill ~99 ~69 ~229 ~99 ~69 ~255 minecraft:barrier strict
fill ~157 ~69 ~229 ~157 ~69 ~255 minecraft:barrier strict
fill ~100 ~69 ~236 ~100 ~69 ~255 minecraft:barrier strict
fill ~156 ~69 ~236 ~156 ~69 ~255 minecraft:barrier strict
fill ~101 ~69 ~239 ~101 ~69 ~255 minecraft:barrier strict
fill ~155 ~69 ~239 ~155 ~69 ~255 minecraft:barrier strict
fill ~102 ~69 ~241 ~102 ~69 ~255 minecraft:barrier strict
fill ~154 ~69 ~241 ~154 ~69 ~255 minecraft:barrier strict
fill ~103 ~69 ~243 ~103 ~69 ~255 minecraft:barrier strict
fill ~153 ~69 ~243 ~153 ~69 ~255 minecraft:barrier strict
fill ~104 ~69 ~254 ~115 ~69 ~255 minecraft:barrier strict
fill ~116 ~69 ~254 ~140 ~69 ~254 minecraft:barrier[waterlogged=false] strict
fill ~141 ~69 ~254 ~152 ~69 ~255 minecraft:barrier strict
fill ~116 ~69 ~255 ~117 ~69 ~255 minecraft:barrier strict
fill ~118 ~69 ~255 ~138 ~69 ~255 minecraft:barrier[waterlogged=false] strict
fill ~139 ~69 ~255 ~140 ~69 ~255 minecraft:barrier strict
fill ~244 ~70 ~41 ~247 ~70 ~42 minecraft:basalt[axis=y] strict
setblock ~250 ~70 ~41 minecraft:magma_block strict
fill ~250 ~70 ~42 ~250 ~70 ~43 minecraft:blackstone strict
setblock ~244 ~70 ~43 minecraft:basalt[axis=y] strict
fill ~253 ~70 ~43 ~253 ~70 ~50 minecraft:blackstone strict
fill ~253 ~70 ~51 ~253 ~70 ~52 minecraft:magma_block strict
setblock ~243 ~70 ~52 minecraft:basalt[axis=y] strict
setblock ~253 ~70 ~53 minecraft:blackstone strict
fill ~127 ~70 ~127 ~127 ~71 ~127 minecraft:deepslate_tiles strict
fill ~129 ~70 ~129 ~129 ~71 ~129 minecraft:deepslate_tiles strict
setblock ~5 ~70 ~201 minecraft:basalt[axis=y] strict
setblock ~6 ~70 ~201 minecraft:magma_block strict
fill ~7 ~70 ~201 ~9 ~70 ~201 minecraft:deepslate[axis=y] strict
fill ~2 ~70 ~203 ~4 ~70 ~203 minecraft:basalt[axis=y] strict
setblock ~5 ~70 ~203 minecraft:magma_block strict
fill ~4 ~70 ~213 ~4 ~70 ~214 minecraft:basalt[axis=y] strict
setblock ~5 ~70 ~215 minecraft:basalt[axis=y] strict
setblock ~6 ~70 ~215 minecraft:magma_block strict
fill ~126 ~71 ~126 ~126 ~72 ~126 minecraft:deepslate_tiles strict
fill ~128 ~71 ~127 ~129 ~72 ~127 minecraft:deepslate_tiles strict
fill ~127 ~71 ~128 ~127 ~72 ~128 minecraft:deepslate_tiles strict
fill ~128 ~71 ~128 ~128 ~72 ~128 minecraft:basalt[axis=y] strict
fill ~129 ~71 ~128 ~129 ~72 ~128 minecraft:deepslate_tiles strict
setblock ~127 ~71 ~129 minecraft:amethyst_block strict
fill ~128 ~71 ~129 ~128 ~72 ~129 minecraft:deepslate_tiles strict
setblock ~130 ~71 ~130 minecraft:amethyst_block strict
fill ~129 ~72 ~124 ~129 ~73 ~125 minecraft:deepslate_tiles strict
fill ~125 ~72 ~125 ~125 ~73 ~125 minecraft:deepslate_tiles strict
fill ~127 ~72 ~125 ~128 ~72 ~126 minecraft:deepslate_tiles strict
fill ~130 ~72 ~125 ~130 ~72 ~130 minecraft:deepslate_tiles strict
setblock ~129 ~72 ~126 minecraft:amethyst_block strict
fill ~131 ~72 ~126 ~131 ~72 ~129 minecraft:deepslate_tiles strict
fill ~125 ~72 ~127 ~126 ~72 ~127 minecraft:deepslate_tiles strict
fill ~127 ~72 ~127 ~127 ~73 ~127 minecraft:blackstone strict
setblock ~132 ~72 ~127 minecraft:amethyst_block strict
fill ~125 ~72 ~128 ~125 ~72 ~130 minecraft:deepslate_tiles strict
setblock ~126 ~72 ~128 minecraft:amethyst_block strict
fill ~124 ~72 ~129 ~124 ~73 ~129 minecraft:deepslate_tiles strict
fill ~126 ~72 ~129 ~127 ~72 ~130 minecraft:deepslate_tiles strict
setblock ~129 ~72 ~129 minecraft:amethyst_block strict
fill ~128 ~72 ~130 ~129 ~72 ~131 minecraft:deepslate_tiles strict
setblock ~126 ~72 ~131 minecraft:amethyst_block strict
fill ~127 ~72 ~131 ~127 ~73 ~132 minecraft:deepslate_tiles strict
fill ~131 ~72 ~131 ~131 ~73 ~131 minecraft:deepslate_tiles strict
fill ~127 ~73 ~122 ~127 ~74 ~122 minecraft:deepslate_tiles strict
fill ~128 ~73 ~123 ~128 ~74 ~124 minecraft:deepslate_tiles strict
fill ~124 ~73 ~124 ~124 ~74 ~124 minecraft:deepslate_tiles strict
fill ~126 ~73 ~124 ~127 ~73 ~125 minecraft:deepslate_tiles strict
fill ~130 ~73 ~124 ~130 ~73 ~129 minecraft:deepslate_tiles strict
setblock ~128 ~73 ~125 minecraft:amethyst_block strict
fill ~131 ~73 ~125 ~131 ~74 ~125 minecraft:deepslate_tiles strict
fill ~124 ~73 ~126 ~125 ~73 ~126 minecraft:deepslate_tiles strict
fill ~126 ~73 ~126 ~126 ~74 ~126 minecraft:blackstone strict
fill ~127 ~73 ~126 ~129 ~73 ~126 minecraft:deepslate_tiles strict
setblock ~131 ~73 ~126 minecraft:amethyst_block strict
fill ~132 ~73 ~126 ~132 ~73 ~130 minecraft:deepslate_tiles strict
fill ~122 ~73 ~127 ~122 ~74 ~127 minecraft:deepslate_tiles strict
fill ~124 ~73 ~127 ~124 ~74 ~128 minecraft:deepslate_tiles strict
setblock ~125 ~73 ~127 minecraft:amethyst_block strict
fill ~126 ~73 ~127 ~126 ~73 ~132 minecraft:deepslate_tiles strict
fill ~128 ~73 ~127 ~129 ~74 ~127 minecraft:blackstone strict
fill ~131 ~73 ~127 ~131 ~73 ~128 minecraft:deepslate_tiles strict
fill ~123 ~73 ~128 ~123 ~74 ~128 minecraft:deepslate_tiles strict
fill ~125 ~73 ~128 ~125 ~73 ~129 minecraft:deepslate_tiles strict
fill ~127 ~73 ~128 ~127 ~76 ~129 minecraft:basalt[axis=y] strict
setblock ~128 ~73 ~128 minecraft:amethyst_block strict
fill ~129 ~73 ~128 ~129 ~73 ~129 minecraft:basalt[axis=y] strict
fill ~133 ~73 ~128 ~133 ~74 ~128 minecraft:deepslate_tiles strict
fill ~128 ~73 ~129 ~128 ~75 ~129 minecraft:basalt[axis=y] strict
setblock ~131 ~73 ~129 minecraft:amethyst_block strict
fill ~134 ~73 ~129 ~134 ~74 ~129 minecraft:deepslate_tiles strict
fill ~124 ~73 ~130 ~124 ~74 ~130 minecraft:deepslate_tiles strict
setblock ~125 ~73 ~130 minecraft:amethyst_block strict
fill ~127 ~73 ~130 ~129 ~73 ~130 minecraft:deepslate_tiles strict
fill ~130 ~73 ~130 ~130 ~79 ~130 minecraft:basalt[axis=y] strict
fill ~131 ~73 ~130 ~131 ~74 ~130 minecraft:deepslate_tiles strict
fill ~125 ~73 ~131 ~125 ~74 ~131 minecraft:deepslate_tiles strict
setblock ~128 ~73 ~131 minecraft:amethyst_block strict
fill ~129 ~73 ~131 ~130 ~73 ~132 minecraft:deepslate_tiles strict
fill ~128 ~73 ~132 ~128 ~74 ~133 minecraft:deepslate_tiles strict
fill ~132 ~73 ~132 ~132 ~74 ~132 minecraft:deepslate_tiles strict
fill ~129 ~73 ~134 ~129 ~74 ~134 minecraft:deepslate_tiles strict
fill ~126 ~74 ~121 ~126 ~74 ~125 minecraft:deepslate_tiles strict
fill ~131 ~74 ~121 ~131 ~75 ~121 minecraft:deepslate_tiles strict
fill ~128 ~74 ~122 ~129 ~75 ~122 minecraft:deepslate_tiles strict
setblock ~130 ~74 ~122 minecraft:amethyst_block strict
setblock ~132 ~74 ~122 minecraft:deepslate_tiles strict
fill ~123 ~74 ~123 ~123 ~75 ~123 minecraft:deepslate_tiles strict
fill ~125 ~74 ~123 ~125 ~75 ~124 minecraft:deepslate_tiles strict
fill ~127 ~74 ~123 ~127 ~75 ~123 minecraft:deepslate_tiles strict
fill ~129 ~74 ~123 ~131 ~75 ~123 minecraft:deepslate_tiles strict
setblock ~133 ~74 ~123 minecraft:amethyst_block strict
setblock ~127 ~74 ~124 minecraft:amethyst_block strict
setblock ~129 ~74 ~124 minecraft:blackstone strict
fill ~130 ~74 ~124 ~132 ~74 ~124 minecraft:deepslate_tiles strict
fill ~134 ~74 ~124 ~134 ~75 ~124 minecraft:deepslate_tiles strict
fill ~123 ~74 ~125 ~124 ~74 ~125 minecraft:deepslate_tiles strict
setblock ~125 ~74 ~125 minecraft:basalt[axis=y] strict
fill ~127 ~74 ~125 ~128 ~75 ~125 minecraft:blackstone strict
setblock ~129 ~74 ~125 minecraft:basalt[axis=y] strict
setblock ~130 ~74 ~125 minecraft:amethyst_block strict
fill ~132 ~74 ~125 ~133 ~74 ~125 minecraft:deepslate_tiles strict
fill ~135 ~74 ~125 ~135 ~75 ~125 minecraft:deepslate_tiles strict
fill ~121 ~74 ~126 ~123 ~75 ~126 minecraft:deepslate_tiles strict
setblock ~124 ~74 ~126 minecraft:amethyst_block strict
setblock ~125 ~74 ~126 minecraft:deepslate_tiles strict
fill ~127 ~74 ~126 ~127 ~76 ~126 minecraft:blackstone strict
setblock ~128 ~74 ~126 minecraft:basalt[axis=y] strict
fill ~129 ~74 ~126 ~131 ~74 ~126 minecraft:blackstone strict
setblock ~132 ~74 ~126 minecraft:deepslate_tiles strict
setblock ~133 ~74 ~126 minecraft:amethyst_block strict
fill ~134 ~74 ~126 ~134 ~75 ~128 minecraft:deepslate_tiles strict
fill ~123 ~74 ~127 ~123 ~75 ~127 minecraft:deepslate_tiles strict
fill ~125 ~74 ~127 ~126 ~74 ~130 minecraft:basalt[axis=y] strict
setblock ~127 ~74 ~127 minecraft:amethyst_block strict
fill ~130 ~74 ~127 ~130 ~76 ~127 minecraft:blackstone strict
fill ~131 ~74 ~127 ~132 ~75 ~127 minecraft:basalt[axis=y] strict
fill ~133 ~74 ~127 ~133 ~75 ~127 minecraft:deepslate_tiles strict
fill ~122 ~74 ~128 ~122 ~75 ~130 minecraft:deepslate_tiles strict
fill ~128 ~74 ~128 ~128 ~77 ~128 minecraft:basalt[axis=y] strict
setblock ~129 ~74 ~128 minecraft:blackstone strict
setblock ~130 ~74 ~128 minecraft:amethyst_block strict
fill ~131 ~74 ~128 ~131 ~78 ~129 minecraft:basalt[axis=y] strict
fill ~132 ~74 ~128 ~132 ~74 ~131 minecraft:deepslate_tiles strict
fill ~123 ~74 ~129 ~123 ~74 ~131 minecraft:deepslate_tiles strict
setblock ~124 ~74 ~129 minecraft:amethyst_block strict
fill ~129 ~74 ~129 ~130 ~76 ~129 minecraft:basalt[axis=y] strict
setblock ~133 ~74 ~129 minecraft:amethyst_block strict
setblock ~127 ~74 ~130 minecraft:amethyst_block strict
fill ~128 ~74 ~130 ~129 ~74 ~131 minecraft:basalt[axis=y] strict
fill ~133 ~74 ~130 ~135 ~75 ~130 minecraft:deepslate_tiles strict
setblock ~121 ~74 ~131 minecraft:amethyst_block strict
fill ~124 ~74 ~131 ~124 ~75 ~131 minecraft:deepslate_tiles strict
fill ~126 ~74 ~131 ~127 ~76 ~131 minecraft:basalt[axis=y] strict
setblock ~130 ~74 ~131 minecraft:amethyst_block strict
fill ~131 ~74 ~131 ~131 ~78 ~131 minecraft:basalt[axis=y] strict
fill ~133 ~74 ~131 ~133 ~75 ~131 minecraft:deepslate_tiles strict
fill ~122 ~74 ~132 ~122 ~75 ~132 minecraft:deepslate_tiles strict
setblock ~124 ~74 ~132 minecraft:amethyst_block strict
fill ~125 ~74 ~132 ~126 ~74 ~133 minecraft:deepslate_tiles strict
fill ~127 ~74 ~132 ~127 ~79 ~132 minecraft:basalt[axis=y] strict
fill ~129 ~74 ~132 ~131 ~74 ~133 minecraft:deepslate_tiles strict
fill ~123 ~74 ~133 ~123 ~75 ~133 minecraft:deepslate_tiles strict
setblock ~127 ~74 ~133 minecraft:amethyst_block strict
fill ~133 ~74 ~133 ~133 ~75 ~133 minecraft:deepslate_tiles strict
fill ~124 ~74 ~134 ~124 ~75 ~134 minecraft:deepslate_tiles strict
fill ~126 ~74 ~134 ~128 ~75 ~134 minecraft:deepslate_tiles strict
setblock ~130 ~74 ~134 minecraft:amethyst_block strict
fill ~125 ~74 ~135 ~125 ~75 ~135 minecraft:deepslate_tiles strict
fill ~130 ~74 ~135 ~130 ~75 ~135 minecraft:deepslate_tiles strict
fill ~129 ~75 ~119 ~129 ~76 ~119 minecraft:deepslate_tiles strict
fill ~125 ~75 ~120 ~125 ~75 ~122 minecraft:deepslate_tiles strict
fill ~130 ~75 ~120 ~130 ~75 ~122 minecraft:deepslate_tiles strict
fill ~126 ~75 ~121 ~128 ~75 ~121 minecraft:deepslate_tiles strict
setblock ~129 ~75 ~121 minecraft:amethyst_block strict
fill ~122 ~75 ~122 ~122 ~75 ~125 minecraft:deepslate_tiles strict
setblock ~123 ~75 ~122 minecraft:amethyst_block strict
fill ~124 ~75 ~122 ~124 ~76 ~123 minecraft:deepslate_tiles strict
setblock ~126 ~75 ~122 minecraft:deepslate_tiles strict
fill ~127 ~75 ~122 ~127 ~76 ~122 minecraft:blackstone strict
fill ~131 ~75 ~122 ~131 ~76 ~122 minecraft:deepslate_tiles strict
setblock ~132 ~75 ~122 minecraft:amethyst_block strict
fill ~133 ~75 ~122 ~133 ~75 ~126 minecraft:deepslate_tiles strict
setblock ~126 ~75 ~123 minecraft:amethyst_block strict
setblock ~128 ~75 ~123 minecraft:basalt[axis=y] strict
fill ~132 ~75 ~123 ~132 ~75 ~124 minecraft:deepslate_tiles strict
fill ~134 ~75 ~123 ~134 ~76 ~123 minecraft:deepslate_tiles strict
fill ~123 ~75 ~124 ~123 ~76 ~124 minecraft:deepslate_tiles strict
setblock ~124 ~75 ~124 minecraft:blackstone strict
fill ~126 ~75 ~124 ~126 ~77 ~124 minecraft:blackstone strict
setblock ~127 ~75 ~124 minecraft:basalt[axis=y] strict
setblock ~128 ~75 ~124 minecraft:blackstone strict
setblock ~129 ~75 ~124 minecraft:amethyst_block strict
fill ~130 ~75 ~124 ~130 ~77 ~124 minecraft:blackstone strict
setblock ~131 ~75 ~124 minecraft:deepslate_tiles strict
fill ~120 ~75 ~125 ~121 ~76 ~125 minecraft:deepslate_tiles strict
setblock ~123 ~75 ~125 minecraft:amethyst_block strict
setblock ~124 ~75 ~125 minecraft:deepslate_tiles strict
setblock ~125 ~75 ~125 minecraft:blackstone strict
setblock ~126 ~75 ~125 minecraft:basalt[axis=y] strict
fill ~129 ~75 ~125 ~129 ~77 ~125 minecraft:blackstone strict
setblock ~130 ~75 ~125 minecraft:basalt[axis=y] strict
fill ~131 ~75 ~125 ~131 ~75 ~126 minecraft:blackstone strict
setblock ~132 ~75 ~125 minecraft:amethyst_block strict
setblock ~134 ~75 ~125 minecraft:deepslate_tiles strict
fill ~124 ~75 ~126 ~125 ~75 ~130 minecraft:basalt[axis=y] strict
setblock ~126 ~75 ~126 minecraft:amethyst_block strict
setblock ~128 ~75 ~126 minecraft:blackstone strict
setblock ~129 ~75 ~126 minecraft:basalt[axis=y] strict
setblock ~130 ~75 ~126 minecraft:blackstone strict
setblock ~132 ~75 ~126 minecraft:blackstone strict
setblock ~135 ~75 ~126 minecraft:amethyst_block strict
fill ~136 ~75 ~126 ~136 ~76 ~126 minecraft:deepslate_tiles strict
fill ~121 ~75 ~127 ~121 ~75 ~131 minecraft:deepslate_tiles strict
setblock ~122 ~75 ~127 minecraft:basalt[axis=y] strict
fill ~126 ~75 ~127 ~126 ~77 ~128 minecraft:basalt[axis=y] strict
fill ~127 ~75 ~127 ~127 ~77 ~127 minecraft:blackstone strict
setblock ~128 ~75 ~127 minecraft:basalt[axis=y] strict
setblock ~129 ~75 ~127 minecraft:amethyst_block strict
fill ~135 ~75 ~127 ~135 ~76 ~128 minecraft:deepslate_tiles strict
fill ~137 ~75 ~127 ~137 ~76 ~127 minecraft:deepslate_tiles strict
setblock ~123 ~75 ~128 minecraft:amethyst_block strict
fill ~129 ~75 ~128 ~130 ~77 ~128 minecraft:basalt[axis=y] strict
setblock ~132 ~75 ~128 minecraft:amethyst_block strict
fill ~133 ~75 ~128 ~133 ~79 ~128 minecraft:basalt[axis=y] strict
setblock ~119 ~75 ~129 minecraft:deepslate_tiles strict
fill ~123 ~75 ~129 ~123 ~75 ~130 minecraft:deepslate_tiles strict
setblock ~126 ~75 ~129 minecraft:amethyst_block strict
fill ~132 ~75 ~129 ~132 ~77 ~130 minecraft:basalt[axis=y] strict
setblock ~133 ~75 ~129 minecraft:deepslate_tiles strict
setblock ~134 ~75 ~129 minecraft:basalt[axis=y] strict
setblock ~135 ~75 ~129 minecraft:amethyst_block strict
setblock ~120 ~75 ~130 minecraft:amethyst_block strict
fill ~126 ~75 ~130 ~128 ~77 ~130 minecraft:basalt[axis=y] strict
setblock ~129 ~75 ~130 minecraft:amethyst_block strict
setblock ~131 ~75 ~130 minecraft:basalt[axis=y] strict
fill ~122 ~75 ~131 ~122 ~76 ~131 minecraft:deepslate_tiles strict
setblock ~123 ~75 ~131 minecraft:amethyst_block strict
setblock ~125 ~75 ~131 minecraft:basalt[axis=y] strict
fill ~128 ~75 ~131 ~130 ~75 ~132 minecraft:basalt[axis=y] strict
setblock ~132 ~75 ~131 minecraft:amethyst_block strict
fill ~134 ~75 ~131 ~136 ~75 ~131 minecraft:deepslate_tiles strict
fill ~123 ~75 ~132 ~125 ~75 ~132 minecraft:deepslate_tiles strict
setblock ~126 ~75 ~132 minecraft:amethyst_block strict
fill ~131 ~75 ~132 ~131 ~75 ~136 minecraft:deepslate_tiles strict
fill ~132 ~75 ~132 ~132 ~77 ~132 minecraft:basalt[axis=y] strict
fill ~133 ~75 ~132 ~134 ~76 ~132 minecraft:deepslate_tiles strict
setblock ~122 ~75 ~133 minecraft:deepslate_tiles strict
fill ~124 ~75 ~133 ~127 ~75 ~133 minecraft:deepslate_tiles strict
fill ~128 ~75 ~133 ~128 ~78 ~133 minecraft:basalt[axis=y] strict
setblock ~129 ~75 ~133 minecraft:amethyst_block strict
fill ~130 ~75 ~133 ~130 ~75 ~134 minecraft:deepslate_tiles strict
fill ~132 ~75 ~133 ~132 ~76 ~133 minecraft:deepslate_tiles strict
fill ~134 ~75 ~133 ~134 ~75 ~134 minecraft:deepslate_tiles strict
setblock ~123 ~75 ~134 minecraft:amethyst_block strict
setblock ~125 ~75 ~134 minecraft:deepslate_tiles strict
setblock ~129 ~75 ~134 minecraft:basalt[axis=y] strict
setblock ~132 ~75 ~134 minecraft:amethyst_block strict
fill ~133 ~75 ~134 ~133 ~76 ~134 minecraft:deepslate_tiles strict
setblock ~126 ~75 ~135 minecraft:amethyst_block strict
fill ~127 ~75 ~135 ~129 ~75 ~135 minecraft:deepslate_tiles strict
fill ~126 ~75 ~136 ~126 ~76 ~136 minecraft:deepslate_tiles strict
fill ~127 ~75 ~137 ~127 ~76 ~137 minecraft:deepslate_tiles strict
fill ~128 ~76 ~118 ~128 ~77 ~119 minecraft:deepslate_tiles strict
fill ~124 ~76 ~119 ~124 ~76 ~121 minecraft:deepslate_tiles strict
fill ~126 ~76 ~119 ~127 ~76 ~120 minecraft:deepslate_tiles strict
fill ~130 ~76 ~119 ~130 ~76 ~121 minecraft:deepslate_tiles strict
fill ~125 ~76 ~120 ~125 ~76 ~121 minecraft:deepslate_tiles strict
setblock ~128 ~76 ~120 minecraft:amethyst_block strict
fill ~129 ~76 ~120 ~129 ~76 ~121 minecraft:deepslate_tiles strict
fill ~131 ~76 ~120 ~132 ~77 ~120 minecraft:deepslate_tiles strict
fill ~135 ~76 ~120 ~135 ~77 ~120 minecraft:deepslate_tiles strict
fill ~121 ~76 ~121 ~121 ~76 ~124 minecraft:deepslate_tiles strict
setblock ~122 ~76 ~121 minecraft:amethyst_block strict
fill ~123 ~76 ~121 ~123 ~76 ~122 minecraft:deepslate_tiles strict
fill ~126 ~76 ~121 ~126 ~77 ~121 minecraft:blackstone strict
fill ~127 ~76 ~121 ~128 ~76 ~121 minecraft:deepslate_tiles strict
setblock ~131 ~76 ~121 minecraft:amethyst_block strict
fill ~132 ~76 ~121 ~134 ~76 ~121 minecraft:deepslate_tiles strict
fill ~136 ~76 ~121 ~136 ~77 ~121 minecraft:deepslate_tiles strict
fill ~122 ~76 ~122 ~122 ~76 ~123 minecraft:deepslate_tiles strict
setblock ~125 ~76 ~122 minecraft:amethyst_block strict
setblock ~126 ~76 ~122 minecraft:basalt[axis=y] strict
fill ~128 ~76 ~122 ~129 ~77 ~122 minecraft:blackstone strict
setblock ~130 ~76 ~122 minecraft:basalt[axis=y] strict
fill ~132 ~76 ~122 ~132 ~77 ~122 minecraft:blackstone strict
setblock ~133 ~76 ~122 minecraft:deepslate_tiles strict
setblock ~134 ~76 ~122 minecraft:amethyst_block strict
fill ~135 ~76 ~122 ~135 ~77 ~124 minecraft:deepslate_tiles strict
fill ~123 ~76 ~123 ~123 ~77 ~123 minecraft:blackstone strict
setblock ~125 ~76 ~123 minecraft:basalt[axis=y] strict
fill ~126 ~76 ~123 ~127 ~76 ~123 minecraft:blackstone strict
setblock ~128 ~76 ~123 minecraft:amethyst_block strict
setblock ~129 ~76 ~123 minecraft:basalt[axis=y] strict
fill ~130 ~76 ~123 ~131 ~76 ~123 minecraft:blackstone strict
setblock ~132 ~76 ~123 minecraft:deepslate_tiles strict
setblock ~133 ~76 ~123 minecraft:basalt[axis=y] strict
fill ~119 ~76 ~124 ~120 ~77 ~124 minecraft:deepslate_tiles strict
setblock ~122 ~76 ~124 minecraft:amethyst_block strict
setblock ~124 ~76 ~124 minecraft:basalt[axis=y] strict
setblock ~125 ~76 ~124 minecraft:blackstone strict
fill ~127 ~76 ~124 ~127 ~78 ~124 minecraft:blackstone strict
setblock ~128 ~76 ~124 minecraft:basalt[axis=y] strict
setblock ~129 ~76 ~124 minecraft:blackstone strict
setblock ~131 ~76 ~124 minecraft:amethyst_block strict
setblock ~132 ~76 ~124 minecraft:basalt[axis=y] strict
setblock ~133 ~76 ~124 minecraft:deepslate_tiles strict
fill ~134 ~76 ~124 ~134 ~77 ~124 minecraft:blackstone strict
fill ~136 ~76 ~124 ~136 ~76 ~125 minecraft:deepslate_tiles strict
