fill ~188 ~25 ~47 ~188 ~25 ~48 minecraft:quartz_slab[type=bottom,waterlogged=false] strict
fill ~186 ~25 ~50 ~186 ~25 ~52 minecraft:quartz_slab[type=bottom,waterlogged=false] strict
fill ~188 ~25 ~50 ~188 ~25 ~52 minecraft:quartz_slab[type=bottom,waterlogged=false] strict
fill ~127 ~25 ~63 ~129 ~25 ~63 minecraft:polished_blackstone_brick_slab[type=bottom,waterlogged=false] strict
setblock ~126 ~25 ~64 minecraft:polished_blackstone_brick_slab[type=bottom,waterlogged=false] strict
setblock ~127 ~25 ~64 minecraft:polished_blackstone_slab[type=bottom,waterlogged=false] strict
fill ~128 ~25 ~64 ~129 ~25 ~64 minecraft:polished_blackstone_brick_slab[type=bottom,waterlogged=false] strict
setblock ~130 ~25 ~64 minecraft:blackstone_slab[type=bottom,waterlogged=false] strict
fill ~125 ~25 ~65 ~125 ~25 ~68 minecraft:polished_blackstone_brick_slab[type=bottom,waterlogged=false] strict
setblock ~126 ~25 ~65 minecraft:polished_blackstone_slab[type=bottom,waterlogged=false] strict
setblock ~127 ~25 ~65 minecraft:polished_blackstone_brick_slab[type=bottom,waterlogged=false] strict
setblock ~128 ~25 ~65 minecraft:polished_blackstone_slab[type=bottom,waterlogged=false] strict
fill ~129 ~25 ~65 ~130 ~25 ~66 minecraft:polished_blackstone_brick_slab[type=bottom,waterlogged=false] strict
setblock ~131 ~25 ~65 minecraft:polished_blackstone_slab[type=bottom,waterlogged=false] strict
fill ~126 ~25 ~66 ~126 ~25 ~67 minecraft:polished_blackstone_brick_slab[type=bottom,waterlogged=false] strict
setblock ~127 ~25 ~66 minecraft:cobbled_deepslate_slab[type=bottom,waterlogged=false] strict
fill ~128 ~25 ~66 ~128 ~25 ~67 minecraft:polished_blackstone_brick_slab[type=bottom,waterlogged=false] strict
setblock ~131 ~25 ~66 minecraft:blackstone_slab[type=bottom,waterlogged=false] strict
fill ~94 ~25 ~67 ~98 ~25 ~67 minecraft:quartz_slab[type=bottom,waterlogged=false] strict
fill ~127 ~25 ~67 ~127 ~25 ~68 minecraft:polished_blackstone_brick_slab[type=bottom,waterlogged=false] strict
fill ~129 ~25 ~67 ~129 ~25 ~68 minecraft:polished_blackstone_brick_slab[type=bottom,waterlogged=false] strict
setblock ~130 ~25 ~67 minecraft:polished_blackstone_slab[type=bottom,waterlogged=false] strict
fill ~131 ~25 ~67 ~131 ~25 ~68 minecraft:polished_blackstone_brick_slab[type=bottom,waterlogged=false] strict
fill ~211 ~25 ~67 ~215 ~25 ~67 minecraft:quartz_slab[type=bottom,waterlogged=false] strict
setblock ~126 ~25 ~68 minecraft:blackstone_slab[type=bottom,waterlogged=false] strict
setblock ~130 ~25 ~68 minecraft:polished_blackstone_brick_slab[type=bottom,waterlogged=false] strict
fill ~94 ~25 ~69 ~98 ~25 ~69 minecraft:quartz_slab[type=bottom,waterlogged=false] strict
fill ~211 ~25 ~69 ~215 ~25 ~69 minecraft:quartz_slab[type=bottom,waterlogged=false] strict
fill ~37 ~25 ~92 ~37 ~25 ~95 minecraft:quartz_slab[type=bottom,waterlogged=false] strict
fill ~39 ~25 ~92 ~39 ~25 ~95 minecraft:quartz_slab[type=bottom,waterlogged=false] strict
setblock ~235 ~25 ~96 minecraft:campfire[facing=north,lit=true,signal_fire=false,waterlogged=false] strict
setblock ~63 ~25 ~125 minecraft:polished_blackstone_brick_slab[type=bottom,waterlogged=false] strict
setblock ~185 ~25 ~125 minecraft:polished_blackstone_brick_slab[type=bottom,waterlogged=false] strict
setblock ~62 ~25 ~126 minecraft:polished_blackstone_brick_slab[type=bottom,waterlogged=false] strict
setblock ~63 ~25 ~126 minecraft:cobbled_deepslate_slab[type=bottom,waterlogged=false] strict
fill ~185 ~25 ~126 ~186 ~25 ~126 minecraft:blackstone_slab[type=bottom,waterlogged=false] strict
setblock ~62 ~25 ~127 minecraft:polished_blackstone_slab[type=bottom,waterlogged=false] strict
setblock ~63 ~25 ~127 minecraft:polished_blackstone_brick_slab[type=bottom,waterlogged=false] strict
setblock ~185 ~25 ~127 minecraft:polished_blackstone_brick_slab[type=bottom,waterlogged=false] strict
fill ~186 ~25 ~127 ~187 ~25 ~127 minecraft:cobbled_deepslate_slab[type=bottom,waterlogged=false] strict
fill ~62 ~25 ~128 ~62 ~25 ~130 minecraft:polished_blackstone_brick_slab[type=bottom,waterlogged=false] strict
fill ~186 ~25 ~128 ~186 ~25 ~129 minecraft:polished_blackstone_brick_slab[type=bottom,waterlogged=false] strict
setblock ~187 ~25 ~128 minecraft:cobbled_deepslate_slab[type=bottom,waterlogged=false] strict
setblock ~63 ~25 ~129 minecraft:polished_blackstone_brick_slab[type=bottom,waterlogged=false] strict
setblock ~185 ~25 ~129 minecraft:polished_blackstone_brick_slab[type=bottom,waterlogged=false] strict
setblock ~187 ~25 ~129 minecraft:blackstone_slab[type=bottom,waterlogged=false] strict
setblock ~63 ~25 ~130 minecraft:blackstone_slab[type=bottom,waterlogged=false] strict
setblock ~185 ~25 ~130 minecraft:cobbled_deepslate_slab[type=bottom,waterlogged=false] strict
setblock ~186 ~25 ~130 minecraft:polished_blackstone_slab[type=bottom,waterlogged=false] strict
setblock ~63 ~25 ~131 minecraft:polished_blackstone_brick_slab[type=bottom,waterlogged=false] strict
setblock ~185 ~25 ~131 minecraft:polished_blackstone_brick_slab[type=bottom,waterlogged=false] strict
fill ~125 ~25 ~189 ~127 ~25 ~189 minecraft:polished_blackstone_brick_slab[type=bottom,waterlogged=false] strict
fill ~129 ~25 ~189 ~131 ~25 ~189 minecraft:polished_blackstone_brick_slab[type=bottom,waterlogged=false] strict
fill ~125 ~25 ~190 ~125 ~25 ~191 minecraft:polished_blackstone_brick_slab[type=bottom,waterlogged=false] strict
setblock ~126 ~25 ~190 minecraft:blackstone_slab[type=bottom,waterlogged=false] strict
setblock ~127 ~25 ~190 minecraft:polished_blackstone_brick_slab[type=bottom,waterlogged=false] strict
fill ~128 ~25 ~190 ~128 ~25 ~191 minecraft:polished_blackstone_slab[type=bottom,waterlogged=false] strict
setblock ~129 ~25 ~190 minecraft:polished_blackstone_brick_slab[type=bottom,waterlogged=false] strict
fill ~130 ~25 ~190 ~131 ~25 ~190 minecraft:blackstone_slab[type=bottom,waterlogged=false] strict
fill ~126 ~25 ~191 ~126 ~25 ~192 minecraft:polished_blackstone_brick_slab[type=bottom,waterlogged=false] strict
setblock ~127 ~25 ~191 minecraft:cobbled_deepslate_slab[type=bottom,waterlogged=false] strict
fill ~129 ~25 ~191 ~130 ~25 ~191 minecraft:cobbled_deepslate_slab[type=bottom,waterlogged=false] strict
fill ~131 ~25 ~191 ~131 ~25 ~192 minecraft:polished_blackstone_brick_slab[type=bottom,waterlogged=false] strict
setblock ~134 ~25 ~191 minecraft:polished_blackstone_brick_slab[type=bottom,waterlogged=false] strict
setblock ~125 ~25 ~192 minecraft:polished_blackstone_slab[type=bottom,waterlogged=false] strict
fill ~127 ~25 ~192 ~128 ~25 ~194 minecraft:polished_blackstone_brick_slab[type=bottom,waterlogged=false] strict
setblock ~129 ~25 ~192 minecraft:polished_blackstone_slab[type=bottom,waterlogged=false] strict
setblock ~130 ~25 ~192 minecraft:blackstone_slab[type=bottom,waterlogged=false] strict
setblock ~126 ~25 ~193 minecraft:polished_blackstone_slab[type=bottom,waterlogged=false] strict
fill ~129 ~25 ~193 ~130 ~25 ~193 minecraft:polished_blackstone_brick_slab[type=bottom,waterlogged=false] strict
fill ~134 ~25 ~193 ~135 ~25 ~193 minecraft:polished_blackstone_brick_slab[type=bottom,waterlogged=false] strict
setblock ~129 ~25 ~194 minecraft:cobbled_deepslate_slab[type=bottom,waterlogged=false] strict
setblock ~112 ~25 ~203 minecraft:polished_blackstone_brick_slab[type=bottom,waterlogged=false] strict
fill ~101 ~25 ~218 ~101 ~25 ~221 minecraft:quartz_slab[type=bottom,waterlogged=false] strict
setblock ~162 ~26 ~20 minecraft:campfire[facing=north,lit=true,signal_fire=false,waterlogged=false] strict
setblock ~94 ~26 ~25 minecraft:campfire[facing=north,lit=true,signal_fire=false,waterlogged=false] strict
fill ~188 ~26 ~32 ~188 ~26 ~33 minecraft:polished_blackstone_brick_slab[type=bottom,waterlogged=false] strict
fill ~187 ~26 ~47 ~187 ~26 ~48 minecraft:quartz_slab[type=bottom,waterlogged=false] strict
fill ~187 ~26 ~50 ~187 ~26 ~52 minecraft:quartz_slab[type=bottom,waterlogged=false] strict
setblock ~128 ~26 ~57 minecraft:mossy_stone_brick_slab[type=bottom,waterlogged=false] strict
fill ~125 ~26 ~58 ~126 ~26 ~58 minecraft:polished_blackstone_brick_slab[type=bottom,waterlogged=false] strict
setblock ~127 ~26 ~58 minecraft:polished_blackstone_slab[type=bottom,waterlogged=false] strict
setblock ~129 ~26 ~58 minecraft:polished_blackstone_brick_slab[type=bottom,waterlogged=false] strict
setblock ~130 ~26 ~58 minecraft:polished_blackstone_slab[type=bottom,waterlogged=false] strict
setblock ~131 ~26 ~58 minecraft:blackstone_slab[type=bottom,waterlogged=false] strict
setblock ~204 ~26 ~58 minecraft:skeleton_skull[rotation=0] strict
setblock ~124 ~26 ~63 minecraft:polished_blackstone_brick_slab[type=bottom,waterlogged=false] strict
fill ~94 ~26 ~68 ~98 ~26 ~68 minecraft:quartz_slab[type=bottom,waterlogged=false] strict
fill ~211 ~26 ~68 ~215 ~26 ~68 minecraft:quartz_slab[type=bottom,waterlogged=false] strict
fill ~105 ~26 ~72 ~106 ~26 ~72 minecraft:quartz_slab[type=bottom,waterlogged=false] strict
fill ~108 ~26 ~72 ~109 ~26 ~72 minecraft:quartz_slab[type=bottom,waterlogged=false] strict
fill ~105 ~26 ~74 ~106 ~26 ~74 minecraft:quartz_slab[type=bottom,waterlogged=false] strict
fill ~108 ~26 ~74 ~109 ~26 ~74 minecraft:quartz_slab[type=bottom,waterlogged=false] strict
fill ~147 ~26 ~76 ~150 ~26 ~76 minecraft:quartz_slab[type=bottom,waterlogged=false] strict
fill ~147 ~26 ~78 ~150 ~26 ~78 minecraft:quartz_slab[type=bottom,waterlogged=false] strict
fill ~17 ~26 ~86 ~18 ~26 ~86 minecraft:polished_blackstone_brick_slab[type=bottom,waterlogged=false] strict
setblock ~17 ~26 ~87 minecraft:polished_blackstone_brick_slab[type=bottom,waterlogged=false] strict
fill ~216 ~26 ~90 ~220 ~26 ~90 minecraft:quartz_slab[type=bottom,waterlogged=false] strict
fill ~38 ~26 ~92 ~38 ~26 ~95 minecraft:quartz_slab[type=bottom,waterlogged=false] strict
setblock ~96 ~26 ~92 minecraft:polished_blackstone_brick_slab[type=bottom,waterlogged=false] strict
fill ~216 ~26 ~92 ~219 ~26 ~92 minecraft:quartz_slab[type=bottom,waterlogged=false] strict
fill ~73 ~26 ~101 ~73 ~26 ~102 minecraft:quartz_slab[type=bottom,waterlogged=false] strict
fill ~75 ~26 ~101 ~75 ~26 ~102 minecraft:quartz_slab[type=bottom,waterlogged=false] strict
setblock ~73 ~26 ~104 minecraft:quartz_slab[type=bottom,waterlogged=false] strict
setblock ~75 ~26 ~104 minecraft:quartz_slab[type=bottom,waterlogged=false] strict
fill ~115 ~26 ~104 ~116 ~26 ~104 minecraft:polished_blackstone_brick_slab[type=bottom,waterlogged=false] strict
fill ~139 ~26 ~106 ~139 ~26 ~109 minecraft:quartz_slab[type=bottom,waterlogged=false] strict
fill ~141 ~26 ~106 ~141 ~26 ~109 minecraft:quartz_slab[type=bottom,waterlogged=false] strict
fill ~111 ~26 ~107 ~115 ~26 ~107 minecraft:quartz_slab[type=bottom,waterlogged=false] strict
fill ~136 ~26 ~107 ~138 ~26 ~107 minecraft:quartz_slab[type=bottom,waterlogged=false] strict
fill ~112 ~26 ~109 ~115 ~26 ~109 minecraft:quartz_slab[type=bottom,waterlogged=false] strict
fill ~136 ~26 ~109 ~138 ~26 ~109 minecraft:quartz_slab[type=bottom,waterlogged=false] strict
fill ~106 ~26 ~114 ~111 ~26 ~114 minecraft:quartz_slab[type=bottom,waterlogged=false] strict
fill ~106 ~26 ~116 ~111 ~26 ~116 minecraft:quartz_slab[type=bottom,waterlogged=false] strict
fill ~147 ~26 ~120 ~147 ~26 ~125 minecraft:quartz_slab[type=bottom,waterlogged=false] strict
fill ~149 ~26 ~120 ~149 ~26 ~125 minecraft:quartz_slab[type=bottom,waterlogged=false] strict
setblock ~153 ~26 ~120 minecraft:polished_blackstone_brick_slab[type=bottom,waterlogged=false] strict
setblock ~58 ~26 ~125 minecraft:polished_blackstone_slab[type=bottom,waterlogged=false] strict
fill ~199 ~26 ~125 ~199 ~26 ~126 minecraft:blackstone_slab[type=bottom,waterlogged=false] strict
setblock ~58 ~26 ~126 minecraft:cobbled_deepslate_slab[type=bottom,waterlogged=false] strict
setblock ~58 ~26 ~127 minecraft:polished_blackstone_brick_slab[type=bottom,waterlogged=false] strict
setblock ~199 ~26 ~127 minecraft:polished_blackstone_brick_slab[type=bottom,waterlogged=false] strict
setblock ~57 ~26 ~128 minecraft:stone_brick_slab[type=bottom,waterlogged=false] strict
setblock ~200 ~26 ~128 minecraft:mossy_stone_brick_slab[type=bottom,waterlogged=false] strict
setblock ~58 ~26 ~129 minecraft:polished_blackstone_brick_slab[type=bottom,waterlogged=false] strict
fill ~199 ~26 ~129 ~199 ~26 ~131 minecraft:polished_blackstone_brick_slab[type=bottom,waterlogged=false] strict
setblock ~58 ~26 ~130 minecraft:polished_blackstone_slab[type=bottom,waterlogged=false] strict
setblock ~58 ~26 ~131 minecraft:polished_blackstone_brick_slab[type=bottom,waterlogged=false] strict
fill ~107 ~26 ~131 ~107 ~26 ~132 minecraft:quartz_slab[type=bottom,waterlogged=false] strict
fill ~109 ~26 ~131 ~109 ~26 ~132 minecraft:quartz_slab[type=bottom,waterlogged=false] strict
fill ~147 ~26 ~131 ~147 ~26 ~135 minecraft:quartz_slab[type=bottom,waterlogged=false] strict
fill ~149 ~26 ~131 ~149 ~26 ~135 minecraft:quartz_slab[type=bottom,waterlogged=false] strict
fill ~107 ~26 ~134 ~107 ~26 ~135 minecraft:quartz_slab[type=bottom,waterlogged=false] strict
fill ~109 ~26 ~134 ~109 ~26 ~135 minecraft:quartz_slab[type=bottom,waterlogged=false] strict
setblock ~100 ~26 ~137 minecraft:polished_blackstone_brick_slab[type=bottom,waterlogged=false] strict
fill ~151 ~26 ~139 ~153 ~26 ~139 minecraft:quartz_slab[type=bottom,waterlogged=false] strict
fill ~155 ~26 ~139 ~156 ~26 ~139 minecraft:quartz_slab[type=bottom,waterlogged=false] strict
fill ~151 ~26 ~141 ~153 ~26 ~141 minecraft:quartz_slab[type=bottom,waterlogged=false] strict
fill ~155 ~26 ~141 ~156 ~26 ~141 minecraft:quartz_slab[type=bottom,waterlogged=false] strict
fill ~136 ~26 ~147 ~138 ~26 ~147 minecraft:quartz_slab[type=bottom,waterlogged=false] strict
fill ~140 ~26 ~147 ~144 ~26 ~147 minecraft:quartz_slab[type=bottom,waterlogged=false] strict
fill ~136 ~26 ~149 ~138 ~26 ~149 minecraft:quartz_slab[type=bottom,waterlogged=false] strict
fill ~140 ~26 ~149 ~145 ~26 ~149 minecraft:quartz_slab[type=bottom,waterlogged=false] strict
setblock ~136 ~26 ~150 minecraft:polished_blackstone_brick_slab[type=bottom,waterlogged=false] strict
setblock ~139 ~26 ~150 minecraft:polished_blackstone_brick_slab[type=bottom,waterlogged=false] strict
setblock ~137 ~26 ~151 minecraft:polished_blackstone_brick_slab[type=bottom,waterlogged=false] strict
setblock ~140 ~26 ~151 minecraft:polished_blackstone_brick_slab[type=bottom,waterlogged=false] strict
fill ~116 ~26 ~152 ~120 ~26 ~152 minecraft:quartz_slab[type=bottom,waterlogged=false] strict
fill ~116 ~26 ~154 ~120 ~26 ~154 minecraft:quartz_slab[type=bottom,waterlogged=false] strict
setblock ~164 ~26 ~160 minecraft:polished_blackstone_brick_slab[type=bottom,waterlogged=false] strict
setblock ~166 ~26 ~184 minecraft:polished_blackstone_brick_slab[type=bottom,waterlogged=false] strict
setblock ~135 ~26 ~198 minecraft:polished_blackstone_brick_slab[type=bottom,waterlogged=false] strict
fill ~125 ~26 ~199 ~126 ~26 ~199 minecraft:polished_blackstone_brick_slab[type=bottom,waterlogged=false] strict
setblock ~127 ~26 ~199 minecraft:cobbled_deepslate_slab[type=bottom,waterlogged=false] strict
setblock ~129 ~26 ~199 minecraft:polished_blackstone_brick_slab[type=bottom,waterlogged=false] strict
fill ~130 ~26 ~199 ~131 ~26 ~199 minecraft:polished_blackstone_slab[type=bottom,waterlogged=false] strict
setblock ~128 ~26 ~200 minecraft:stone_brick_slab[type=bottom,waterlogged=false] strict
setblock ~100 ~26 ~221 minecraft:quartz_slab[type=bottom,waterlogged=false] strict
setblock ~65 ~27 ~49 minecraft:crimson_slab[type=bottom,waterlogged=false] strict
setblock ~59 ~27 ~51 minecraft:crimson_slab[type=bottom,waterlogged=false] strict
setblock ~128 ~27 ~53 minecraft:stone_brick_slab[type=bottom,waterlogged=false] strict
fill ~125 ~27 ~54 ~126 ~27 ~54 minecraft:stone_brick_slab[type=bottom,waterlogged=false] strict
setblock ~127 ~27 ~54 minecraft:polished_andesite_slab[type=bottom,waterlogged=false] strict
setblock ~129 ~27 ~54 minecraft:andesite_slab[type=bottom,waterlogged=false] strict
setblock ~130 ~27 ~54 minecraft:stone_brick_slab[type=bottom,waterlogged=false] strict
setblock ~131 ~27 ~54 minecraft:mossy_stone_brick_slab[type=bottom,waterlogged=false] strict
setblock ~33 ~27 ~62 minecraft:polished_blackstone_brick_slab[type=bottom,waterlogged=false] strict
setblock ~33 ~27 ~64 minecraft:polished_blackstone_brick_slab[type=bottom,waterlogged=false] strict
fill ~33 ~27 ~67 ~33 ~27 ~69 minecraft:polished_blackstone_brick_slab[type=bottom,waterlogged=false] strict
setblock ~25 ~27 ~69 minecraft:polished_blackstone_brick_slab[type=bottom,waterlogged=false] strict
setblock ~88 ~27 ~69 minecraft:crimson_slab[type=bottom,waterlogged=false] strict
fill ~105 ~27 ~73 ~106 ~27 ~73 minecraft:quartz_slab[type=bottom,waterlogged=false] strict
fill ~108 ~27 ~73 ~109 ~27 ~73 minecraft:quartz_slab[type=bottom,waterlogged=false] strict
setblock ~86 ~27 ~75 minecraft:crimson_slab[type=bottom,waterlogged=false] strict
fill ~147 ~27 ~77 ~150 ~27 ~77 minecraft:quartz_slab[type=bottom,waterlogged=false] strict
setblock ~53 ~27 ~80 minecraft:crimson_slab[type=bottom,waterlogged=false] strict
setblock ~57 ~27 ~84 minecraft:crimson_slab[type=bottom,waterlogged=false] strict
setblock ~21 ~27 ~87 minecraft:polished_blackstone_brick_slab[type=bottom,waterlogged=false] strict
fill ~216 ~27 ~91 ~220 ~27 ~91 minecraft:quartz_slab[type=bottom,waterlogged=false] strict
setblock ~99 ~27 ~95 minecraft:polished_blackstone_brick_slab[type=bottom,waterlogged=false] strict
setblock ~157 ~27 ~95 minecraft:polished_blackstone_brick_slab[type=bottom,waterlogged=false] strict
setblock ~164 ~27 ~96 minecraft:polished_blackstone_brick_slab[type=bottom,waterlogged=false] strict
fill ~74 ~27 ~101 ~74 ~27 ~102 minecraft:quartz_slab[type=bottom,waterlogged=false] strict
setblock ~74 ~27 ~104 minecraft:quartz_slab[type=bottom,waterlogged=false] strict
fill ~140 ~27 ~106 ~140 ~27 ~109 minecraft:quartz_slab[type=bottom,waterlogged=false] strict
fill ~111 ~27 ~108 ~115 ~27 ~108 minecraft:quartz_slab[type=bottom,waterlogged=false] strict
fill ~136 ~27 ~108 ~139 ~27 ~108 minecraft:quartz_slab[type=bottom,waterlogged=false] strict
fill ~106 ~27 ~115 ~111 ~27 ~115 minecraft:quartz_slab[type=bottom,waterlogged=false] strict
fill ~148 ~27 ~120 ~148 ~27 ~125 minecraft:quartz_slab[type=bottom,waterlogged=false] strict
setblock ~54 ~27 ~125 minecraft:andesite_slab[type=bottom,waterlogged=false] strict
fill ~54 ~27 ~126 ~54 ~27 ~127 minecraft:stone_brick_slab[type=bottom,waterlogged=false] strict
setblock ~203 ~27 ~126 minecraft:polished_andesite_slab[type=bottom,waterlogged=false] strict
fill ~204 ~27 ~126 ~204 ~27 ~127 minecraft:stone_brick_slab[type=bottom,waterlogged=false] strict
setblock ~203 ~27 ~127 minecraft:cobblestone_slab[type=bottom,waterlogged=false] strict
setblock ~53 ~27 ~128 minecraft:mossy_stone_brick_slab[type=bottom,waterlogged=false] strict
fill ~204 ~27 ~128 ~204 ~27 ~129 minecraft:polished_andesite_slab[type=bottom,waterlogged=false] strict
fill ~54 ~27 ~129 ~54 ~27 ~131 minecraft:stone_brick_slab[type=bottom,waterlogged=false] strict
setblock ~203 ~27 ~129 minecraft:cobblestone_slab[type=bottom,waterlogged=false] strict
setblock ~203 ~27 ~130 minecraft:polished_andesite_slab[type=bottom,waterlogged=false] strict
setblock ~204 ~27 ~130 minecraft:andesite_slab[type=bottom,waterlogged=false] strict
fill ~108 ~27 ~131 ~108 ~27 ~132 minecraft:quartz_slab[type=bottom,waterlogged=false] strict
fill ~148 ~27 ~131 ~148 ~27 ~135 minecraft:quartz_slab[type=bottom,waterlogged=false] strict
fill ~108 ~27 ~134 ~108 ~27 ~135 minecraft:quartz_slab[type=bottom,waterlogged=false] strict
setblock ~99 ~27 ~138 minecraft:quartz_slab[type=bottom,waterlogged=false] strict
fill ~151 ~27 ~140 ~153 ~27 ~140 minecraft:quartz_slab[type=bottom,waterlogged=false] strict
fill ~155 ~27 ~140 ~156 ~27 ~140 minecraft:quartz_slab[type=bottom,waterlogged=false] strict
fill ~136 ~27 ~148 ~138 ~27 ~148 minecraft:quartz_slab[type=bottom,waterlogged=false] strict
fill ~140 ~27 ~148 ~145 ~27 ~148 minecraft:quartz_slab[type=bottom,waterlogged=false] strict
setblock ~138 ~27 ~149 minecraft:polished_blackstone_brick_slab[type=bottom,waterlogged=false] strict
fill ~116 ~27 ~153 ~120 ~27 ~153 minecraft:quartz_slab[type=bottom,waterlogged=false] strict
setblock ~41 ~27 ~159 minecraft:polished_blackstone_brick_slab[type=bottom,waterlogged=false] strict
setblock ~38 ~27 ~160 minecraft:polished_blackstone_brick_slab[type=bottom,waterlogged=false] strict
setblock ~157 ~27 ~161 minecraft:polished_blackstone_brick_slab[type=bottom,waterlogged=false] strict
setblock ~96 ~27 ~164 minecraft:polished_blackstone_brick_slab[type=bottom,waterlogged=false] strict
setblock ~153 ~27 ~180 minecraft:campfire[facing=north,lit=true,signal_fire=false,waterlogged=false] strict
setblock ~167 ~27 ~185 minecraft:polished_blackstone_brick_slab[type=bottom,waterlogged=false] strict
fill ~208 ~27 ~186 ~211 ~27 ~186 minecraft:quartz_slab[type=bottom,waterlogged=false] strict
fill ~208 ~27 ~188 ~211 ~27 ~188 minecraft:quartz_slab[type=bottom,waterlogged=false] strict
setblock ~146 ~27 ~192 minecraft:polished_blackstone_brick_slab[type=bottom,waterlogged=false] strict
fill ~126 ~27 ~203 ~126 ~27 ~204 minecraft:andesite_slab[type=bottom,waterlogged=false] strict
setblock ~127 ~27 ~203 minecraft:polished_andesite_slab[type=bottom,waterlogged=false] strict
setblock ~129 ~27 ~203 minecraft:andesite_slab[type=bottom,waterlogged=false] strict
setblock ~130 ~27 ~203 minecraft:stone_brick_slab[type=bottom,waterlogged=false] strict
fill ~127 ~27 ~204 ~128 ~27 ~204 minecraft:stone_brick_slab[type=bottom,waterlogged=false] strict
fill ~129 ~27 ~204 ~130 ~27 ~204 minecraft:polished_andesite_slab[type=bottom,waterlogged=false] strict
setblock ~79 ~27 ~224 minecraft:polished_blackstone_brick_slab[type=bottom,waterlogged=false] strict
setblock ~78 ~27 ~225 minecraft:polished_blackstone_brick_slab[type=bottom,waterlogged=false] strict
setblock ~78 ~27 ~229 minecraft:polished_blackstone_brick_slab[type=bottom,waterlogged=false] strict
fill ~187 ~28 ~30 ~192 ~28 ~30 minecraft:polished_blackstone_brick_slab[type=bottom,waterlogged=false] strict
fill ~182 ~28 ~36 ~182 ~28 ~37 minecraft:polished_blackstone_brick_slab[type=bottom,waterlogged=false] strict
setblock ~26 ~28 ~69 minecraft:polished_blackstone_brick_slab[type=bottom,waterlogged=false] strict
setblock ~27 ~28 ~69 minecraft:cobbled_deepslate_slab[type=bottom,waterlogged=false] strict
setblock ~163 ~28 ~73 minecraft:campfire[facing=north,lit=true,signal_fire=false,waterlogged=false] strict
setblock ~21 ~28 ~88 minecraft:cobbled_deepslate_slab[type=bottom,waterlogged=false] strict
fill ~31 ~28 ~89 ~32 ~28 ~89 minecraft:quartz_slab[type=bottom,waterlogged=false] strict
setblock ~122 ~28 ~93 minecraft:fire strict
setblock ~134 ~28 ~93 minecraft:fire strict
setblock ~121 ~28 ~94 minecraft:fire strict
setblock ~123 ~28 ~94 minecraft:fire strict
setblock ~133 ~28 ~94 minecraft:fire strict
setblock ~135 ~28 ~94 minecraft:fire strict
setblock ~122 ~28 ~95 minecraft:fire strict
setblock ~134 ~28 ~95 minecraft:fire strict
setblock ~161 ~28 ~99 minecraft:polished_blackstone_brick_slab[type=bottom,waterlogged=false] strict
setblock ~122 ~28 ~105 minecraft:quartz_slab[type=bottom,waterlogged=false] strict
setblock ~134 ~28 ~105 minecraft:quartz_slab[type=bottom,waterlogged=false] strict
setblock ~153 ~28 ~110 minecraft:quartz_slab[type=bottom,waterlogged=false] strict
setblock ~192 ~28 ~111 minecraft:polished_blackstone_brick_slab[type=bottom,waterlogged=false] strict
setblock ~192 ~28 ~113 minecraft:polished_blackstone_brick_slab[type=bottom,waterlogged=false] strict
setblock ~94 ~28 ~121 minecraft:fire strict
setblock ~162 ~28 ~121 minecraft:fire strict
setblock ~93 ~28 ~122 minecraft:fire strict
setblock ~95 ~28 ~122 minecraft:fire strict
setblock ~105 ~28 ~122 minecraft:quartz_slab[type=bottom,waterlogged=false] strict
setblock ~151 ~28 ~122 minecraft:quartz_slab[type=bottom,waterlogged=false] strict
setblock ~161 ~28 ~122 minecraft:fire strict
setblock ~163 ~28 ~122 minecraft:fire strict
setblock ~94 ~28 ~123 minecraft:fire strict
setblock ~159 ~28 ~123 minecraft:quartz_slab[type=bottom,waterlogged=false] strict
setblock ~162 ~28 ~123 minecraft:fire strict
setblock ~194 ~28 ~123 minecraft:polished_blackstone_brick_slab[type=bottom,waterlogged=false] strict
setblock ~94 ~28 ~133 minecraft:fire strict
setblock ~162 ~28 ~133 minecraft:fire strict
setblock ~93 ~28 ~134 minecraft:fire strict
setblock ~95 ~28 ~134 minecraft:fire strict
setblock ~105 ~28 ~134 minecraft:quartz_slab[type=bottom,waterlogged=false] strict
setblock ~151 ~28 ~134 minecraft:quartz_slab[type=bottom,waterlogged=false] strict
setblock ~161 ~28 ~134 minecraft:fire strict
setblock ~163 ~28 ~134 minecraft:fire strict
setblock ~94 ~28 ~135 minecraft:fire strict
setblock ~162 ~28 ~135 minecraft:fire strict
setblock ~198 ~28 ~138 minecraft:campfire[facing=north,lit=true,signal_fire=false,waterlogged=false] strict
fill ~64 ~28 ~142 ~64 ~28 ~143 minecraft:polished_blackstone_brick_slab[type=bottom,waterlogged=false] strict
setblock ~64 ~28 ~145 minecraft:polished_blackstone_brick_slab[type=bottom,waterlogged=false] strict
setblock ~122 ~28 ~151 minecraft:quartz_slab[type=bottom,waterlogged=false] strict
setblock ~134 ~28 ~151 minecraft:quartz_slab[type=bottom,waterlogged=false] strict
setblock ~39 ~28 ~161 minecraft:polished_blackstone_brick_slab[type=bottom,waterlogged=false] strict
setblock ~122 ~28 ~161 minecraft:fire strict
setblock ~134 ~28 ~161 minecraft:fire strict
setblock ~121 ~28 ~162 minecraft:fire strict
setblock ~123 ~28 ~162 minecraft:fire strict
setblock ~133 ~28 ~162 minecraft:fire strict
setblock ~135 ~28 ~162 minecraft:fire strict
setblock ~122 ~28 ~163 minecraft:fire strict
setblock ~134 ~28 ~163 minecraft:fire strict
setblock ~165 ~28 ~186 minecraft:polished_diorite_slab[type=bottom,waterlogged=false] strict
setblock ~167 ~28 ~186 minecraft:polished_diorite_slab[type=bottom,waterlogged=false] strict
fill ~53 ~28 ~187 ~54 ~28 ~187 minecraft:crimson_slab[type=top,waterlogged=false] strict
fill ~57 ~28 ~187 ~58 ~28 ~187 minecraft:crimson_slab[type=top,waterlogged=false] strict
fill ~208 ~28 ~187 ~211 ~28 ~187 minecraft:quartz_slab[type=bottom,waterlogged=false] strict
fill ~53 ~28 ~188 ~53 ~28 ~189 minecraft:crimson_slab[type=top,waterlogged=false] strict
fill ~58 ~28 ~188 ~58 ~28 ~189 minecraft:crimson_slab[type=top,waterlogged=false] strict
setblock ~135 ~28 ~190 minecraft:polished_blackstone_brick_slab[type=bottom,waterlogged=false] strict
setblock ~135 ~28 ~194 minecraft:polished_blackstone_brick_slab[type=bottom,waterlogged=false] strict
fill ~67 ~28 ~198 ~69 ~28 ~198 minecraft:crimson_slab[type=top,waterlogged=false] strict
setblock ~69 ~28 ~199 minecraft:crimson_slab[type=top,waterlogged=false] strict
setblock ~110 ~28 ~199 minecraft:polished_blackstone_brick_slab[type=bottom,waterlogged=false] strict
fill ~67 ~28 ~203 ~69 ~28 ~203 minecraft:crimson_slab[type=top,waterlogged=false] strict
fill ~75 ~28 ~229 ~76 ~28 ~229 minecraft:quartz_slab[type=bottom,waterlogged=false] strict
fill ~78 ~28 ~229 ~79 ~28 ~229 minecraft:quartz_slab[type=bottom,waterlogged=false] strict
fill ~75 ~28 ~231 ~76 ~28 ~231 minecraft:quartz_slab[type=bottom,waterlogged=false] strict
fill ~78 ~28 ~231 ~79 ~28 ~231 minecraft:quartz_slab[type=bottom,waterlogged=false] strict
setblock ~186 ~29 ~30 minecraft:polished_blackstone_brick_slab[type=bottom,waterlogged=false] strict
setblock ~182 ~29 ~33 minecraft:polished_blackstone_brick_slab[type=bottom,waterlogged=false] strict
setblock ~124 ~29 ~60 minecraft:lantern[hanging=false,waterlogged=false] strict
setblock ~110 ~29 ~64 minecraft:cobbled_deepslate_slab[type=bottom,waterlogged=false] strict
fill ~93 ~29 ~65 ~94 ~29 ~65 minecraft:quartz_slab[type=bottom,waterlogged=false] strict
setblock ~93 ~29 ~66 minecraft:quartz_slab[type=bottom,waterlogged=false] strict
fill ~90 ~29 ~67 ~91 ~29 ~67 minecraft:quartz_slab[type=bottom,waterlogged=false] strict
setblock ~109 ~29 ~68 minecraft:polished_blackstone_brick_slab[type=bottom,waterlogged=false] strict
setblock ~29 ~29 ~69 minecraft:polished_blackstone_brick_slab[type=bottom,waterlogged=false] strict
fill ~214 ~29 ~71 ~215 ~29 ~71 minecraft:quartz_slab[type=bottom,waterlogged=false] strict
setblock ~16 ~29 ~84 minecraft:polished_blackstone_brick_slab[type=bottom,waterlogged=false] strict
setblock ~18 ~29 ~84 minecraft:polished_blackstone_brick_slab[type=bottom,waterlogged=false] strict
setblock ~21 ~29 ~84 minecraft:cobbled_deepslate_slab[type=bottom,waterlogged=false] strict
setblock ~29 ~29 ~85 minecraft:quartz_slab[type=bottom,waterlogged=false] strict
setblock ~30 ~29 ~86 minecraft:quartz_slab[type=bottom,waterlogged=false] strict
setblock ~223 ~29 ~86 minecraft:quartz_slab[type=bottom,waterlogged=false] strict
setblock ~122 ~29 ~94 minecraft:fire strict
setblock ~134 ~29 ~94 minecraft:fire strict
setblock ~38 ~29 ~99 minecraft:quartz_slab[type=bottom,waterlogged=false] strict
setblock ~114 ~29 ~100 minecraft:quartz_slab[type=bottom,waterlogged=false] strict
setblock ~122 ~29 ~104 minecraft:campfire[facing=north,lit=true,signal_fire=false,waterlogged=false] strict
setblock ~134 ~29 ~104 minecraft:campfire[facing=north,lit=true,signal_fire=false,waterlogged=false] strict
setblock ~122 ~29 ~106 minecraft:quartz_slab[type=bottom,waterlogged=false] strict
setblock ~134 ~29 ~106 minecraft:quartz_slab[type=bottom,waterlogged=false] strict
setblock ~192 ~29 ~110 minecraft:polished_blackstone_brick_slab[type=bottom,waterlogged=false] strict
setblock ~94 ~29 ~122 minecraft:fire strict
setblock ~104 ~29 ~122 minecraft:campfire[facing=north,lit=true,signal_fire=false,waterlogged=false] strict
setblock ~106 ~29 ~122 minecraft:quartz_slab[type=bottom,waterlogged=false] strict
setblock ~150 ~29 ~122 minecraft:quartz_slab[type=bottom,waterlogged=false] strict
setblock ~152 ~29 ~122 minecraft:campfire[facing=north,lit=true,signal_fire=false,waterlogged=false] strict
setblock ~162 ~29 ~122 minecraft:fire strict
setblock ~60 ~29 ~124 minecraft:lantern[hanging=false,waterlogged=false] strict
setblock ~196 ~29 ~124 minecraft:lantern[hanging=false,waterlogged=false] strict
setblock ~60 ~29 ~132 minecraft:lantern[hanging=false,waterlogged=false] strict
setblock ~196 ~29 ~132 minecraft:lantern[hanging=false,waterlogged=false] strict
setblock ~94 ~29 ~134 minecraft:fire strict
setblock ~104 ~29 ~134 minecraft:campfire[facing=north,lit=true,signal_fire=false,waterlogged=false] strict
setblock ~106 ~29 ~134 minecraft:quartz_slab[type=bottom,waterlogged=false] strict
setblock ~150 ~29 ~134 minecraft:quartz_slab[type=bottom,waterlogged=false] strict
setblock ~152 ~29 ~134 minecraft:campfire[facing=north,lit=true,signal_fire=false,waterlogged=false] strict
setblock ~162 ~29 ~134 minecraft:fire strict
setblock ~64 ~29 ~141 minecraft:polished_blackstone_brick_slab[type=bottom,waterlogged=false] strict
setblock ~64 ~29 ~146 minecraft:polished_blackstone_brick_slab[type=bottom,waterlogged=false] strict
setblock ~122 ~29 ~150 minecraft:quartz_slab[type=bottom,waterlogged=false] strict
setblock ~134 ~29 ~150 minecraft:quartz_slab[type=bottom,waterlogged=false] strict
setblock ~122 ~29 ~152 minecraft:campfire[facing=north,lit=true,signal_fire=false,waterlogged=false] strict
setblock ~134 ~29 ~152 minecraft:campfire[facing=north,lit=true,signal_fire=false,waterlogged=false] strict
setblock ~39 ~29 ~162 minecraft:polished_blackstone_brick_slab[type=bottom,waterlogged=false] strict
