setblock ~22 ~39 ~124 minecraft:smooth_quartz_slab[type=top,waterlogged=false] strict
setblock ~234 ~39 ~124 minecraft:smooth_quartz_slab[type=top,waterlogged=false] strict
fill ~236 ~39 ~124 ~242 ~39 ~124 minecraft:smooth_quartz_slab[type=top,waterlogged=false] strict
setblock ~244 ~39 ~124 minecraft:smooth_quartz_slab[type=top,waterlogged=false] strict
setblock ~250 ~39 ~127 minecraft:spruce_slab[type=bottom,waterlogged=false] strict
setblock ~251 ~39 ~127 minecraft:spruce_slab[type=top,waterlogged=false] strict
setblock ~5 ~39 ~129 minecraft:spruce_slab[type=top,waterlogged=false] strict
setblock ~6 ~39 ~129 minecraft:spruce_slab[type=bottom,waterlogged=false] strict
setblock ~12 ~39 ~132 minecraft:smooth_quartz_slab[type=top,waterlogged=false] strict
fill ~14 ~39 ~132 ~20 ~39 ~132 minecraft:smooth_quartz_slab[type=top,waterlogged=false] strict
setblock ~22 ~39 ~132 minecraft:smooth_quartz_slab[type=top,waterlogged=false] strict
setblock ~234 ~39 ~132 minecraft:smooth_quartz_slab[type=top,waterlogged=false] strict
fill ~236 ~39 ~132 ~242 ~39 ~132 minecraft:smooth_quartz_slab[type=top,waterlogged=false] strict
setblock ~244 ~39 ~132 minecraft:smooth_quartz_slab[type=top,waterlogged=false] strict
fill ~12 ~39 ~133 ~22 ~39 ~133 minecraft:smooth_quartz_slab[type=bottom,waterlogged=false] strict
fill ~234 ~39 ~133 ~244 ~39 ~133 minecraft:smooth_quartz_slab[type=bottom,waterlogged=false] strict
setblock ~143 ~39 ~137 minecraft:quartz_slab[type=bottom,waterlogged=false] strict
setblock ~142 ~39 ~138 minecraft:quartz_slab[type=bottom,waterlogged=false] strict
setblock ~143 ~39 ~139 minecraft:quartz_slab[type=bottom,waterlogged=false] strict
fill ~123 ~39 ~234 ~123 ~39 ~244 minecraft:smooth_quartz_slab[type=bottom,waterlogged=false] strict
setblock ~124 ~39 ~234 minecraft:smooth_quartz_slab[type=top,waterlogged=false] strict
setblock ~132 ~39 ~234 minecraft:smooth_quartz_slab[type=top,waterlogged=false] strict
fill ~133 ~39 ~234 ~133 ~39 ~244 minecraft:smooth_quartz_slab[type=bottom,waterlogged=false] strict
fill ~124 ~39 ~236 ~124 ~39 ~242 minecraft:smooth_quartz_slab[type=top,waterlogged=false] strict
fill ~132 ~39 ~236 ~132 ~39 ~242 minecraft:smooth_quartz_slab[type=top,waterlogged=false] strict
setblock ~124 ~39 ~244 minecraft:smooth_quartz_slab[type=top,waterlogged=false] strict
setblock ~132 ~39 ~244 minecraft:smooth_quartz_slab[type=top,waterlogged=false] strict
setblock ~129 ~39 ~250 minecraft:spruce_slab[type=bottom,waterlogged=false] strict
setblock ~129 ~39 ~251 minecraft:spruce_slab[type=top,waterlogged=false] strict
setblock ~128 ~40 ~5 minecraft:spruce_slab[type=bottom,waterlogged=false] strict
setblock ~129 ~40 ~7 minecraft:spruce_slab[type=top,waterlogged=false] strict
fill ~125 ~40 ~12 ~125 ~40 ~22 minecraft:smooth_quartz_slab[type=bottom,waterlogged=false] strict
setblock ~126 ~40 ~12 minecraft:smooth_quartz_slab[type=top,waterlogged=false] strict
setblock ~130 ~40 ~12 minecraft:smooth_quartz_slab[type=top,waterlogged=false] strict
fill ~131 ~40 ~12 ~131 ~40 ~22 minecraft:smooth_quartz_slab[type=bottom,waterlogged=false] strict
fill ~126 ~40 ~14 ~126 ~40 ~20 minecraft:smooth_quartz_slab[type=top,waterlogged=false] strict
fill ~130 ~40 ~14 ~130 ~40 ~20 minecraft:smooth_quartz_slab[type=top,waterlogged=false] strict
setblock ~106 ~40 ~16 minecraft:lantern[hanging=false,waterlogged=false] strict
setblock ~112 ~40 ~16 minecraft:lantern[hanging=false,waterlogged=false] strict
setblock ~144 ~40 ~16 minecraft:lantern[hanging=false,waterlogged=false] strict
setblock ~150 ~40 ~16 minecraft:lantern[hanging=false,waterlogged=false] strict
setblock ~106 ~40 ~22 minecraft:lantern[hanging=false,waterlogged=false] strict
setblock ~112 ~40 ~22 minecraft:lantern[hanging=false,waterlogged=false] strict
setblock ~126 ~40 ~22 minecraft:smooth_quartz_slab[type=top,waterlogged=false] strict
setblock ~130 ~40 ~22 minecraft:smooth_quartz_slab[type=top,waterlogged=false] strict
setblock ~144 ~40 ~22 minecraft:lantern[hanging=false,waterlogged=false] strict
setblock ~150 ~40 ~22 minecraft:lantern[hanging=false,waterlogged=false] strict
setblock ~119 ~40 ~46 minecraft:lantern[hanging=false,waterlogged=false] strict
setblock ~125 ~40 ~46 minecraft:lantern[hanging=false,waterlogged=false] strict
setblock ~131 ~40 ~46 minecraft:lantern[hanging=false,waterlogged=false] strict
setblock ~137 ~40 ~46 minecraft:lantern[hanging=false,waterlogged=false] strict
setblock ~204 ~40 ~46 minecraft:lantern[hanging=false,waterlogged=false] strict
setblock ~119 ~40 ~52 minecraft:lantern[hanging=false,waterlogged=false] strict
setblock ~125 ~40 ~52 minecraft:lantern[hanging=false,waterlogged=false] strict
setblock ~131 ~40 ~52 minecraft:lantern[hanging=false,waterlogged=false] strict
setblock ~137 ~40 ~52 minecraft:lantern[hanging=false,waterlogged=false] strict
setblock ~210 ~40 ~52 minecraft:lantern[hanging=false,waterlogged=false] strict
setblock ~16 ~40 ~106 minecraft:lantern[hanging=false,waterlogged=false] strict
setblock ~22 ~40 ~106 minecraft:lantern[hanging=false,waterlogged=false] strict
setblock ~234 ~40 ~106 minecraft:lantern[hanging=false,waterlogged=false] strict
setblock ~240 ~40 ~106 minecraft:lantern[hanging=false,waterlogged=false] strict
setblock ~16 ~40 ~112 minecraft:lantern[hanging=false,waterlogged=false] strict
setblock ~22 ~40 ~112 minecraft:lantern[hanging=false,waterlogged=false] strict
setblock ~234 ~40 ~112 minecraft:lantern[hanging=false,waterlogged=false] strict
setblock ~240 ~40 ~112 minecraft:lantern[hanging=false,waterlogged=false] strict
setblock ~46 ~40 ~119 minecraft:lantern[hanging=false,waterlogged=false] strict
setblock ~52 ~40 ~119 minecraft:lantern[hanging=false,waterlogged=false] strict
setblock ~204 ~40 ~119 minecraft:lantern[hanging=false,waterlogged=false] strict
setblock ~210 ~40 ~119 minecraft:lantern[hanging=false,waterlogged=false] strict
fill ~12 ~40 ~125 ~22 ~40 ~125 minecraft:smooth_quartz_slab[type=bottom,waterlogged=false] strict
setblock ~46 ~40 ~125 minecraft:lantern[hanging=false,waterlogged=false] strict
setblock ~52 ~40 ~125 minecraft:lantern[hanging=false,waterlogged=false] strict
setblock ~204 ~40 ~125 minecraft:lantern[hanging=false,waterlogged=false] strict
setblock ~210 ~40 ~125 minecraft:lantern[hanging=false,waterlogged=false] strict
fill ~234 ~40 ~125 ~244 ~40 ~125 minecraft:smooth_quartz_slab[type=bottom,waterlogged=false] strict
setblock ~12 ~40 ~126 minecraft:smooth_quartz_slab[type=top,waterlogged=false] strict
fill ~14 ~40 ~126 ~20 ~40 ~126 minecraft:smooth_quartz_slab[type=top,waterlogged=false] strict
setblock ~22 ~40 ~126 minecraft:smooth_quartz_slab[type=top,waterlogged=false] strict
setblock ~234 ~40 ~126 minecraft:smooth_quartz_slab[type=top,waterlogged=false] strict
fill ~236 ~40 ~126 ~242 ~40 ~126 minecraft:smooth_quartz_slab[type=top,waterlogged=false] strict
setblock ~244 ~40 ~126 minecraft:smooth_quartz_slab[type=top,waterlogged=false] strict
setblock ~7 ~40 ~127 minecraft:spruce_slab[type=top,waterlogged=false] strict
setblock ~5 ~40 ~128 minecraft:spruce_slab[type=bottom,waterlogged=false] strict
setblock ~251 ~40 ~128 minecraft:spruce_slab[type=bottom,waterlogged=false] strict
setblock ~249 ~40 ~129 minecraft:spruce_slab[type=top,waterlogged=false] strict
setblock ~12 ~40 ~130 minecraft:smooth_quartz_slab[type=top,waterlogged=false] strict
fill ~14 ~40 ~130 ~20 ~40 ~130 minecraft:smooth_quartz_slab[type=top,waterlogged=false] strict
setblock ~22 ~40 ~130 minecraft:smooth_quartz_slab[type=top,waterlogged=false] strict
setblock ~234 ~40 ~130 minecraft:smooth_quartz_slab[type=top,waterlogged=false] strict
fill ~236 ~40 ~130 ~242 ~40 ~130 minecraft:smooth_quartz_slab[type=top,waterlogged=false] strict
setblock ~244 ~40 ~130 minecraft:smooth_quartz_slab[type=top,waterlogged=false] strict
fill ~12 ~40 ~131 ~22 ~40 ~131 minecraft:smooth_quartz_slab[type=bottom,waterlogged=false] strict
setblock ~46 ~40 ~131 minecraft:lantern[hanging=false,waterlogged=false] strict
setblock ~52 ~40 ~131 minecraft:lantern[hanging=false,waterlogged=false] strict
setblock ~204 ~40 ~131 minecraft:lantern[hanging=false,waterlogged=false] strict
setblock ~210 ~40 ~131 minecraft:lantern[hanging=false,waterlogged=false] strict
fill ~234 ~40 ~131 ~244 ~40 ~131 minecraft:smooth_quartz_slab[type=bottom,waterlogged=false] strict
setblock ~46 ~40 ~137 minecraft:lantern[hanging=false,waterlogged=false] strict
setblock ~52 ~40 ~137 minecraft:lantern[hanging=false,waterlogged=false] strict
setblock ~204 ~40 ~137 minecraft:lantern[hanging=false,waterlogged=false] strict
setblock ~210 ~40 ~137 minecraft:lantern[hanging=false,waterlogged=false] strict
setblock ~16 ~40 ~144 minecraft:lantern[hanging=false,waterlogged=false] strict
setblock ~22 ~40 ~144 minecraft:lantern[hanging=false,waterlogged=false] strict
setblock ~234 ~40 ~144 minecraft:lantern[hanging=false,waterlogged=false] strict
setblock ~240 ~40 ~144 minecraft:lantern[hanging=false,waterlogged=false] strict
setblock ~16 ~40 ~150 minecraft:lantern[hanging=false,waterlogged=false] strict
setblock ~22 ~40 ~150 minecraft:lantern[hanging=false,waterlogged=false] strict
setblock ~234 ~40 ~150 minecraft:lantern[hanging=false,waterlogged=false] strict
setblock ~240 ~40 ~150 minecraft:lantern[hanging=false,waterlogged=false] strict
setblock ~119 ~40 ~204 minecraft:lantern[hanging=false,waterlogged=false] strict
setblock ~125 ~40 ~204 minecraft:lantern[hanging=false,waterlogged=false] strict
setblock ~131 ~40 ~204 minecraft:lantern[hanging=false,waterlogged=false] strict
setblock ~137 ~40 ~204 minecraft:lantern[hanging=false,waterlogged=false] strict
setblock ~119 ~40 ~210 minecraft:lantern[hanging=false,waterlogged=false] strict
setblock ~125 ~40 ~210 minecraft:lantern[hanging=false,waterlogged=false] strict
setblock ~131 ~40 ~210 minecraft:lantern[hanging=false,waterlogged=false] strict
setblock ~137 ~40 ~210 minecraft:lantern[hanging=false,waterlogged=false] strict
setblock ~106 ~40 ~234 minecraft:lantern[hanging=false,waterlogged=false] strict
setblock ~112 ~40 ~234 minecraft:lantern[hanging=false,waterlogged=false] strict
fill ~125 ~40 ~234 ~125 ~40 ~244 minecraft:smooth_quartz_slab[type=bottom,waterlogged=false] strict
setblock ~126 ~40 ~234 minecraft:smooth_quartz_slab[type=top,waterlogged=false] strict
setblock ~130 ~40 ~234 minecraft:smooth_quartz_slab[type=top,waterlogged=false] strict
fill ~131 ~40 ~234 ~131 ~40 ~244 minecraft:smooth_quartz_slab[type=bottom,waterlogged=false] strict
setblock ~144 ~40 ~234 minecraft:lantern[hanging=false,waterlogged=false] strict
setblock ~150 ~40 ~234 minecraft:lantern[hanging=false,waterlogged=false] strict
fill ~126 ~40 ~236 ~126 ~40 ~242 minecraft:smooth_quartz_slab[type=top,waterlogged=false] strict
fill ~130 ~40 ~236 ~130 ~40 ~242 minecraft:smooth_quartz_slab[type=top,waterlogged=false] strict
setblock ~106 ~40 ~240 minecraft:lantern[hanging=false,waterlogged=false] strict
setblock ~112 ~40 ~240 minecraft:lantern[hanging=false,waterlogged=false] strict
setblock ~144 ~40 ~240 minecraft:lantern[hanging=false,waterlogged=false] strict
setblock ~150 ~40 ~240 minecraft:lantern[hanging=false,waterlogged=false] strict
setblock ~126 ~40 ~244 minecraft:smooth_quartz_slab[type=top,waterlogged=false] strict
setblock ~130 ~40 ~244 minecraft:smooth_quartz_slab[type=top,waterlogged=false] strict
setblock ~127 ~40 ~249 minecraft:spruce_slab[type=top,waterlogged=false] strict
setblock ~128 ~40 ~251 minecraft:spruce_slab[type=bottom,waterlogged=false] strict
fill ~127 ~41 ~12 ~127 ~41 ~22 minecraft:smooth_quartz_slab[type=bottom,waterlogged=false] strict
setblock ~128 ~41 ~12 minecraft:smooth_quartz_slab[type=top,waterlogged=false] strict
fill ~129 ~41 ~12 ~129 ~41 ~22 minecraft:smooth_quartz_slab[type=bottom,waterlogged=false] strict
fill ~128 ~41 ~14 ~128 ~41 ~20 minecraft:smooth_quartz_slab[type=top,waterlogged=false] strict
setblock ~147 ~41 ~20 minecraft:wall_torch[facing=south] strict
setblock ~128 ~41 ~22 minecraft:smooth_quartz_slab[type=top,waterlogged=false] strict
setblock ~20 ~41 ~109 minecraft:wall_torch[facing=east] strict
fill ~12 ~41 ~127 ~22 ~41 ~127 minecraft:smooth_quartz_slab[type=bottom,waterlogged=false] strict
fill ~234 ~41 ~127 ~244 ~41 ~127 minecraft:smooth_quartz_slab[type=bottom,waterlogged=false] strict
setblock ~12 ~41 ~128 minecraft:smooth_quartz_slab[type=top,waterlogged=false] strict
fill ~14 ~41 ~128 ~20 ~41 ~128 minecraft:smooth_quartz_slab[type=top,waterlogged=false] strict
setblock ~22 ~41 ~128 minecraft:smooth_quartz_slab[type=top,waterlogged=false] strict
setblock ~234 ~41 ~128 minecraft:smooth_quartz_slab[type=top,waterlogged=false] strict
fill ~236 ~41 ~128 ~242 ~41 ~128 minecraft:smooth_quartz_slab[type=top,waterlogged=false] strict
setblock ~244 ~41 ~128 minecraft:smooth_quartz_slab[type=top,waterlogged=false] strict
fill ~12 ~41 ~129 ~22 ~41 ~129 minecraft:smooth_quartz_slab[type=bottom,waterlogged=false] strict
fill ~234 ~41 ~129 ~244 ~41 ~129 minecraft:smooth_quartz_slab[type=bottom,waterlogged=false] strict
setblock ~236 ~41 ~147 minecraft:wall_torch[facing=west] strict
fill ~127 ~41 ~234 ~127 ~41 ~244 minecraft:smooth_quartz_slab[type=bottom,waterlogged=false] strict
setblock ~128 ~41 ~234 minecraft:smooth_quartz_slab[type=top,waterlogged=false] strict
fill ~129 ~41 ~234 ~129 ~41 ~244 minecraft:smooth_quartz_slab[type=bottom,waterlogged=false] strict
setblock ~109 ~41 ~236 minecraft:wall_torch[facing=north] strict
fill ~128 ~41 ~236 ~128 ~41 ~242 minecraft:smooth_quartz_slab[type=top,waterlogged=false] strict
setblock ~128 ~41 ~244 minecraft:smooth_quartz_slab[type=top,waterlogged=false] strict
setblock ~125 ~42 ~3 minecraft:lantern[hanging=false,waterlogged=false] strict
setblock ~131 ~42 ~3 minecraft:lantern[hanging=false,waterlogged=false] strict
setblock ~125 ~42 ~9 minecraft:lantern[hanging=false,waterlogged=false] strict
setblock ~131 ~42 ~9 minecraft:lantern[hanging=false,waterlogged=false] strict
fill ~119 ~42 ~119 ~131 ~42 ~119 minecraft:smooth_quartz_slab[type=bottom,waterlogged=false] strict
fill ~119 ~42 ~120 ~119 ~42 ~130 minecraft:smooth_quartz_slab[type=bottom,waterlogged=false] strict
setblock ~3 ~42 ~125 minecraft:lantern[hanging=false,waterlogged=false] strict
setblock ~9 ~42 ~125 minecraft:lantern[hanging=false,waterlogged=false] strict
setblock ~137 ~42 ~125 minecraft:smooth_quartz_slab[type=bottom,waterlogged=false] strict
setblock ~247 ~42 ~125 minecraft:lantern[hanging=false,waterlogged=false] strict
setblock ~253 ~42 ~125 minecraft:lantern[hanging=false,waterlogged=false] strict
fill ~137 ~42 ~127 ~137 ~42 ~137 minecraft:smooth_quartz_slab[type=bottom,waterlogged=false] strict
setblock ~3 ~42 ~131 minecraft:lantern[hanging=false,waterlogged=false] strict
setblock ~9 ~42 ~131 minecraft:lantern[hanging=false,waterlogged=false] strict
setblock ~247 ~42 ~131 minecraft:lantern[hanging=false,waterlogged=false] strict
setblock ~253 ~42 ~131 minecraft:lantern[hanging=false,waterlogged=false] strict
fill ~124 ~42 ~137 ~136 ~42 ~137 minecraft:smooth_quartz_slab[type=bottom,waterlogged=false] strict
fill ~215 ~42 ~203 ~216 ~42 ~203 minecraft:smooth_red_sandstone_slab[type=bottom,waterlogged=false] strict
fill ~228 ~42 ~203 ~229 ~42 ~203 minecraft:smooth_red_sandstone_slab[type=bottom,waterlogged=false] strict
fill ~213 ~42 ~204 ~214 ~42 ~204 minecraft:smooth_red_sandstone_slab[type=bottom,waterlogged=false] strict
fill ~230 ~42 ~204 ~231 ~42 ~204 minecraft:smooth_red_sandstone_slab[type=bottom,waterlogged=false] strict
fill ~232 ~42 ~205 ~233 ~42 ~205 minecraft:smooth_red_sandstone_slab[type=bottom,waterlogged=false] strict
fill ~233 ~42 ~206 ~234 ~42 ~206 minecraft:smooth_red_sandstone_slab[type=bottom,waterlogged=false] strict
setblock ~235 ~42 ~207 minecraft:smooth_red_sandstone_slab[type=bottom,waterlogged=false] strict
setblock ~236 ~42 ~208 minecraft:smooth_red_sandstone_slab[type=bottom,waterlogged=false] strict
setblock ~237 ~42 ~209 minecraft:smooth_red_sandstone_slab[type=bottom,waterlogged=false] strict
fill ~238 ~42 ~210 ~238 ~42 ~211 minecraft:smooth_red_sandstone_slab[type=bottom,waterlogged=false] strict
fill ~239 ~42 ~211 ~239 ~42 ~212 minecraft:smooth_red_sandstone_slab[type=bottom,waterlogged=false] strict
fill ~204 ~42 ~213 ~204 ~42 ~214 minecraft:smooth_red_sandstone_slab[type=bottom,waterlogged=false] strict
fill ~240 ~42 ~213 ~240 ~42 ~214 minecraft:smooth_red_sandstone_slab[type=bottom,waterlogged=false] strict
fill ~203 ~42 ~215 ~203 ~42 ~216 minecraft:smooth_red_sandstone_slab[type=bottom,waterlogged=false] strict
fill ~241 ~42 ~215 ~241 ~42 ~218 minecraft:smooth_red_sandstone_slab[type=bottom,waterlogged=false] strict
fill ~242 ~42 ~218 ~242 ~42 ~226 minecraft:smooth_red_sandstone_slab[type=bottom,waterlogged=false] strict
fill ~241 ~42 ~226 ~241 ~42 ~229 minecraft:smooth_red_sandstone_slab[type=bottom,waterlogged=false] strict
fill ~203 ~42 ~228 ~203 ~42 ~229 minecraft:smooth_red_sandstone_slab[type=bottom,waterlogged=false] strict
fill ~204 ~42 ~230 ~204 ~42 ~231 minecraft:smooth_red_sandstone_slab[type=bottom,waterlogged=false] strict
fill ~240 ~42 ~230 ~240 ~42 ~231 minecraft:smooth_red_sandstone_slab[type=bottom,waterlogged=false] strict
fill ~205 ~42 ~232 ~205 ~42 ~233 minecraft:smooth_red_sandstone_slab[type=bottom,waterlogged=false] strict
fill ~239 ~42 ~232 ~239 ~42 ~233 minecraft:smooth_red_sandstone_slab[type=bottom,waterlogged=false] strict
fill ~206 ~42 ~233 ~206 ~42 ~234 minecraft:smooth_red_sandstone_slab[type=bottom,waterlogged=false] strict
fill ~238 ~42 ~233 ~238 ~42 ~234 minecraft:smooth_red_sandstone_slab[type=bottom,waterlogged=false] strict
setblock ~207 ~42 ~235 minecraft:smooth_red_sandstone_slab[type=bottom,waterlogged=false] strict
setblock ~237 ~42 ~235 minecraft:smooth_red_sandstone_slab[type=bottom,waterlogged=false] strict
setblock ~208 ~42 ~236 minecraft:smooth_red_sandstone_slab[type=bottom,waterlogged=false] strict
setblock ~236 ~42 ~236 minecraft:smooth_red_sandstone_slab[type=bottom,waterlogged=false] strict
setblock ~209 ~42 ~237 minecraft:smooth_red_sandstone_slab[type=bottom,waterlogged=false] strict
setblock ~235 ~42 ~237 minecraft:smooth_red_sandstone_slab[type=bottom,waterlogged=false] strict
fill ~210 ~42 ~238 ~211 ~42 ~238 minecraft:smooth_red_sandstone_slab[type=bottom,waterlogged=false] strict
fill ~233 ~42 ~238 ~234 ~42 ~238 minecraft:smooth_red_sandstone_slab[type=bottom,waterlogged=false] strict
fill ~211 ~42 ~239 ~212 ~42 ~239 minecraft:smooth_red_sandstone_slab[type=bottom,waterlogged=false] strict
fill ~232 ~42 ~239 ~233 ~42 ~239 minecraft:smooth_red_sandstone_slab[type=bottom,waterlogged=false] strict
fill ~213 ~42 ~240 ~214 ~42 ~240 minecraft:smooth_red_sandstone_slab[type=bottom,waterlogged=false] strict
fill ~230 ~42 ~240 ~231 ~42 ~240 minecraft:smooth_red_sandstone_slab[type=bottom,waterlogged=false] strict
fill ~215 ~42 ~241 ~218 ~42 ~241 minecraft:smooth_red_sandstone_slab[type=bottom,waterlogged=false] strict
fill ~226 ~42 ~241 ~229 ~42 ~241 minecraft:smooth_red_sandstone_slab[type=bottom,waterlogged=false] strict
fill ~218 ~42 ~242 ~226 ~42 ~242 minecraft:smooth_red_sandstone_slab[type=bottom,waterlogged=false] strict
setblock ~125 ~42 ~247 minecraft:lantern[hanging=false,waterlogged=false] strict
setblock ~131 ~42 ~247 minecraft:lantern[hanging=false,waterlogged=false] strict
setblock ~125 ~42 ~253 minecraft:lantern[hanging=false,waterlogged=false] strict
setblock ~131 ~42 ~253 minecraft:lantern[hanging=false,waterlogged=false] strict
fill ~212 ~43 ~200 ~216 ~43 ~202 minecraft:smooth_red_sandstone_slab[type=bottom,waterlogged=false] strict
fill ~228 ~43 ~200 ~231 ~43 ~202 minecraft:smooth_red_sandstone_slab[type=bottom,waterlogged=false] strict
fill ~211 ~43 ~201 ~211 ~43 ~203 minecraft:smooth_red_sandstone_slab[type=bottom,waterlogged=false] strict
setblock ~210 ~43 ~202 minecraft:smooth_red_sandstone_slab[type=bottom,waterlogged=false] strict
fill ~212 ~43 ~203 ~213 ~43 ~203 minecraft:smooth_red_sandstone_slab[type=bottom,waterlogged=false] strict
setblock ~212 ~43 ~204 minecraft:smooth_red_sandstone_slab[type=bottom,waterlogged=false] strict
fill ~202 ~43 ~210 ~202 ~43 ~216 minecraft:smooth_red_sandstone_slab[type=bottom,waterlogged=false] strict
fill ~201 ~43 ~211 ~201 ~43 ~216 minecraft:smooth_red_sandstone_slab[type=bottom,waterlogged=false] strict
fill ~203 ~43 ~211 ~203 ~43 ~213 minecraft:smooth_red_sandstone_slab[type=bottom,waterlogged=false] strict
fill ~200 ~43 ~212 ~200 ~43 ~216 minecraft:smooth_red_sandstone_slab[type=bottom,waterlogged=false] strict
setblock ~204 ~43 ~212 minecraft:smooth_red_sandstone_slab[type=bottom,waterlogged=false] strict
fill ~200 ~43 ~228 ~202 ~43 ~231 minecraft:smooth_red_sandstone_slab[type=bottom,waterlogged=false] strict
setblock ~141 ~47 ~117 minecraft:smooth_quartz_slab[type=bottom,waterlogged=false] strict
setblock ~215 ~48 ~201 minecraft:campfire[facing=north,lit=true,signal_fire=false,waterlogged=false] strict
setblock ~230 ~48 ~201 minecraft:campfire[facing=north,lit=true,signal_fire=false,waterlogged=false] strict
setblock ~213 ~48 ~202 minecraft:campfire[facing=north,lit=true,signal_fire=false,waterlogged=false] strict
setblock ~202 ~48 ~213 minecraft:campfire[facing=north,lit=true,signal_fire=false,waterlogged=false] strict
setblock ~201 ~48 ~215 minecraft:campfire[facing=north,lit=true,signal_fire=false,waterlogged=false] strict
setblock ~201 ~48 ~230 minecraft:campfire[facing=north,lit=true,signal_fire=false,waterlogged=false] strict
fill ~118 ~49 ~113 ~133 ~49 ~113 minecraft:smooth_quartz_slab[type=bottom,waterlogged=false] strict
fill ~143 ~49 ~113 ~143 ~49 ~118 minecraft:smooth_quartz_slab[type=bottom,waterlogged=false] strict
fill ~113 ~49 ~123 ~113 ~49 ~128 minecraft:smooth_quartz_slab[type=bottom,waterlogged=false] strict
fill ~113 ~49 ~138 ~113 ~49 ~143 minecraft:smooth_quartz_slab[type=bottom,waterlogged=false] strict
fill ~118 ~49 ~143 ~133 ~49 ~143 minecraft:smooth_quartz_slab[type=bottom,waterlogged=false] strict
setblock ~8 ~55 ~215 minecraft:lantern[hanging=false,waterlogged=false] strict
setblock ~41 ~55 ~248 minecraft:lantern[hanging=false,waterlogged=false] strict
setblock ~123 ~93 ~115 minecraft:lantern[hanging=false,waterlogged=false] strict
setblock ~133 ~93 ~115 minecraft:lantern[hanging=false,waterlogged=false] strict
setblock ~115 ~93 ~123 minecraft:lantern[hanging=false,waterlogged=false] strict
setblock ~141 ~93 ~123 minecraft:lantern[hanging=false,waterlogged=false] strict
setblock ~115 ~93 ~133 minecraft:lantern[hanging=false,waterlogged=false] strict
setblock ~141 ~93 ~133 minecraft:lantern[hanging=false,waterlogged=false] strict
setblock ~123 ~93 ~141 minecraft:lantern[hanging=false,waterlogged=false] strict
setblock ~133 ~93 ~141 minecraft:lantern[hanging=false,waterlogged=false] strict
