fill ~224 ~48 ~64 ~255 ~63 ~95 minecraft:air strict
fill ~224 ~32 ~64 ~255 ~47 ~95 minecraft:air strict
fill ~224 ~16 ~64 ~255 ~31 ~95 minecraft:air strict
fill ~224 ~0 ~64 ~255 ~15 ~95 minecraft:air strict
fill ~224 ~80 ~96 ~255 ~95 ~127 minecraft:air strict
fill ~224 ~64 ~96 ~255 ~79 ~127 minecraft:air strict
fill ~224 ~48 ~96 ~255 ~63 ~127 minecraft:air strict
fill ~224 ~32 ~96 ~255 ~47 ~127 minecraft:air strict
fill ~224 ~16 ~96 ~255 ~31 ~127 minecraft:air strict
fill ~224 ~0 ~96 ~255 ~15 ~127 minecraft:air strict
fill ~224 ~80 ~128 ~255 ~95 ~159 minecraft:air strict
fill ~224 ~64 ~128 ~255 ~79 ~159 minecraft:air strict
fill ~224 ~48 ~128 ~255 ~63 ~159 minecraft:air strict
fill ~224 ~32 ~128 ~255 ~47 ~159 minecraft:air strict
fill ~224 ~16 ~128 ~255 ~31 ~159 minecraft:air strict
fill ~224 ~0 ~128 ~255 ~15 ~159 minecraft:air strict
fill ~224 ~80 ~160 ~255 ~95 ~191 minecraft:air strict
fill ~224 ~64 ~160 ~255 ~79 ~191 minecraft:air strict
fill ~224 ~48 ~160 ~255 ~63 ~191 minecraft:air strict
fill ~224 ~32 ~160 ~255 ~47 ~191 minecraft:air strict
fill ~224 ~16 ~160 ~255 ~31 ~191 minecraft:air strict
fill ~224 ~0 ~160 ~255 ~15 ~191 minecraft:air strict
fill ~224 ~80 ~192 ~255 ~95 ~223 minecraft:air strict
fill ~224 ~64 ~192 ~255 ~79 ~223 minecraft:air strict
fill ~224 ~48 ~192 ~255 ~63 ~223 minecraft:air strict
fill ~224 ~32 ~192 ~255 ~47 ~223 minecraft:air strict
fill ~224 ~16 ~192 ~255 ~31 ~223 minecraft:air strict
fill ~224 ~0 ~192 ~255 ~15 ~223 minecraft:air strict
fill ~224 ~80 ~224 ~255 ~95 ~255 minecraft:air strict
fill ~224 ~64 ~224 ~255 ~79 ~255 minecraft:air strict
fill ~224 ~48 ~224 ~255 ~63 ~255 minecraft:air strict
fill ~224 ~32 ~224 ~255 ~47 ~255 minecraft:air strict
fill ~224 ~16 ~224 ~255 ~31 ~255 minecraft:air strict
fill ~224 ~0 ~224 ~255 ~15 ~255 minecraft:air strict
fill ~69 ~10 ~171 ~72 ~10 ~176 minecraft:tuff strict
fill ~66 ~10 ~172 ~68 ~10 ~173 minecraft:tuff strict
fill ~66 ~10 ~174 ~66 ~10 ~180 minecraft:stone strict
fill ~67 ~10 ~174 ~68 ~10 ~179 minecraft:tuff strict
fill ~65 ~10 ~176 ~65 ~10 ~179 minecraft:stone strict
fill ~69 ~10 ~177 ~71 ~10 ~177 minecraft:tuff strict
fill ~64 ~10 ~178 ~64 ~10 ~179 minecraft:stone strict
setblock ~69 ~10 ~178 minecraft:tuff strict
fill ~81 ~10 ~181 ~82 ~11 ~185 minecraft:stone strict
fill ~80 ~10 ~182 ~80 ~11 ~185 minecraft:stone strict
fill ~83 ~10 ~182 ~83 ~11 ~185 minecraft:stone strict
fill ~79 ~10 ~184 ~79 ~11 ~184 minecraft:stone strict
fill ~82 ~10 ~195 ~82 ~11 ~195 minecraft:stone strict
fill ~81 ~10 ~196 ~81 ~11 ~198 minecraft:stone strict
fill ~80 ~10 ~198 ~80 ~11 ~199 minecraft:stone strict
fill ~69 ~11 ~171 ~72 ~12 ~179 minecraft:stone strict
fill ~66 ~11 ~172 ~68 ~12 ~173 minecraft:stone strict
fill ~73 ~11 ~172 ~74 ~11 ~182 minecraft:stone strict
fill ~63 ~11 ~173 ~65 ~11 ~180 minecraft:tuff strict
fill ~75 ~11 ~173 ~75 ~11 ~184 minecraft:stone strict
fill ~60 ~11 ~174 ~62 ~11 ~181 minecraft:tuff strict
fill ~66 ~11 ~174 ~66 ~11 ~180 minecraft:tuff strict
fill ~67 ~11 ~174 ~68 ~12 ~180 minecraft:stone strict
fill ~76 ~11 ~174 ~76 ~11 ~186 minecraft:stone strict
fill ~58 ~11 ~175 ~59 ~11 ~191 minecraft:tuff strict
fill ~77 ~11 ~175 ~77 ~11 ~187 minecraft:stone strict
fill ~57 ~11 ~176 ~57 ~11 ~192 minecraft:tuff strict
fill ~78 ~11 ~176 ~78 ~11 ~201 minecraft:stone strict
fill ~56 ~11 ~177 ~56 ~11 ~192 minecraft:tuff strict
fill ~79 ~11 ~177 ~79 ~11 ~183 minecraft:stone strict
fill ~54 ~11 ~178 ~55 ~11 ~192 minecraft:tuff strict
fill ~80 ~11 ~178 ~80 ~11 ~181 minecraft:stone strict
fill ~53 ~11 ~179 ~53 ~11 ~192 minecraft:tuff strict
fill ~81 ~11 ~179 ~81 ~11 ~180 minecraft:stone strict
fill ~69 ~11 ~180 ~69 ~12 ~180 minecraft:stone strict
fill ~72 ~11 ~180 ~72 ~12 ~180 minecraft:stone strict
setblock ~82 ~11 ~180 minecraft:stone strict
setblock ~63 ~11 ~181 minecraft:tuff strict
fill ~67 ~11 ~181 ~67 ~12 ~181 minecraft:stone strict
setblock ~60 ~11 ~182 minecraft:tuff strict
fill ~79 ~11 ~185 ~79 ~11 ~200 minecraft:stone strict
fill ~80 ~11 ~186 ~84 ~11 ~192 minecraft:stone strict
fill ~60 ~11 ~187 ~60 ~11 ~188 minecraft:tuff strict
fill ~85 ~11 ~189 ~85 ~11 ~190 minecraft:stone strict
fill ~77 ~11 ~190 ~77 ~11 ~201 minecraft:stone strict
fill ~60 ~11 ~191 ~60 ~11 ~202 minecraft:stone strict
fill ~76 ~11 ~191 ~76 ~11 ~202 minecraft:stone strict
setblock ~58 ~11 ~192 minecraft:tuff strict
fill ~59 ~11 ~192 ~59 ~11 ~201 minecraft:stone strict
fill ~61 ~11 ~192 ~61 ~11 ~202 minecraft:stone strict
fill ~75 ~11 ~192 ~75 ~11 ~202 minecraft:stone strict
fill ~53 ~11 ~193 ~58 ~12 ~195 minecraft:stone strict
fill ~74 ~11 ~193 ~74 ~11 ~203 minecraft:stone strict
fill ~80 ~11 ~193 ~83 ~11 ~193 minecraft:stone strict
fill ~62 ~11 ~194 ~62 ~11 ~202 minecraft:stone strict
fill ~80 ~11 ~194 ~82 ~11 ~194 minecraft:stone strict
fill ~63 ~11 ~195 ~66 ~11 ~202 minecraft:stone strict
fill ~73 ~11 ~195 ~73 ~11 ~203 minecraft:stone strict
fill ~80 ~11 ~195 ~81 ~11 ~195 minecraft:stone strict
fill ~54 ~11 ~196 ~58 ~12 ~197 minecraft:stone strict
fill ~67 ~11 ~196 ~67 ~11 ~204 minecraft:stone strict
fill ~71 ~11 ~196 ~72 ~11 ~204 minecraft:stone strict
fill ~80 ~11 ~196 ~80 ~11 ~197 minecraft:stone strict
fill ~68 ~11 ~197 ~70 ~11 ~205 minecraft:stone strict
fill ~55 ~11 ~198 ~58 ~12 ~199 minecraft:stone strict
fill ~56 ~11 ~200 ~58 ~11 ~200 minecraft:stone strict
fill ~57 ~11 ~201 ~58 ~11 ~201 minecraft:stone strict
fill ~64 ~11 ~203 ~66 ~11 ~203 minecraft:stone strict
setblock ~66 ~11 ~204 minecraft:stone strict
fill ~73 ~12 ~172 ~73 ~12 ~178 minecraft:stone strict
fill ~74 ~12 ~172 ~74 ~12 ~182 minecraft:andesite strict
fill ~63 ~12 ~173 ~65 ~13 ~180 minecraft:stone strict
fill ~75 ~12 ~173 ~75 ~12 ~184 minecraft:andesite strict
fill ~60 ~12 ~174 ~62 ~13 ~181 minecraft:stone strict
fill ~66 ~12 ~174 ~66 ~12 ~180 minecraft:stone strict
fill ~76 ~12 ~174 ~76 ~12 ~186 minecraft:andesite strict
fill ~58 ~12 ~175 ~59 ~12 ~192 minecraft:stone strict
fill ~77 ~12 ~175 ~77 ~12 ~187 minecraft:andesite strict
fill ~57 ~12 ~176 ~57 ~13 ~192 minecraft:stone strict
fill ~78 ~12 ~176 ~78 ~12 ~201 minecraft:andesite strict
fill ~56 ~12 ~177 ~56 ~13 ~192 minecraft:stone strict
fill ~79 ~12 ~177 ~79 ~12 ~200 minecraft:andesite strict
fill ~54 ~12 ~178 ~55 ~13 ~192 minecraft:stone strict
fill ~80 ~12 ~178 ~80 ~12 ~199 minecraft:andesite strict
fill ~53 ~12 ~179 ~53 ~13 ~192 minecraft:stone strict
fill ~73 ~12 ~179 ~73 ~12 ~182 minecraft:andesite strict
fill ~81 ~12 ~179 ~81 ~12 ~198 minecraft:andesite strict
fill ~82 ~12 ~180 ~82 ~12 ~195 minecraft:andesite strict
fill ~63 ~12 ~181 ~63 ~13 ~181 minecraft:stone strict
fill ~60 ~12 ~182 ~60 ~13 ~182 minecraft:stone strict
fill ~83 ~12 ~182 ~83 ~12 ~193 minecraft:andesite strict
fill ~84 ~12 ~186 ~84 ~12 ~192 minecraft:andesite strict
fill ~60 ~12 ~187 ~60 ~13 ~188 minecraft:stone strict
fill ~85 ~12 ~189 ~85 ~12 ~190 minecraft:andesite strict
fill ~77 ~12 ~190 ~77 ~12 ~201 minecraft:andesite strict
fill ~60 ~12 ~191 ~60 ~12 ~199 minecraft:stone strict
fill ~76 ~12 ~191 ~76 ~12 ~202 minecraft:andesite strict
fill ~61 ~12 ~192 ~61 ~12 ~198 minecraft:stone strict
fill ~75 ~12 ~192 ~75 ~12 ~202 minecraft:andesite strict
fill ~59 ~12 ~193 ~59 ~12 ~199 minecraft:stone strict
fill ~74 ~12 ~193 ~74 ~12 ~203 minecraft:andesite strict
fill ~62 ~12 ~194 ~62 ~12 ~198 minecraft:stone strict
fill ~63 ~12 ~195 ~66 ~12 ~196 minecraft:stone strict
fill ~73 ~12 ~195 ~73 ~12 ~203 minecraft:andesite strict
fill ~67 ~12 ~196 ~67 ~12 ~204 minecraft:andesite strict
fill ~71 ~12 ~196 ~72 ~12 ~204 minecraft:andesite strict
fill ~63 ~12 ~197 ~64 ~12 ~197 minecraft:stone strict
fill ~65 ~12 ~197 ~66 ~12 ~203 minecraft:andesite strict
fill ~68 ~12 ~197 ~70 ~12 ~205 minecraft:andesite strict
setblock ~63 ~12 ~198 minecraft:stone strict
fill ~64 ~12 ~198 ~64 ~12 ~203 minecraft:andesite strict
fill ~61 ~12 ~199 ~63 ~12 ~202 minecraft:andesite strict
setblock ~56 ~12 ~200 minecraft:stone strict
fill ~57 ~12 ~200 ~60 ~12 ~201 minecraft:andesite strict
setblock ~60 ~12 ~202 minecraft:andesite strict
setblock ~66 ~12 ~204 minecraft:andesite strict
fill ~68 ~13 ~170 ~73 ~13 ~174 minecraft:andesite strict
fill ~65 ~13 ~171 ~65 ~13 ~172 minecraft:stone strict
fill ~66 ~13 ~171 ~67 ~13 ~173 minecraft:andesite strict
fill ~74 ~13 ~172 ~74 ~13 ~182 minecraft:gravel strict
fill ~75 ~13 ~173 ~75 ~13 ~184 minecraft:gravel strict
setblock ~66 ~13 ~174 minecraft:stone strict
setblock ~67 ~13 ~174 minecraft:andesite strict
fill ~76 ~13 ~174 ~76 ~13 ~186 minecraft:gravel strict
fill ~58 ~13 ~175 ~59 ~13 ~191 minecraft:stone strict
fill ~66 ~13 ~175 ~66 ~28 ~177 minecraft:stone_bricks strict
fill ~67 ~13 ~175 ~68 ~28 ~175 minecraft:mossy_stone_bricks strict
fill ~69 ~13 ~175 ~70 ~28 ~175 minecraft:stone_bricks strict
fill ~71 ~13 ~175 ~73 ~13 ~178 minecraft:andesite strict
fill ~77 ~13 ~175 ~77 ~13 ~187 minecraft:gravel strict
fill ~67 ~13 ~176 ~68 ~28 ~176 minecraft:cracked_stone_bricks strict
fill ~69 ~13 ~176 ~70 ~28 ~176 minecraft:mossy_stone_bricks strict
fill ~78 ~13 ~176 ~78 ~13 ~201 minecraft:gravel strict
fill ~67 ~13 ~177 ~67 ~29 ~177 minecraft:stone_bricks strict
fill ~68 ~13 ~177 ~68 ~29 ~177 minecraft:mossy_stone_bricks strict
fill ~69 ~13 ~177 ~70 ~28 ~177 minecraft:stone_bricks strict
fill ~79 ~13 ~177 ~79 ~13 ~185 minecraft:gravel strict
fill ~66 ~13 ~178 ~66 ~13 ~181 minecraft:stone strict
fill ~67 ~13 ~178 ~70 ~13 ~179 minecraft:andesite strict
fill ~80 ~13 ~178 ~80 ~13 ~185 minecraft:gravel strict
fill ~71 ~13 ~179 ~72 ~13 ~179 minecraft:andesite strict
fill ~73 ~13 ~179 ~73 ~13 ~182 minecraft:gravel strict
fill ~81 ~13 ~179 ~81 ~13 ~185 minecraft:gravel strict
fill ~67 ~13 ~180 ~69 ~13 ~180 minecraft:andesite strict
setblock ~72 ~13 ~180 minecraft:andesite strict
fill ~82 ~13 ~180 ~83 ~13 ~196 minecraft:gravel strict
setblock ~65 ~13 ~181 minecraft:stone strict
setblock ~67 ~13 ~181 minecraft:andesite strict
fill ~84 ~13 ~181 ~84 ~13 ~192 minecraft:gravel strict
fill ~79 ~13 ~186 ~80 ~28 ~186 minecraft:stone_bricks strict
fill ~81 ~13 ~186 ~81 ~28 ~186 minecraft:cracked_stone_bricks strict
fill ~79 ~13 ~187 ~79 ~28 ~188 minecraft:mossy_stone_bricks strict
fill ~80 ~13 ~187 ~80 ~28 ~188 minecraft:cracked_stone_bricks strict
fill ~81 ~13 ~187 ~81 ~29 ~187 minecraft:mossy_stone_bricks strict
fill ~81 ~13 ~188 ~81 ~29 ~189 minecraft:stone_bricks strict
fill ~79 ~13 ~189 ~80 ~29 ~189 minecraft:stone_bricks strict
fill ~85 ~13 ~189 ~85 ~13 ~190 minecraft:gravel strict
fill ~77 ~13 ~190 ~77 ~13 ~201 minecraft:gravel strict
fill ~79 ~13 ~190 ~79 ~28 ~190 minecraft:stone_bricks strict
fill ~80 ~13 ~190 ~80 ~28 ~190 minecraft:cracked_stone_bricks strict
fill ~81 ~13 ~190 ~81 ~28 ~190 minecraft:mossy_stone_bricks strict
fill ~60 ~13 ~191 ~60 ~13 ~199 minecraft:andesite strict
fill ~76 ~13 ~191 ~76 ~13 ~202 minecraft:gravel strict
fill ~79 ~13 ~191 ~81 ~13 ~200 minecraft:gravel strict
setblock ~58 ~13 ~192 minecraft:stone strict
fill ~59 ~13 ~192 ~59 ~13 ~199 minecraft:andesite strict
fill ~61 ~13 ~192 ~61 ~13 ~198 minecraft:andesite strict
fill ~75 ~13 ~192 ~75 ~13 ~202 minecraft:gravel strict
fill ~53 ~13 ~193 ~58 ~13 ~195 minecraft:andesite strict
fill ~74 ~13 ~193 ~74 ~13 ~203 minecraft:gravel strict
fill ~62 ~13 ~194 ~62 ~13 ~198 minecraft:andesite strict
fill ~63 ~13 ~195 ~66 ~13 ~196 minecraft:andesite strict
fill ~73 ~13 ~195 ~73 ~13 ~203 minecraft:gravel strict
fill ~54 ~13 ~196 ~58 ~13 ~197 minecraft:andesite strict
fill ~67 ~13 ~196 ~67 ~13 ~204 minecraft:gravel strict
fill ~71 ~13 ~196 ~72 ~13 ~204 minecraft:gravel strict
fill ~63 ~13 ~197 ~64 ~13 ~197 minecraft:andesite strict
fill ~65 ~13 ~197 ~66 ~13 ~203 minecraft:gravel strict
fill ~68 ~13 ~197 ~70 ~13 ~205 minecraft:gravel strict
fill ~82 ~13 ~197 ~82 ~13 ~199 minecraft:gravel strict
fill ~55 ~13 ~198 ~58 ~13 ~199 minecraft:andesite strict
setblock ~63 ~13 ~198 minecraft:andesite strict
fill ~64 ~13 ~198 ~64 ~13 ~203 minecraft:gravel strict
fill ~61 ~13 ~199 ~63 ~13 ~202 minecraft:gravel strict
setblock ~56 ~13 ~200 minecraft:andesite strict
fill ~57 ~13 ~200 ~60 ~13 ~201 minecraft:gravel strict
setblock ~60 ~13 ~202 minecraft:gravel strict
setblock ~66 ~13 ~204 minecraft:gravel strict
fill ~59 ~14 ~69 ~63 ~14 ~73 minecraft:stone strict
fill ~58 ~14 ~70 ~58 ~14 ~73 minecraft:stone strict
fill ~64 ~14 ~70 ~64 ~14 ~75 minecraft:stone strict
fill ~57 ~14 ~71 ~57 ~14 ~73 minecraft:stone strict
fill ~65 ~14 ~71 ~65 ~14 ~76 minecraft:stone strict
fill ~56 ~14 ~72 ~56 ~14 ~73 minecraft:stone strict
fill ~66 ~14 ~72 ~66 ~14 ~76 minecraft:stone strict
fill ~56 ~14 ~74 ~59 ~14 ~76 minecraft:moss_block strict
fill ~60 ~14 ~74 ~63 ~14 ~74 minecraft:stone strict
fill ~60 ~14 ~75 ~62 ~14 ~79 minecraft:moss_block strict
setblock ~63 ~14 ~75 minecraft:stone strict
fill ~63 ~14 ~76 ~64 ~14 ~78 minecraft:moss_block strict
fill ~57 ~14 ~77 ~59 ~14 ~77 minecraft:moss_block strict
setblock ~65 ~14 ~77 minecraft:moss_block strict
fill ~58 ~14 ~78 ~59 ~14 ~78 minecraft:moss_block strict
setblock ~59 ~14 ~79 minecraft:moss_block strict
setblock ~63 ~14 ~79 minecraft:moss_block strict
fill ~68 ~14 ~170 ~73 ~14 ~170 minecraft:gravel strict
fill ~65 ~14 ~171 ~65 ~14 ~175 minecraft:andesite strict
fill ~66 ~14 ~171 ~68 ~14 ~171 minecraft:gravel strict
fill ~69 ~14 ~171 ~70 ~14 ~171 minecraft:andesite strict
fill ~71 ~14 ~171 ~72 ~14 ~171 minecraft:stone strict
fill ~73 ~14 ~171 ~73 ~14 ~178 minecraft:gravel strict
fill ~74 ~14 ~171 ~75 ~14 ~185 minecraft:stone strict
fill ~62 ~14 ~172 ~64 ~14 ~177 minecraft:andesite strict
setblock ~66 ~14 ~172 minecraft:gravel strict
setblock ~67 ~14 ~172 minecraft:andesite strict
fill ~68 ~14 ~172 ~71 ~14 ~173 minecraft:stone strict
fill ~72 ~14 ~172 ~72 ~14 ~174 minecraft:gravel strict
fill ~76 ~14 ~172 ~76 ~14 ~203 minecraft:stone strict
fill ~59 ~14 ~173 ~61 ~14 ~183 minecraft:andesite strict
fill ~66 ~14 ~173 ~67 ~14 ~173 minecraft:stone strict
fill ~77 ~14 ~173 ~77 ~14 ~203 minecraft:stone strict
fill ~57 ~14 ~174 ~58 ~14 ~192 minecraft:andesite strict
setblock ~66 ~14 ~174 minecraft:andesite strict
setblock ~67 ~14 ~174 minecraft:stone strict
fill ~68 ~14 ~174 ~69 ~14 ~174 minecraft:gravel strict
setblock ~70 ~14 ~174 minecraft:andesite strict
setblock ~71 ~14 ~174 minecraft:stone strict
fill ~78 ~14 ~174 ~78 ~14 ~202 minecraft:stone strict
fill ~56 ~14 ~175 ~56 ~14 ~192 minecraft:andesite strict
fill ~71 ~14 ~175 ~71 ~14 ~181 minecraft:gravel strict
fill ~72 ~14 ~175 ~72 ~14 ~176 minecraft:andesite strict
fill ~79 ~14 ~175 ~79 ~14 ~183 minecraft:stone strict
fill ~55 ~14 ~176 ~55 ~14 ~192 minecraft:andesite strict
fill ~65 ~14 ~176 ~65 ~14 ~177 minecraft:stone strict
fill ~80 ~14 ~176 ~80 ~14 ~181 minecraft:stone strict
fill ~53 ~14 ~177 ~54 ~14 ~192 minecraft:andesite strict
fill ~72 ~14 ~177 ~72 ~14 ~183 minecraft:gravel strict
fill ~81 ~14 ~177 ~81 ~14 ~181 minecraft:stone strict
fill ~52 ~14 ~178 ~52 ~14 ~192 minecraft:andesite strict
fill ~62 ~14 ~178 ~63 ~14 ~182 minecraft:andesite strict
fill ~64 ~14 ~178 ~64 ~14 ~179 minecraft:stone strict
setblock ~65 ~14 ~178 minecraft:gravel strict
setblock ~66 ~14 ~178 minecraft:stone strict
setblock ~67 ~14 ~178 minecraft:gravel strict
fill ~68 ~14 ~178 ~68 ~14 ~179 minecraft:andesite strict
setblock ~69 ~14 ~178 minecraft:stone strict
fill ~70 ~14 ~178 ~70 ~14 ~181 minecraft:gravel strict
fill ~82 ~14 ~178 ~82 ~14 ~180 minecraft:stone strict
fill ~65 ~14 ~179 ~65 ~14 ~181 minecraft:andesite strict
fill ~66 ~14 ~179 ~66 ~14 ~180 minecraft:gravel strict
setblock ~67 ~14 ~179 minecraft:stone strict
fill ~69 ~14 ~179 ~69 ~14 ~181 minecraft:gravel strict
fill ~73 ~14 ~179 ~73 ~14 ~183 minecraft:stone strict
fill ~83 ~14 ~179 ~83 ~14 ~181 minecraft:stone strict
fill ~64 ~14 ~180 ~64 ~14 ~182 minecraft:andesite strict
fill ~67 ~14 ~180 ~68 ~14 ~182 minecraft:gravel strict
setblock ~66 ~14 ~181 minecraft:andesite strict
fill ~82 ~14 ~181 ~82 ~14 ~182 minecraft:andesite strict
fill ~84 ~14 ~181 ~84 ~14 ~194 minecraft:stone strict
setblock ~66 ~14 ~182 minecraft:gravel strict
fill ~80 ~14 ~182 ~80 ~14 ~185 minecraft:gravel strict
setblock ~81 ~14 ~182 minecraft:andesite strict
fill ~83 ~14 ~182 ~83 ~14 ~183 minecraft:gravel strict
setblock ~81 ~14 ~183 minecraft:stone strict
setblock ~82 ~14 ~183 minecraft:gravel strict
fill ~59 ~14 ~184 ~60 ~14 ~190 minecraft:andesite strict
setblock ~79 ~14 ~184 minecraft:gravel strict
fill ~81 ~14 ~184 ~81 ~14 ~185 minecraft:gravel strict
setblock ~82 ~14 ~184 minecraft:andesite strict
fill ~83 ~14 ~184 ~83 ~14 ~196 minecraft:stone strict
fill ~79 ~14 ~185 ~79 ~15 ~185 minecraft:stone strict
fill ~82 ~14 ~185 ~82 ~14 ~199 minecraft:stone strict
fill ~85 ~14 ~185 ~85 ~14 ~193 minecraft:stone strict
fill ~61 ~14 ~186 ~61 ~14 ~190 minecraft:andesite strict
fill ~75 ~14 ~186 ~75 ~14 ~187 minecraft:stone strict
fill ~86 ~14 ~188 ~86 ~14 ~191 minecraft:stone strict
fill ~75 ~14 ~190 ~75 ~14 ~204 minecraft:stone strict
fill ~59 ~14 ~191 ~59 ~15 ~191 minecraft:andesite strict
fill ~60 ~14 ~191 ~62 ~14 ~198 minecraft:gravel strict
fill ~74 ~14 ~191 ~74 ~14 ~204 minecraft:stone strict
fill ~79 ~14 ~191 ~81 ~14 ~195 minecraft:stone strict
fill ~59 ~14 ~192 ~59 ~14 ~199 minecraft:gravel strict
fill ~73 ~14 ~192 ~73 ~14 ~205 minecraft:stone strict
fill ~52 ~14 ~193 ~58 ~14 ~196 minecraft:gravel strict
fill ~63 ~14 ~193 ~63 ~14 ~198 minecraft:gravel strict
fill ~64 ~14 ~194 ~67 ~14 ~195 minecraft:gravel strict
fill ~72 ~14 ~194 ~72 ~14 ~205 minecraft:stone strict
fill ~68 ~14 ~195 ~68 ~14 ~206 minecraft:stone strict
fill ~70 ~14 ~195 ~71 ~14 ~206 minecraft:stone strict
fill ~64 ~14 ~196 ~66 ~14 ~196 minecraft:gravel strict
fill ~67 ~14 ~196 ~67 ~14 ~206 minecraft:stone strict
fill ~69 ~14 ~196 ~69 ~14 ~206 minecraft:stone strict
fill ~79 ~14 ~196 ~80 ~14 ~198 minecraft:stone strict
setblock ~81 ~14 ~196 minecraft:gravel strict
fill ~53 ~14 ~197 ~58 ~14 ~198 minecraft:gravel strict
setblock ~64 ~14 ~197 minecraft:gravel strict
fill ~65 ~14 ~197 ~66 ~14 ~205 minecraft:stone strict
fill ~81 ~14 ~197 ~81 ~14 ~200 minecraft:stone strict
fill ~64 ~14 ~198 ~64 ~14 ~204 minecraft:stone strict
fill ~54 ~14 ~199 ~58 ~14 ~199 minecraft:gravel strict
setblock ~60 ~14 ~199 minecraft:gravel strict
fill ~61 ~14 ~199 ~63 ~14 ~203 minecraft:stone strict
fill ~79 ~14 ~199 ~79 ~14 ~202 minecraft:stone strict
setblock ~80 ~14 ~199 minecraft:andesite strict
fill ~54 ~14 ~200 ~56 ~14 ~200 minecraft:gravel strict
fill ~57 ~14 ~200 ~60 ~14 ~202 minecraft:stone strict
fill ~80 ~14 ~200 ~80 ~14 ~201 minecraft:stone strict
fill ~55 ~14 ~201 ~56 ~14 ~201 minecraft:stone strict
setblock ~56 ~14 ~202 minecraft:stone strict
fill ~59 ~14 ~203 ~60 ~14 ~203 minecraft:stone strict
setblock ~63 ~14 ~204 minecraft:stone strict
fill ~59 ~15 ~69 ~63 ~15 ~73 minecraft:mossy_cobblestone strict
fill ~58 ~15 ~70 ~58 ~15 ~73 minecraft:mossy_cobblestone strict
fill ~64 ~15 ~70 ~64 ~15 ~75 minecraft:mossy_cobblestone strict
fill ~57 ~15 ~71 ~57 ~15 ~73 minecraft:mossy_cobblestone strict
fill ~65 ~15 ~71 ~65 ~15 ~76 minecraft:mossy_cobblestone strict
