fill ~224 ~48 ~64 ~255 ~63 ~95 minecraft:air strict
fill ~224 ~32 ~64 ~255 ~47 ~95 minecraft:air strict
fill ~224 ~16 ~64 ~255 ~31 ~95 minecraft:air strict
fill ~224 ~0 ~64 ~255 ~15 ~95 minecraft:air strict
fill ~224 ~80 ~96 ~255 ~95 ~127 minecraft:air strict
fill ~224 ~64 ~96 ~255 ~79 ~127 minecraft:air strict
fill ~224 ~48 ~96 ~255 ~63 ~127 minecraft:air strict
fill ~224 ~32 ~96 ~255 ~47 ~127 minecraft:air strict
fill ~224 ~16 ~96 ~255 ~31 ~127 minecraft:air strict
fill ~224 ~0 ~96 ~255 ~15 ~127 minecraft:air strict
fill ~224 ~80 ~128 ~255 ~95 ~159 minecraft:air strict
fill ~224 ~64 ~128 ~255 ~79 ~159 minecraft:air strict
fill ~224 ~48 ~128 ~255 ~63 ~159 minecraft:air strict
fill ~224 ~32 ~128 ~255 ~47 ~159 minecraft:air strict
fill ~224 ~16 ~128 ~255 ~31 ~159 minecraft:air strict
fill ~224 ~0 ~128 ~255 ~15 ~159 minecraft:air strict
fill ~224 ~80 ~160 ~255 ~95 ~191 minecraft:air strict
fill ~224 ~64 ~160 ~255 ~79 ~191 minecraft:air strict
fill ~224 ~48 ~160 ~255 ~63 ~191 minecraft:air strict
fill ~224 ~32 ~160 ~255 ~47 ~191 minecraft:air strict
fill ~224 ~16 ~160 ~255 ~31 ~191 minecraft:air strict
fill ~224 ~0 ~160 ~255 ~15 ~191 minecraft:air strict
fill ~224 ~80 ~192 ~255 ~95 ~223 minecraft:air strict
fill ~224 ~64 ~192 ~255 ~79 ~223 minecraft:air strict
fill ~224 ~48 ~192 ~255 ~63 ~223 minecraft:air strict
fill ~224 ~32 ~192 ~255 ~47 ~223 minecraft:air strict
fill ~224 ~16 ~192 ~255 ~31 ~223 minecraft:air strict
fill ~224 ~0 ~192 ~255 ~15 ~223 minecraft:air strict
fill ~224 ~80 ~224 ~255 ~95 ~255 minecraft:air strict
fill ~224 ~64 ~224 ~255 ~79 ~255 minecraft:air strict
fill ~224 ~48 ~224 ~255 ~63 ~255 minecraft:air strict
fill ~224 ~32 ~224 ~255 ~47 ~255 minecraft:air strict
fill ~224 ~16 ~224 ~255 ~31 ~255 minecraft:air strict
fill ~224 ~0 ~224 ~255 ~15 ~255 minecraft:air strict
fill ~103 ~0 ~2 ~103 ~3 ~7 minecraft:sand strict
fill ~154 ~0 ~2 ~154 ~0 ~5 minecraft:sand strict
fill ~102 ~0 ~4 ~102 ~0 ~6 minecraft:sand strict
fill ~155 ~0 ~4 ~155 ~0 ~5 minecraft:sand strict
fill ~0 ~0 ~91 ~0 ~1 ~95 minecraft:sand strict
fill ~1 ~0 ~92 ~1 ~3 ~94 minecraft:sand strict
fill ~3 ~0 ~102 ~3 ~4 ~102 minecraft:sand strict
fill ~5 ~0 ~102 ~5 ~1 ~102 minecraft:sand strict
fill ~252 ~0 ~103 ~254 ~1 ~108 minecraft:sand strict
fill ~255 ~0 ~104 ~255 ~1 ~108 minecraft:sand strict
fill ~251 ~0 ~105 ~251 ~0 ~107 minecraft:sand strict
fill ~253 ~0 ~109 ~254 ~0 ~109 minecraft:sand strict
fill ~2 ~0 ~153 ~7 ~1 ~153 minecraft:sand strict
fill ~250 ~0 ~153 ~254 ~2 ~153 minecraft:sand strict
fill ~3 ~0 ~154 ~5 ~5 ~154 minecraft:sand strict
fill ~251 ~0 ~154 ~251 ~1 ~154 minecraft:sand strict
fill ~255 ~0 ~157 ~255 ~1 ~159 minecraft:sand strict
fill ~103 ~0 ~249 ~103 ~2 ~255 minecraft:sand strict
fill ~102 ~0 ~250 ~102 ~4 ~255 minecraft:sand strict
fill ~153 ~0 ~250 ~153 ~3 ~255 minecraft:sand strict
fill ~101 ~0 ~251 ~101 ~0 ~255 minecraft:sand strict
fill ~105 ~0 ~251 ~107 ~0 ~255 minecraft:sand strict
fill ~154 ~0 ~251 ~154 ~1 ~255 minecraft:sand strict
fill ~104 ~0 ~253 ~104 ~0 ~255 minecraft:sand strict
fill ~152 ~0 ~254 ~152 ~1 ~255 minecraft:sand strict
fill ~155 ~0 ~255 ~155 ~1 ~255 minecraft:sand strict
fill ~154 ~1 ~3 ~154 ~1 ~5 minecraft:sand strict
fill ~102 ~1 ~4 ~102 ~1 ~5 minecraft:sand strict
setblock ~155 ~1 ~4 minecraft:sand strict
fill ~105 ~1 ~252 ~106 ~2 ~255 minecraft:sand strict
fill ~101 ~1 ~254 ~101 ~3 ~255 minecraft:sand strict
fill ~104 ~1 ~254 ~104 ~1 ~255 minecraft:sand strict
fill ~107 ~1 ~254 ~107 ~6 ~255 minecraft:sand strict
setblock ~154 ~2 ~4 minecraft:sand strict
setblock ~102 ~2 ~5 minecraft:sand strict
fill ~0 ~2 ~91 ~0 ~2 ~94 minecraft:sand strict
fill ~252 ~2 ~103 ~254 ~6 ~103 minecraft:sand strict
fill ~252 ~2 ~105 ~255 ~3 ~107 minecraft:sand strict
fill ~253 ~2 ~108 ~255 ~2 ~108 minecraft:sand strict
fill ~2 ~2 ~153 ~6 ~9 ~153 minecraft:sand strict
fill ~154 ~2 ~251 ~154 ~2 ~254 minecraft:sand strict
setblock ~104 ~2 ~254 minecraft:sand strict
setblock ~152 ~2 ~254 minecraft:sand strict
fill ~0 ~3 ~92 ~0 ~3 ~94 minecraft:sand strict
fill ~250 ~3 ~153 ~253 ~3 ~153 minecraft:sand strict
fill ~103 ~3 ~250 ~103 ~7 ~255 minecraft:sand strict
fill ~105 ~3 ~252 ~105 ~8 ~255 minecraft:sand strict
fill ~106 ~3 ~253 ~106 ~10 ~255 minecraft:sand strict
fill ~154 ~3 ~253 ~154 ~5 ~253 minecraft:sand strict
fill ~103 ~4 ~3 ~103 ~5 ~6 minecraft:sand strict
setblock ~0 ~4 ~92 minecraft:sand strict
setblock ~1 ~4 ~93 minecraft:sand strict
fill ~253 ~4 ~105 ~254 ~4 ~107 minecraft:sand strict
fill ~251 ~4 ~153 ~253 ~5 ~153 minecraft:sand strict
fill ~153 ~4 ~251 ~153 ~8 ~255 minecraft:sand strict
fill ~102 ~5 ~251 ~102 ~8 ~255 minecraft:sand strict
fill ~103 ~6 ~3 ~103 ~7 ~5 minecraft:sand strict
fill ~252 ~6 ~153 ~253 ~6 ~153 minecraft:sand strict
fill ~4 ~6 ~154 ~5 ~8 ~154 minecraft:sand strict
fill ~253 ~7 ~103 ~254 ~8 ~103 minecraft:sand strict
setblock ~253 ~7 ~153 minecraft:sand strict
fill ~103 ~8 ~3 ~103 ~8 ~4 minecraft:sand strict
fill ~103 ~8 ~251 ~103 ~22 ~255 minecraft:sand strict
fill ~103 ~9 ~4 ~103 ~10 ~4 minecraft:sand strict
fill ~153 ~9 ~251 ~153 ~14 ~254 minecraft:sand strict
fill ~102 ~9 ~252 ~102 ~13 ~255 minecraft:sand strict
fill ~105 ~9 ~253 ~105 ~12 ~255 minecraft:sand strict
fill ~3 ~10 ~153 ~6 ~10 ~153 minecraft:sand strict
fill ~69 ~10 ~171 ~70 ~10 ~177 minecraft:tuff strict
fill ~71 ~10 ~171 ~72 ~13 ~176 minecraft:stone strict
fill ~66 ~10 ~172 ~68 ~10 ~179 minecraft:tuff strict
fill ~65 ~10 ~176 ~65 ~10 ~179 minecraft:tuff strict
fill ~71 ~10 ~177 ~71 ~13 ~177 minecraft:stone strict
fill ~64 ~10 ~178 ~64 ~11 ~179 minecraft:tuff strict
setblock ~69 ~10 ~178 minecraft:tuff strict
setblock ~66 ~10 ~180 minecraft:tuff strict
fill ~81 ~10 ~181 ~82 ~13 ~185 minecraft:stone strict
fill ~80 ~10 ~182 ~80 ~13 ~185 minecraft:stone strict
fill ~83 ~10 ~182 ~83 ~13 ~185 minecraft:stone strict
fill ~79 ~10 ~184 ~79 ~13 ~184 minecraft:stone strict
fill ~82 ~10 ~195 ~82 ~14 ~195 minecraft:stone strict
fill ~81 ~10 ~196 ~81 ~13 ~198 minecraft:stone strict
fill ~80 ~10 ~198 ~80 ~13 ~199 minecraft:stone strict
fill ~4 ~11 ~153 ~6 ~11 ~153 minecraft:sand strict
fill ~69 ~11 ~171 ~70 ~12 ~179 minecraft:stone strict
fill ~66 ~11 ~172 ~68 ~12 ~180 minecraft:stone strict
fill ~73 ~11 ~172 ~74 ~14 ~182 minecraft:stone strict
fill ~63 ~11 ~173 ~64 ~11 ~177 minecraft:tuff strict
fill ~65 ~11 ~173 ~65 ~13 ~180 minecraft:stone strict
fill ~75 ~11 ~173 ~75 ~14 ~184 minecraft:stone strict
fill ~60 ~11 ~174 ~62 ~11 ~181 minecraft:tuff strict
fill ~76 ~11 ~174 ~76 ~14 ~186 minecraft:stone strict
fill ~58 ~11 ~175 ~59 ~11 ~189 minecraft:tuff strict
fill ~77 ~11 ~175 ~77 ~14 ~187 minecraft:stone strict
fill ~57 ~11 ~176 ~57 ~11 ~190 minecraft:tuff strict
fill ~78 ~11 ~176 ~78 ~14 ~201 minecraft:stone strict
fill ~56 ~11 ~177 ~56 ~11 ~191 minecraft:tuff strict
fill ~72 ~11 ~177 ~72 ~14 ~180 minecraft:stone strict
fill ~79 ~11 ~177 ~79 ~14 ~183 minecraft:stone strict
fill ~54 ~11 ~178 ~55 ~11 ~191 minecraft:tuff strict
fill ~63 ~11 ~178 ~63 ~11 ~181 minecraft:tuff strict
fill ~71 ~11 ~178 ~71 ~14 ~179 minecraft:stone strict
fill ~80 ~11 ~178 ~80 ~14 ~181 minecraft:stone strict
fill ~53 ~11 ~179 ~53 ~11 ~191 minecraft:tuff strict
fill ~81 ~11 ~179 ~81 ~14 ~180 minecraft:stone strict
setblock ~64 ~11 ~180 minecraft:tuff strict
fill ~69 ~11 ~180 ~69 ~14 ~180 minecraft:stone strict
fill ~82 ~11 ~180 ~82 ~14 ~180 minecraft:stone strict
fill ~67 ~11 ~181 ~67 ~14 ~181 minecraft:stone strict
setblock ~60 ~11 ~182 minecraft:tuff strict
fill ~79 ~11 ~185 ~79 ~12 ~200 minecraft:stone strict
fill ~80 ~11 ~186 ~84 ~12 ~192 minecraft:stone strict
fill ~60 ~11 ~187 ~60 ~11 ~188 minecraft:tuff strict
fill ~85 ~11 ~189 ~85 ~14 ~190 minecraft:stone strict
setblock ~58 ~11 ~190 minecraft:tuff strict
fill ~59 ~11 ~190 ~59 ~14 ~201 minecraft:stone strict
fill ~77 ~11 ~190 ~77 ~14 ~201 minecraft:stone strict
fill ~57 ~11 ~191 ~58 ~14 ~201 minecraft:stone strict
fill ~60 ~11 ~191 ~60 ~14 ~202 minecraft:stone strict
fill ~76 ~11 ~191 ~76 ~14 ~202 minecraft:stone strict
fill ~53 ~11 ~192 ~56 ~14 ~195 minecraft:stone strict
fill ~61 ~11 ~192 ~61 ~14 ~202 minecraft:stone strict
fill ~75 ~11 ~192 ~75 ~14 ~202 minecraft:stone strict
fill ~74 ~11 ~193 ~74 ~14 ~203 minecraft:stone strict
fill ~80 ~11 ~193 ~83 ~14 ~193 minecraft:stone strict
fill ~62 ~11 ~194 ~62 ~14 ~202 minecraft:stone strict
fill ~80 ~11 ~194 ~82 ~14 ~194 minecraft:stone strict
fill ~63 ~11 ~195 ~66 ~14 ~202 minecraft:stone strict
fill ~73 ~11 ~195 ~73 ~14 ~203 minecraft:stone strict
fill ~80 ~11 ~195 ~81 ~14 ~195 minecraft:stone strict
fill ~54 ~11 ~196 ~56 ~14 ~197 minecraft:stone strict
fill ~67 ~11 ~196 ~67 ~14 ~204 minecraft:stone strict
fill ~71 ~11 ~196 ~72 ~14 ~204 minecraft:stone strict
fill ~80 ~11 ~196 ~80 ~14 ~197 minecraft:stone strict
fill ~68 ~11 ~197 ~70 ~14 ~205 minecraft:stone strict
fill ~55 ~11 ~198 ~56 ~14 ~199 minecraft:stone strict
fill ~56 ~11 ~200 ~56 ~14 ~200 minecraft:stone strict
fill ~64 ~11 ~203 ~66 ~14 ~203 minecraft:stone strict
fill ~66 ~11 ~204 ~66 ~14 ~204 minecraft:stone strict
fill ~106 ~11 ~253 ~106 ~12 ~254 minecraft:sand strict
fill ~4 ~12 ~153 ~5 ~12 ~153 minecraft:sand strict
fill ~63 ~12 ~173 ~64 ~14 ~180 minecraft:stone strict
fill ~60 ~12 ~174 ~62 ~14 ~181 minecraft:stone strict
fill ~58 ~12 ~175 ~59 ~14 ~189 minecraft:stone strict
fill ~57 ~12 ~176 ~57 ~14 ~190 minecraft:stone strict
fill ~56 ~12 ~177 ~56 ~14 ~191 minecraft:stone strict
fill ~54 ~12 ~178 ~55 ~14 ~191 minecraft:stone strict
fill ~53 ~12 ~179 ~53 ~14 ~191 minecraft:stone strict
fill ~63 ~12 ~181 ~63 ~14 ~181 minecraft:stone strict
fill ~60 ~12 ~182 ~60 ~15 ~182 minecraft:stone strict
fill ~60 ~12 ~187 ~60 ~14 ~188 minecraft:stone strict
fill ~58 ~12 ~190 ~58 ~14 ~190 minecraft:stone strict
setblock ~5 ~13 ~153 minecraft:sand strict
fill ~68 ~13 ~170 ~73 ~15 ~170 minecraft:stone strict
fill ~65 ~13 ~171 ~70 ~13 ~172 minecraft:stone strict
fill ~73 ~13 ~171 ~73 ~15 ~171 minecraft:stone strict
fill ~66 ~13 ~173 ~70 ~13 ~174 minecraft:stone strict
fill ~66 ~13 ~175 ~66 ~28 ~176 minecraft:stone_bricks strict
fill ~67 ~13 ~175 ~67 ~29 ~175 minecraft:mossy_stone_bricks strict
fill ~68 ~13 ~175 ~69 ~28 ~175 minecraft:stone_bricks strict
fill ~70 ~13 ~175 ~70 ~28 ~175 minecraft:mossy_stone_bricks strict
fill ~67 ~13 ~176 ~68 ~28 ~176 minecraft:stone_bricks strict
fill ~69 ~13 ~176 ~69 ~28 ~177 minecraft:cracked_stone_bricks strict
fill ~70 ~13 ~176 ~70 ~28 ~177 minecraft:stone_bricks strict
fill ~66 ~13 ~177 ~66 ~28 ~177 minecraft:cracked_stone_bricks strict
fill ~67 ~13 ~177 ~67 ~28 ~177 minecraft:mossy_stone_bricks strict
fill ~68 ~13 ~177 ~68 ~29 ~177 minecraft:stone_bricks strict
fill ~66 ~13 ~178 ~70 ~13 ~179 minecraft:stone strict
fill ~66 ~13 ~180 ~68 ~13 ~180 minecraft:stone strict
fill ~83 ~13 ~180 ~83 ~14 ~181 minecraft:stone strict
fill ~65 ~13 ~181 ~66 ~16 ~181 minecraft:stone strict
fill ~84 ~13 ~181 ~84 ~14 ~192 minecraft:stone strict
fill ~79 ~13 ~185 ~79 ~15 ~185 minecraft:stone strict
fill ~79 ~13 ~186 ~80 ~28 ~186 minecraft:mossy_stone_bricks strict
fill ~81 ~13 ~186 ~81 ~28 ~186 minecraft:stone_bricks strict
fill ~82 ~13 ~186 ~83 ~14 ~192 minecraft:stone strict
fill ~79 ~13 ~187 ~80 ~29 ~187 minecraft:stone_bricks strict
fill ~81 ~13 ~187 ~81 ~28 ~187 minecraft:cracked_stone_bricks strict
fill ~79 ~13 ~188 ~79 ~28 ~189 minecraft:stone_bricks strict
fill ~80 ~13 ~188 ~81 ~28 ~188 minecraft:mossy_stone_bricks strict
fill ~80 ~13 ~189 ~80 ~28 ~190 minecraft:stone_bricks strict
fill ~81 ~13 ~189 ~81 ~28 ~189 minecraft:mossy_stone_bricks strict
fill ~79 ~13 ~190 ~79 ~28 ~190 minecraft:cracked_stone_bricks strict
fill ~81 ~13 ~190 ~81 ~28 ~190 minecraft:stone_bricks strict
fill ~79 ~13 ~191 ~81 ~14 ~192 minecraft:stone strict
fill ~79 ~13 ~193 ~79 ~14 ~200 minecraft:stone strict
fill ~83 ~13 ~194 ~83 ~14 ~196 minecraft:stone strict
fill ~82 ~13 ~196 ~82 ~14 ~199 minecraft:stone strict
fill ~81 ~13 ~199 ~81 ~14 ~200 minecraft:stone strict
fill ~80 ~13 ~200 ~80 ~14 ~200 minecraft:stone strict
fill ~105 ~13 ~254 ~105 ~14 ~255 minecraft:sand strict
fill ~59 ~14 ~69 ~63 ~15 ~75 minecraft:mossy_cobblestone strict
fill ~58 ~14 ~70 ~58 ~16 ~75 minecraft:mossy_cobblestone strict
fill ~64 ~14 ~70 ~64 ~16 ~78 minecraft:mossy_cobblestone strict
fill ~57 ~14 ~71 ~57 ~16 ~74 minecraft:mossy_cobblestone strict
fill ~65 ~14 ~71 ~65 ~16 ~77 minecraft:mossy_cobblestone strict
fill ~56 ~14 ~72 ~56 ~16 ~74 minecraft:mossy_cobblestone strict
fill ~66 ~14 ~72 ~66 ~16 ~76 minecraft:mossy_cobblestone strict
fill ~56 ~14 ~75 ~57 ~14 ~76 minecraft:stone strict
fill ~58 ~14 ~76 ~60 ~14 ~78 minecraft:stone strict
fill ~61 ~14 ~76 ~63 ~16 ~76 minecraft:mossy_cobblestone strict
setblock ~57 ~14 ~77 minecraft:stone strict
fill ~61 ~14 ~77 ~62 ~14 ~79 minecraft:stone strict
fill ~63 ~14 ~77 ~63 ~16 ~77 minecraft:mossy_cobblestone strict
fill ~63 ~14 ~78 ~63 ~14 ~79 minecraft:stone strict
fill ~59 ~14 ~79 ~60 ~14 ~79 minecraft:stone strict
fill ~65 ~14 ~171 ~68 ~16 ~171 minecraft:stone strict
fill ~69 ~14 ~171 ~70 ~14 ~171 minecraft:andesite strict
fill ~71 ~14 ~171 ~72 ~14 ~171 minecraft:stone strict
fill ~74 ~14 ~171 ~75 ~15 ~171 minecraft:stone strict
fill ~62 ~14 ~172 ~65 ~16 ~172 minecraft:stone strict
setblock ~66 ~14 ~172 minecraft:gravel strict
setblock ~67 ~14 ~172 minecraft:andesite strict
fill ~68 ~14 ~172 ~71 ~14 ~173 minecraft:stone strict
fill ~72 ~14 ~172 ~72 ~14 ~174 minecraft:gravel strict
fill ~75 ~14 ~172 ~76 ~15 ~172 minecraft:stone strict
fill ~59 ~14 ~173 ~62 ~17 ~173 minecraft:stone strict
fill ~65 ~14 ~173 ~67 ~14 ~173 minecraft:stone strict
fill ~76 ~14 ~173 ~77 ~15 ~173 minecraft:stone strict
fill ~57 ~14 ~174 ~59 ~17 ~174 minecraft:stone strict
fill ~65 ~14 ~174 ~65 ~14 ~177 minecraft:stone strict
setblock ~66 ~14 ~174 minecraft:andesite strict
setblock ~67 ~14 ~174 minecraft:stone strict
fill ~68 ~14 ~174 ~69 ~14 ~174 minecraft:gravel strict
setblock ~70 ~14 ~174 minecraft:andesite strict
setblock ~71 ~14 ~174 minecraft:stone strict
fill ~77 ~14 ~174 ~78 ~14 ~174 minecraft:stone strict
fill ~56 ~14 ~175 ~57 ~17 ~175 minecraft:stone strict
fill ~71 ~14 ~175 ~71 ~14 ~177 minecraft:gravel strict
fill ~72 ~14 ~175 ~72 ~14 ~176 minecraft:andesite strict
fill ~78 ~14 ~175 ~79 ~14 ~175 minecraft:stone strict
fill ~55 ~14 ~176 ~56 ~17 ~176 minecraft:stone strict
fill ~79 ~14 ~176 ~80 ~14 ~176 minecraft:stone strict
fill ~53 ~14 ~177 ~55 ~17 ~177 minecraft:stone strict
fill ~80 ~14 ~177 ~81 ~14 ~177 minecraft:stone strict
fill ~52 ~14 ~178 ~53 ~17 ~178 minecraft:stone strict
setblock ~65 ~14 ~178 minecraft:gravel strict
setblock ~66 ~14 ~178 minecraft:stone strict
setblock ~67 ~14 ~178 minecraft:gravel strict
fill ~68 ~14 ~178 ~68 ~14 ~179 minecraft:andesite strict
fill ~69 ~14 ~178 ~70 ~14 ~179 minecraft:stone strict
fill ~81 ~14 ~178 ~82 ~14 ~178 minecraft:stone strict
fill ~52 ~14 ~179 ~52 ~16 ~196 minecraft:stone strict
setblock ~65 ~14 ~179 minecraft:andesite strict
fill ~66 ~14 ~179 ~66 ~14 ~180 minecraft:gravel strict
fill ~67 ~14 ~179 ~67 ~14 ~180 minecraft:stone strict
fill ~82 ~14 ~179 ~83 ~14 ~179 minecraft:stone strict
setblock ~65 ~14 ~180 minecraft:stone strict
fill ~68 ~14 ~180 ~68 ~15 ~182 minecraft:stone strict
fill ~70 ~14 ~180 ~71 ~15 ~181 minecraft:stone strict
fill ~64 ~14 ~181 ~64 ~17 ~182 minecraft:stone strict
fill ~69 ~14 ~181 ~69 ~16 ~181 minecraft:stone strict
fill ~72 ~14 ~181 ~72 ~15 ~183 minecraft:stone strict
setblock ~81 ~14 ~181 minecraft:stone strict
fill ~82 ~14 ~181 ~82 ~14 ~182 minecraft:andesite strict
fill ~61 ~14 ~182 ~63 ~17 ~182 minecraft:stone strict
fill ~66 ~14 ~182 ~67 ~16 ~182 minecraft:stone strict
fill ~80 ~14 ~182 ~80 ~14 ~185 minecraft:gravel strict
setblock ~81 ~14 ~182 minecraft:andesite strict
fill ~83 ~14 ~182 ~83 ~14 ~183 minecraft:gravel strict
fill ~60 ~14 ~183 ~61 ~17 ~183 minecraft:stone strict
fill ~73 ~14 ~183 ~74 ~15 ~183 minecraft:stone strict
setblock ~81 ~14 ~183 minecraft:stone strict
setblock ~82 ~14 ~183 minecraft:gravel strict
fill ~60 ~14 ~184 ~60 ~17 ~186 minecraft:stone strict
fill ~74 ~14 ~184 ~74 ~15 ~185 minecraft:stone strict
setblock ~79 ~14 ~184 minecraft:gravel strict
fill ~81 ~14 ~184 ~81 ~14 ~185 minecraft:gravel strict
setblock ~82 ~14 ~184 minecraft:andesite strict
fill ~83 ~14 ~184 ~83 ~14 ~185 minecraft:stone strict
fill ~75 ~14 ~185 ~75 ~14 ~187 minecraft:stone strict
setblock ~82 ~14 ~185 minecraft:stone strict
fill ~85 ~14 ~185 ~85 ~14 ~188 minecraft:stone strict
fill ~61 ~14 ~186 ~61 ~16 ~191 minecraft:stone strict
fill ~76 ~14 ~187 ~76 ~14 ~190 minecraft:stone strict
fill ~77 ~14 ~188 ~77 ~14 ~189 minecraft:stone strict
fill ~86 ~14 ~188 ~86 ~14 ~191 minecraft:stone strict
fill ~60 ~14 ~189 ~60 ~16 ~190 minecraft:stone strict
fill ~75 ~14 ~190 ~75 ~14 ~191 minecraft:stone strict
fill ~62 ~14 ~191 ~62 ~16 ~193 minecraft:stone strict
fill ~74 ~14 ~191 ~74 ~14 ~192 minecraft:stone strict
fill ~85 ~14 ~191 ~85 ~14 ~193 minecraft:stone strict
fill ~73 ~14 ~192 ~73 ~15 ~194 minecraft:stone strict
fill ~63 ~14 ~193 ~63 ~16 ~194 minecraft:stone strict
fill ~84 ~14 ~193 ~84 ~14 ~194 minecraft:stone strict
fill ~64 ~14 ~194 ~67 ~15 ~194 minecraft:stone strict
fill ~72 ~14 ~194 ~72 ~15 ~195 minecraft:stone strict
fill ~67 ~14 ~195 ~68 ~15 ~195 minecraft:stone strict
fill ~70 ~14 ~195 ~71 ~15 ~195 minecraft:stone strict
fill ~53 ~14 ~196 ~53 ~15 ~198 minecraft:stone strict
fill ~68 ~14 ~196 ~70 ~15 ~196 minecraft:stone strict
setblock ~81 ~14 ~196 minecraft:gravel strict
fill ~81 ~14 ~197 ~81 ~14 ~198 minecraft:stone strict
fill ~54 ~14 ~198 ~54 ~15 ~200 minecraft:stone strict
setblock ~80 ~14 ~198 minecraft:stone strict
setblock ~80 ~14 ~199 minecraft:andesite strict
fill ~55 ~14 ~200 ~55 ~15 ~201 minecraft:stone strict
fill ~56 ~14 ~201 ~56 ~15 ~202 minecraft:stone strict
fill ~79 ~14 ~201 ~80 ~14 ~201 minecraft:stone strict
fill ~57 ~14 ~202 ~59 ~15 ~202 minecraft:stone strict
fill ~77 ~14 ~202 ~79 ~14 ~202 minecraft:stone strict
fill ~59 ~14 ~203 ~63 ~14 ~203 minecraft:stone strict
fill ~75 ~14 ~203 ~77 ~14 ~203 minecraft:stone strict
fill ~63 ~14 ~204 ~65 ~14 ~204 minecraft:stone strict
fill ~73 ~14 ~204 ~75 ~14 ~204 minecraft:stone strict
fill ~65 ~14 ~205 ~67 ~14 ~205 minecraft:stone strict
fill ~71 ~14 ~205 ~73 ~14 ~205 minecraft:stone strict
fill ~67 ~14 ~206 ~71 ~14 ~206 minecraft:stone strict
fill ~102 ~14 ~252 ~102 ~15 ~254 minecraft:sand strict
fill ~56 ~15 ~75 ~57 ~17 ~76 minecraft:mossy_cobblestone strict
fill ~58 ~15 ~76 ~60 ~17 ~78 minecraft:mossy_cobblestone strict
fill ~57 ~15 ~77 ~57 ~17 ~77 minecraft:mossy_cobblestone strict
fill ~61 ~15 ~77 ~62 ~17 ~79 minecraft:mossy_cobblestone strict
fill ~63 ~15 ~78 ~63 ~17 ~79 minecraft:mossy_cobblestone strict
fill ~59 ~15 ~79 ~60 ~17 ~79 minecraft:mossy_cobblestone strict
fill ~69 ~15 ~171 ~72 ~16 ~174 minecraft:water[level=0] strict
