fill ~224 ~48 ~64 ~255 ~63 ~95 minecraft:air strict
fill ~224 ~32 ~64 ~255 ~47 ~95 minecraft:air strict
fill ~224 ~16 ~64 ~255 ~31 ~95 minecraft:air strict
fill ~224 ~0 ~64 ~255 ~15 ~95 minecraft:air strict
fill ~224 ~80 ~96 ~255 ~95 ~127 minecraft:air strict
fill ~224 ~64 ~96 ~255 ~79 ~127 minecraft:air strict
fill ~224 ~48 ~96 ~255 ~63 ~127 minecraft:air strict
fill ~224 ~32 ~96 ~255 ~47 ~127 minecraft:air strict
fill ~224 ~16 ~96 ~255 ~31 ~127 minecraft:air strict
fill ~224 ~0 ~96 ~255 ~15 ~127 minecraft:air strict
fill ~224 ~80 ~128 ~255 ~95 ~159 minecraft:air strict
fill ~224 ~64 ~128 ~255 ~79 ~159 minecraft:air strict
fill ~224 ~48 ~128 ~255 ~63 ~159 minecraft:air strict
fill ~224 ~32 ~128 ~255 ~47 ~159 minecraft:air strict
fill ~224 ~16 ~128 ~255 ~31 ~159 minecraft:air strict
fill ~224 ~0 ~128 ~255 ~15 ~159 minecraft:air strict
fill ~224 ~80 ~160 ~255 ~95 ~191 minecraft:air strict
fill ~224 ~64 ~160 ~255 ~79 ~191 minecraft:air strict
fill ~224 ~48 ~160 ~255 ~63 ~191 minecraft:air strict
fill ~224 ~32 ~160 ~255 ~47 ~191 minecraft:air strict
fill ~224 ~16 ~160 ~255 ~31 ~191 minecraft:air strict
fill ~224 ~0 ~160 ~255 ~15 ~191 minecraft:air strict
fill ~224 ~80 ~192 ~255 ~95 ~223 minecraft:air strict
fill ~224 ~64 ~192 ~255 ~79 ~223 minecraft:air strict
fill ~224 ~48 ~192 ~255 ~63 ~223 minecraft:air strict
fill ~224 ~32 ~192 ~255 ~47 ~223 minecraft:air strict
fill ~224 ~16 ~192 ~255 ~31 ~223 minecraft:air strict
fill ~224 ~0 ~192 ~255 ~15 ~223 minecraft:air strict
fill ~224 ~80 ~224 ~255 ~95 ~255 minecraft:air strict
fill ~224 ~64 ~224 ~255 ~79 ~255 minecraft:air strict
fill ~224 ~48 ~224 ~255 ~63 ~255 minecraft:air strict
fill ~224 ~32 ~224 ~255 ~47 ~255 minecraft:air strict
fill ~224 ~16 ~224 ~255 ~31 ~255 minecraft:air strict
fill ~224 ~0 ~224 ~255 ~15 ~255 minecraft:air strict
fill ~69 ~10 ~171 ~70 ~10 ~177 minecraft:tuff strict
fill ~71 ~10 ~171 ~72 ~13 ~176 minecraft:stone strict
fill ~66 ~10 ~172 ~68 ~10 ~179 minecraft:tuff strict
fill ~65 ~10 ~176 ~65 ~10 ~179 minecraft:tuff strict
fill ~71 ~10 ~177 ~71 ~13 ~177 minecraft:stone strict
fill ~64 ~10 ~178 ~64 ~11 ~179 minecraft:tuff strict
setblock ~69 ~10 ~178 minecraft:tuff strict
setblock ~66 ~10 ~180 minecraft:tuff strict
fill ~81 ~10 ~181 ~82 ~13 ~185 minecraft:stone strict
fill ~80 ~10 ~182 ~80 ~13 ~185 minecraft:stone strict
fill ~83 ~10 ~182 ~83 ~13 ~185 minecraft:stone strict
fill ~79 ~10 ~184 ~79 ~13 ~184 minecraft:stone strict
fill ~82 ~10 ~195 ~82 ~14 ~195 minecraft:stone strict
fill ~81 ~10 ~196 ~81 ~13 ~198 minecraft:stone strict
fill ~80 ~10 ~198 ~80 ~13 ~199 minecraft:stone strict
fill ~69 ~11 ~171 ~70 ~12 ~179 minecraft:stone strict
fill ~66 ~11 ~172 ~68 ~12 ~180 minecraft:stone strict
fill ~73 ~11 ~172 ~74 ~14 ~182 minecraft:stone strict
fill ~63 ~11 ~173 ~64 ~11 ~177 minecraft:tuff strict
fill ~65 ~11 ~173 ~65 ~13 ~180 minecraft:stone strict
fill ~75 ~11 ~173 ~75 ~14 ~184 minecraft:stone strict
fill ~60 ~11 ~174 ~62 ~11 ~181 minecraft:tuff strict
fill ~76 ~11 ~174 ~76 ~14 ~186 minecraft:stone strict
fill ~58 ~11 ~175 ~59 ~11 ~189 minecraft:tuff strict
fill ~77 ~11 ~175 ~77 ~14 ~187 minecraft:stone strict
fill ~57 ~11 ~176 ~57 ~11 ~190 minecraft:tuff strict
fill ~78 ~11 ~176 ~78 ~14 ~201 minecraft:stone strict
fill ~56 ~11 ~177 ~56 ~11 ~191 minecraft:tuff strict
fill ~72 ~11 ~177 ~72 ~14 ~180 minecraft:stone strict
fill ~79 ~11 ~177 ~79 ~14 ~183 minecraft:stone strict
fill ~54 ~11 ~178 ~55 ~11 ~191 minecraft:tuff strict
fill ~63 ~11 ~178 ~63 ~11 ~181 minecraft:tuff strict
fill ~71 ~11 ~178 ~71 ~14 ~179 minecraft:stone strict
fill ~80 ~11 ~178 ~80 ~14 ~181 minecraft:stone strict
fill ~53 ~11 ~179 ~53 ~11 ~191 minecraft:tuff strict
fill ~81 ~11 ~179 ~81 ~14 ~180 minecraft:stone strict
setblock ~64 ~11 ~180 minecraft:tuff strict
fill ~69 ~11 ~180 ~69 ~14 ~180 minecraft:stone strict
fill ~82 ~11 ~180 ~82 ~14 ~180 minecraft:stone strict
fill ~67 ~11 ~181 ~67 ~14 ~181 minecraft:stone strict
setblock ~60 ~11 ~182 minecraft:tuff strict
fill ~79 ~11 ~185 ~79 ~12 ~200 minecraft:stone strict
fill ~80 ~11 ~186 ~84 ~12 ~192 minecraft:stone strict
fill ~60 ~11 ~187 ~60 ~11 ~188 minecraft:tuff strict
fill ~85 ~11 ~189 ~85 ~14 ~190 minecraft:stone strict
setblock ~58 ~11 ~190 minecraft:tuff strict
fill ~59 ~11 ~190 ~59 ~14 ~201 minecraft:stone strict
fill ~77 ~11 ~190 ~77 ~14 ~201 minecraft:stone strict
fill ~57 ~11 ~191 ~58 ~14 ~201 minecraft:stone strict
fill ~60 ~11 ~191 ~60 ~14 ~202 minecraft:stone strict
fill ~76 ~11 ~191 ~76 ~14 ~202 minecraft:stone strict
fill ~53 ~11 ~192 ~56 ~14 ~195 minecraft:stone strict
fill ~61 ~11 ~192 ~61 ~14 ~202 minecraft:stone strict
fill ~75 ~11 ~192 ~75 ~14 ~202 minecraft:stone strict
fill ~74 ~11 ~193 ~74 ~14 ~203 minecraft:stone strict
fill ~80 ~11 ~193 ~83 ~14 ~193 minecraft:stone strict
fill ~62 ~11 ~194 ~62 ~14 ~202 minecraft:stone strict
fill ~80 ~11 ~194 ~82 ~14 ~194 minecraft:stone strict
fill ~63 ~11 ~195 ~66 ~14 ~202 minecraft:stone strict
fill ~73 ~11 ~195 ~73 ~14 ~203 minecraft:stone strict
fill ~80 ~11 ~195 ~81 ~14 ~195 minecraft:stone strict
fill ~54 ~11 ~196 ~56 ~14 ~197 minecraft:stone strict
fill ~67 ~11 ~196 ~67 ~14 ~204 minecraft:stone strict
fill ~71 ~11 ~196 ~72 ~14 ~204 minecraft:stone strict
fill ~80 ~11 ~196 ~80 ~14 ~197 minecraft:stone strict
fill ~68 ~11 ~197 ~70 ~14 ~205 minecraft:stone strict
fill ~55 ~11 ~198 ~56 ~14 ~199 minecraft:stone strict
fill ~56 ~11 ~200 ~56 ~14 ~200 minecraft:stone strict
fill ~64 ~11 ~203 ~66 ~14 ~203 minecraft:stone strict
fill ~66 ~11 ~204 ~66 ~14 ~204 minecraft:stone strict
fill ~63 ~12 ~173 ~64 ~14 ~180 minecraft:stone strict
fill ~60 ~12 ~174 ~62 ~14 ~181 minecraft:stone strict
fill ~58 ~12 ~175 ~59 ~14 ~189 minecraft:stone strict
fill ~57 ~12 ~176 ~57 ~14 ~190 minecraft:stone strict
fill ~56 ~12 ~177 ~56 ~14 ~191 minecraft:stone strict
fill ~54 ~12 ~178 ~55 ~14 ~191 minecraft:stone strict
fill ~53 ~12 ~179 ~53 ~14 ~191 minecraft:stone strict
fill ~63 ~12 ~181 ~63 ~14 ~181 minecraft:stone strict
fill ~60 ~12 ~182 ~60 ~15 ~182 minecraft:stone strict
fill ~60 ~12 ~187 ~60 ~14 ~188 minecraft:stone strict
fill ~58 ~12 ~190 ~58 ~14 ~190 minecraft:stone strict
fill ~68 ~13 ~170 ~73 ~15 ~170 minecraft:stone strict
fill ~65 ~13 ~171 ~70 ~13 ~172 minecraft:stone strict
fill ~73 ~13 ~171 ~73 ~15 ~171 minecraft:stone strict
fill ~66 ~13 ~173 ~70 ~13 ~174 minecraft:stone strict
fill ~66 ~13 ~175 ~66 ~28 ~176 minecraft:stone_bricks strict
fill ~67 ~13 ~175 ~67 ~29 ~175 minecraft:mossy_stone_bricks strict
fill ~68 ~13 ~175 ~69 ~28 ~175 minecraft:stone_bricks strict
fill ~70 ~13 ~175 ~70 ~28 ~175 minecraft:mossy_stone_bricks strict
fill ~67 ~13 ~176 ~68 ~28 ~176 minecraft:stone_bricks strict
fill ~69 ~13 ~176 ~69 ~28 ~177 minecraft:cracked_stone_bricks strict
fill ~70 ~13 ~176 ~70 ~28 ~177 minecraft:stone_bricks strict
fill ~66 ~13 ~177 ~66 ~28 ~177 minecraft:cracked_stone_bricks strict
fill ~67 ~13 ~177 ~67 ~28 ~177 minecraft:mossy_stone_bricks strict
fill ~68 ~13 ~177 ~68 ~29 ~177 minecraft:stone_bricks strict
fill ~66 ~13 ~178 ~70 ~13 ~179 minecraft:stone strict
fill ~66 ~13 ~180 ~68 ~13 ~180 minecraft:stone strict
fill ~83 ~13 ~180 ~83 ~14 ~181 minecraft:stone strict
fill ~65 ~13 ~181 ~66 ~16 ~181 minecraft:stone strict
fill ~84 ~13 ~181 ~84 ~14 ~192 minecraft:stone strict
fill ~79 ~13 ~185 ~79 ~15 ~185 minecraft:stone strict
fill ~79 ~13 ~186 ~80 ~28 ~186 minecraft:mossy_stone_bricks strict
fill ~81 ~13 ~186 ~81 ~28 ~186 minecraft:stone_bricks strict
fill ~82 ~13 ~186 ~83 ~14 ~192 minecraft:stone strict
fill ~79 ~13 ~187 ~80 ~29 ~187 minecraft:stone_bricks strict
fill ~81 ~13 ~187 ~81 ~28 ~187 minecraft:cracked_stone_bricks strict
fill ~79 ~13 ~188 ~79 ~28 ~189 minecraft:stone_bricks strict
fill ~80 ~13 ~188 ~81 ~28 ~188 minecraft:mossy_stone_bricks strict
fill ~80 ~13 ~189 ~80 ~28 ~190 minecraft:stone_bricks strict
fill ~81 ~13 ~189 ~81 ~28 ~189 minecraft:mossy_stone_bricks strict
fill ~79 ~13 ~190 ~79 ~28 ~190 minecraft:cracked_stone_bricks strict
fill ~81 ~13 ~190 ~81 ~28 ~190 minecraft:stone_bricks strict
fill ~79 ~13 ~191 ~81 ~14 ~192 minecraft:stone strict
fill ~79 ~13 ~193 ~79 ~14 ~200 minecraft:stone strict
fill ~83 ~13 ~194 ~83 ~14 ~196 minecraft:stone strict
fill ~82 ~13 ~196 ~82 ~14 ~199 minecraft:stone strict
fill ~81 ~13 ~199 ~81 ~14 ~200 minecraft:stone strict
fill ~80 ~13 ~200 ~80 ~14 ~200 minecraft:stone strict
fill ~59 ~14 ~69 ~63 ~15 ~75 minecraft:mossy_cobblestone strict
fill ~58 ~14 ~70 ~58 ~16 ~75 minecraft:mossy_cobblestone strict
fill ~64 ~14 ~70 ~64 ~16 ~78 minecraft:mossy_cobblestone strict
fill ~57 ~14 ~71 ~57 ~16 ~74 minecraft:mossy_cobblestone strict
fill ~65 ~14 ~71 ~65 ~16 ~77 minecraft:mossy_cobblestone strict
fill ~56 ~14 ~72 ~56 ~16 ~74 minecraft:mossy_cobblestone strict
fill ~66 ~14 ~72 ~66 ~16 ~76 minecraft:mossy_cobblestone strict
fill ~56 ~14 ~75 ~57 ~14 ~76 minecraft:stone strict
fill ~58 ~14 ~76 ~60 ~14 ~78 minecraft:stone strict
fill ~61 ~14 ~76 ~63 ~16 ~76 minecraft:mossy_cobblestone strict
setblock ~57 ~14 ~77 minecraft:stone strict
fill ~61 ~14 ~77 ~62 ~14 ~79 minecraft:stone strict
fill ~63 ~14 ~77 ~63 ~16 ~77 minecraft:mossy_cobblestone strict
fill ~63 ~14 ~78 ~63 ~14 ~79 minecraft:stone strict
fill ~59 ~14 ~79 ~60 ~14 ~79 minecraft:stone strict
fill ~65 ~14 ~171 ~68 ~16 ~171 minecraft:stone strict
fill ~69 ~14 ~171 ~70 ~14 ~171 minecraft:andesite strict
fill ~71 ~14 ~171 ~72 ~14 ~171 minecraft:stone strict
fill ~74 ~14 ~171 ~75 ~15 ~171 minecraft:stone strict
fill ~62 ~14 ~172 ~65 ~16 ~172 minecraft:stone strict
setblock ~66 ~14 ~172 minecraft:gravel strict
setblock ~67 ~14 ~172 minecraft:andesite strict
fill ~68 ~14 ~172 ~71 ~14 ~173 minecraft:stone strict
fill ~72 ~14 ~172 ~72 ~14 ~174 minecraft:gravel strict
fill ~75 ~14 ~172 ~76 ~15 ~172 minecraft:stone strict
fill ~59 ~14 ~173 ~62 ~17 ~173 minecraft:stone strict
fill ~65 ~14 ~173 ~67 ~14 ~173 minecraft:stone strict
fill ~76 ~14 ~173 ~77 ~15 ~173 minecraft:stone strict
fill ~57 ~14 ~174 ~59 ~17 ~174 minecraft:stone strict
fill ~65 ~14 ~174 ~65 ~14 ~177 minecraft:stone strict
setblock ~66 ~14 ~174 minecraft:andesite strict
setblock ~67 ~14 ~174 minecraft:stone strict
fill ~68 ~14 ~174 ~69 ~14 ~174 minecraft:gravel strict
setblock ~70 ~14 ~174 minecraft:andesite strict
setblock ~71 ~14 ~174 minecraft:stone strict
fill ~77 ~14 ~174 ~78 ~14 ~174 minecraft:stone strict
fill ~56 ~14 ~175 ~57 ~17 ~175 minecraft:stone strict
fill ~71 ~14 ~175 ~71 ~14 ~177 minecraft:gravel strict
fill ~72 ~14 ~175 ~72 ~14 ~176 minecraft:andesite strict
fill ~78 ~14 ~175 ~79 ~14 ~175 minecraft:stone strict
fill ~55 ~14 ~176 ~56 ~17 ~176 minecraft:stone strict
fill ~79 ~14 ~176 ~80 ~14 ~176 minecraft:stone strict
fill ~53 ~14 ~177 ~55 ~17 ~177 minecraft:stone strict
fill ~80 ~14 ~177 ~81 ~14 ~177 minecraft:stone strict
fill ~52 ~14 ~178 ~53 ~17 ~178 minecraft:stone strict
setblock ~65 ~14 ~178 minecraft:gravel strict
setblock ~66 ~14 ~178 minecraft:stone strict
setblock ~67 ~14 ~178 minecraft:gravel strict
fill ~68 ~14 ~178 ~68 ~14 ~179 minecraft:andesite strict
fill ~69 ~14 ~178 ~70 ~14 ~179 minecraft:stone strict
fill ~81 ~14 ~178 ~82 ~14 ~178 minecraft:stone strict
fill ~52 ~14 ~179 ~52 ~16 ~196 minecraft:stone strict
setblock ~65 ~14 ~179 minecraft:andesite strict
fill ~66 ~14 ~179 ~66 ~14 ~180 minecraft:gravel strict
fill ~67 ~14 ~179 ~67 ~14 ~180 minecraft:stone strict
fill ~82 ~14 ~179 ~83 ~14 ~179 minecraft:stone strict
setblock ~65 ~14 ~180 minecraft:stone strict
fill ~68 ~14 ~180 ~68 ~15 ~182 minecraft:stone strict
fill ~70 ~14 ~180 ~71 ~15 ~181 minecraft:stone strict
fill ~64 ~14 ~181 ~64 ~17 ~182 minecraft:stone strict
fill ~69 ~14 ~181 ~69 ~16 ~181 minecraft:stone strict
fill ~72 ~14 ~181 ~72 ~15 ~183 minecraft:stone strict
setblock ~81 ~14 ~181 minecraft:stone strict
fill ~82 ~14 ~181 ~82 ~14 ~182 minecraft:andesite strict
fill ~61 ~14 ~182 ~63 ~17 ~182 minecraft:stone strict
fill ~66 ~14 ~182 ~67 ~16 ~182 minecraft:stone strict
fill ~80 ~14 ~182 ~80 ~14 ~185 minecraft:gravel strict
setblock ~81 ~14 ~182 minecraft:andesite strict
fill ~83 ~14 ~182 ~83 ~14 ~183 minecraft:gravel strict
fill ~60 ~14 ~183 ~61 ~17 ~183 minecraft:stone strict
fill ~73 ~14 ~183 ~74 ~15 ~183 minecraft:stone strict
setblock ~81 ~14 ~183 minecraft:stone strict
setblock ~82 ~14 ~183 minecraft:gravel strict
fill ~60 ~14 ~184 ~60 ~17 ~186 minecraft:stone strict
fill ~74 ~14 ~184 ~74 ~15 ~185 minecraft:stone strict
setblock ~79 ~14 ~184 minecraft:gravel strict
fill ~81 ~14 ~184 ~81 ~14 ~185 minecraft:gravel strict
setblock ~82 ~14 ~184 minecraft:andesite strict
fill ~83 ~14 ~184 ~83 ~14 ~185 minecraft:stone strict
fill ~75 ~14 ~185 ~75 ~14 ~187 minecraft:stone strict
setblock ~82 ~14 ~185 minecraft:stone strict
fill ~85 ~14 ~185 ~85 ~14 ~188 minecraft:stone strict
fill ~61 ~14 ~186 ~61 ~16 ~191 minecraft:stone strict
fill ~76 ~14 ~187 ~76 ~14 ~190 minecraft:stone strict
fill ~77 ~14 ~188 ~77 ~14 ~189 minecraft:stone strict
fill ~86 ~14 ~188 ~86 ~14 ~191 minecraft:stone strict
fill ~60 ~14 ~189 ~60 ~16 ~190 minecraft:stone strict
fill ~75 ~14 ~190 ~75 ~14 ~191 minecraft:stone strict
fill ~62 ~14 ~191 ~62 ~16 ~193 minecraft:stone strict
fill ~74 ~14 ~191 ~74 ~14 ~192 minecraft:stone strict
fill ~85 ~14 ~191 ~85 ~14 ~193 minecraft:stone strict
fill ~73 ~14 ~192 ~73 ~15 ~194 minecraft:stone strict
fill ~63 ~14 ~193 ~63 ~16 ~194 minecraft:stone strict
fill ~84 ~14 ~193 ~84 ~14 ~194 minecraft:stone strict
fill ~64 ~14 ~194 ~67 ~15 ~194 minecraft:stone strict
fill ~72 ~14 ~194 ~72 ~15 ~195 minecraft:stone strict
fill ~67 ~14 ~195 ~68 ~15 ~195 minecraft:stone strict
fill ~70 ~14 ~195 ~71 ~15 ~195 minecraft:stone strict
fill ~53 ~14 ~196 ~53 ~15 ~198 minecraft:stone strict
fill ~68 ~14 ~196 ~70 ~15 ~196 minecraft:stone strict
setblock ~81 ~14 ~196 minecraft:gravel strict
fill ~81 ~14 ~197 ~81 ~14 ~198 minecraft:stone strict
fill ~54 ~14 ~198 ~54 ~15 ~200 minecraft:stone strict
setblock ~80 ~14 ~198 minecraft:stone strict
setblock ~80 ~14 ~199 minecraft:andesite strict
fill ~55 ~14 ~200 ~55 ~15 ~201 minecraft:stone strict
fill ~56 ~14 ~201 ~56 ~15 ~202 minecraft:stone strict
fill ~79 ~14 ~201 ~80 ~14 ~201 minecraft:stone strict
fill ~57 ~14 ~202 ~59 ~15 ~202 minecraft:stone strict
fill ~77 ~14 ~202 ~79 ~14 ~202 minecraft:stone strict
fill ~59 ~14 ~203 ~63 ~14 ~203 minecraft:stone strict
fill ~75 ~14 ~203 ~77 ~14 ~203 minecraft:stone strict
fill ~63 ~14 ~204 ~65 ~14 ~204 minecraft:stone strict
fill ~73 ~14 ~204 ~75 ~14 ~204 minecraft:stone strict
fill ~65 ~14 ~205 ~67 ~14 ~205 minecraft:stone strict
fill ~71 ~14 ~205 ~73 ~14 ~205 minecraft:stone strict
fill ~67 ~14 ~206 ~71 ~14 ~206 minecraft:stone strict
fill ~56 ~15 ~75 ~57 ~17 ~76 minecraft:mossy_cobblestone strict
fill ~58 ~15 ~76 ~60 ~17 ~78 minecraft:mossy_cobblestone strict
fill ~57 ~15 ~77 ~57 ~17 ~77 minecraft:mossy_cobblestone strict
fill ~61 ~15 ~77 ~62 ~17 ~79 minecraft:mossy_cobblestone strict
fill ~63 ~15 ~78 ~63 ~17 ~79 minecraft:mossy_cobblestone strict
fill ~59 ~15 ~79 ~60 ~17 ~79 minecraft:mossy_cobblestone strict
fill ~69 ~15 ~171 ~72 ~16 ~174 minecraft:water strict
fill ~66 ~15 ~172 ~68 ~16 ~174 minecraft:water strict
fill ~73 ~15 ~172 ~74 ~15 ~172 minecraft:stone strict
fill ~63 ~15 ~173 ~64 ~15 ~173 minecraft:gravel strict
setblock ~65 ~15 ~173 minecraft:andesite strict
fill ~73 ~15 ~173 ~73 ~15 ~174 minecraft:andesite strict
fill ~74 ~15 ~173 ~75 ~15 ~173 minecraft:stone strict
setblock ~60 ~15 ~174 minecraft:gravel strict
setblock ~61 ~15 ~174 minecraft:stone strict
fill ~62 ~15 ~174 ~62 ~15 ~175 minecraft:gravel strict
fill ~63 ~15 ~174 ~64 ~15 ~174 minecraft:stone strict
setblock ~65 ~15 ~174 minecraft:gravel strict
setblock ~74 ~15 ~174 minecraft:stone strict
setblock ~75 ~15 ~174 minecraft:andesite strict
setblock ~76 ~15 ~174 minecraft:gravel strict
setblock ~77 ~15 ~174 minecraft:stone strict
fill ~78 ~15 ~174 ~78 ~17 ~175 minecraft:andesite strict
fill ~58 ~15 ~175 ~60 ~15 ~175 minecraft:stone strict
fill ~61 ~15 ~175 ~61 ~15 ~177 minecraft:andesite strict
fill ~63 ~15 ~175 ~64 ~15 ~176 minecraft:gravel strict
setblock ~65 ~15 ~175 minecraft:andesite strict
fill ~71 ~15 ~175 ~72 ~16 ~176 minecraft:water strict
fill ~73 ~15 ~175 ~75 ~15 ~176 minecraft:gravel strict
setblock ~76 ~15 ~175 minecraft:stone strict
setblock ~77 ~15 ~175 minecraft:andesite strict
fill ~79 ~15 ~175 ~79 ~17 ~176 minecraft:andesite strict
fill ~57 ~15 ~176 ~58 ~15 ~176 minecraft:andesite strict
fill ~59 ~15 ~176 ~60 ~15 ~176 minecraft:stone strict
setblock ~62 ~15 ~176 minecraft:stone strict
fill ~65 ~15 ~176 ~65 ~16 ~179 minecraft:water strict
fill ~76 ~15 ~176 ~78 ~15 ~176 minecraft:gravel strict
fill ~80 ~15 ~176 ~80 ~17 ~177 minecraft:andesite strict
fill ~56 ~15 ~177 ~57 ~15 ~179 minecraft:gravel strict
setblock ~58 ~15 ~177 minecraft:andesite strict
fill ~59 ~15 ~177 ~59 ~15 ~178 minecraft:gravel strict
fill ~60 ~15 ~177 ~60 ~15 ~178 minecraft:stone strict
fill ~62 ~15 ~177 ~62 ~15 ~179 minecraft:andesite strict
setblock ~63 ~15 ~177 minecraft:gravel strict
setblock ~64 ~15 ~177 minecraft:andesite strict
fill ~71 ~15 ~177 ~71 ~16 ~177 minecraft:water strict
fill ~72 ~15 ~177 ~72 ~15 ~178 minecraft:gravel strict
setblock ~73 ~15 ~177 minecraft:stone strict
fill ~74 ~15 ~177 ~75 ~15 ~178 minecraft:gravel strict
fill ~76 ~15 ~177 ~77 ~15 ~177 minecraft:stone strict
fill ~78 ~15 ~177 ~78 ~15 ~178 minecraft:gravel strict
setblock ~79 ~15 ~177 minecraft:stone strict
fill ~81 ~15 ~177 ~81 ~17 ~178 minecraft:andesite strict
setblock ~54 ~15 ~178 minecraft:gravel strict
setblock ~55 ~15 ~178 minecraft:stone strict
fill ~58 ~15 ~178 ~58 ~15 ~180 minecraft:gravel strict
setblock ~61 ~15 ~178 minecraft:gravel strict
setblock ~63 ~15 ~178 minecraft:andesite strict
fill ~64 ~15 ~178 ~64 ~16 ~179 minecraft:water strict
fill ~66 ~15 ~178 ~69 ~16 ~178 minecraft:water strict
setblock ~70 ~15 ~178 minecraft:andesite strict
setblock ~71 ~15 ~178 minecraft:stone strict
setblock ~73 ~15 ~178 minecraft:andesite strict
fill ~76 ~15 ~178 ~77 ~15 ~178 minecraft:gravel strict
fill ~79 ~15 ~178 ~80 ~15 ~178 minecraft:gravel strict
fill ~82 ~15 ~178 ~82 ~15 ~180 minecraft:andesite strict
fill ~53 ~15 ~179 ~54 ~15 ~179 minecraft:andesite strict
setblock ~55 ~15 ~179 minecraft:gravel strict
setblock ~59 ~15 ~179 minecraft:andesite strict
setblock ~60 ~15 ~179 minecraft:gravel strict
fill ~61 ~15 ~179 ~61 ~15 ~181 minecraft:andesite strict
setblock ~63 ~15 ~179 minecraft:stone strict
fill ~66 ~15 ~179 ~68 ~16 ~179 minecraft:water strict
fill ~69 ~15 ~179 ~70 ~15 ~179 minecraft:stone strict
setblock ~71 ~15 ~179 minecraft:gravel strict
fill ~72 ~15 ~179 ~72 ~15 ~180 minecraft:andesite strict
setblock ~73 ~15 ~179 minecraft:stone strict
setblock ~74 ~15 ~179 minecraft:gravel strict
setblock ~75 ~15 ~179 minecraft:andesite strict
fill ~76 ~15 ~179 ~76 ~15 ~183 minecraft:stone strict
fill ~77 ~15 ~179 ~77 ~15 ~181 minecraft:andesite strict
