fill ~67 ~48 ~253 ~80 ~50 ~253 minecraft:dirt strict
fill ~81 ~48 ~253 ~81 ~51 ~253 minecraft:stone strict
setblock ~85 ~48 ~253 minecraft:grass_block[snowy=false] strict
fill ~153 ~48 ~253 ~154 ~52 ~253 minecraft:stone strict
fill ~155 ~48 ~253 ~155 ~50 ~253 minecraft:dirt strict
fill ~161 ~48 ~253 ~165 ~48 ~253 minecraft:grass_block[snowy=false] strict
fill ~223 ~48 ~253 ~223 ~48 ~255 minecraft:grass_block[snowy=false] strict
fill ~232 ~48 ~253 ~233 ~50 ~253 minecraft:stone strict
fill ~243 ~48 ~253 ~248 ~48 ~253 minecraft:grass_block[snowy=false] strict
setblock ~10 ~48 ~254 minecraft:andesite strict
fill ~11 ~48 ~254 ~11 ~48 ~255 minecraft:grass_block[snowy=false] strict
fill ~16 ~48 ~254 ~21 ~50 ~254 minecraft:dirt strict
fill ~33 ~48 ~254 ~36 ~48 ~255 minecraft:grass_block[snowy=false] strict
fill ~61 ~48 ~254 ~62 ~48 ~255 minecraft:grass_block[snowy=false] strict
fill ~66 ~48 ~254 ~67 ~50 ~255 minecraft:dirt strict
fill ~68 ~48 ~254 ~80 ~48 ~255 minecraft:stone strict
fill ~81 ~48 ~254 ~82 ~50 ~254 minecraft:dirt strict
setblock ~87 ~48 ~254 minecraft:grass_block[snowy=false] strict
fill ~134 ~48 ~254 ~137 ~48 ~254 minecraft:tuff strict
fill ~140 ~48 ~254 ~141 ~50 ~254 minecraft:dirt strict
setblock ~142 ~48 ~254 minecraft:tuff strict
setblock ~143 ~48 ~254 minecraft:stone strict
fill ~154 ~48 ~254 ~155 ~48 ~254 minecraft:stone strict
fill ~156 ~48 ~254 ~156 ~50 ~255 minecraft:dirt strict
fill ~163 ~48 ~254 ~166 ~48 ~254 minecraft:grass_block[snowy=false] strict
fill ~228 ~48 ~254 ~235 ~50 ~254 minecraft:dirt strict
fill ~247 ~48 ~254 ~255 ~48 ~254 minecraft:grass_block[snowy=false] strict
setblock ~10 ~48 ~255 minecraft:grass_block[snowy=false] strict
fill ~17 ~48 ~255 ~20 ~50 ~255 minecraft:dirt strict
fill ~37 ~48 ~255 ~38 ~48 ~255 minecraft:grass_block[snowy=false] strict
setblock ~81 ~48 ~255 minecraft:stone strict
fill ~82 ~48 ~255 ~83 ~50 ~255 minecraft:dirt strict
fill ~88 ~48 ~255 ~89 ~48 ~255 minecraft:grass_block[snowy=false] strict
fill ~125 ~48 ~255 ~129 ~48 ~255 minecraft:tuff strict
fill ~141 ~48 ~255 ~142 ~50 ~255 minecraft:dirt strict
fill ~153 ~48 ~255 ~154 ~48 ~255 minecraft:stone strict
fill ~155 ~48 ~255 ~155 ~50 ~255 minecraft:dirt strict
fill ~163 ~48 ~255 ~165 ~48 ~255 minecraft:grass_block[snowy=false] strict
setblock ~224 ~48 ~255 minecraft:grass_block[snowy=false] strict
fill ~231 ~48 ~255 ~232 ~50 ~255 minecraft:dirt strict
fill ~84 ~49 ~0 ~94 ~49 ~0 minecraft:grass_block[snowy=false] strict
fill ~99 ~49 ~0 ~100 ~49 ~1 minecraft:grass_block[snowy=false] strict
fill ~147 ~49 ~0 ~148 ~49 ~0 minecraft:moss_block strict
fill ~154 ~49 ~0 ~158 ~51 ~1 minecraft:dirt strict
fill ~163 ~49 ~0 ~164 ~49 ~2 minecraft:grass_block[snowy=false] strict
fill ~168 ~49 ~0 ~173 ~49 ~2 minecraft:grass_block[snowy=false] strict
fill ~202 ~49 ~0 ~202 ~49 ~3 minecraft:moss_block strict
fill ~207 ~49 ~0 ~209 ~51 ~0 minecraft:dirt strict
fill ~210 ~49 ~0 ~213 ~49 ~3 minecraft:stone strict
fill ~214 ~49 ~0 ~215 ~51 ~0 minecraft:dirt strict
fill ~218 ~49 ~0 ~218 ~49 ~2 minecraft:grass_block[snowy=false] strict
fill ~47 ~49 ~1 ~50 ~49 ~2 minecraft:grass_block[snowy=false] strict
fill ~84 ~49 ~1 ~92 ~49 ~1 minecraft:grass_block[snowy=false] strict
fill ~145 ~49 ~1 ~147 ~49 ~2 minecraft:stone strict
fill ~148 ~49 ~1 ~148 ~49 ~2 minecraft:moss_block strict
fill ~153 ~49 ~1 ~153 ~51 ~2 minecraft:dirt strict
fill ~206 ~49 ~1 ~208 ~51 ~2 minecraft:dirt strict
fill ~209 ~49 ~1 ~209 ~49 ~2 minecraft:stone strict
fill ~214 ~49 ~1 ~214 ~49 ~2 minecraft:stone strict
fill ~215 ~49 ~1 ~215 ~51 ~2 minecraft:dirt strict
fill ~219 ~49 ~1 ~219 ~49 ~2 minecraft:grass_block[snowy=false] strict
fill ~84 ~49 ~2 ~88 ~49 ~2 minecraft:grass_block[snowy=false] strict
fill ~98 ~49 ~2 ~99 ~49 ~2 minecraft:grass_block[snowy=false] strict
setblock ~100 ~49 ~2 minecraft:stone strict
fill ~154 ~49 ~2 ~157 ~51 ~2 minecraft:dirt strict
fill ~158 ~49 ~2 ~158 ~51 ~2 minecraft:stone strict
fill ~89 ~49 ~3 ~90 ~49 ~3 minecraft:grass_block[snowy=false] strict
fill ~95 ~49 ~3 ~98 ~49 ~3 minecraft:grass_block[snowy=false] strict
fill ~147 ~49 ~3 ~152 ~49 ~3 minecraft:stone strict
fill ~161 ~49 ~3 ~163 ~49 ~3 minecraft:grass_block[snowy=false] strict
setblock ~203 ~49 ~3 minecraft:moss_block strict
fill ~208 ~49 ~3 ~209 ~51 ~3 minecraft:dirt strict
fill ~214 ~49 ~3 ~214 ~51 ~3 minecraft:dirt strict
fill ~215 ~49 ~3 ~215 ~50 ~4 minecraft:stone strict
setblock ~218 ~49 ~3 minecraft:andesite strict
fill ~91 ~49 ~4 ~94 ~49 ~4 minecraft:grass_block[snowy=false] strict
fill ~158 ~49 ~4 ~159 ~49 ~4 minecraft:grass_block[snowy=false] strict
setblock ~206 ~49 ~4 minecraft:moss_block strict
fill ~208 ~49 ~4 ~211 ~50 ~4 minecraft:stone strict
fill ~214 ~49 ~4 ~214 ~51 ~4 minecraft:stone strict
fill ~153 ~49 ~5 ~155 ~51 ~5 minecraft:stone strict
setblock ~211 ~49 ~5 minecraft:stone strict
fill ~153 ~49 ~6 ~154 ~50 ~6 minecraft:stone strict
setblock ~151 ~49 ~7 minecraft:stone strict
fill ~153 ~49 ~7 ~153 ~50 ~7 minecraft:stone strict
fill ~255 ~49 ~7 ~255 ~49 ~10 minecraft:grass_block[snowy=false] strict
fill ~254 ~49 ~71 ~255 ~49 ~75 minecraft:grass_block[snowy=false] strict
fill ~253 ~49 ~73 ~253 ~49 ~80 minecraft:grass_block[snowy=false] strict
fill ~255 ~49 ~76 ~255 ~49 ~82 minecraft:grass_block[snowy=false] strict
fill ~254 ~49 ~79 ~254 ~49 ~82 minecraft:grass_block[snowy=false] strict
fill ~0 ~49 ~92 ~1 ~49 ~103 minecraft:grass_block[snowy=false] strict
fill ~2 ~49 ~94 ~2 ~49 ~105 minecraft:grass_block[snowy=false] strict
setblock ~1 ~49 ~104 minecraft:grass_block[snowy=false] strict
fill ~113 ~49 ~111 ~118 ~49 ~111 minecraft:quartz_stairs[facing=south,half=top,shape=straight,waterlogged=false] strict
fill ~133 ~49 ~111 ~143 ~49 ~111 minecraft:quartz_stairs[facing=south,half=top,shape=straight,waterlogged=false] strict
fill ~113 ~49 ~112 ~118 ~49 ~112 minecraft:smooth_quartz strict
fill ~133 ~49 ~112 ~143 ~49 ~112 minecraft:smooth_quartz strict
fill ~111 ~49 ~113 ~111 ~49 ~133 minecraft:quartz_stairs[facing=east,half=top,shape=straight,waterlogged=false] strict
fill ~112 ~49 ~113 ~112 ~49 ~133 minecraft:smooth_quartz strict
fill ~254 ~49 ~114 ~255 ~49 ~115 minecraft:grass_block[snowy=false] strict
fill ~254 ~49 ~119 ~254 ~49 ~123 minecraft:tuff strict
fill ~144 ~49 ~123 ~144 ~49 ~128 minecraft:smooth_quartz strict
fill ~145 ~49 ~123 ~145 ~49 ~128 minecraft:quartz_stairs[facing=west,half=top,shape=straight,waterlogged=false] strict
setblock ~114 ~49 ~130 minecraft:quartz_bricks strict
fill ~254 ~49 ~131 ~254 ~49 ~137 minecraft:tuff strict
fill ~255 ~49 ~133 ~255 ~49 ~136 minecraft:tuff strict
fill ~255 ~49 ~137 ~255 ~51 ~139 minecraft:dirt strict
fill ~1 ~49 ~138 ~2 ~49 ~139 minecraft:stone strict
fill ~254 ~49 ~138 ~254 ~51 ~139 minecraft:dirt strict
fill ~0 ~49 ~139 ~0 ~50 ~139 minecraft:stone strict
fill ~0 ~49 ~140 ~2 ~49 ~143 minecraft:dirt strict
fill ~3 ~49 ~140 ~3 ~49 ~151 minecraft:stone strict
setblock ~0 ~49 ~144 minecraft:grass_block[snowy=false] strict
fill ~1 ~49 ~144 ~2 ~49 ~149 minecraft:dirt strict
fill ~118 ~49 ~144 ~123 ~49 ~144 minecraft:smooth_quartz strict
fill ~138 ~49 ~144 ~143 ~49 ~144 minecraft:smooth_quartz strict
fill ~254 ~49 ~144 ~255 ~49 ~145 minecraft:grass_block[snowy=false] strict
fill ~0 ~49 ~145 ~0 ~49 ~149 minecraft:dirt strict
fill ~118 ~49 ~145 ~123 ~49 ~145 minecraft:quartz_stairs[facing=north,half=top,shape=straight,waterlogged=false] strict
fill ~138 ~49 ~145 ~143 ~49 ~145 minecraft:quartz_stairs[facing=north,half=top,shape=straight,waterlogged=false] strict
fill ~0 ~49 ~150 ~2 ~49 ~151 minecraft:grass_block[snowy=false] strict
setblock ~5 ~49 ~151 minecraft:stone strict
fill ~4 ~49 ~153 ~5 ~49 ~153 minecraft:stone strict
fill ~4 ~49 ~154 ~4 ~50 ~154 minecraft:stone strict
fill ~4 ~49 ~155 ~4 ~49 ~156 minecraft:grass_block[snowy=false] strict
setblock ~3 ~49 ~157 minecraft:stone strict
setblock ~4 ~49 ~157 minecraft:andesite strict
setblock ~3 ~49 ~160 minecraft:grass_block[snowy=false] strict
fill ~3 ~49 ~161 ~3 ~49 ~162 minecraft:andesite strict
fill ~2 ~49 ~162 ~2 ~49 ~163 minecraft:grass_block[snowy=false] strict
fill ~1 ~49 ~163 ~1 ~49 ~164 minecraft:grass_block[snowy=false] strict
fill ~0 ~49 ~164 ~0 ~49 ~165 minecraft:grass_block[snowy=false] strict
setblock ~2 ~49 ~164 minecraft:andesite strict
fill ~2 ~49 ~204 ~2 ~49 ~205 minecraft:grass_block[snowy=false] strict
fill ~0 ~49 ~205 ~1 ~49 ~205 minecraft:grass_block[snowy=false] strict
setblock ~3 ~49 ~205 minecraft:andesite strict
setblock ~3 ~49 ~206 minecraft:grass_block[snowy=false] strict
fill ~0 ~49 ~209 ~1 ~51 ~211 minecraft:dirt strict
fill ~2 ~49 ~210 ~2 ~52 ~210 minecraft:stone strict
fill ~2 ~49 ~211 ~2 ~51 ~213 minecraft:dirt strict
fill ~0 ~49 ~212 ~0 ~51 ~212 minecraft:dirt strict
fill ~249 ~49 ~212 ~250 ~49 ~216 minecraft:jungle_leaves[distance=7,persistent=true,waterlogged=false] strict
setblock ~0 ~49 ~213 minecraft:stone strict
fill ~3 ~49 ~213 ~3 ~52 ~218 minecraft:stone strict
setblock ~247 ~49 ~213 minecraft:jungle_leaves[distance=7,persistent=true,waterlogged=false] strict
fill ~2 ~49 ~214 ~2 ~49 ~220 minecraft:stone strict
setblock ~248 ~49 ~214 minecraft:jungle_leaves[distance=7,persistent=true,waterlogged=false] strict
setblock ~251 ~49 ~214 minecraft:jungle_leaves[distance=7,persistent=true,waterlogged=false] strict
setblock ~247 ~49 ~215 minecraft:jungle_leaves[distance=7,persistent=true,waterlogged=false] strict
fill ~3 ~49 ~219 ~3 ~51 ~220 minecraft:dirt strict
fill ~0 ~49 ~220 ~1 ~49 ~220 minecraft:stone strict
fill ~0 ~49 ~221 ~2 ~51 ~222 minecraft:dirt strict
fill ~3 ~49 ~221 ~3 ~52 ~221 minecraft:stone strict
fill ~0 ~49 ~223 ~1 ~51 ~223 minecraft:dirt strict
fill ~0 ~49 ~224 ~0 ~51 ~224 minecraft:dirt strict
setblock ~3 ~49 ~227 minecraft:grass_block[snowy=false] strict
fill ~3 ~49 ~232 ~3 ~50 ~232 minecraft:stone strict
setblock ~3 ~49 ~233 minecraft:grass_block[snowy=false] strict
setblock ~2 ~49 ~234 minecraft:grass_block[snowy=false] strict
setblock ~3 ~49 ~234 minecraft:stone strict
setblock ~1 ~49 ~235 minecraft:grass_block[snowy=false] strict
setblock ~2 ~49 ~235 minecraft:andesite strict
setblock ~0 ~49 ~236 minecraft:grass_block[snowy=false] strict
fill ~150 ~49 ~251 ~151 ~49 ~255 minecraft:stone strict
fill ~216 ~49 ~251 ~216 ~51 ~251 minecraft:jungle_log[axis=y] strict
fill ~16 ~49 ~252 ~24 ~49 ~252 minecraft:grass_block[snowy=false] strict
fill ~25 ~49 ~252 ~26 ~49 ~252 minecraft:stone strict
fill ~67 ~49 ~252 ~68 ~49 ~252 minecraft:grass_block[snowy=false] strict
fill ~73 ~49 ~252 ~74 ~49 ~252 minecraft:grass_block[snowy=false] strict
setblock ~80 ~49 ~252 minecraft:grass_block[snowy=false] strict
setblock ~81 ~49 ~252 minecraft:stone strict
fill ~149 ~49 ~252 ~149 ~50 ~255 minecraft:stone strict
fill ~153 ~49 ~252 ~155 ~50 ~252 minecraft:stone strict
fill ~226 ~49 ~252 ~228 ~49 ~252 minecraft:grass_block[snowy=false] strict
fill ~229 ~49 ~252 ~231 ~49 ~252 minecraft:andesite strict
fill ~232 ~49 ~252 ~235 ~49 ~252 minecraft:moss_block strict
fill ~236 ~49 ~252 ~239 ~49 ~252 minecraft:grass_block[snowy=false] strict
fill ~13 ~49 ~253 ~13 ~49 ~255 minecraft:grass_block[snowy=false] strict
fill ~26 ~49 ~253 ~30 ~49 ~253 minecraft:grass_block[snowy=false] strict
fill ~64 ~49 ~253 ~65 ~49 ~253 minecraft:grass_block[snowy=false] strict
setblock ~83 ~49 ~253 minecraft:grass_block[snowy=false] strict
fill ~145 ~49 ~253 ~147 ~49 ~255 minecraft:stone strict
fill ~158 ~49 ~253 ~160 ~49 ~253 minecraft:grass_block[snowy=false] strict
fill ~224 ~49 ~253 ~225 ~49 ~254 minecraft:grass_block[snowy=false] strict
fill ~229 ~49 ~253 ~231 ~50 ~253 minecraft:stone strict
fill ~240 ~49 ~253 ~242 ~49 ~253 minecraft:grass_block[snowy=false] strict
fill ~12 ~49 ~254 ~12 ~49 ~255 minecraft:grass_block[snowy=false] strict
fill ~27 ~49 ~254 ~32 ~49 ~255 minecraft:grass_block[snowy=false] strict
fill ~63 ~49 ~254 ~64 ~49 ~255 minecraft:grass_block[snowy=false] strict
fill ~68 ~49 ~254 ~80 ~51 ~255 minecraft:dirt strict
fill ~85 ~49 ~254 ~86 ~49 ~254 minecraft:grass_block[snowy=false] strict
fill ~135 ~49 ~254 ~137 ~49 ~254 minecraft:tuff strict
fill ~142 ~49 ~254 ~143 ~51 ~254 minecraft:dirt strict
fill ~144 ~49 ~254 ~144 ~49 ~255 minecraft:stone strict
setblock ~153 ~49 ~254 minecraft:stone strict
fill ~154 ~49 ~254 ~155 ~51 ~254 minecraft:dirt strict
fill ~159 ~49 ~254 ~162 ~49 ~254 minecraft:grass_block[snowy=false] strict
fill ~241 ~49 ~254 ~246 ~49 ~255 minecraft:grass_block[snowy=false] strict
fill ~24 ~49 ~255 ~26 ~49 ~255 minecraft:grass_block[snowy=false] strict
fill ~81 ~49 ~255 ~81 ~51 ~255 minecraft:dirt strict
fill ~86 ~49 ~255 ~87 ~49 ~255 minecraft:grass_block[snowy=false] strict
fill ~131 ~49 ~255 ~133 ~49 ~255 minecraft:tuff strict
fill ~134 ~49 ~255 ~137 ~49 ~255 minecraft:grass_block[snowy=false] strict
fill ~143 ~49 ~255 ~143 ~51 ~255 minecraft:dirt strict
fill ~153 ~49 ~255 ~154 ~51 ~255 minecraft:dirt strict
fill ~160 ~49 ~255 ~162 ~49 ~255 minecraft:grass_block[snowy=false] strict
fill ~225 ~49 ~255 ~226 ~49 ~255 minecraft:grass_block[snowy=false] strict
setblock ~240 ~49 ~255 minecraft:grass_block[snowy=false] strict
fill ~247 ~49 ~255 ~255 ~49 ~255 minecraft:grass_block[snowy=false] strict
fill ~95 ~50 ~0 ~98 ~50 ~1 minecraft:grass_block[snowy=false] strict
fill ~149 ~50 ~0 ~150 ~50 ~2 minecraft:grass_block[snowy=false] strict
fill ~161 ~50 ~0 ~162 ~50 ~2 minecraft:grass_block[snowy=false] strict
fill ~203 ~50 ~0 ~204 ~50 ~0 minecraft:moss_block strict
fill ~210 ~50 ~0 ~213 ~52 ~3 minecraft:dirt strict
fill ~217 ~50 ~0 ~217 ~50 ~3 minecraft:grass_block[snowy=false] strict
fill ~93 ~50 ~1 ~94 ~50 ~3 minecraft:grass_block[snowy=false] strict
fill ~203 ~50 ~1 ~203 ~50 ~2 minecraft:moss_block strict
fill ~209 ~50 ~1 ~209 ~52 ~2 minecraft:dirt strict
fill ~214 ~50 ~1 ~214 ~52 ~2 minecraft:dirt strict
fill ~89 ~50 ~2 ~92 ~50 ~2 minecraft:grass_block[snowy=false] strict
fill ~95 ~50 ~2 ~97 ~50 ~2 minecraft:grass_block[snowy=false] strict
fill ~204 ~50 ~2 ~204 ~50 ~3 minecraft:moss_block strict
fill ~91 ~50 ~3 ~92 ~50 ~3 minecraft:grass_block[snowy=false] strict
fill ~149 ~50 ~3 ~152 ~50 ~5 minecraft:stone strict
fill ~159 ~50 ~3 ~160 ~50 ~3 minecraft:grass_block[snowy=false] strict
setblock ~205 ~50 ~3 minecraft:moss_block strict
fill ~153 ~50 ~4 ~153 ~52 ~4 minecraft:stone strict
fill ~154 ~50 ~4 ~155 ~50 ~4 minecraft:andesite strict
fill ~156 ~50 ~4 ~157 ~50 ~4 minecraft:stone strict
fill ~213 ~50 ~4 ~213 ~51 ~4 minecraft:stone strict
fill ~254 ~50 ~76 ~254 ~50 ~78 minecraft:grass_block[snowy=false] strict
fill ~112 ~50 ~112 ~113 ~50 ~112 minecraft:quartz_stairs[facing=east,half=bottom,shape=straight,waterlogged=false] strict
fill ~114 ~50 ~112 ~142 ~50 ~112 minecraft:quartz_bricks strict
fill ~143 ~50 ~112 ~144 ~50 ~112 minecraft:quartz_stairs[facing=west,half=bottom,shape=straight,waterlogged=false] strict
fill ~114 ~50 ~113 ~115 ~50 ~113 minecraft:oxidized_cut_copper strict
fill ~141 ~50 ~113 ~142 ~50 ~113 minecraft:weathered_cut_copper strict
fill ~115 ~50 ~114 ~115 ~50 ~115 minecraft:oxidized_cut_copper strict
fill ~141 ~50 ~114 ~141 ~50 ~115 minecraft:oxidized_cut_copper strict
setblock ~142 ~50 ~114 minecraft:weathered_cut_copper strict
fill ~114 ~50 ~116 ~114 ~50 ~117 minecraft:oxidized_cut_copper strict
fill ~254 ~50 ~116 ~255 ~50 ~118 minecraft:grass_block[snowy=false] strict
fill ~254 ~50 ~119 ~254 ~50 ~122 minecraft:stone strict
fill ~255 ~50 ~119 ~255 ~50 ~121 minecraft:grass_block[snowy=false] strict
fill ~255 ~50 ~123 ~255 ~51 ~133 minecraft:stone strict
fill ~254 ~50 ~132 ~254 ~50 ~137 minecraft:stone strict
fill ~255 ~50 ~134 ~255 ~52 ~136 minecraft:dirt strict
fill ~1 ~50 ~139 ~2 ~50 ~149 minecraft:stone strict
fill ~0 ~50 ~140 ~0 ~50 ~143 minecraft:stone strict
fill ~3 ~50 ~140 ~3 ~50 ~142 minecraft:stone strict
fill ~114 ~50 ~141 ~115 ~50 ~143 minecraft:oxidized_cut_copper strict
setblock ~130 ~50 ~141 minecraft:oxidized_cut_copper strict
fill ~254 ~50 ~142 ~255 ~50 ~143 minecraft:grass_block[snowy=false] strict
setblock ~130 ~50 ~143 minecraft:oxidized_cut_copper strict
fill ~3 ~50 ~144 ~3 ~50 ~149 minecraft:stone strict
fill ~112 ~50 ~144 ~113 ~50 ~144 minecraft:quartz_stairs[facing=east,half=bottom,shape=straight,waterlogged=false] strict
fill ~114 ~50 ~144 ~130 ~50 ~144 minecraft:quartz_bricks strict
fill ~131 ~50 ~144 ~132 ~50 ~144 minecraft:quartz_stairs[facing=west,half=bottom,shape=straight,waterlogged=false] strict
fill ~133 ~50 ~144 ~133 ~51 ~144 minecraft:quartz_bricks strict
fill ~134 ~50 ~144 ~144 ~50 ~144 minecraft:quartz_stairs[facing=west,half=bottom,shape=straight,waterlogged=false] strict
fill ~0 ~50 ~145 ~0 ~50 ~149 minecraft:stone strict
fill ~0 ~50 ~152 ~2 ~50 ~154 minecraft:grass_block[snowy=false] strict
fill ~4 ~50 ~152 ~4 ~50 ~153 minecraft:stone strict
setblock ~3 ~50 ~153 minecraft:stone strict
fill ~3 ~50 ~154 ~3 ~50 ~156 minecraft:grass_block[snowy=false] strict
fill ~1 ~50 ~155 ~2 ~50 ~161 minecraft:grass_block[snowy=false] strict
fill ~3 ~50 ~157 ~3 ~50 ~159 minecraft:andesite strict
fill ~0 ~50 ~162 ~1 ~50 ~162 minecraft:grass_block[snowy=false] strict
setblock ~0 ~50 ~163 minecraft:grass_block[snowy=false] strict
fill ~0 ~50 ~206 ~2 ~50 ~206 minecraft:grass_block[snowy=false] strict
setblock ~0 ~50 ~207 minecraft:grass_block[snowy=false] strict
setblock ~2 ~50 ~207 minecraft:grass_block[snowy=false] strict
fill ~3 ~50 ~207 ~3 ~50 ~209 minecraft:andesite strict
fill ~3 ~50 ~210 ~3 ~51 ~210 minecraft:stone strict
fill ~1 ~50 ~212 ~1 ~52 ~220 minecraft:dirt strict
fill ~0 ~50 ~213 ~0 ~52 ~220 minecraft:dirt strict
fill ~4 ~50 ~213 ~4 ~50 ~218 minecraft:stone strict
fill ~2 ~50 ~214 ~2 ~52 ~220 minecraft:dirt strict
setblock ~4 ~50 ~219 minecraft:grass_block[snowy=false] strict
fill ~3 ~50 ~224 ~3 ~50 ~226 minecraft:grass_block[snowy=false] strict
fill ~2 ~50 ~226 ~2 ~50 ~229 minecraft:grass_block[snowy=false] strict
fill ~3 ~50 ~228 ~3 ~50 ~231 minecraft:grass_block[snowy=false] strict
fill ~2 ~50 ~232 ~2 ~50 ~233 minecraft:grass_block[snowy=false] strict
fill ~1 ~50 ~233 ~1 ~50 ~234 minecraft:grass_block[snowy=false] strict
setblock ~0 ~50 ~234 minecraft:grass_block[snowy=false] strict
setblock ~0 ~50 ~235 minecraft:andesite strict
fill ~150 ~50 ~251 ~151 ~50 ~254 minecraft:stone strict
setblock ~77 ~50 ~252 minecraft:grass_block[snowy=false] strict
fill ~152 ~50 ~252 ~152 ~53 ~253 minecraft:stone strict
fill ~14 ~50 ~253 ~25 ~50 ~253 minecraft:grass_block[snowy=false] strict
setblock ~66 ~50 ~253 minecraft:grass_block[snowy=false] strict
setblock ~82 ~50 ~253 minecraft:grass_block[snowy=false] strict
fill ~148 ~50 ~253 ~148 ~50 ~255 minecraft:stone strict
fill ~156 ~50 ~253 ~157 ~50 ~253 minecraft:grass_block[snowy=false] strict
fill ~226 ~50 ~253 ~228 ~50 ~253 minecraft:grass_block[snowy=false] strict
fill ~234 ~50 ~253 ~235 ~50 ~253 minecraft:moss_block strict
fill ~236 ~50 ~253 ~239 ~50 ~255 minecraft:grass_block[snowy=false] strict
fill ~14 ~50 ~254 ~15 ~50 ~255 minecraft:grass_block[snowy=false] strict
fill ~22 ~50 ~254 ~26 ~50 ~254 minecraft:grass_block[snowy=false] strict
fill ~65 ~50 ~254 ~65 ~50 ~255 minecraft:grass_block[snowy=false] strict
fill ~83 ~50 ~254 ~84 ~50 ~254 minecraft:grass_block[snowy=false] strict
setblock ~137 ~50 ~254 minecraft:stone strict
fill ~138 ~50 ~254 ~139 ~50 ~255 minecraft:grass_block[snowy=false] strict
fill ~144 ~50 ~254 ~145 ~52 ~255 minecraft:dirt strict
fill ~146 ~50 ~254 ~147 ~50 ~254 minecraft:stone strict
fill ~152 ~50 ~254 ~153 ~52 ~254 minecraft:dirt strict
fill ~157 ~50 ~254 ~158 ~50 ~255 minecraft:grass_block[snowy=false] strict
fill ~226 ~50 ~254 ~227 ~50 ~254 minecraft:grass_block[snowy=false] strict
setblock ~240 ~50 ~254 minecraft:grass_block[snowy=false] strict
setblock ~16 ~50 ~255 minecraft:grass_block[snowy=false] strict
fill ~21 ~50 ~255 ~23 ~50 ~255 minecraft:grass_block[snowy=false] strict
fill ~84 ~50 ~255 ~85 ~50 ~255 minecraft:grass_block[snowy=false] strict
setblock ~140 ~50 ~255 minecraft:grass_block[snowy=false] strict
fill ~146 ~50 ~255 ~146 ~52 ~255 minecraft:dirt strict
setblock ~147 ~50 ~255 minecraft:stone strict
setblock ~150 ~50 ~255 minecraft:stone strict
fill ~151 ~50 ~255 ~152 ~53 ~255 minecraft:dirt strict
setblock ~159 ~50 ~255 minecraft:grass_block[snowy=false] strict
fill ~227 ~50 ~255 ~230 ~50 ~255 minecraft:moss_block strict
fill ~233 ~50 ~255 ~235 ~50 ~255 minecraft:moss_block strict
fill ~151 ~51 ~0 ~153 ~51 ~0 minecraft:grass_block[snowy=false] strict
fill ~159 ~51 ~0 ~160 ~51 ~2 minecraft:grass_block[snowy=false] strict
fill ~205 ~51 ~0 ~206 ~51 ~0 minecraft:moss_block strict
fill ~216 ~51 ~0 ~216 ~51 ~3 minecraft:grass_block[snowy=false] strict
fill ~151 ~51 ~1 ~152 ~51 ~1 minecraft:grass_block[snowy=false] strict
fill ~204 ~51 ~1 ~205 ~51 ~1 minecraft:moss_block strict
setblock ~151 ~51 ~2 minecraft:grass_block[snowy=false] strict
setblock ~152 ~51 ~2 minecraft:dirt strict
setblock ~205 ~51 ~2 minecraft:moss_block strict
fill ~151 ~51 ~3 ~151 ~51 ~5 minecraft:stone strict
fill ~153 ~51 ~3 ~154 ~51 ~3 minecraft:dirt strict
fill ~155 ~51 ~3 ~156 ~51 ~3 minecraft:grass_block[snowy=false] strict
fill ~157 ~51 ~3 ~158 ~51 ~3 minecraft:andesite strict
fill ~206 ~51 ~3 ~207 ~51 ~3 minecraft:moss_block strict
fill ~215 ~51 ~3 ~215 ~52 ~3 minecraft:stone strict
fill ~150 ~51 ~4 ~150 ~51 ~5 minecraft:stone strict
fill ~152 ~51 ~4 ~152 ~51 ~5 minecraft:stone strict
fill ~154 ~51 ~4 ~155 ~51 ~4 minecraft:stone strict
fill ~209 ~51 ~4 ~211 ~51 ~4 minecraft:stone strict
setblock ~212 ~51 ~4 minecraft:moss_block strict
fill ~114 ~51 ~112 ~115 ~51 ~112 minecraft:quartz_stairs[facing=east,half=bottom,shape=straight,waterlogged=false] strict
fill ~116 ~51 ~112 ~140 ~51 ~112 minecraft:quartz_bricks strict
fill ~141 ~51 ~112 ~142 ~51 ~112 minecraft:quartz_stairs[facing=west,half=bottom,shape=straight,waterlogged=false] strict
fill ~114 ~51 ~113 ~115 ~51 ~113 minecraft:oxidized_cut_copper_stairs[facing=east,half=bottom,shape=straight,waterlogged=false] strict
fill ~116 ~51 ~113 ~117 ~51 ~113 minecraft:oxidized_cut_copper strict
fill ~139 ~51 ~113 ~140 ~51 ~115 minecraft:oxidized_cut_copper strict
fill ~141 ~51 ~113 ~142 ~51 ~113 minecraft:oxidized_cut_copper_stairs[facing=west,half=bottom,shape=straight,waterlogged=false] strict
fill ~115 ~51 ~114 ~115 ~51 ~115 minecraft:oxidized_cut_copper_stairs[facing=east,half=bottom,shape=straight,waterlogged=false] strict
fill ~117 ~51 ~114 ~117 ~51 ~117 minecraft:oxidized_cut_copper strict
setblock ~141 ~51 ~114 minecraft:weathered_cut_copper_stairs[facing=west,half=bottom,shape=straight,waterlogged=false] strict
setblock ~142 ~51 ~114 minecraft:oxidized_cut_copper_stairs[facing=west,half=bottom,shape=straight,waterlogged=false] strict
