setblock ~151 ~50 ~3 minecraft:grass_block strict
fill ~159 ~50 ~3 ~160 ~50 ~3 minecraft:grass_block strict
setblock ~205 ~50 ~3 minecraft:moss_block strict
setblock ~153 ~50 ~4 minecraft:stone strict
fill ~154 ~50 ~4 ~155 ~50 ~4 minecraft:andesite strict
fill ~156 ~50 ~4 ~157 ~50 ~4 minecraft:stone strict
fill ~213 ~50 ~4 ~213 ~51 ~4 minecraft:stone strict
fill ~254 ~50 ~76 ~254 ~50 ~78 minecraft:grass_block strict
fill ~112 ~50 ~112 ~113 ~50 ~112 minecraft:quartz_stairs[facing=east,half=bottom,shape=straight,waterlogged=false] strict
fill ~114 ~50 ~112 ~142 ~50 ~112 minecraft:quartz_bricks strict
fill ~143 ~50 ~112 ~144 ~50 ~112 minecraft:quartz_stairs[facing=west,half=bottom,shape=straight,waterlogged=false] strict
fill ~114 ~50 ~113 ~115 ~50 ~113 minecraft:weathered_cut_copper strict
fill ~141 ~50 ~113 ~142 ~50 ~114 minecraft:weathered_cut_copper strict
fill ~115 ~50 ~114 ~115 ~50 ~115 minecraft:weathered_cut_copper strict
setblock ~141 ~50 ~115 minecraft:weathered_cut_copper strict
fill ~114 ~50 ~116 ~114 ~50 ~117 minecraft:weathered_cut_copper strict
fill ~254 ~50 ~116 ~255 ~50 ~118 minecraft:grass_block strict
setblock ~253 ~50 ~118 minecraft:stone strict
fill ~254 ~50 ~119 ~254 ~50 ~122 minecraft:stone strict
fill ~255 ~50 ~119 ~255 ~50 ~121 minecraft:grass_block strict
fill ~255 ~50 ~123 ~255 ~51 ~133 minecraft:stone strict
fill ~254 ~50 ~132 ~254 ~50 ~137 minecraft:stone strict
fill ~255 ~50 ~134 ~255 ~52 ~136 minecraft:dirt strict
fill ~253 ~50 ~137 ~253 ~50 ~140 minecraft:stone strict
fill ~114 ~50 ~141 ~115 ~50 ~143 minecraft:weathered_cut_copper strict
setblock ~130 ~50 ~141 minecraft:weathered_cut_copper strict
fill ~253 ~50 ~141 ~253 ~50 ~142 minecraft:grass_block strict
fill ~254 ~50 ~142 ~255 ~50 ~143 minecraft:grass_block strict
setblock ~130 ~50 ~143 minecraft:weathered_cut_copper strict
fill ~112 ~50 ~144 ~113 ~50 ~144 minecraft:quartz_stairs[facing=east,half=bottom,shape=straight,waterlogged=false] strict
fill ~114 ~50 ~144 ~130 ~50 ~144 minecraft:quartz_bricks strict
fill ~131 ~50 ~144 ~132 ~50 ~144 minecraft:quartz_stairs[facing=west,half=bottom,shape=straight,waterlogged=false] strict
fill ~133 ~50 ~144 ~133 ~51 ~144 minecraft:quartz_bricks strict
fill ~134 ~50 ~144 ~144 ~50 ~144 minecraft:quartz_stairs[facing=west,half=bottom,shape=straight,waterlogged=false] strict
fill ~0 ~50 ~152 ~2 ~50 ~154 minecraft:grass_block strict
fill ~3 ~50 ~154 ~3 ~50 ~156 minecraft:grass_block strict
fill ~1 ~50 ~155 ~2 ~50 ~161 minecraft:grass_block strict
fill ~3 ~50 ~157 ~3 ~50 ~159 minecraft:andesite strict
fill ~0 ~50 ~162 ~1 ~50 ~162 minecraft:grass_block strict
setblock ~0 ~50 ~163 minecraft:grass_block strict
fill ~0 ~50 ~206 ~2 ~50 ~206 minecraft:grass_block strict
setblock ~0 ~50 ~207 minecraft:grass_block strict
setblock ~2 ~50 ~207 minecraft:grass_block strict
fill ~3 ~50 ~207 ~3 ~50 ~209 minecraft:andesite strict
fill ~3 ~50 ~210 ~3 ~51 ~210 minecraft:stone strict
fill ~1 ~50 ~212 ~1 ~52 ~220 minecraft:dirt strict
fill ~0 ~50 ~213 ~0 ~52 ~220 minecraft:dirt strict
fill ~4 ~50 ~213 ~4 ~50 ~218 minecraft:stone strict
fill ~2 ~50 ~214 ~2 ~52 ~220 minecraft:dirt strict
setblock ~4 ~50 ~219 minecraft:grass_block strict
fill ~3 ~50 ~224 ~3 ~50 ~226 minecraft:grass_block strict
fill ~2 ~50 ~226 ~2 ~50 ~229 minecraft:grass_block strict
fill ~3 ~50 ~228 ~3 ~50 ~231 minecraft:grass_block strict
fill ~2 ~50 ~232 ~2 ~50 ~233 minecraft:grass_block strict
fill ~1 ~50 ~233 ~1 ~50 ~234 minecraft:grass_block strict
setblock ~0 ~50 ~234 minecraft:grass_block strict
setblock ~0 ~50 ~235 minecraft:andesite strict
setblock ~77 ~50 ~252 minecraft:grass_block strict
fill ~140 ~50 ~252 ~143 ~50 ~252 minecraft:stone strict
fill ~148 ~50 ~252 ~152 ~51 ~252 minecraft:stone strict
fill ~14 ~50 ~253 ~25 ~50 ~253 minecraft:grass_block strict
setblock ~66 ~50 ~253 minecraft:grass_block strict
setblock ~82 ~50 ~253 minecraft:grass_block strict
fill ~138 ~50 ~253 ~140 ~50 ~253 minecraft:stone strict
fill ~144 ~50 ~253 ~146 ~52 ~253 minecraft:dirt strict
fill ~147 ~50 ~253 ~149 ~50 ~255 minecraft:stone strict
fill ~150 ~50 ~253 ~150 ~52 ~253 minecraft:dirt strict
fill ~151 ~50 ~253 ~152 ~53 ~253 minecraft:stone strict
fill ~156 ~50 ~253 ~157 ~50 ~253 minecraft:grass_block strict
fill ~226 ~50 ~253 ~228 ~50 ~253 minecraft:grass_block strict
fill ~234 ~50 ~253 ~235 ~50 ~253 minecraft:moss_block strict
fill ~236 ~50 ~253 ~239 ~50 ~255 minecraft:grass_block strict
fill ~14 ~50 ~254 ~15 ~50 ~255 minecraft:grass_block strict
fill ~22 ~50 ~254 ~26 ~50 ~254 minecraft:grass_block strict
fill ~65 ~50 ~254 ~65 ~50 ~255 minecraft:grass_block strict
fill ~83 ~50 ~254 ~84 ~50 ~254 minecraft:grass_block strict
setblock ~137 ~50 ~254 minecraft:stone strict
fill ~138 ~50 ~254 ~139 ~50 ~255 minecraft:grass_block strict
fill ~144 ~50 ~254 ~145 ~52 ~255 minecraft:dirt strict
setblock ~146 ~50 ~254 minecraft:stone strict
fill ~150 ~50 ~254 ~151 ~50 ~254 minecraft:stone strict
fill ~152 ~50 ~254 ~153 ~52 ~254 minecraft:dirt strict
fill ~157 ~50 ~254 ~158 ~50 ~255 minecraft:grass_block strict
fill ~226 ~50 ~254 ~227 ~50 ~254 minecraft:grass_block strict
setblock ~240 ~50 ~254 minecraft:grass_block strict
setblock ~16 ~50 ~255 minecraft:grass_block strict
fill ~21 ~50 ~255 ~23 ~50 ~255 minecraft:grass_block strict
fill ~84 ~50 ~255 ~85 ~50 ~255 minecraft:grass_block strict
setblock ~140 ~50 ~255 minecraft:grass_block strict
fill ~146 ~50 ~255 ~146 ~52 ~255 minecraft:dirt strict
setblock ~150 ~50 ~255 minecraft:stone strict
fill ~151 ~50 ~255 ~152 ~52 ~255 minecraft:dirt strict
setblock ~159 ~50 ~255 minecraft:grass_block strict
fill ~227 ~50 ~255 ~230 ~50 ~255 minecraft:moss_block strict
fill ~233 ~50 ~255 ~235 ~50 ~255 minecraft:moss_block strict
fill ~151 ~51 ~0 ~153 ~51 ~0 minecraft:grass_block strict
fill ~159 ~51 ~0 ~160 ~51 ~2 minecraft:grass_block strict
fill ~205 ~51 ~0 ~206 ~51 ~0 minecraft:moss_block strict
fill ~216 ~51 ~0 ~216 ~51 ~3 minecraft:grass_block strict
fill ~151 ~51 ~1 ~152 ~51 ~2 minecraft:grass_block strict
fill ~204 ~51 ~1 ~205 ~51 ~1 minecraft:moss_block strict
setblock ~205 ~51 ~2 minecraft:moss_block strict
setblock ~152 ~51 ~3 minecraft:andesite strict
fill ~153 ~51 ~3 ~156 ~51 ~3 minecraft:grass_block strict
fill ~157 ~51 ~3 ~158 ~51 ~3 minecraft:andesite strict
fill ~206 ~51 ~3 ~207 ~51 ~3 minecraft:moss_block strict
fill ~215 ~51 ~3 ~215 ~52 ~3 minecraft:stone strict
fill ~209 ~51 ~4 ~211 ~51 ~4 minecraft:stone strict
setblock ~212 ~51 ~4 minecraft:moss_block strict
fill ~114 ~51 ~112 ~115 ~51 ~112 minecraft:quartz_stairs[facing=east,half=bottom,shape=straight,waterlogged=false] strict
fill ~116 ~51 ~112 ~140 ~51 ~112 minecraft:quartz_bricks strict
fill ~141 ~51 ~112 ~142 ~51 ~112 minecraft:quartz_stairs[facing=west,half=bottom,shape=straight,waterlogged=false] strict
fill ~114 ~51 ~113 ~115 ~51 ~113 minecraft:weathered_cut_copper_stairs[facing=east,half=bottom,shape=straight,waterlogged=false] strict
fill ~116 ~51 ~113 ~117 ~51 ~113 minecraft:weathered_cut_copper strict
fill ~139 ~51 ~113 ~140 ~51 ~115 minecraft:weathered_cut_copper strict
fill ~141 ~51 ~113 ~142 ~51 ~114 minecraft:weathered_cut_copper_stairs[facing=west,half=bottom,shape=straight,waterlogged=false] strict
fill ~115 ~51 ~114 ~115 ~51 ~115 minecraft:weathered_cut_copper_stairs[facing=east,half=bottom,shape=straight,waterlogged=false] strict
fill ~117 ~51 ~114 ~117 ~51 ~117 minecraft:weathered_cut_copper strict
setblock ~116 ~51 ~115 minecraft:weathered_cut_copper strict
setblock ~141 ~51 ~115 minecraft:weathered_cut_copper_stairs[facing=west,half=bottom,shape=straight,waterlogged=false] strict
fill ~114 ~51 ~116 ~114 ~51 ~117 minecraft:weathered_cut_copper_stairs[facing=east,half=bottom,shape=straight,waterlogged=false] strict
setblock ~255 ~51 ~122 minecraft:grass_block strict
fill ~254 ~51 ~133 ~254 ~51 ~137 minecraft:stone strict
fill ~253 ~51 ~138 ~253 ~51 ~140 minecraft:stone strict
setblock ~254 ~51 ~140 minecraft:moss_block strict
fill ~255 ~51 ~140 ~255 ~51 ~141 minecraft:grass_block strict
fill ~114 ~51 ~141 ~115 ~51 ~143 minecraft:weathered_cut_copper_stairs[facing=east,half=bottom,shape=straight,waterlogged=false] strict
setblock ~130 ~51 ~141 minecraft:weathered_cut_copper_stairs[facing=west,half=bottom,shape=straight,waterlogged=false] strict
setblock ~254 ~51 ~141 minecraft:grass_block strict
setblock ~133 ~51 ~142 minecraft:weathered_cut_copper strict
setblock ~117 ~51 ~143 minecraft:weathered_cut_copper strict
setblock ~130 ~51 ~143 minecraft:weathered_cut_copper_stairs[facing=west,half=bottom,shape=straight,waterlogged=false] strict
fill ~114 ~51 ~144 ~115 ~51 ~144 minecraft:quartz_stairs[facing=east,half=bottom,shape=straight,waterlogged=false] strict
fill ~116 ~51 ~144 ~129 ~51 ~144 minecraft:quartz_bricks strict
setblock ~130 ~51 ~144 minecraft:quartz_stairs[facing=west,half=bottom,shape=straight,waterlogged=false] strict
fill ~0 ~51 ~155 ~0 ~51 ~161 minecraft:grass_block strict
fill ~1 ~51 ~207 ~1 ~51 ~208 minecraft:grass_block strict
setblock ~0 ~51 ~208 minecraft:grass_block strict
fill ~2 ~51 ~208 ~2 ~51 ~209 minecraft:grass_block strict
fill ~3 ~51 ~222 ~3 ~51 ~223 minecraft:grass_block strict
fill ~2 ~51 ~223 ~2 ~51 ~225 minecraft:grass_block strict
fill ~1 ~51 ~224 ~1 ~51 ~232 minecraft:grass_block strict
fill ~0 ~51 ~225 ~0 ~51 ~233 minecraft:grass_block strict
fill ~2 ~51 ~230 ~2 ~51 ~231 minecraft:grass_block strict
setblock ~214 ~51 ~246 minecraft:jungle_leaves[distance=7,persistent=true,waterlogged=false] strict
setblock ~218 ~51 ~247 minecraft:jungle_leaves[distance=7,persistent=true,waterlogged=false] strict
setblock ~211 ~51 ~248 minecraft:jungle_leaves[distance=7,persistent=true,waterlogged=false] strict
setblock ~219 ~51 ~250 minecraft:jungle_leaves[distance=7,persistent=true,waterlogged=false] strict
fill ~142 ~51 ~252 ~143 ~51 ~252 minecraft:stone strict
setblock ~144 ~51 ~252 minecraft:grass_block strict
fill ~145 ~51 ~252 ~145 ~52 ~252 minecraft:stone strict
setblock ~153 ~51 ~252 minecraft:stone strict
setblock ~211 ~51 ~252 minecraft:jungle_leaves[distance=7,persistent=true,waterlogged=false] strict
fill ~67 ~51 ~253 ~80 ~51 ~253 minecraft:grass_block strict
setblock ~140 ~51 ~253 minecraft:stone strict
fill ~141 ~51 ~253 ~141 ~51 ~255 minecraft:grass_block strict
fill ~147 ~51 ~253 ~149 ~53 ~253 minecraft:stone strict
setblock ~155 ~51 ~253 minecraft:grass_block strict
setblock ~217 ~51 ~253 minecraft:jungle_leaves[distance=7,persistent=true,waterlogged=false] strict
fill ~229 ~51 ~253 ~233 ~51 ~253 minecraft:andesite strict
fill ~16 ~51 ~254 ~21 ~51 ~254 minecraft:grass_block strict
fill ~66 ~51 ~254 ~67 ~51 ~255 minecraft:grass_block strict
fill ~81 ~51 ~254 ~82 ~51 ~254 minecraft:grass_block strict
setblock ~140 ~51 ~254 minecraft:grass_block strict
fill ~146 ~51 ~254 ~151 ~53 ~254 minecraft:dirt strict
fill ~156 ~51 ~254 ~156 ~51 ~255 minecraft:grass_block strict
setblock ~214 ~51 ~254 minecraft:jungle_leaves[distance=7,persistent=true,waterlogged=false] strict
fill ~228 ~51 ~254 ~235 ~51 ~254 minecraft:moss_block strict
fill ~17 ~51 ~255 ~20 ~51 ~255 minecraft:grass_block strict
fill ~82 ~51 ~255 ~83 ~51 ~255 minecraft:grass_block strict
setblock ~142 ~51 ~255 minecraft:grass_block strict
fill ~147 ~51 ~255 ~150 ~53 ~255 minecraft:dirt strict
setblock ~155 ~51 ~255 minecraft:grass_block strict
fill ~231 ~51 ~255 ~232 ~51 ~255 minecraft:moss_block strict
fill ~154 ~52 ~0 ~158 ~52 ~1 minecraft:grass_block strict
fill ~207 ~52 ~0 ~209 ~52 ~0 minecraft:moss_block strict
fill ~214 ~52 ~0 ~215 ~52 ~0 minecraft:grass_block strict
fill ~153 ~52 ~1 ~153 ~52 ~2 minecraft:grass_block strict
fill ~206 ~52 ~1 ~208 ~52 ~2 minecraft:moss_block strict
fill ~215 ~52 ~1 ~215 ~52 ~2 minecraft:grass_block strict
fill ~154 ~52 ~2 ~157 ~52 ~2 minecraft:grass_block strict
setblock ~158 ~52 ~2 minecraft:andesite strict
fill ~208 ~52 ~3 ~209 ~52 ~3 minecraft:moss_block strict
setblock ~214 ~52 ~3 minecraft:grass_block strict
fill ~116 ~52 ~112 ~117 ~52 ~112 minecraft:quartz_stairs[facing=east,half=bottom,shape=straight,waterlogged=false] strict
fill ~118 ~52 ~112 ~138 ~52 ~112 minecraft:quartz_bricks strict
fill ~139 ~52 ~112 ~140 ~52 ~112 minecraft:quartz_stairs[facing=west,half=bottom,shape=straight,waterlogged=false] strict
fill ~116 ~52 ~113 ~117 ~52 ~113 minecraft:weathered_cut_copper_stairs[facing=east,half=bottom,shape=straight,waterlogged=false] strict
fill ~118 ~52 ~113 ~118 ~52 ~114 minecraft:weathered_cut_copper strict
fill ~137 ~52 ~113 ~138 ~52 ~113 minecraft:weathered_cut_copper strict
fill ~139 ~52 ~113 ~140 ~52 ~115 minecraft:weathered_cut_copper_stairs[facing=west,half=bottom,shape=straight,waterlogged=false] strict
fill ~117 ~52 ~114 ~117 ~52 ~117 minecraft:weathered_cut_copper_stairs[facing=east,half=bottom,shape=straight,waterlogged=false] strict
fill ~137 ~52 ~114 ~137 ~52 ~115 minecraft:weathered_cut_copper strict
setblock ~116 ~52 ~115 minecraft:weathered_cut_copper_stairs[facing=east,half=bottom,shape=straight,waterlogged=false] strict
fill ~119 ~52 ~115 ~119 ~52 ~116 minecraft:weathered_cut_copper strict
setblock ~118 ~52 ~116 minecraft:weathered_cut_copper strict
fill ~137 ~52 ~117 ~138 ~52 ~117 minecraft:weathered_cut_copper strict
fill ~255 ~52 ~125 ~255 ~52 ~133 minecraft:stone strict
fill ~254 ~52 ~134 ~254 ~52 ~137 minecraft:stone strict
fill ~255 ~52 ~137 ~255 ~52 ~139 minecraft:moss_block strict
fill ~254 ~52 ~138 ~254 ~52 ~139 minecraft:moss_block strict
setblock ~115 ~52 ~141 minecraft:calcite strict
fill ~118 ~52 ~141 ~118 ~52 ~143 minecraft:weathered_cut_copper strict
fill ~119 ~52 ~142 ~119 ~52 ~143 minecraft:weathered_cut_copper strict
setblock ~133 ~52 ~142 minecraft:weathered_cut_copper_stairs[facing=west,half=bottom,shape=straight,waterlogged=false] strict
setblock ~117 ~52 ~143 minecraft:weathered_cut_copper_stairs[facing=east,half=bottom,shape=straight,waterlogged=false] strict
fill ~116 ~52 ~144 ~117 ~52 ~144 minecraft:quartz_stairs[facing=east,half=bottom,shape=straight,waterlogged=false] strict
fill ~118 ~52 ~144 ~129 ~52 ~144 minecraft:quartz_bricks strict
setblock ~133 ~52 ~144 minecraft:quartz_stairs[facing=west,half=bottom,shape=straight,waterlogged=false] strict
fill ~0 ~52 ~209 ~1 ~52 ~211 minecraft:grass_block strict
fill ~2 ~52 ~211 ~2 ~52 ~213 minecraft:grass_block strict
setblock ~0 ~52 ~212 minecraft:grass_block strict
fill ~3 ~52 ~219 ~3 ~52 ~220 minecraft:grass_block strict
fill ~0 ~52 ~221 ~2 ~52 ~222 minecraft:grass_block strict
fill ~0 ~52 ~223 ~1 ~52 ~223 minecraft:grass_block strict
setblock ~0 ~52 ~224 minecraft:grass_block strict
setblock ~214 ~52 ~247 minecraft:jungle_leaves[distance=7,persistent=true,waterlogged=false] strict
setblock ~217 ~52 ~248 minecraft:jungle_leaves[distance=7,persistent=true,waterlogged=false] strict
setblock ~212 ~52 ~249 minecraft:jungle_leaves[distance=7,persistent=true,waterlogged=false] strict
setblock ~215 ~52 ~250 minecraft:jungle_log[axis=y] strict
setblock ~218 ~52 ~250 minecraft:jungle_leaves[distance=7,persistent=true,waterlogged=false] strict
setblock ~212 ~52 ~251 minecraft:jungle_leaves[distance=7,persistent=true,waterlogged=false] strict
fill ~148 ~52 ~252 ~151 ~52 ~252 minecraft:stone strict
setblock ~217 ~52 ~252 minecraft:jungle_leaves[distance=7,persistent=true,waterlogged=false] strict
fill ~142 ~52 ~253 ~143 ~52 ~254 minecraft:grass_block strict
setblock ~214 ~52 ~253 minecraft:jungle_leaves[distance=7,persistent=true,waterlogged=false] strict
fill ~68 ~52 ~254 ~80 ~52 ~255 minecraft:grass_block strict
fill ~154 ~52 ~254 ~155 ~52 ~254 minecraft:grass_block strict
setblock ~81 ~52 ~255 minecraft:grass_block strict
setblock ~143 ~52 ~255 minecraft:grass_block strict
fill ~153 ~52 ~255 ~154 ~52 ~255 minecraft:grass_block strict
fill ~210 ~53 ~0 ~212 ~53 ~3 minecraft:moss_block strict
fill ~213 ~53 ~0 ~213 ~53 ~1 minecraft:grass_block strict
fill ~209 ~53 ~1 ~209 ~53 ~2 minecraft:moss_block strict
fill ~214 ~53 ~1 ~214 ~53 ~2 minecraft:grass_block strict
fill ~213 ~53 ~2 ~213 ~53 ~3 minecraft:moss_block strict
fill ~118 ~53 ~112 ~119 ~53 ~112 minecraft:quartz_stairs[facing=east,half=bottom,shape=straight,waterlogged=false] strict
fill ~120 ~53 ~112 ~136 ~53 ~112 minecraft:quartz_bricks strict
fill ~137 ~53 ~112 ~138 ~53 ~112 minecraft:quartz_stairs[facing=west,half=bottom,shape=straight,waterlogged=false] strict
fill ~118 ~53 ~113 ~118 ~53 ~114 minecraft:weathered_cut_copper_stairs[facing=east,half=bottom,shape=straight,waterlogged=false] strict
fill ~120 ~53 ~113 ~121 ~53 ~113 minecraft:weathered_cut_copper strict
fill ~135 ~53 ~113 ~136 ~53 ~114 minecraft:weathered_cut_copper strict
fill ~137 ~53 ~113 ~138 ~53 ~113 minecraft:weathered_cut_copper_stairs[facing=west,half=bottom,shape=straight,waterlogged=false] strict
setblock ~120 ~53 ~114 minecraft:weathered_cut_copper strict
fill ~137 ~53 ~114 ~137 ~53 ~115 minecraft:weathered_cut_copper_stairs[facing=west,half=bottom,shape=straight,waterlogged=false] strict
setblock ~139 ~53 ~114 minecraft:quartz_bricks strict
setblock ~116 ~53 ~115 minecraft:quartz_bricks strict
setblock ~117 ~53 ~115 minecraft:weathered_cut_copper_stairs[facing=north,half=bottom,shape=straight,waterlogged=false] strict
fill ~119 ~53 ~115 ~119 ~53 ~116 minecraft:weathered_cut_copper_stairs[facing=east,half=bottom,shape=straight,waterlogged=false] strict
fill ~121 ~53 ~115 ~121 ~53 ~116 minecraft:weathered_cut_copper strict
setblock ~136 ~53 ~115 minecraft:weathered_cut_copper strict
setblock ~118 ~53 ~116 minecraft:weathered_cut_copper_stairs[facing=east,half=bottom,shape=straight,waterlogged=false] strict
setblock ~135 ~53 ~117 minecraft:weathered_cut_copper strict
fill ~137 ~53 ~117 ~138 ~53 ~117 minecraft:weathered_cut_copper_stairs[facing=west,half=bottom,shape=straight,waterlogged=false] strict
setblock ~120 ~53 ~118 minecraft:weathered_cut_copper strict
fill ~255 ~53 ~128 ~255 ~53 ~133 minecraft:stone strict
fill ~255 ~53 ~134 ~255 ~53 ~136 minecraft:moss_block strict
setblock ~254 ~53 ~135 minecraft:stone strict
fill ~118 ~53 ~141 ~118 ~53 ~143 minecraft:weathered_cut_copper_stairs[facing=east,half=bottom,shape=straight,waterlogged=false] strict
fill ~120 ~53 ~141 ~120 ~53 ~143 minecraft:weathered_cut_copper strict
fill ~119 ~53 ~142 ~119 ~53 ~143 minecraft:weathered_cut_copper_stairs[facing=east,half=bottom,shape=straight,waterlogged=false] strict
setblock ~121 ~53 ~142 minecraft:weathered_cut_copper strict
fill ~118 ~53 ~144 ~119 ~53 ~144 minecraft:quartz_stairs[facing=east,half=bottom,shape=straight,waterlogged=false] strict
fill ~120 ~53 ~144 ~129 ~53 ~144 minecraft:quartz_bricks strict
fill ~1 ~53 ~212 ~1 ~53 ~220 minecraft:grass_block strict
fill ~0 ~53 ~213 ~0 ~53 ~220 minecraft:grass_block strict
fill ~2 ~53 ~214 ~2 ~53 ~220 minecraft:grass_block strict
fill ~215 ~53 ~248 ~216 ~53 ~252 minecraft:jungle_leaves[distance=7,persistent=true,waterlogged=false] strict
setblock ~213 ~53 ~249 minecraft:jungle_leaves[distance=7,persistent=true,waterlogged=false] strict
setblock ~214 ~53 ~250 minecraft:jungle_leaves[distance=7,persistent=true,waterlogged=false] strict
setblock ~217 ~53 ~250 minecraft:jungle_leaves[distance=7,persistent=true,waterlogged=false] strict
setblock ~213 ~53 ~251 minecraft:jungle_leaves[distance=7,persistent=true,waterlogged=false] strict
fill ~144 ~53 ~253 ~146 ~53 ~253 minecraft:grass_block strict
setblock ~150 ~53 ~253 minecraft:grass_block strict
fill ~144 ~53 ~254 ~145 ~53 ~255 minecraft:grass_block strict
fill ~152 ~53 ~254 ~153 ~53 ~254 minecraft:grass_block strict
setblock ~146 ~53 ~255 minecraft:grass_block strict
fill ~151 ~53 ~255 ~152 ~53 ~255 minecraft:grass_block strict
fill ~120 ~54 ~112 ~121 ~54 ~112 minecraft:quartz_stairs[facing=east,half=bottom,shape=straight,waterlogged=false] strict
fill ~122 ~54 ~112 ~134 ~54 ~112 minecraft:quartz_bricks strict
fill ~135 ~54 ~112 ~136 ~54 ~112 minecraft:quartz_stairs[facing=west,half=bottom,shape=straight,waterlogged=false] strict
fill ~120 ~54 ~113 ~121 ~54 ~113 minecraft:weathered_cut_copper_stairs[facing=east,half=bottom,shape=straight,waterlogged=false] strict
fill ~122 ~54 ~113 ~123 ~54 ~113 minecraft:weathered_cut_copper strict
setblock ~134 ~54 ~113 minecraft:weathered_cut_copper strict
fill ~135 ~54 ~113 ~136 ~54 ~114 minecraft:weathered_cut_copper_stairs[facing=west,half=bottom,shape=straight,waterlogged=false] strict
setblock ~120 ~54 ~114 minecraft:weathered_cut_copper_stairs[facing=east,half=bottom,shape=straight,waterlogged=false] strict
setblock ~123 ~54 ~114 minecraft:weathered_cut_copper strict
fill ~133 ~54 ~114 ~133 ~54 ~116 minecraft:weathered_cut_copper strict
setblock ~116 ~54 ~115 minecraft:weathered_cut_copper_stairs[facing=north,half=bottom,shape=straight,waterlogged=false] strict
fill ~121 ~54 ~115 ~121 ~54 ~116 minecraft:weathered_cut_copper_stairs[facing=east,half=bottom,shape=straight,waterlogged=false] strict
setblock ~136 ~54 ~115 minecraft:weathered_cut_copper_stairs[facing=west,half=bottom,shape=straight,waterlogged=false] strict
setblock ~137 ~54 ~115 minecraft:calcite strict
setblock ~122 ~54 ~116 minecraft:weathered_cut_copper strict
setblock ~135 ~54 ~117 minecraft:weathered_cut_copper_stairs[facing=west,half=bottom,shape=straight,waterlogged=false] strict
setblock ~137 ~54 ~117 minecraft:quartz_bricks strict
setblock ~120 ~54 ~118 minecraft:weathered_cut_copper_stairs[facing=east,half=bottom,shape=straight,waterlogged=false] strict
fill ~120 ~54 ~141 ~120 ~54 ~143 minecraft:weathered_cut_copper_stairs[facing=east,half=bottom,shape=straight,waterlogged=false] strict
setblock ~121 ~54 ~142 minecraft:weathered_cut_copper_stairs[facing=east,half=bottom,shape=straight,waterlogged=false] strict
fill ~122 ~54 ~142 ~122 ~54 ~143 minecraft:weathered_cut_copper strict
setblock ~123 ~54 ~143 minecraft:weathered_cut_copper strict
fill ~120 ~54 ~144 ~121 ~54 ~144 minecraft:quartz_stairs[facing=east,half=bottom,shape=straight,waterlogged=false] strict
fill ~122 ~54 ~144 ~129 ~54 ~144 minecraft:quartz_bricks strict
setblock ~147 ~54 ~253 minecraft:andesite strict
fill ~148 ~54 ~253 ~149 ~54 ~253 minecraft:stone strict
fill ~146 ~54 ~254 ~151 ~54 ~254 minecraft:grass_block strict
fill ~147 ~54 ~255 ~150 ~54 ~255 minecraft:grass_block strict
fill ~122 ~55 ~112 ~123 ~55 ~112 minecraft:quartz_stairs[facing=east,half=bottom,shape=straight,waterlogged=false] strict
fill ~124 ~55 ~112 ~132 ~55 ~112 minecraft:quartz_bricks strict
fill ~133 ~55 ~112 ~134 ~55 ~112 minecraft:quartz_stairs[facing=west,half=bottom,shape=straight,waterlogged=false] strict
fill ~122 ~55 ~113 ~123 ~55 ~113 minecraft:weathered_cut_copper_stairs[facing=east,half=bottom,shape=straight,waterlogged=false] strict
fill ~124 ~55 ~113 ~124 ~55 ~116 minecraft:weathered_cut_copper strict
fill ~131 ~55 ~113 ~132 ~55 ~114 minecraft:weathered_cut_copper strict
setblock ~134 ~55 ~113 minecraft:weathered_cut_copper_stairs[facing=west,half=bottom,shape=straight,waterlogged=false] strict
setblock ~123 ~55 ~114 minecraft:weathered_cut_copper_stairs[facing=east,half=bottom,shape=straight,waterlogged=false] strict
fill ~125 ~55 ~114 ~125 ~55 ~115 minecraft:weathered_cut_copper strict
fill ~133 ~55 ~114 ~133 ~55 ~116 minecraft:weathered_cut_copper_stairs[facing=west,half=bottom,shape=straight,waterlogged=false] strict
setblock ~122 ~55 ~116 minecraft:weathered_cut_copper_stairs[facing=east,half=bottom,shape=straight,waterlogged=false] strict
fill ~124 ~55 ~141 ~125 ~55 ~141 minecraft:weathered_cut_copper strict
fill ~122 ~55 ~142 ~122 ~55 ~143 minecraft:weathered_cut_copper_stairs[facing=east,half=bottom,shape=straight,waterlogged=false] strict
fill ~125 ~55 ~142 ~125 ~55 ~143 minecraft:weathered_cut_copper strict
setblock ~123 ~55 ~143 minecraft:weathered_cut_copper_stairs[facing=east,half=bottom,shape=straight,waterlogged=false] strict
setblock ~124 ~55 ~143 minecraft:weathered_cut_copper strict
fill ~122 ~55 ~144 ~123 ~55 ~144 minecraft:quartz_stairs[facing=east,half=bottom,shape=straight,waterlogged=false] strict
fill ~124 ~55 ~144 ~129 ~55 ~144 minecraft:quartz_bricks strict
fill ~124 ~56 ~112 ~125 ~56 ~112 minecraft:quartz_stairs[facing=east,half=bottom,shape=straight,waterlogged=false] strict
fill ~126 ~56 ~112 ~130 ~56 ~112 minecraft:quartz_bricks strict
fill ~131 ~56 ~112 ~132 ~56 ~112 minecraft:quartz_stairs[facing=west,half=bottom,shape=straight,waterlogged=false] strict
fill ~124 ~56 ~113 ~124 ~56 ~116 minecraft:weathered_cut_copper_stairs[facing=east,half=bottom,shape=straight,waterlogged=false] strict
fill ~127 ~56 ~113 ~127 ~56 ~116 minecraft:weathered_cut_copper strict
fill ~129 ~56 ~113 ~130 ~56 ~114 minecraft:weathered_cut_copper strict
fill ~131 ~56 ~113 ~132 ~56 ~114 minecraft:weathered_cut_copper_stairs[facing=west,half=bottom,shape=straight,waterlogged=false] strict
fill ~125 ~56 ~114 ~125 ~56 ~115 minecraft:weathered_cut_copper_stairs[facing=east,half=bottom,shape=straight,waterlogged=false] strict
setblock ~126 ~56 ~114 minecraft:weathered_cut_copper strict
fill ~129 ~56 ~116 ~130 ~56 ~116 minecraft:weathered_cut_copper strict
setblock ~130 ~56 ~117 minecraft:weathered_cut_copper strict
setblock ~129 ~56 ~118 minecraft:weathered_cut_copper strict
fill ~124 ~56 ~141 ~125 ~56 ~141 minecraft:weathered_cut_copper_stairs[facing=east,half=bottom,shape=straight,waterlogged=false] strict
fill ~125 ~56 ~142 ~125 ~56 ~143 minecraft:weathered_cut_copper_stairs[facing=east,half=bottom,shape=straight,waterlogged=false] strict
fill ~127 ~56 ~142 ~127 ~56 ~143 minecraft:weathered_cut_copper strict
fill ~129 ~56 ~142 ~129 ~56 ~143 minecraft:weathered_cut_copper strict
setblock ~124 ~56 ~143 minecraft:weathered_cut_copper_stairs[facing=east,half=bottom,shape=straight,waterlogged=false] strict
setblock ~126 ~56 ~143 minecraft:weathered_cut_copper strict
fill ~124 ~56 ~144 ~125 ~56 ~144 minecraft:quartz_stairs[facing=east,half=bottom,shape=straight,waterlogged=false] strict
fill ~126 ~56 ~144 ~129 ~56 ~144 minecraft:quartz_bricks strict
fill ~126 ~57 ~112 ~127 ~57 ~112 minecraft:quartz_stairs[facing=east,half=bottom,shape=straight,waterlogged=false] strict
setblock ~128 ~57 ~112 minecraft:quartz_bricks strict
fill ~129 ~57 ~112 ~130 ~57 ~112 minecraft:quartz_stairs[facing=west,half=bottom,shape=straight,waterlogged=false] strict
fill ~127 ~57 ~113 ~127 ~57 ~116 minecraft:weathered_cut_copper_stairs[facing=east,half=bottom,shape=straight,waterlogged=false] strict
fill ~128 ~57 ~113 ~128 ~58 ~116 minecraft:weathered_cut_copper strict
fill ~129 ~57 ~113 ~130 ~57 ~114 minecraft:weathered_cut_copper_stairs[facing=west,half=bottom,shape=straight,waterlogged=false] strict
