setblock ~213 ~53 ~251 minecraft:jungle_leaves[distance=7,persistent=true,waterlogged=false] strict
fill ~144 ~53 ~253 ~146 ~53 ~253 minecraft:grass_block strict
setblock ~150 ~53 ~253 minecraft:grass_block strict
fill ~144 ~53 ~254 ~145 ~53 ~255 minecraft:grass_block strict
fill ~152 ~53 ~254 ~153 ~53 ~254 minecraft:grass_block strict
setblock ~146 ~53 ~255 minecraft:grass_block strict
fill ~151 ~53 ~255 ~152 ~53 ~255 minecraft:grass_block strict
fill ~120 ~54 ~112 ~121 ~54 ~112 minecraft:quartz_stairs[facing=east,half=bottom,shape=straight,waterlogged=false] strict
fill ~122 ~54 ~112 ~134 ~54 ~112 minecraft:quartz_bricks strict
fill ~135 ~54 ~112 ~136 ~54 ~112 minecraft:quartz_stairs[facing=west,half=bottom,shape=straight,waterlogged=false] strict
fill ~120 ~54 ~113 ~121 ~54 ~113 minecraft:weathered_cut_copper_stairs[facing=east,half=bottom,shape=straight,waterlogged=false] strict
fill ~122 ~54 ~113 ~123 ~54 ~113 minecraft:weathered_cut_copper strict
setblock ~134 ~54 ~113 minecraft:weathered_cut_copper strict
fill ~135 ~54 ~113 ~136 ~54 ~114 minecraft:weathered_cut_copper_stairs[facing=west,half=bottom,shape=straight,waterlogged=false] strict
setblock ~120 ~54 ~114 minecraft:weathered_cut_copper_stairs[facing=east,half=bottom,shape=straight,waterlogged=false] strict
setblock ~123 ~54 ~114 minecraft:weathered_cut_copper strict
fill ~133 ~54 ~114 ~133 ~54 ~116 minecraft:weathered_cut_copper strict
setblock ~116 ~54 ~115 minecraft:weathered_cut_copper_stairs[facing=north,half=bottom,shape=straight,waterlogged=false] strict
fill ~121 ~54 ~115 ~121 ~54 ~116 minecraft:weathered_cut_copper_stairs[facing=east,half=bottom,shape=straight,waterlogged=false] strict
setblock ~136 ~54 ~115 minecraft:weathered_cut_copper_stairs[facing=west,half=bottom,shape=straight,waterlogged=false] strict
setblock ~137 ~54 ~115 minecraft:calcite strict
setblock ~122 ~54 ~116 minecraft:weathered_cut_copper strict
setblock ~135 ~54 ~117 minecraft:weathered_cut_copper_stairs[facing=west,half=bottom,shape=straight,waterlogged=false] strict
setblock ~137 ~54 ~117 minecraft:quartz_bricks strict
setblock ~120 ~54 ~118 minecraft:weathered_cut_copper_stairs[facing=east,half=bottom,shape=straight,waterlogged=false] strict
fill ~120 ~54 ~141 ~120 ~54 ~143 minecraft:weathered_cut_copper_stairs[facing=east,half=bottom,shape=straight,waterlogged=false] strict
setblock ~121 ~54 ~142 minecraft:weathered_cut_copper_stairs[facing=east,half=bottom,shape=straight,waterlogged=false] strict
fill ~122 ~54 ~142 ~122 ~54 ~143 minecraft:weathered_cut_copper strict
setblock ~123 ~54 ~143 minecraft:weathered_cut_copper strict
fill ~120 ~54 ~144 ~121 ~54 ~144 minecraft:quartz_stairs[facing=east,half=bottom,shape=straight,waterlogged=false] strict
fill ~122 ~54 ~144 ~129 ~54 ~144 minecraft:quartz_bricks strict
setblock ~147 ~54 ~253 minecraft:andesite strict
fill ~148 ~54 ~253 ~149 ~54 ~253 minecraft:stone strict
fill ~146 ~54 ~254 ~151 ~54 ~254 minecraft:grass_block strict
fill ~147 ~54 ~255 ~150 ~54 ~255 minecraft:grass_block strict
fill ~122 ~55 ~112 ~123 ~55 ~112 minecraft:quartz_stairs[facing=east,half=bottom,shape=straight,waterlogged=false] strict
fill ~124 ~55 ~112 ~132 ~55 ~112 minecraft:quartz_bricks strict
fill ~133 ~55 ~112 ~134 ~55 ~112 minecraft:quartz_stairs[facing=west,half=bottom,shape=straight,waterlogged=false] strict
fill ~122 ~55 ~113 ~123 ~55 ~113 minecraft:weathered_cut_copper_stairs[facing=east,half=bottom,shape=straight,waterlogged=false] strict
fill ~124 ~55 ~113 ~124 ~55 ~116 minecraft:weathered_cut_copper strict
fill ~131 ~55 ~113 ~132 ~55 ~114 minecraft:weathered_cut_copper strict
setblock ~134 ~55 ~113 minecraft:weathered_cut_copper_stairs[facing=west,half=bottom,shape=straight,waterlogged=false] strict
setblock ~123 ~55 ~114 minecraft:weathered_cut_copper_stairs[facing=east,half=bottom,shape=straight,waterlogged=false] strict
fill ~125 ~55 ~114 ~125 ~55 ~115 minecraft:weathered_cut_copper strict
fill ~133 ~55 ~114 ~133 ~55 ~116 minecraft:weathered_cut_copper_stairs[facing=west,half=bottom,shape=straight,waterlogged=false] strict
setblock ~122 ~55 ~116 minecraft:weathered_cut_copper_stairs[facing=east,half=bottom,shape=straight,waterlogged=false] strict
fill ~124 ~55 ~141 ~125 ~55 ~141 minecraft:weathered_cut_copper strict
fill ~122 ~55 ~142 ~122 ~55 ~143 minecraft:weathered_cut_copper_stairs[facing=east,half=bottom,shape=straight,waterlogged=false] strict
fill ~125 ~55 ~142 ~125 ~55 ~143 minecraft:weathered_cut_copper strict
setblock ~123 ~55 ~143 minecraft:weathered_cut_copper_stairs[facing=east,half=bottom,shape=straight,waterlogged=false] strict
setblock ~124 ~55 ~143 minecraft:weathered_cut_copper strict
fill ~122 ~55 ~144 ~123 ~55 ~144 minecraft:quartz_stairs[facing=east,half=bottom,shape=straight,waterlogged=false] strict
fill ~124 ~55 ~144 ~129 ~55 ~144 minecraft:quartz_bricks strict
fill ~124 ~56 ~112 ~125 ~56 ~112 minecraft:quartz_stairs[facing=east,half=bottom,shape=straight,waterlogged=false] strict
fill ~126 ~56 ~112 ~130 ~56 ~112 minecraft:quartz_bricks strict
fill ~131 ~56 ~112 ~132 ~56 ~112 minecraft:quartz_stairs[facing=west,half=bottom,shape=straight,waterlogged=false] strict
fill ~124 ~56 ~113 ~124 ~56 ~116 minecraft:weathered_cut_copper_stairs[facing=east,half=bottom,shape=straight,waterlogged=false] strict
fill ~127 ~56 ~113 ~127 ~56 ~116 minecraft:weathered_cut_copper strict
fill ~129 ~56 ~113 ~130 ~56 ~114 minecraft:weathered_cut_copper strict
fill ~131 ~56 ~113 ~132 ~56 ~114 minecraft:weathered_cut_copper_stairs[facing=west,half=bottom,shape=straight,waterlogged=false] strict
fill ~125 ~56 ~114 ~125 ~56 ~115 minecraft:weathered_cut_copper_stairs[facing=east,half=bottom,shape=straight,waterlogged=false] strict
setblock ~126 ~56 ~114 minecraft:weathered_cut_copper strict
fill ~129 ~56 ~116 ~130 ~56 ~116 minecraft:weathered_cut_copper strict
setblock ~130 ~56 ~117 minecraft:weathered_cut_copper strict
setblock ~129 ~56 ~118 minecraft:weathered_cut_copper strict
fill ~124 ~56 ~141 ~125 ~56 ~141 minecraft:weathered_cut_copper_stairs[facing=east,half=bottom,shape=straight,waterlogged=false] strict
fill ~125 ~56 ~142 ~125 ~56 ~143 minecraft:weathered_cut_copper_stairs[facing=east,half=bottom,shape=straight,waterlogged=false] strict
fill ~127 ~56 ~142 ~127 ~56 ~143 minecraft:weathered_cut_copper strict
fill ~129 ~56 ~142 ~129 ~56 ~143 minecraft:weathered_cut_copper strict
setblock ~124 ~56 ~143 minecraft:weathered_cut_copper_stairs[facing=east,half=bottom,shape=straight,waterlogged=false] strict
setblock ~126 ~56 ~143 minecraft:weathered_cut_copper strict
fill ~124 ~56 ~144 ~125 ~56 ~144 minecraft:quartz_stairs[facing=east,half=bottom,shape=straight,waterlogged=false] strict
fill ~126 ~56 ~144 ~129 ~56 ~144 minecraft:quartz_bricks strict
fill ~126 ~57 ~112 ~127 ~57 ~112 minecraft:quartz_stairs[facing=east,half=bottom,shape=straight,waterlogged=false] strict
setblock ~128 ~57 ~112 minecraft:quartz_bricks strict
fill ~129 ~57 ~112 ~130 ~57 ~112 minecraft:quartz_stairs[facing=west,half=bottom,shape=straight,waterlogged=false] strict
fill ~127 ~57 ~113 ~127 ~57 ~116 minecraft:weathered_cut_copper_stairs[facing=east,half=bottom,shape=straight,waterlogged=false] strict
fill ~128 ~57 ~113 ~128 ~58 ~116 minecraft:weathered_cut_copper strict
fill ~129 ~57 ~113 ~130 ~57 ~114 minecraft:weathered_cut_copper_stairs[facing=west,half=bottom,shape=straight,waterlogged=false] strict
setblock ~126 ~57 ~114 minecraft:weathered_cut_copper_stairs[facing=east,half=bottom,shape=straight,waterlogged=false] strict
setblock ~131 ~57 ~114 minecraft:weathered_cut_copper_stairs[facing=north,half=bottom,shape=straight,waterlogged=false] strict
fill ~129 ~57 ~116 ~130 ~57 ~116 minecraft:weathered_cut_copper_stairs[facing=west,half=bottom,shape=straight,waterlogged=false] strict
setblock ~130 ~57 ~117 minecraft:weathered_cut_copper_stairs[facing=west,half=bottom,shape=straight,waterlogged=false] strict
setblock ~129 ~57 ~118 minecraft:weathered_cut_copper_stairs[facing=west,half=bottom,shape=straight,waterlogged=false] strict
fill ~128 ~57 ~141 ~128 ~58 ~143 minecraft:weathered_cut_copper strict
fill ~127 ~57 ~142 ~127 ~57 ~143 minecraft:weathered_cut_copper_stairs[facing=east,half=bottom,shape=straight,waterlogged=false] strict
fill ~129 ~57 ~142 ~129 ~57 ~143 minecraft:weathered_cut_copper_stairs[facing=west,half=bottom,shape=straight,waterlogged=false] strict
setblock ~126 ~57 ~143 minecraft:weathered_cut_copper_stairs[facing=east,half=bottom,shape=straight,waterlogged=false] strict
fill ~126 ~57 ~144 ~127 ~57 ~144 minecraft:quartz_stairs[facing=east,half=bottom,shape=straight,waterlogged=false] strict
setblock ~128 ~57 ~144 minecraft:quartz_bricks strict
setblock ~129 ~57 ~144 minecraft:quartz_stairs[facing=west,half=bottom,shape=straight,waterlogged=false] strict
setblock ~128 ~58 ~112 minecraft:chiseled_quartz_block strict
setblock ~128 ~58 ~144 minecraft:chiseled_quartz_block strict
fill ~128 ~69 ~128 ~128 ~70 ~128 minecraft:deepslate_tiles strict
fill ~127 ~70 ~127 ~127 ~71 ~127 minecraft:deepslate_tiles strict
fill ~129 ~70 ~129 ~129 ~71 ~129 minecraft:deepslate_tiles strict
fill ~126 ~71 ~126 ~126 ~72 ~126 minecraft:deepslate_tiles strict
fill ~128 ~71 ~127 ~129 ~72 ~127 minecraft:deepslate_tiles strict
fill ~127 ~71 ~128 ~127 ~72 ~128 minecraft:deepslate_tiles strict
setblock ~128 ~71 ~128 minecraft:stone strict
fill ~129 ~71 ~128 ~129 ~72 ~128 minecraft:deepslate_tiles strict
setblock ~127 ~71 ~129 minecraft:amethyst_block strict
fill ~128 ~71 ~129 ~128 ~72 ~129 minecraft:deepslate_tiles strict
setblock ~130 ~71 ~130 minecraft:amethyst_block strict
fill ~129 ~72 ~124 ~129 ~73 ~125 minecraft:deepslate_tiles strict
fill ~125 ~72 ~125 ~125 ~73 ~125 minecraft:deepslate_tiles strict
fill ~127 ~72 ~125 ~128 ~72 ~126 minecraft:deepslate_tiles strict
fill ~130 ~72 ~125 ~130 ~72 ~130 minecraft:deepslate_tiles strict
setblock ~129 ~72 ~126 minecraft:amethyst_block strict
fill ~131 ~72 ~126 ~131 ~72 ~129 minecraft:deepslate_tiles strict
fill ~125 ~72 ~127 ~126 ~72 ~127 minecraft:deepslate_tiles strict
fill ~127 ~72 ~127 ~127 ~73 ~127 minecraft:stone strict
setblock ~132 ~72 ~127 minecraft:amethyst_block strict
fill ~125 ~72 ~128 ~125 ~72 ~130 minecraft:deepslate_tiles strict
setblock ~126 ~72 ~128 minecraft:amethyst_block strict
setblock ~128 ~72 ~128 minecraft:andesite strict
fill ~124 ~72 ~129 ~124 ~73 ~129 minecraft:deepslate_tiles strict
fill ~126 ~72 ~129 ~127 ~72 ~130 minecraft:deepslate_tiles strict
setblock ~129 ~72 ~129 minecraft:amethyst_block strict
fill ~128 ~72 ~130 ~129 ~72 ~131 minecraft:deepslate_tiles strict
setblock ~126 ~72 ~131 minecraft:amethyst_block strict
fill ~127 ~72 ~131 ~127 ~73 ~132 minecraft:deepslate_tiles strict
fill ~131 ~72 ~131 ~131 ~73 ~131 minecraft:deepslate_tiles strict
fill ~127 ~73 ~122 ~127 ~74 ~122 minecraft:deepslate_tiles strict
fill ~128 ~73 ~123 ~128 ~74 ~124 minecraft:deepslate_tiles strict
fill ~124 ~73 ~124 ~124 ~74 ~124 minecraft:deepslate_tiles strict
fill ~126 ~73 ~124 ~127 ~73 ~125 minecraft:deepslate_tiles strict
fill ~130 ~73 ~124 ~130 ~73 ~129 minecraft:deepslate_tiles strict
setblock ~128 ~73 ~125 minecraft:amethyst_block strict
fill ~131 ~73 ~125 ~131 ~74 ~125 minecraft:deepslate_tiles strict
fill ~124 ~73 ~126 ~125 ~73 ~126 minecraft:deepslate_tiles strict
fill ~126 ~73 ~126 ~126 ~74 ~126 minecraft:stone strict
fill ~127 ~73 ~126 ~129 ~73 ~126 minecraft:deepslate_tiles strict
setblock ~131 ~73 ~126 minecraft:amethyst_block strict
fill ~132 ~73 ~126 ~132 ~73 ~130 minecraft:deepslate_tiles strict
fill ~122 ~73 ~127 ~122 ~74 ~127 minecraft:deepslate_tiles strict
fill ~124 ~73 ~127 ~124 ~74 ~128 minecraft:deepslate_tiles strict
setblock ~125 ~73 ~127 minecraft:amethyst_block strict
fill ~126 ~73 ~127 ~126 ~73 ~132 minecraft:deepslate_tiles strict
fill ~128 ~73 ~127 ~129 ~74 ~127 minecraft:stone strict
fill ~131 ~73 ~127 ~131 ~73 ~128 minecraft:deepslate_tiles strict
fill ~123 ~73 ~128 ~123 ~74 ~128 minecraft:deepslate_tiles strict
fill ~125 ~73 ~128 ~125 ~73 ~129 minecraft:deepslate_tiles strict
fill ~127 ~73 ~128 ~127 ~74 ~129 minecraft:stone strict
setblock ~128 ~73 ~128 minecraft:amethyst_block strict
setblock ~129 ~73 ~128 minecraft:andesite strict
fill ~133 ~73 ~128 ~133 ~74 ~128 minecraft:deepslate_tiles strict
setblock ~128 ~73 ~129 minecraft:andesite strict
setblock ~129 ~73 ~129 minecraft:stone strict
setblock ~131 ~73 ~129 minecraft:amethyst_block strict
fill ~134 ~73 ~129 ~134 ~74 ~129 minecraft:deepslate_tiles strict
fill ~124 ~73 ~130 ~124 ~74 ~130 minecraft:deepslate_tiles strict
setblock ~125 ~73 ~130 minecraft:amethyst_block strict
fill ~127 ~73 ~130 ~129 ~73 ~130 minecraft:deepslate_tiles strict
fill ~130 ~73 ~130 ~130 ~75 ~130 minecraft:stone strict
fill ~131 ~73 ~130 ~131 ~74 ~130 minecraft:deepslate_tiles strict
fill ~125 ~73 ~131 ~125 ~74 ~131 minecraft:deepslate_tiles strict
setblock ~128 ~73 ~131 minecraft:amethyst_block strict
fill ~129 ~73 ~131 ~130 ~73 ~132 minecraft:deepslate_tiles strict
fill ~128 ~73 ~132 ~128 ~74 ~133 minecraft:deepslate_tiles strict
fill ~132 ~73 ~132 ~132 ~74 ~132 minecraft:deepslate_tiles strict
fill ~129 ~73 ~134 ~129 ~74 ~134 minecraft:deepslate_tiles strict
fill ~126 ~74 ~121 ~126 ~74 ~125 minecraft:deepslate_tiles strict
fill ~131 ~74 ~121 ~131 ~75 ~121 minecraft:deepslate_tiles strict
fill ~128 ~74 ~122 ~129 ~75 ~122 minecraft:deepslate_tiles strict
setblock ~130 ~74 ~122 minecraft:amethyst_block strict
setblock ~132 ~74 ~122 minecraft:deepslate_tiles strict
fill ~123 ~74 ~123 ~123 ~75 ~123 minecraft:deepslate_tiles strict
fill ~125 ~74 ~123 ~125 ~75 ~124 minecraft:deepslate_tiles strict
fill ~127 ~74 ~123 ~127 ~75 ~123 minecraft:deepslate_tiles strict
fill ~129 ~74 ~123 ~131 ~75 ~123 minecraft:deepslate_tiles strict
setblock ~133 ~74 ~123 minecraft:amethyst_block strict
setblock ~127 ~74 ~124 minecraft:amethyst_block strict
setblock ~129 ~74 ~124 minecraft:stone strict
fill ~130 ~74 ~124 ~132 ~74 ~124 minecraft:deepslate_tiles strict
fill ~134 ~74 ~124 ~134 ~75 ~124 minecraft:deepslate_tiles strict
fill ~123 ~74 ~125 ~124 ~74 ~125 minecraft:deepslate_tiles strict
setblock ~125 ~74 ~125 minecraft:andesite strict
fill ~127 ~74 ~125 ~128 ~75 ~125 minecraft:stone strict
setblock ~129 ~74 ~125 minecraft:andesite strict
setblock ~130 ~74 ~125 minecraft:amethyst_block strict
fill ~132 ~74 ~125 ~133 ~74 ~125 minecraft:deepslate_tiles strict
fill ~135 ~74 ~125 ~135 ~75 ~125 minecraft:deepslate_tiles strict
fill ~121 ~74 ~126 ~123 ~75 ~126 minecraft:deepslate_tiles strict
setblock ~124 ~74 ~126 minecraft:amethyst_block strict
setblock ~125 ~74 ~126 minecraft:deepslate_tiles strict
fill ~127 ~74 ~126 ~127 ~76 ~126 minecraft:stone strict
setblock ~128 ~74 ~126 minecraft:andesite strict
fill ~129 ~74 ~126 ~131 ~74 ~126 minecraft:stone strict
setblock ~132 ~74 ~126 minecraft:deepslate_tiles strict
setblock ~133 ~74 ~126 minecraft:amethyst_block strict
fill ~134 ~74 ~126 ~134 ~75 ~128 minecraft:deepslate_tiles strict
fill ~123 ~74 ~127 ~123 ~75 ~127 minecraft:deepslate_tiles strict
fill ~125 ~74 ~127 ~126 ~75 ~127 minecraft:stone strict
setblock ~127 ~74 ~127 minecraft:amethyst_block strict
fill ~130 ~74 ~127 ~130 ~76 ~127 minecraft:stone strict
setblock ~131 ~74 ~127 minecraft:andesite strict
setblock ~132 ~74 ~127 minecraft:stone strict
fill ~133 ~74 ~127 ~133 ~75 ~127 minecraft:deepslate_tiles strict
fill ~122 ~74 ~128 ~122 ~75 ~130 minecraft:deepslate_tiles strict
fill ~125 ~74 ~128 ~125 ~75 ~128 minecraft:stone strict
setblock ~126 ~74 ~128 minecraft:andesite strict
fill ~128 ~74 ~128 ~129 ~75 ~128 minecraft:stone strict
setblock ~130 ~74 ~128 minecraft:amethyst_block strict
fill ~131 ~74 ~128 ~131 ~74 ~129 minecraft:stone strict
fill ~132 ~74 ~128 ~132 ~74 ~131 minecraft:deepslate_tiles strict
fill ~123 ~74 ~129 ~123 ~74 ~131 minecraft:deepslate_tiles strict
setblock ~124 ~74 ~129 minecraft:amethyst_block strict
setblock ~125 ~74 ~129 minecraft:andesite strict
fill ~126 ~74 ~129 ~126 ~74 ~131 minecraft:stone strict
fill ~128 ~74 ~129 ~128 ~75 ~129 minecraft:stone strict
setblock ~129 ~74 ~129 minecraft:andesite strict
setblock ~130 ~74 ~129 minecraft:stone strict
setblock ~133 ~74 ~129 minecraft:amethyst_block strict
setblock ~125 ~74 ~130 minecraft:stone strict
setblock ~127 ~74 ~130 minecraft:amethyst_block strict
setblock ~128 ~74 ~130 minecraft:andesite strict
fill ~129 ~74 ~130 ~129 ~74 ~131 minecraft:stone strict
fill ~133 ~74 ~130 ~135 ~75 ~130 minecraft:deepslate_tiles strict
setblock ~121 ~74 ~131 minecraft:amethyst_block strict
fill ~124 ~74 ~131 ~124 ~75 ~131 minecraft:deepslate_tiles strict
setblock ~127 ~74 ~131 minecraft:andesite strict
setblock ~128 ~74 ~131 minecraft:stone strict
setblock ~130 ~74 ~131 minecraft:amethyst_block strict
setblock ~131 ~74 ~131 minecraft:andesite strict
fill ~133 ~74 ~131 ~133 ~75 ~131 minecraft:deepslate_tiles strict
fill ~122 ~74 ~132 ~122 ~75 ~132 minecraft:deepslate_tiles strict
setblock ~124 ~74 ~132 minecraft:amethyst_block strict
fill ~125 ~74 ~132 ~126 ~74 ~133 minecraft:deepslate_tiles strict
setblock ~127 ~74 ~132 minecraft:stone strict
fill ~129 ~74 ~132 ~131 ~74 ~133 minecraft:deepslate_tiles strict
fill ~123 ~74 ~133 ~123 ~75 ~133 minecraft:deepslate_tiles strict
setblock ~127 ~74 ~133 minecraft:amethyst_block strict
fill ~133 ~74 ~133 ~133 ~75 ~133 minecraft:deepslate_tiles strict
fill ~124 ~74 ~134 ~124 ~75 ~134 minecraft:deepslate_tiles strict
fill ~126 ~74 ~134 ~128 ~75 ~134 minecraft:deepslate_tiles strict
setblock ~130 ~74 ~134 minecraft:amethyst_block strict
fill ~125 ~74 ~135 ~125 ~75 ~135 minecraft:deepslate_tiles strict
fill ~130 ~74 ~135 ~130 ~75 ~135 minecraft:deepslate_tiles strict
fill ~129 ~75 ~119 ~129 ~76 ~119 minecraft:deepslate_tiles strict
fill ~125 ~75 ~120 ~125 ~75 ~122 minecraft:deepslate_tiles strict
fill ~130 ~75 ~120 ~130 ~75 ~122 minecraft:deepslate_tiles strict
fill ~126 ~75 ~121 ~128 ~75 ~121 minecraft:deepslate_tiles strict
setblock ~129 ~75 ~121 minecraft:amethyst_block strict
fill ~122 ~75 ~122 ~122 ~75 ~125 minecraft:deepslate_tiles strict
setblock ~123 ~75 ~122 minecraft:amethyst_block strict
fill ~124 ~75 ~122 ~124 ~76 ~123 minecraft:deepslate_tiles strict
setblock ~126 ~75 ~122 minecraft:deepslate_tiles strict
fill ~127 ~75 ~122 ~127 ~76 ~122 minecraft:stone strict
fill ~131 ~75 ~122 ~131 ~76 ~122 minecraft:deepslate_tiles strict
setblock ~132 ~75 ~122 minecraft:amethyst_block strict
fill ~133 ~75 ~122 ~133 ~75 ~126 minecraft:deepslate_tiles strict
setblock ~126 ~75 ~123 minecraft:amethyst_block strict
setblock ~128 ~75 ~123 minecraft:andesite strict
fill ~132 ~75 ~123 ~132 ~75 ~124 minecraft:deepslate_tiles strict
fill ~134 ~75 ~123 ~134 ~76 ~123 minecraft:deepslate_tiles strict
fill ~123 ~75 ~124 ~123 ~76 ~124 minecraft:deepslate_tiles strict
setblock ~124 ~75 ~124 minecraft:stone strict
fill ~126 ~75 ~124 ~126 ~77 ~124 minecraft:stone strict
setblock ~127 ~75 ~124 minecraft:andesite strict
setblock ~128 ~75 ~124 minecraft:stone strict
setblock ~129 ~75 ~124 minecraft:amethyst_block strict
fill ~130 ~75 ~124 ~130 ~77 ~124 minecraft:stone strict
setblock ~131 ~75 ~124 minecraft:deepslate_tiles strict
fill ~120 ~75 ~125 ~121 ~76 ~125 minecraft:deepslate_tiles strict
setblock ~123 ~75 ~125 minecraft:amethyst_block strict
setblock ~124 ~75 ~125 minecraft:deepslate_tiles strict
setblock ~125 ~75 ~125 minecraft:stone strict
setblock ~126 ~75 ~125 minecraft:andesite strict
fill ~129 ~75 ~125 ~129 ~77 ~125 minecraft:stone strict
setblock ~130 ~75 ~125 minecraft:andesite strict
fill ~131 ~75 ~125 ~131 ~75 ~127 minecraft:stone strict
setblock ~132 ~75 ~125 minecraft:amethyst_block strict
setblock ~134 ~75 ~125 minecraft:deepslate_tiles strict
fill ~124 ~75 ~126 ~124 ~77 ~126 minecraft:stone strict
setblock ~125 ~75 ~126 minecraft:andesite strict
setblock ~126 ~75 ~126 minecraft:amethyst_block strict
setblock ~128 ~75 ~126 minecraft:stone strict
setblock ~129 ~75 ~126 minecraft:andesite strict
setblock ~130 ~75 ~126 minecraft:stone strict
fill ~132 ~75 ~126 ~132 ~77 ~126 minecraft:stone strict
setblock ~135 ~75 ~126 minecraft:amethyst_block strict
fill ~136 ~75 ~126 ~136 ~76 ~126 minecraft:deepslate_tiles strict
fill ~121 ~75 ~127 ~121 ~75 ~131 minecraft:deepslate_tiles strict
setblock ~122 ~75 ~127 minecraft:stone strict
setblock ~124 ~75 ~127 minecraft:andesite strict
fill ~127 ~75 ~127 ~127 ~77 ~127 minecraft:stone strict
setblock ~128 ~75 ~127 minecraft:andesite strict
setblock ~129 ~75 ~127 minecraft:amethyst_block strict
setblock ~132 ~75 ~127 minecraft:andesite strict
fill ~135 ~75 ~127 ~135 ~76 ~128 minecraft:deepslate_tiles strict
fill ~137 ~75 ~127 ~137 ~76 ~127 minecraft:deepslate_tiles strict
setblock ~123 ~75 ~128 minecraft:amethyst_block strict
fill ~124 ~75 ~128 ~124 ~75 ~130 minecraft:stone strict
fill ~126 ~75 ~128 ~126 ~77 ~128 minecraft:stone strict
setblock ~127 ~75 ~128 minecraft:andesite strict
fill ~130 ~75 ~128 ~130 ~77 ~128 minecraft:stone strict
setblock ~131 ~75 ~128 minecraft:andesite strict
setblock ~132 ~75 ~128 minecraft:amethyst_block strict
fill ~133 ~75 ~128 ~133 ~76 ~128 minecraft:stone strict
setblock ~119 ~75 ~129 minecraft:deepslate_tiles strict
fill ~123 ~75 ~129 ~123 ~75 ~130 minecraft:deepslate_tiles strict
fill ~125 ~75 ~129 ~125 ~77 ~129 minecraft:stone strict
setblock ~126 ~75 ~129 minecraft:amethyst_block strict
fill ~127 ~75 ~129 ~127 ~75 ~131 minecraft:stone strict
fill ~129 ~75 ~129 ~129 ~77 ~129 minecraft:stone strict
setblock ~130 ~75 ~129 minecraft:andesite strict
fill ~131 ~75 ~129 ~132 ~75 ~130 minecraft:stone strict
setblock ~133 ~75 ~129 minecraft:deepslate_tiles strict
setblock ~134 ~75 ~129 minecraft:andesite strict
setblock ~135 ~75 ~129 minecraft:amethyst_block strict
setblock ~120 ~75 ~130 minecraft:amethyst_block strict
setblock ~125 ~75 ~130 minecraft:andesite strict
fill ~126 ~75 ~130 ~126 ~75 ~131 minecraft:stone strict
fill ~128 ~75 ~130 ~128 ~77 ~130 minecraft:stone strict
setblock ~129 ~75 ~130 minecraft:amethyst_block strict
fill ~122 ~75 ~131 ~122 ~76 ~131 minecraft:deepslate_tiles strict
setblock ~123 ~75 ~131 minecraft:amethyst_block strict
setblock ~125 ~75 ~131 minecraft:stone strict
setblock ~128 ~75 ~131 minecraft:andesite strict
fill ~129 ~75 ~131 ~131 ~75 ~131 minecraft:stone strict
setblock ~132 ~75 ~131 minecraft:amethyst_block strict
fill ~134 ~75 ~131 ~136 ~75 ~131 minecraft:deepslate_tiles strict
fill ~123 ~75 ~132 ~125 ~75 ~132 minecraft:deepslate_tiles strict
setblock ~126 ~75 ~132 minecraft:amethyst_block strict
setblock ~127 ~75 ~132 minecraft:andesite strict
fill ~128 ~75 ~132 ~130 ~75 ~132 minecraft:stone strict
fill ~131 ~75 ~132 ~131 ~75 ~136 minecraft:deepslate_tiles strict
setblock ~132 ~75 ~132 minecraft:stone strict
fill ~133 ~75 ~132 ~134 ~76 ~132 minecraft:deepslate_tiles strict
setblock ~122 ~75 ~133 minecraft:deepslate_tiles strict
fill ~124 ~75 ~133 ~127 ~75 ~133 minecraft:deepslate_tiles strict
fill ~128 ~75 ~133 ~128 ~76 ~133 minecraft:stone strict
setblock ~129 ~75 ~133 minecraft:amethyst_block strict
fill ~130 ~75 ~133 ~130 ~75 ~134 minecraft:deepslate_tiles strict
fill ~132 ~75 ~133 ~132 ~76 ~133 minecraft:deepslate_tiles strict
fill ~134 ~75 ~133 ~134 ~75 ~134 minecraft:deepslate_tiles strict
setblock ~123 ~75 ~134 minecraft:amethyst_block strict
setblock ~125 ~75 ~134 minecraft:deepslate_tiles strict
setblock ~129 ~75 ~134 minecraft:andesite strict
setblock ~132 ~75 ~134 minecraft:amethyst_block strict
fill ~133 ~75 ~134 ~133 ~76 ~134 minecraft:deepslate_tiles strict
setblock ~126 ~75 ~135 minecraft:amethyst_block strict
fill ~127 ~75 ~135 ~129 ~75 ~135 minecraft:deepslate_tiles strict
fill ~126 ~75 ~136 ~126 ~76 ~136 minecraft:deepslate_tiles strict
fill ~127 ~75 ~137 ~127 ~76 ~137 minecraft:deepslate_tiles strict
fill ~128 ~76 ~118 ~128 ~77 ~119 minecraft:deepslate_tiles strict
fill ~124 ~76 ~119 ~124 ~76 ~121 minecraft:deepslate_tiles strict
fill ~126 ~76 ~119 ~127 ~76 ~120 minecraft:deepslate_tiles strict
fill ~130 ~76 ~119 ~130 ~76 ~121 minecraft:deepslate_tiles strict
