setblock ~126 ~57 ~114 minecraft:weathered_cut_copper_stairs[facing=east,half=bottom,shape=straight,waterlogged=false] strict
setblock ~131 ~57 ~114 minecraft:weathered_cut_copper_stairs[facing=north,half=bottom,shape=straight,waterlogged=false] strict
fill ~129 ~57 ~116 ~130 ~57 ~116 minecraft:weathered_cut_copper_stairs[facing=west,half=bottom,shape=straight,waterlogged=false] strict
setblock ~130 ~57 ~117 minecraft:weathered_cut_copper_stairs[facing=west,half=bottom,shape=straight,waterlogged=false] strict
setblock ~129 ~57 ~118 minecraft:weathered_cut_copper_stairs[facing=west,half=bottom,shape=straight,waterlogged=false] strict
fill ~128 ~57 ~141 ~128 ~58 ~143 minecraft:weathered_cut_copper strict
fill ~127 ~57 ~142 ~127 ~57 ~143 minecraft:weathered_cut_copper_stairs[facing=east,half=bottom,shape=straight,waterlogged=false] strict
fill ~129 ~57 ~142 ~129 ~57 ~143 minecraft:weathered_cut_copper_stairs[facing=west,half=bottom,shape=straight,waterlogged=false] strict
setblock ~126 ~57 ~143 minecraft:weathered_cut_copper_stairs[facing=east,half=bottom,shape=straight,waterlogged=false] strict
fill ~126 ~57 ~144 ~127 ~57 ~144 minecraft:quartz_stairs[facing=east,half=bottom,shape=straight,waterlogged=false] strict
setblock ~128 ~57 ~144 minecraft:quartz_bricks strict
setblock ~129 ~57 ~144 minecraft:quartz_stairs[facing=west,half=bottom,shape=straight,waterlogged=false] strict
setblock ~128 ~58 ~112 minecraft:chiseled_quartz_block strict
setblock ~128 ~58 ~144 minecraft:chiseled_quartz_block strict
setblock ~28 ~21 ~208 minecraft:stone_slab[type=bottom,waterlogged=false] strict
setblock ~20 ~21 ~224 minecraft:stone_slab[type=bottom,waterlogged=false] strict
setblock ~49 ~21 ~229 minecraft:stone_slab[type=bottom,waterlogged=false] strict
setblock ~32 ~21 ~237 minecraft:stone_slab[type=bottom,waterlogged=false] strict
fill ~77 ~22 ~52 ~77 ~22 ~53 minecraft:short_grass strict
setblock ~78 ~22 ~53 minecraft:lily_of_the_valley strict
setblock ~79 ~22 ~53 minecraft:short_grass strict
setblock ~80 ~22 ~54 minecraft:fern strict
setblock ~82 ~22 ~54 minecraft:short_grass strict
fill ~74 ~22 ~55 ~78 ~22 ~57 minecraft:wheat[age=7] strict
setblock ~80 ~22 ~56 minecraft:short_grass strict
fill ~73 ~22 ~59 ~73 ~22 ~60 minecraft:short_grass strict
fill ~75 ~22 ~60 ~75 ~22 ~61 minecraft:short_grass strict
setblock ~76 ~22 ~60 minecraft:lily_of_the_valley strict
fill ~77 ~22 ~60 ~78 ~22 ~60 minecraft:short_grass strict
setblock ~86 ~22 ~60 minecraft:lily_of_the_valley strict
fill ~64 ~22 ~61 ~65 ~22 ~61 minecraft:short_grass strict
setblock ~67 ~22 ~61 minecraft:short_grass strict
fill ~69 ~22 ~61 ~70 ~22 ~61 minecraft:short_grass strict
setblock ~72 ~22 ~61 minecraft:dandelion strict
setblock ~74 ~22 ~61 minecraft:short_grass strict
setblock ~78 ~22 ~61 minecraft:short_grass strict
setblock ~64 ~22 ~62 minecraft:short_grass strict
setblock ~83 ~22 ~62 minecraft:azure_bluet strict
setblock ~85 ~22 ~62 minecraft:short_grass strict
fill ~51 ~22 ~63 ~52 ~22 ~63 minecraft:short_grass strict
setblock ~53 ~22 ~63 minecraft:cornflower strict
setblock ~54 ~22 ~63 minecraft:short_grass strict
setblock ~76 ~22 ~63 minecraft:short_grass strict
setblock ~78 ~22 ~63 minecraft:short_grass strict
setblock ~79 ~22 ~63 minecraft:red_tulip strict
setblock ~80 ~22 ~63 minecraft:short_grass strict
setblock ~83 ~22 ~63 minecraft:fern strict
setblock ~85 ~22 ~63 minecraft:oxeye_daisy strict
fill ~50 ~22 ~64 ~50 ~22 ~65 minecraft:short_grass strict
setblock ~52 ~22 ~64 minecraft:short_grass strict
fill ~56 ~22 ~64 ~56 ~22 ~65 minecraft:short_grass strict
fill ~59 ~22 ~64 ~60 ~22 ~64 minecraft:short_grass strict
setblock ~61 ~22 ~64 minecraft:allium strict
setblock ~75 ~22 ~64 minecraft:allium strict
setblock ~76 ~22 ~64 minecraft:cornflower strict
setblock ~79 ~22 ~64 minecraft:oxeye_daisy strict
fill ~81 ~22 ~64 ~82 ~22 ~64 minecraft:short_grass strict
setblock ~85 ~22 ~64 minecraft:short_grass strict
setblock ~51 ~22 ~65 minecraft:short_grass strict
fill ~53 ~22 ~65 ~53 ~22 ~68 minecraft:short_grass strict
fill ~57 ~22 ~65 ~58 ~22 ~66 minecraft:short_grass strict
setblock ~74 ~22 ~65 minecraft:fern strict
fill ~75 ~22 ~65 ~77 ~22 ~65 minecraft:short_grass strict
setblock ~81 ~22 ~65 minecraft:short_grass strict
setblock ~82 ~22 ~65 minecraft:azure_bluet strict
fill ~83 ~22 ~65 ~83 ~22 ~69 minecraft:short_grass strict
setblock ~84 ~22 ~65 minecraft:oxeye_daisy strict
setblock ~85 ~22 ~65 minecraft:azure_bluet strict
setblock ~50 ~22 ~66 minecraft:fern strict
setblock ~51 ~22 ~66 minecraft:bush strict
setblock ~52 ~22 ~66 minecraft:oxeye_daisy strict
fill ~61 ~22 ~66 ~61 ~22 ~67 minecraft:short_grass strict
setblock ~75 ~22 ~66 minecraft:oxeye_daisy strict
fill ~77 ~22 ~66 ~78 ~22 ~66 minecraft:short_grass strict
setblock ~79 ~22 ~66 minecraft:oxeye_daisy strict
setblock ~82 ~22 ~66 minecraft:short_grass strict
fill ~87 ~22 ~66 ~87 ~22 ~67 minecraft:fern strict
setblock ~50 ~22 ~67 minecraft:short_grass strict
setblock ~52 ~22 ~67 minecraft:short_grass strict
setblock ~54 ~22 ~67 minecraft:short_grass strict
fill ~57 ~22 ~67 ~57 ~22 ~68 minecraft:short_grass strict
fill ~59 ~22 ~67 ~60 ~22 ~67 minecraft:short_grass strict
setblock ~75 ~22 ~67 minecraft:cornflower strict
setblock ~76 ~22 ~67 minecraft:allium strict
setblock ~77 ~22 ~67 minecraft:fern strict
fill ~78 ~22 ~67 ~79 ~22 ~67 minecraft:lily_of_the_valley strict
setblock ~80 ~22 ~67 minecraft:oxeye_daisy strict
setblock ~82 ~22 ~67 minecraft:cornflower strict
setblock ~85 ~22 ~67 minecraft:short_grass strict
setblock ~51 ~22 ~68 minecraft:short_grass strict
fill ~55 ~22 ~68 ~56 ~22 ~68 minecraft:short_grass strict
fill ~76 ~22 ~68 ~77 ~22 ~68 minecraft:short_grass strict
setblock ~87 ~22 ~68 minecraft:bush strict
setblock ~50 ~22 ~69 minecraft:short_grass strict
setblock ~52 ~22 ~69 minecraft:short_grass strict
setblock ~56 ~22 ~69 minecraft:short_grass strict
setblock ~76 ~22 ~69 minecraft:short_grass strict
setblock ~82 ~22 ~69 minecraft:short_grass strict
setblock ~50 ~22 ~70 minecraft:dandelion strict
fill ~53 ~22 ~70 ~53 ~22 ~71 minecraft:short_grass strict
setblock ~54 ~22 ~70 minecraft:dandelion strict
setblock ~77 ~22 ~70 minecraft:allium strict
setblock ~79 ~22 ~70 minecraft:short_grass strict
setblock ~83 ~22 ~70 minecraft:dandelion strict
fill ~50 ~22 ~71 ~52 ~22 ~71 minecraft:short_grass strict
fill ~54 ~22 ~71 ~54 ~22 ~72 minecraft:short_grass strict
fill ~74 ~22 ~71 ~74 ~22 ~72 minecraft:short_grass strict
setblock ~76 ~22 ~71 minecraft:cornflower strict
setblock ~77 ~22 ~71 minecraft:dandelion strict
fill ~78 ~22 ~71 ~78 ~22 ~72 minecraft:short_grass strict
fill ~80 ~22 ~71 ~81 ~22 ~71 minecraft:short_grass strict
setblock ~84 ~22 ~71 minecraft:fern strict
fill ~85 ~22 ~71 ~85 ~22 ~72 minecraft:short_grass strict
setblock ~50 ~22 ~72 minecraft:short_grass strict
setblock ~52 ~22 ~72 minecraft:azure_bluet strict
fill ~75 ~22 ~72 ~76 ~22 ~72 minecraft:short_grass strict
fill ~80 ~22 ~72 ~80 ~22 ~73 minecraft:short_grass strict
fill ~83 ~22 ~72 ~84 ~22 ~72 minecraft:short_grass strict
setblock ~86 ~22 ~72 minecraft:allium strict
fill ~52 ~22 ~73 ~53 ~22 ~73 minecraft:short_grass strict
setblock ~74 ~22 ~73 minecraft:cornflower strict
setblock ~77 ~22 ~73 minecraft:short_grass strict
setblock ~82 ~22 ~73 minecraft:azure_bluet strict
setblock ~83 ~22 ~73 minecraft:red_tulip strict
setblock ~84 ~22 ~73 minecraft:short_grass strict
fill ~53 ~22 ~74 ~54 ~22 ~74 minecraft:short_grass strict
fill ~76 ~22 ~74 ~76 ~22 ~75 minecraft:short_grass strict
fill ~86 ~22 ~74 ~86 ~22 ~75 minecraft:short_grass strict
setblock ~53 ~22 ~75 minecraft:short_grass strict
setblock ~75 ~22 ~75 minecraft:short_grass strict
fill ~78 ~22 ~75 ~82 ~22 ~76 minecraft:wheat[age=7] strict
fill ~84 ~22 ~75 ~85 ~22 ~75 minecraft:short_grass strict
fill ~51 ~22 ~76 ~51 ~22 ~80 minecraft:quartz_slab[type=bottom,waterlogged=false] strict
fill ~53 ~22 ~76 ~53 ~22 ~80 minecraft:quartz_slab[type=bottom,waterlogged=false] strict
setblock ~76 ~22 ~76 minecraft:oxeye_daisy strict
setblock ~84 ~22 ~76 minecraft:short_grass strict
setblock ~82 ~22 ~77 minecraft:wheat[age=7] strict
fill ~54 ~22 ~78 ~55 ~22 ~78 minecraft:short_grass strict
setblock ~77 ~22 ~78 minecraft:poppy strict
setblock ~84 ~22 ~78 minecraft:bush strict
setblock ~83 ~22 ~79 minecraft:oxeye_daisy strict
setblock ~61 ~22 ~80 minecraft:dandelion strict
setblock ~62 ~22 ~80 minecraft:wheat[age=7] strict
setblock ~77 ~23 ~50 minecraft:cornflower strict
fill ~78 ~23 ~50 ~78 ~23 ~51 minecraft:short_grass strict
setblock ~79 ~23 ~50 minecraft:bush strict
setblock ~80 ~23 ~51 minecraft:short_grass strict
setblock ~82 ~23 ~52 minecraft:lily_of_the_valley strict
setblock ~80 ~23 ~53 minecraft:short_grass strict
setblock ~81 ~23 ~53 minecraft:fern strict
setblock ~85 ~23 ~53 minecraft:short_grass strict
setblock ~85 ~23 ~54 minecraft:bush strict
setblock ~86 ~23 ~54 minecraft:short_grass strict
fill ~88 ~23 ~54 ~89 ~23 ~54 minecraft:short_grass strict
setblock ~50 ~23 ~59 minecraft:short_grass strict
setblock ~48 ~23 ~61 minecraft:short_grass strict
setblock ~50 ~23 ~61 minecraft:fern strict
setblock ~87 ~23 ~61 minecraft:short_grass strict
setblock ~89 ~23 ~61 minecraft:dandelion strict
setblock ~50 ~23 ~62 minecraft:short_grass strict
fill ~49 ~23 ~63 ~49 ~23 ~65 minecraft:short_grass strict
fill ~87 ~23 ~63 ~88 ~23 ~63 minecraft:short_grass strict
setblock ~48 ~23 ~64 minecraft:short_grass strict
setblock ~87 ~23 ~64 minecraft:fern strict
setblock ~88 ~23 ~64 minecraft:dandelion strict
fill ~89 ~23 ~64 ~89 ~23 ~65 minecraft:short_grass strict
setblock ~88 ~23 ~65 minecraft:azure_bluet strict
setblock ~48 ~23 ~66 minecraft:cornflower strict
setblock ~47 ~23 ~67 minecraft:short_grass strict
fill ~88 ~23 ~67 ~90 ~23 ~67 minecraft:short_grass strict
setblock ~88 ~23 ~68 minecraft:lily_of_the_valley strict
setblock ~89 ~23 ~68 minecraft:bush strict
setblock ~90 ~23 ~68 minecraft:short_grass strict
setblock ~48 ~23 ~69 minecraft:short_grass strict
setblock ~89 ~23 ~69 minecraft:short_grass strict
setblock ~88 ~23 ~70 minecraft:short_grass strict
fill ~90 ~23 ~70 ~90 ~23 ~72 minecraft:short_grass strict
fill ~48 ~23 ~71 ~49 ~23 ~71 minecraft:short_grass strict
setblock ~49 ~23 ~72 minecraft:red_tulip strict
setblock ~88 ~23 ~72 minecraft:allium strict
setblock ~48 ~23 ~73 minecraft:short_grass strict
setblock ~63 ~23 ~73 minecraft:campfire[facing=north,lit=true,signal_fire=false,waterlogged=false] strict
fill ~87 ~23 ~73 ~88 ~23 ~73 minecraft:short_grass strict
setblock ~49 ~23 ~74 minecraft:oxeye_daisy strict
setblock ~88 ~23 ~74 minecraft:fern strict
setblock ~90 ~23 ~74 minecraft:short_grass strict
setblock ~50 ~23 ~75 minecraft:short_grass strict
fill ~52 ~23 ~76 ~52 ~23 ~80 minecraft:quartz_slab[type=bottom,waterlogged=false] strict
setblock ~86 ~23 ~76 minecraft:short_grass strict
setblock ~87 ~23 ~76 minecraft:allium strict
setblock ~88 ~23 ~77 minecraft:fern strict
fill ~87 ~23 ~78 ~88 ~23 ~78 minecraft:short_grass strict
setblock ~88 ~23 ~79 minecraft:cornflower strict
setblock ~78 ~23 ~83 minecraft:short_grass strict
fill ~62 ~23 ~87 ~63 ~23 ~87 minecraft:short_grass strict
setblock ~60 ~23 ~88 minecraft:poppy strict
setblock ~61 ~23 ~88 minecraft:short_grass strict
fill ~64 ~23 ~88 ~65 ~23 ~88 minecraft:short_grass strict
setblock ~64 ~23 ~89 minecraft:dandelion strict
setblock ~67 ~23 ~89 minecraft:short_grass strict
setblock ~224 ~23 ~203 minecraft:sandstone_slab[type=bottom,waterlogged=false] strict
setblock ~216 ~23 ~204 minecraft:sandstone_slab[type=bottom,waterlogged=false] strict
setblock ~218 ~23 ~204 minecraft:sandstone_slab[type=bottom,waterlogged=false] strict
setblock ~220 ~23 ~204 minecraft:sandstone_slab[type=bottom,waterlogged=false] strict
fill ~222 ~23 ~204 ~223 ~23 ~204 minecraft:sandstone_slab[type=bottom,waterlogged=false] strict
setblock ~219 ~23 ~205 minecraft:sandstone_slab[type=bottom,waterlogged=false] strict
setblock ~221 ~23 ~205 minecraft:sandstone_slab[type=bottom,waterlogged=false] strict
fill ~230 ~23 ~205 ~231 ~23 ~205 minecraft:sandstone_slab[type=bottom,waterlogged=false] strict
setblock ~212 ~23 ~206 minecraft:sandstone_slab[type=bottom,waterlogged=false] strict
setblock ~231 ~23 ~206 minecraft:sandstone_slab[type=bottom,waterlogged=false] strict
fill ~27 ~23 ~207 ~27 ~23 ~208 minecraft:smooth_stone_slab[type=bottom,waterlogged=false] strict
fill ~213 ~23 ~207 ~214 ~23 ~207 minecraft:sandstone_slab[type=bottom,waterlogged=false] strict
setblock ~235 ~23 ~208 minecraft:sandstone_slab[type=bottom,waterlogged=false] strict
fill ~232 ~23 ~210 ~234 ~23 ~210 minecraft:smooth_sandstone_slab[type=bottom,waterlogged=false] strict
fill ~235 ~23 ~210 ~237 ~23 ~212 minecraft:sandstone_slab[type=bottom,waterlogged=false] strict
fill ~232 ~23 ~211 ~232 ~23 ~212 minecraft:smooth_sandstone_slab[type=bottom,waterlogged=false] strict
fill ~234 ~23 ~211 ~234 ~23 ~212 minecraft:smooth_sandstone_slab[type=bottom,waterlogged=false] strict
setblock ~206 ~23 ~212 minecraft:sandstone_slab[type=bottom,waterlogged=false] strict
setblock ~233 ~23 ~212 minecraft:smooth_sandstone_slab[type=bottom,waterlogged=false] strict
fill ~238 ~23 ~212 ~238 ~23 ~214 minecraft:sandstone_slab[type=bottom,waterlogged=false] strict
setblock ~205 ~23 ~214 minecraft:sandstone_slab[type=bottom,waterlogged=false] strict
setblock ~239 ~23 ~214 minecraft:sandstone_slab[type=bottom,waterlogged=false] strict
setblock ~204 ~23 ~217 minecraft:sandstone_slab[type=bottom,waterlogged=false] strict
fill ~240 ~23 ~217 ~240 ~23 ~218 minecraft:sandstone_slab[type=bottom,waterlogged=false] strict
setblock ~203 ~23 ~219 minecraft:sandstone_slab[type=bottom,waterlogged=false] strict
setblock ~241 ~23 ~219 minecraft:sandstone_slab[type=bottom,waterlogged=false] strict
setblock ~205 ~23 ~220 minecraft:sandstone_slab[type=bottom,waterlogged=false] strict
setblock ~241 ~23 ~221 minecraft:sandstone_slab[type=bottom,waterlogged=false] strict
fill ~204 ~23 ~222 ~204 ~23 ~223 minecraft:sandstone_slab[type=bottom,waterlogged=false] strict
fill ~19 ~23 ~223 ~19 ~23 ~224 minecraft:smooth_stone_slab[type=bottom,waterlogged=false] strict
setblock ~203 ~23 ~223 minecraft:sandstone_slab[type=bottom,waterlogged=false] strict
fill ~203 ~23 ~225 ~204 ~23 ~225 minecraft:sandstone_slab[type=bottom,waterlogged=false] strict
fill ~236 ~23 ~225 ~238 ~23 ~225 minecraft:smooth_sandstone_slab[type=bottom,waterlogged=false] strict
fill ~236 ~23 ~226 ~236 ~23 ~227 minecraft:smooth_sandstone_slab[type=bottom,waterlogged=false] strict
fill ~238 ~23 ~226 ~238 ~23 ~227 minecraft:smooth_sandstone_slab[type=bottom,waterlogged=false] strict
setblock ~237 ~23 ~227 minecraft:smooth_sandstone_slab[type=bottom,waterlogged=false] strict
fill ~240 ~23 ~227 ~240 ~23 ~228 minecraft:sandstone_slab[type=bottom,waterlogged=false] strict
fill ~48 ~23 ~228 ~48 ~23 ~229 minecraft:smooth_stone_slab[type=bottom,waterlogged=false] strict
setblock ~205 ~23 ~229 minecraft:sandstone_slab[type=bottom,waterlogged=false] strict
fill ~238 ~23 ~229 ~238 ~23 ~232 minecraft:sandstone_slab[type=bottom,waterlogged=false] strict
setblock ~239 ~23 ~230 minecraft:sandstone_slab[type=bottom,waterlogged=false] strict
setblock ~205 ~23 ~231 minecraft:sandstone_slab[type=bottom,waterlogged=false] strict
fill ~210 ~23 ~232 ~212 ~23 ~232 minecraft:smooth_sandstone_slab[type=bottom,waterlogged=false] strict
fill ~210 ~23 ~233 ~210 ~23 ~234 minecraft:smooth_sandstone_slab[type=bottom,waterlogged=false] strict
fill ~212 ~23 ~233 ~212 ~23 ~234 minecraft:smooth_sandstone_slab[type=bottom,waterlogged=false] strict
setblock ~211 ~23 ~234 minecraft:smooth_sandstone_slab[type=bottom,waterlogged=false] strict
fill ~208 ~23 ~235 ~209 ~23 ~235 minecraft:sandstone_slab[type=bottom,waterlogged=false] strict
fill ~31 ~23 ~236 ~31 ~23 ~237 minecraft:smooth_stone_slab[type=bottom,waterlogged=false] strict
fill ~210 ~23 ~236 ~211 ~23 ~236 minecraft:sandstone_slab[type=bottom,waterlogged=false] strict
fill ~225 ~23 ~236 ~227 ~23 ~236 minecraft:smooth_sandstone_slab[type=bottom,waterlogged=false] strict
fill ~211 ~23 ~237 ~212 ~23 ~237 minecraft:sandstone_slab[type=bottom,waterlogged=false] strict
fill ~225 ~23 ~237 ~225 ~23 ~238 minecraft:smooth_sandstone_slab[type=bottom,waterlogged=false] strict
fill ~227 ~23 ~237 ~227 ~23 ~238 minecraft:smooth_sandstone_slab[type=bottom,waterlogged=false] strict
fill ~212 ~23 ~238 ~213 ~23 ~238 minecraft:sandstone_slab[type=bottom,waterlogged=false] strict
setblock ~217 ~23 ~238 minecraft:sandstone_slab[type=bottom,waterlogged=false] strict
setblock ~226 ~23 ~238 minecraft:smooth_sandstone_slab[type=bottom,waterlogged=false] strict
setblock ~232 ~23 ~238 minecraft:sandstone_slab[type=bottom,waterlogged=false] strict
fill ~213 ~23 ~239 ~214 ~23 ~239 minecraft:sandstone_slab[type=bottom,waterlogged=false] strict
setblock ~216 ~23 ~239 minecraft:sandstone_slab[type=bottom,waterlogged=false] strict
fill ~218 ~23 ~239 ~219 ~23 ~239 minecraft:sandstone_slab[type=bottom,waterlogged=false] strict
setblock ~231 ~23 ~239 minecraft:sandstone_slab[type=bottom,waterlogged=false] strict
setblock ~217 ~23 ~240 minecraft:sandstone_slab[type=bottom,waterlogged=false] strict
setblock ~220 ~23 ~240 minecraft:sandstone_slab[type=bottom,waterlogged=false] strict
fill ~227 ~23 ~240 ~228 ~23 ~240 minecraft:sandstone_slab[type=bottom,waterlogged=false] strict
fill ~221 ~23 ~241 ~222 ~23 ~241 minecraft:sandstone_slab[type=bottom,waterlogged=false] strict
setblock ~225 ~23 ~241 minecraft:sandstone_slab[type=bottom,waterlogged=false] strict
setblock ~56 ~24 ~14 minecraft:short_grass strict
setblock ~58 ~24 ~15 minecraft:short_grass strict
setblock ~58 ~24 ~17 minecraft:short_grass strict
setblock ~60 ~24 ~19 minecraft:short_grass strict
setblock ~61 ~24 ~20 minecraft:poppy strict
fill ~61 ~24 ~21 ~61 ~24 ~22 minecraft:short_grass strict
setblock ~62 ~24 ~22 minecraft:short_grass strict
setblock ~63 ~24 ~25 minecraft:short_grass strict
setblock ~63 ~24 ~27 minecraft:allium strict
setblock ~76 ~24 ~44 minecraft:short_grass strict
setblock ~79 ~24 ~44 minecraft:fern strict
setblock ~75 ~24 ~45 minecraft:short_grass strict
fill ~78 ~24 ~45 ~79 ~24 ~45 minecraft:short_grass strict
fill ~81 ~24 ~45 ~82 ~24 ~45 minecraft:short_grass strict
setblock ~76 ~24 ~46 minecraft:short_grass strict
fill ~79 ~24 ~46 ~80 ~24 ~46 minecraft:short_grass strict
fill ~77 ~24 ~47 ~77 ~24 ~48 minecraft:short_grass strict
setblock ~79 ~24 ~47 minecraft:cornflower strict
fill ~80 ~24 ~47 ~81 ~24 ~47 minecraft:short_grass strict
setblock ~82 ~24 ~47 minecraft:fern strict
setblock ~83 ~24 ~47 minecraft:short_grass strict
setblock ~76 ~24 ~48 minecraft:short_grass strict
setblock ~78 ~24 ~48 minecraft:short_grass strict
setblock ~80 ~24 ~48 minecraft:allium strict
fill ~79 ~24 ~49 ~82 ~24 ~49 minecraft:short_grass strict
setblock ~84 ~24 ~49 minecraft:short_grass strict
setblock ~80 ~24 ~50 minecraft:short_grass strict
setblock ~82 ~24 ~50 minecraft:oxeye_daisy strict
setblock ~83 ~24 ~50 minecraft:azure_bluet strict
fill ~84 ~24 ~51 ~86 ~24 ~51 minecraft:short_grass strict
setblock ~85 ~24 ~52 minecraft:red_tulip strict
setblock ~89 ~24 ~53 minecraft:short_grass strict
setblock ~90 ~24 ~54 minecraft:short_grass strict
setblock ~242 ~24 ~56 minecraft:short_grass strict
fill ~241 ~24 ~57 ~241 ~24 ~58 minecraft:short_grass strict
setblock ~121 ~24 ~58 minecraft:short_grass strict
setblock ~240 ~24 ~58 minecraft:poppy strict
setblock ~52 ~24 ~59 minecraft:poppy strict
setblock ~48 ~24 ~60 minecraft:short_grass strict
fill ~237 ~24 ~60 ~237 ~24 ~61 minecraft:short_grass strict
fill ~90 ~24 ~61 ~92 ~24 ~61 minecraft:short_grass strict
setblock ~121 ~24 ~61 minecraft:short_grass strict
fill ~206 ~24 ~61 ~207 ~24 ~61 minecraft:dead_bush strict
setblock ~236 ~24 ~61 minecraft:short_grass strict
fill ~47 ~24 ~62 ~47 ~24 ~63 minecraft:short_grass strict
fill ~92 ~24 ~62 ~92 ~24 ~63 minecraft:short_grass strict
setblock ~231 ~24 ~62 minecraft:short_grass strict
fill ~233 ~24 ~62 ~234 ~24 ~62 minecraft:short_grass strict
setblock ~45 ~24 ~63 minecraft:allium strict
fill ~58 ~24 ~63 ~59 ~24 ~63 minecraft:short_grass strict
setblock ~63 ~24 ~63 minecraft:campfire[facing=north,lit=true,signal_fire=false,waterlogged=false] strict
setblock ~73 ~24 ~63 minecraft:campfire[facing=north,lit=true,signal_fire=false,waterlogged=false] strict
setblock ~230 ~24 ~63 minecraft:short_grass strict
fill ~45 ~24 ~64 ~45 ~24 ~68 minecraft:short_grass strict
fill ~46 ~24 ~64 ~47 ~24 ~64 minecraft:fern strict
fill ~91 ~24 ~64 ~91 ~24 ~67 minecraft:short_grass strict
fill ~92 ~24 ~65 ~92 ~24 ~67 minecraft:short_grass strict
setblock ~122 ~24 ~65 minecraft:stone_brick_slab[type=bottom,waterlogged=false] strict
setblock ~46 ~24 ~66 minecraft:dandelion strict
setblock ~47 ~24 ~66 minecraft:short_grass strict
fill ~209 ~24 ~66 ~210 ~24 ~67 minecraft:short_grass strict
fill ~46 ~24 ~67 ~46 ~24 ~69 minecraft:short_grass strict
setblock ~92 ~24 ~68 minecraft:fern strict
setblock ~121 ~24 ~68 minecraft:short_grass strict
setblock ~91 ~24 ~69 minecraft:dandelion strict
setblock ~122 ~24 ~69 minecraft:short_grass strict
setblock ~46 ~24 ~71 minecraft:fern strict
setblock ~91 ~24 ~71 minecraft:short_grass strict
fill ~121 ~24 ~71 ~122 ~24 ~71 minecraft:short_grass strict
setblock ~47 ~24 ~72 minecraft:short_grass strict
setblock ~126 ~24 ~72 minecraft:mossy_stone_brick_slab[type=bottom,waterlogged=false] strict
setblock ~127 ~24 ~72 minecraft:stone_brick_slab[type=bottom,waterlogged=false] strict
setblock ~128 ~24 ~72 minecraft:polished_andesite_slab[type=bottom,waterlogged=false] strict
fill ~129 ~24 ~72 ~130 ~24 ~73 minecraft:stone_brick_slab[type=bottom,waterlogged=false] strict
fill ~46 ~24 ~73 ~46 ~24 ~74 minecraft:short_grass strict
setblock ~73 ~24 ~73 minecraft:campfire[facing=north,lit=true,signal_fire=false,waterlogged=false] strict
setblock ~91 ~24 ~73 minecraft:short_grass strict
setblock ~125 ~24 ~73 minecraft:cobblestone_slab[type=bottom,waterlogged=false] strict
setblock ~126 ~24 ~73 minecraft:stone_brick_slab[type=bottom,waterlogged=false] strict
setblock ~127 ~24 ~73 minecraft:polished_andesite_slab[type=bottom,waterlogged=false] strict
setblock ~131 ~24 ~73 minecraft:stone_brick_slab[type=bottom,waterlogged=false] strict
setblock ~91 ~24 ~74 minecraft:fern strict
setblock ~112 ~24 ~75 minecraft:short_grass strict
setblock ~108 ~24 ~76 minecraft:short_grass strict
