setblock ~116 ~51 ~115 minecraft:oxidized_cut_copper strict
setblock ~141 ~51 ~115 minecraft:oxidized_cut_copper_stairs[facing=west,half=bottom,shape=straight,waterlogged=false] strict
fill ~114 ~51 ~116 ~114 ~51 ~117 minecraft:oxidized_cut_copper_stairs[facing=east,half=bottom,shape=straight,waterlogged=false] strict
setblock ~255 ~51 ~122 minecraft:grass_block[snowy=false] strict
fill ~254 ~51 ~133 ~254 ~51 ~137 minecraft:stone strict
fill ~1 ~51 ~140 ~2 ~51 ~142 minecraft:stone strict
setblock ~254 ~51 ~140 minecraft:moss_block strict
fill ~255 ~51 ~140 ~255 ~51 ~141 minecraft:grass_block[snowy=false] strict
fill ~114 ~51 ~141 ~115 ~51 ~143 minecraft:oxidized_cut_copper_stairs[facing=east,half=bottom,shape=straight,waterlogged=false] strict
setblock ~130 ~51 ~141 minecraft:oxidized_cut_copper_stairs[facing=west,half=bottom,shape=straight,waterlogged=false] strict
setblock ~254 ~51 ~141 minecraft:grass_block[snowy=false] strict
setblock ~133 ~51 ~142 minecraft:oxidized_cut_copper strict
setblock ~117 ~51 ~143 minecraft:oxidized_cut_copper strict
setblock ~130 ~51 ~143 minecraft:oxidized_cut_copper_stairs[facing=west,half=bottom,shape=straight,waterlogged=false] strict
fill ~114 ~51 ~144 ~115 ~51 ~144 minecraft:quartz_stairs[facing=east,half=bottom,shape=straight,waterlogged=false] strict
fill ~116 ~51 ~144 ~129 ~51 ~144 minecraft:quartz_bricks strict
setblock ~130 ~51 ~144 minecraft:quartz_stairs[facing=west,half=bottom,shape=straight,waterlogged=false] strict
fill ~2 ~51 ~145 ~4 ~51 ~147 minecraft:stone strict
fill ~1 ~51 ~146 ~1 ~51 ~148 minecraft:stone strict
fill ~2 ~51 ~148 ~3 ~51 ~148 minecraft:stone strict
fill ~0 ~51 ~155 ~0 ~51 ~161 minecraft:grass_block[snowy=false] strict
fill ~1 ~51 ~207 ~1 ~51 ~208 minecraft:grass_block[snowy=false] strict
setblock ~0 ~51 ~208 minecraft:grass_block[snowy=false] strict
fill ~2 ~51 ~208 ~2 ~51 ~209 minecraft:grass_block[snowy=false] strict
fill ~3 ~51 ~222 ~3 ~51 ~223 minecraft:grass_block[snowy=false] strict
fill ~2 ~51 ~223 ~2 ~51 ~225 minecraft:grass_block[snowy=false] strict
fill ~1 ~51 ~224 ~1 ~51 ~232 minecraft:grass_block[snowy=false] strict
fill ~0 ~51 ~225 ~0 ~51 ~233 minecraft:grass_block[snowy=false] strict
fill ~2 ~51 ~230 ~2 ~51 ~231 minecraft:grass_block[snowy=false] strict
setblock ~214 ~51 ~246 minecraft:jungle_leaves[distance=7,persistent=true,waterlogged=false] strict
setblock ~218 ~51 ~247 minecraft:jungle_leaves[distance=7,persistent=true,waterlogged=false] strict
setblock ~211 ~51 ~248 minecraft:jungle_leaves[distance=7,persistent=true,waterlogged=false] strict
setblock ~219 ~51 ~250 minecraft:jungle_leaves[distance=7,persistent=true,waterlogged=false] strict
fill ~150 ~51 ~251 ~151 ~51 ~253 minecraft:stone strict
fill ~149 ~51 ~252 ~149 ~53 ~253 minecraft:stone strict
fill ~153 ~51 ~252 ~153 ~53 ~252 minecraft:stone strict
setblock ~211 ~51 ~252 minecraft:jungle_leaves[distance=7,persistent=true,waterlogged=false] strict
fill ~67 ~51 ~253 ~80 ~51 ~253 minecraft:grass_block[snowy=false] strict
fill ~148 ~51 ~253 ~148 ~52 ~253 minecraft:stone strict
setblock ~155 ~51 ~253 minecraft:grass_block[snowy=false] strict
setblock ~217 ~51 ~253 minecraft:jungle_leaves[distance=7,persistent=true,waterlogged=false] strict
fill ~229 ~51 ~253 ~233 ~51 ~253 minecraft:andesite strict
fill ~16 ~51 ~254 ~21 ~51 ~254 minecraft:grass_block[snowy=false] strict
fill ~66 ~51 ~254 ~67 ~51 ~255 minecraft:grass_block[snowy=false] strict
fill ~81 ~51 ~254 ~82 ~51 ~254 minecraft:grass_block[snowy=false] strict
fill ~140 ~51 ~254 ~141 ~51 ~254 minecraft:grass_block[snowy=false] strict
fill ~146 ~51 ~254 ~151 ~53 ~254 minecraft:dirt strict
fill ~156 ~51 ~254 ~156 ~51 ~255 minecraft:grass_block[snowy=false] strict
setblock ~214 ~51 ~254 minecraft:jungle_leaves[distance=7,persistent=true,waterlogged=false] strict
fill ~228 ~51 ~254 ~235 ~51 ~254 minecraft:moss_block strict
fill ~17 ~51 ~255 ~20 ~51 ~255 minecraft:grass_block[snowy=false] strict
fill ~82 ~51 ~255 ~83 ~51 ~255 minecraft:grass_block[snowy=false] strict
fill ~141 ~51 ~255 ~142 ~51 ~255 minecraft:grass_block[snowy=false] strict
fill ~147 ~51 ~255 ~150 ~53 ~255 minecraft:dirt strict
setblock ~155 ~51 ~255 minecraft:grass_block[snowy=false] strict
fill ~231 ~51 ~255 ~232 ~51 ~255 minecraft:moss_block strict
fill ~154 ~52 ~0 ~158 ~52 ~1 minecraft:grass_block[snowy=false] strict
fill ~207 ~52 ~0 ~209 ~52 ~0 minecraft:moss_block strict
fill ~214 ~52 ~0 ~215 ~52 ~0 minecraft:grass_block[snowy=false] strict
fill ~153 ~52 ~1 ~153 ~52 ~2 minecraft:grass_block[snowy=false] strict
fill ~206 ~52 ~1 ~208 ~52 ~2 minecraft:moss_block strict
fill ~215 ~52 ~1 ~215 ~52 ~2 minecraft:grass_block[snowy=false] strict
setblock ~152 ~52 ~2 minecraft:stone strict
fill ~154 ~52 ~2 ~157 ~52 ~2 minecraft:grass_block[snowy=false] strict
setblock ~158 ~52 ~2 minecraft:andesite strict
fill ~153 ~52 ~3 ~154 ~52 ~3 minecraft:stone strict
fill ~208 ~52 ~3 ~209 ~52 ~3 minecraft:moss_block strict
setblock ~214 ~52 ~3 minecraft:grass_block[snowy=false] strict
setblock ~154 ~52 ~4 minecraft:stone strict
fill ~116 ~52 ~112 ~117 ~52 ~112 minecraft:quartz_stairs[facing=east,half=bottom,shape=straight,waterlogged=false] strict
fill ~118 ~52 ~112 ~138 ~52 ~112 minecraft:quartz_bricks strict
fill ~139 ~52 ~112 ~140 ~52 ~112 minecraft:quartz_stairs[facing=west,half=bottom,shape=straight,waterlogged=false] strict
fill ~116 ~52 ~113 ~117 ~52 ~113 minecraft:oxidized_cut_copper_stairs[facing=east,half=bottom,shape=straight,waterlogged=false] strict
fill ~118 ~52 ~113 ~118 ~52 ~114 minecraft:oxidized_cut_copper strict
fill ~137 ~52 ~113 ~138 ~52 ~113 minecraft:oxidized_cut_copper strict
fill ~139 ~52 ~113 ~140 ~52 ~115 minecraft:oxidized_cut_copper_stairs[facing=west,half=bottom,shape=straight,waterlogged=false] strict
fill ~117 ~52 ~114 ~117 ~52 ~117 minecraft:oxidized_cut_copper_stairs[facing=east,half=bottom,shape=straight,waterlogged=false] strict
fill ~137 ~52 ~114 ~137 ~52 ~115 minecraft:oxidized_cut_copper strict
setblock ~116 ~52 ~115 minecraft:oxidized_cut_copper_stairs[facing=east,half=bottom,shape=straight,waterlogged=false] strict
fill ~119 ~52 ~115 ~119 ~52 ~116 minecraft:oxidized_cut_copper strict
setblock ~118 ~52 ~116 minecraft:oxidized_cut_copper strict
fill ~137 ~52 ~117 ~138 ~52 ~117 minecraft:oxidized_cut_copper strict
fill ~255 ~52 ~125 ~255 ~52 ~133 minecraft:stone strict
fill ~254 ~52 ~134 ~254 ~52 ~137 minecraft:stone strict
fill ~255 ~52 ~137 ~255 ~52 ~139 minecraft:moss_block strict
fill ~254 ~52 ~138 ~254 ~52 ~139 minecraft:moss_block strict
setblock ~115 ~52 ~141 minecraft:calcite strict
fill ~118 ~52 ~141 ~118 ~52 ~143 minecraft:oxidized_cut_copper strict
fill ~119 ~52 ~142 ~119 ~52 ~143 minecraft:oxidized_cut_copper strict
setblock ~133 ~52 ~142 minecraft:oxidized_cut_copper_stairs[facing=west,half=bottom,shape=straight,waterlogged=false] strict
setblock ~117 ~52 ~143 minecraft:oxidized_cut_copper_stairs[facing=east,half=bottom,shape=straight,waterlogged=false] strict
fill ~116 ~52 ~144 ~117 ~52 ~144 minecraft:quartz_stairs[facing=east,half=bottom,shape=straight,waterlogged=false] strict
fill ~118 ~52 ~144 ~129 ~52 ~144 minecraft:quartz_bricks strict
setblock ~133 ~52 ~144 minecraft:quartz_stairs[facing=west,half=bottom,shape=straight,waterlogged=false] strict
fill ~0 ~52 ~209 ~1 ~52 ~211 minecraft:grass_block[snowy=false] strict
fill ~2 ~52 ~211 ~2 ~52 ~213 minecraft:grass_block[snowy=false] strict
setblock ~0 ~52 ~212 minecraft:grass_block[snowy=false] strict
fill ~3 ~52 ~219 ~3 ~52 ~220 minecraft:grass_block[snowy=false] strict
fill ~0 ~52 ~221 ~2 ~52 ~222 minecraft:grass_block[snowy=false] strict
fill ~0 ~52 ~223 ~1 ~52 ~223 minecraft:grass_block[snowy=false] strict
setblock ~0 ~52 ~224 minecraft:grass_block[snowy=false] strict
setblock ~214 ~52 ~247 minecraft:jungle_leaves[distance=7,persistent=true,waterlogged=false] strict
setblock ~217 ~52 ~248 minecraft:jungle_leaves[distance=7,persistent=true,waterlogged=false] strict
setblock ~212 ~52 ~249 minecraft:jungle_leaves[distance=7,persistent=true,waterlogged=false] strict
setblock ~215 ~52 ~250 minecraft:jungle_log[axis=y] strict
setblock ~218 ~52 ~250 minecraft:jungle_leaves[distance=7,persistent=true,waterlogged=false] strict
setblock ~212 ~52 ~251 minecraft:jungle_leaves[distance=7,persistent=true,waterlogged=false] strict
fill ~150 ~52 ~252 ~151 ~53 ~253 minecraft:stone strict
setblock ~217 ~52 ~252 minecraft:jungle_leaves[distance=7,persistent=true,waterlogged=false] strict
setblock ~214 ~52 ~253 minecraft:jungle_leaves[distance=7,persistent=true,waterlogged=false] strict
fill ~68 ~52 ~254 ~80 ~52 ~255 minecraft:grass_block[snowy=false] strict
fill ~142 ~52 ~254 ~143 ~52 ~254 minecraft:grass_block[snowy=false] strict
fill ~154 ~52 ~254 ~155 ~52 ~254 minecraft:grass_block[snowy=false] strict
setblock ~81 ~52 ~255 minecraft:grass_block[snowy=false] strict
setblock ~143 ~52 ~255 minecraft:grass_block[snowy=false] strict
setblock ~153 ~52 ~255 minecraft:dirt strict
setblock ~154 ~52 ~255 minecraft:grass_block[snowy=false] strict
fill ~210 ~53 ~0 ~212 ~53 ~3 minecraft:moss_block strict
fill ~213 ~53 ~0 ~213 ~53 ~1 minecraft:grass_block[snowy=false] strict
fill ~209 ~53 ~1 ~209 ~53 ~2 minecraft:moss_block strict
fill ~214 ~53 ~1 ~214 ~53 ~2 minecraft:grass_block[snowy=false] strict
fill ~213 ~53 ~2 ~213 ~53 ~3 minecraft:moss_block strict
fill ~118 ~53 ~112 ~119 ~53 ~112 minecraft:quartz_stairs[facing=east,half=bottom,shape=straight,waterlogged=false] strict
fill ~120 ~53 ~112 ~136 ~53 ~112 minecraft:quartz_bricks strict
fill ~137 ~53 ~112 ~138 ~53 ~112 minecraft:quartz_stairs[facing=west,half=bottom,shape=straight,waterlogged=false] strict
fill ~118 ~53 ~113 ~118 ~53 ~114 minecraft:oxidized_cut_copper_stairs[facing=east,half=bottom,shape=straight,waterlogged=false] strict
fill ~120 ~53 ~113 ~121 ~53 ~113 minecraft:oxidized_cut_copper strict
fill ~135 ~53 ~113 ~136 ~53 ~114 minecraft:oxidized_cut_copper strict
fill ~137 ~53 ~113 ~138 ~53 ~113 minecraft:oxidized_cut_copper_stairs[facing=west,half=bottom,shape=straight,waterlogged=false] strict
setblock ~120 ~53 ~114 minecraft:oxidized_cut_copper strict
fill ~137 ~53 ~114 ~137 ~53 ~115 minecraft:oxidized_cut_copper_stairs[facing=west,half=bottom,shape=straight,waterlogged=false] strict
setblock ~139 ~53 ~114 minecraft:quartz_bricks strict
setblock ~116 ~53 ~115 minecraft:quartz_bricks strict
setblock ~117 ~53 ~115 minecraft:oxidized_cut_copper_stairs[facing=north,half=bottom,shape=straight,waterlogged=false] strict
fill ~119 ~53 ~115 ~119 ~53 ~116 minecraft:oxidized_cut_copper_stairs[facing=east,half=bottom,shape=straight,waterlogged=false] strict
fill ~121 ~53 ~115 ~121 ~53 ~116 minecraft:oxidized_cut_copper strict
setblock ~136 ~53 ~115 minecraft:oxidized_cut_copper strict
setblock ~118 ~53 ~116 minecraft:oxidized_cut_copper_stairs[facing=east,half=bottom,shape=straight,waterlogged=false] strict
setblock ~135 ~53 ~117 minecraft:oxidized_cut_copper strict
fill ~137 ~53 ~117 ~138 ~53 ~117 minecraft:oxidized_cut_copper_stairs[facing=west,half=bottom,shape=straight,waterlogged=false] strict
setblock ~120 ~53 ~118 minecraft:oxidized_cut_copper strict
fill ~255 ~53 ~128 ~255 ~53 ~133 minecraft:stone strict
fill ~255 ~53 ~134 ~255 ~53 ~136 minecraft:moss_block strict
setblock ~254 ~53 ~135 minecraft:stone strict
fill ~118 ~53 ~141 ~118 ~53 ~143 minecraft:oxidized_cut_copper_stairs[facing=east,half=bottom,shape=straight,waterlogged=false] strict
fill ~120 ~53 ~141 ~120 ~53 ~143 minecraft:oxidized_cut_copper strict
fill ~119 ~53 ~142 ~119 ~53 ~143 minecraft:oxidized_cut_copper_stairs[facing=east,half=bottom,shape=straight,waterlogged=false] strict
setblock ~121 ~53 ~142 minecraft:oxidized_cut_copper strict
fill ~118 ~53 ~144 ~119 ~53 ~144 minecraft:quartz_stairs[facing=east,half=bottom,shape=straight,waterlogged=false] strict
fill ~120 ~53 ~144 ~129 ~53 ~144 minecraft:quartz_bricks strict
fill ~1 ~53 ~212 ~1 ~53 ~220 minecraft:grass_block[snowy=false] strict
fill ~0 ~53 ~213 ~0 ~53 ~220 minecraft:grass_block[snowy=false] strict
fill ~2 ~53 ~214 ~2 ~53 ~220 minecraft:grass_block[snowy=false] strict
fill ~215 ~53 ~248 ~216 ~53 ~252 minecraft:jungle_leaves[distance=7,persistent=true,waterlogged=false] strict
setblock ~213 ~53 ~249 minecraft:jungle_leaves[distance=7,persistent=true,waterlogged=false] strict
setblock ~214 ~53 ~250 minecraft:jungle_leaves[distance=7,persistent=true,waterlogged=false] strict
setblock ~217 ~53 ~250 minecraft:jungle_leaves[distance=7,persistent=true,waterlogged=false] strict
setblock ~213 ~53 ~251 minecraft:jungle_leaves[distance=7,persistent=true,waterlogged=false] strict
setblock ~153 ~53 ~253 minecraft:stone strict
fill ~144 ~53 ~254 ~145 ~53 ~255 minecraft:grass_block[snowy=false] strict
setblock ~152 ~53 ~254 minecraft:dirt strict
setblock ~153 ~53 ~254 minecraft:grass_block[snowy=false] strict
setblock ~146 ~53 ~255 minecraft:grass_block[snowy=false] strict
setblock ~153 ~53 ~255 minecraft:stone strict
fill ~120 ~54 ~112 ~121 ~54 ~112 minecraft:quartz_stairs[facing=east,half=bottom,shape=straight,waterlogged=false] strict
fill ~122 ~54 ~112 ~134 ~54 ~112 minecraft:quartz_bricks strict
fill ~135 ~54 ~112 ~136 ~54 ~112 minecraft:quartz_stairs[facing=west,half=bottom,shape=straight,waterlogged=false] strict
fill ~120 ~54 ~113 ~121 ~54 ~113 minecraft:oxidized_cut_copper_stairs[facing=east,half=bottom,shape=straight,waterlogged=false] strict
fill ~122 ~54 ~113 ~123 ~54 ~113 minecraft:oxidized_cut_copper strict
setblock ~134 ~54 ~113 minecraft:oxidized_cut_copper strict
fill ~135 ~54 ~113 ~136 ~54 ~114 minecraft:oxidized_cut_copper_stairs[facing=west,half=bottom,shape=straight,waterlogged=false] strict
setblock ~120 ~54 ~114 minecraft:oxidized_cut_copper_stairs[facing=east,half=bottom,shape=straight,waterlogged=false] strict
setblock ~123 ~54 ~114 minecraft:oxidized_cut_copper strict
fill ~133 ~54 ~114 ~133 ~54 ~116 minecraft:oxidized_cut_copper strict
setblock ~116 ~54 ~115 minecraft:oxidized_cut_copper_stairs[facing=north,half=bottom,shape=straight,waterlogged=false] strict
fill ~121 ~54 ~115 ~121 ~54 ~116 minecraft:oxidized_cut_copper_stairs[facing=east,half=bottom,shape=straight,waterlogged=false] strict
setblock ~136 ~54 ~115 minecraft:oxidized_cut_copper_stairs[facing=west,half=bottom,shape=straight,waterlogged=false] strict
setblock ~137 ~54 ~115 minecraft:calcite strict
setblock ~122 ~54 ~116 minecraft:oxidized_cut_copper strict
setblock ~135 ~54 ~117 minecraft:oxidized_cut_copper_stairs[facing=west,half=bottom,shape=straight,waterlogged=false] strict
setblock ~137 ~54 ~117 minecraft:quartz_bricks strict
setblock ~120 ~54 ~118 minecraft:oxidized_cut_copper_stairs[facing=east,half=bottom,shape=straight,waterlogged=false] strict
fill ~120 ~54 ~141 ~120 ~54 ~143 minecraft:oxidized_cut_copper_stairs[facing=east,half=bottom,shape=straight,waterlogged=false] strict
setblock ~121 ~54 ~142 minecraft:oxidized_cut_copper_stairs[facing=east,half=bottom,shape=straight,waterlogged=false] strict
fill ~122 ~54 ~142 ~122 ~54 ~143 minecraft:oxidized_cut_copper strict
setblock ~123 ~54 ~143 minecraft:oxidized_cut_copper strict
fill ~120 ~54 ~144 ~121 ~54 ~144 minecraft:quartz_stairs[facing=east,half=bottom,shape=straight,waterlogged=false] strict
fill ~122 ~54 ~144 ~129 ~54 ~144 minecraft:quartz_bricks strict
fill ~150 ~54 ~253 ~152 ~54 ~253 minecraft:stone strict
fill ~146 ~54 ~254 ~151 ~54 ~254 minecraft:grass_block[snowy=false] strict
fill ~152 ~54 ~254 ~152 ~54 ~255 minecraft:stone strict
fill ~147 ~54 ~255 ~150 ~54 ~255 minecraft:grass_block[snowy=false] strict
setblock ~151 ~54 ~255 minecraft:stone strict
fill ~116 ~55 ~17 ~116 ~60 ~17 minecraft:red_wool strict
fill ~117 ~55 ~17 ~117 ~60 ~17 minecraft:stone_brick_wall[east=none,north=none,south=none,up=true,waterlogged=false,west=tall] strict
fill ~122 ~55 ~112 ~123 ~55 ~112 minecraft:quartz_stairs[facing=east,half=bottom,shape=straight,waterlogged=false] strict
fill ~124 ~55 ~112 ~132 ~55 ~112 minecraft:quartz_bricks strict
fill ~133 ~55 ~112 ~134 ~55 ~112 minecraft:quartz_stairs[facing=west,half=bottom,shape=straight,waterlogged=false] strict
fill ~122 ~55 ~113 ~123 ~55 ~113 minecraft:oxidized_cut_copper_stairs[facing=east,half=bottom,shape=straight,waterlogged=false] strict
fill ~124 ~55 ~113 ~124 ~55 ~116 minecraft:oxidized_cut_copper strict
fill ~131 ~55 ~113 ~132 ~55 ~114 minecraft:oxidized_cut_copper strict
setblock ~134 ~55 ~113 minecraft:oxidized_cut_copper_stairs[facing=west,half=bottom,shape=straight,waterlogged=false] strict
setblock ~123 ~55 ~114 minecraft:oxidized_cut_copper_stairs[facing=east,half=bottom,shape=straight,waterlogged=false] strict
fill ~125 ~55 ~114 ~125 ~55 ~115 minecraft:oxidized_cut_copper strict
fill ~133 ~55 ~114 ~133 ~55 ~116 minecraft:oxidized_cut_copper_stairs[facing=west,half=bottom,shape=straight,waterlogged=false] strict
setblock ~122 ~55 ~116 minecraft:oxidized_cut_copper_stairs[facing=east,half=bottom,shape=straight,waterlogged=false] strict
fill ~239 ~55 ~116 ~239 ~60 ~116 minecraft:blue_wool strict
fill ~239 ~55 ~117 ~239 ~60 ~117 minecraft:stone_brick_wall[east=none,north=tall,south=none,up=true,waterlogged=false,west=none] strict
fill ~17 ~55 ~139 ~17 ~60 ~139 minecraft:stone_brick_wall[east=none,north=none,south=tall,up=true,waterlogged=false,west=none] strict
fill ~17 ~55 ~140 ~17 ~60 ~140 minecraft:yellow_wool strict
fill ~124 ~55 ~141 ~125 ~55 ~141 minecraft:oxidized_cut_copper strict
fill ~122 ~55 ~142 ~122 ~55 ~143 minecraft:oxidized_cut_copper_stairs[facing=east,half=bottom,shape=straight,waterlogged=false] strict
fill ~125 ~55 ~142 ~125 ~55 ~143 minecraft:oxidized_cut_copper strict
setblock ~123 ~55 ~143 minecraft:oxidized_cut_copper_stairs[facing=east,half=bottom,shape=straight,waterlogged=false] strict
setblock ~124 ~55 ~143 minecraft:oxidized_cut_copper strict
fill ~122 ~55 ~144 ~123 ~55 ~144 minecraft:quartz_stairs[facing=east,half=bottom,shape=straight,waterlogged=false] strict
fill ~124 ~55 ~144 ~129 ~55 ~144 minecraft:quartz_bricks strict
fill ~139 ~55 ~239 ~139 ~60 ~239 minecraft:stone_brick_wall[east=tall,north=none,south=none,up=true,waterlogged=false,west=none] strict
fill ~140 ~55 ~239 ~140 ~60 ~239 minecraft:lime_wool strict
fill ~110 ~56 ~17 ~110 ~57 ~17 minecraft:red_wool strict
fill ~115 ~56 ~17 ~115 ~60 ~17 minecraft:red_wool strict
fill ~111 ~56 ~18 ~114 ~56 ~18 minecraft:red_wool strict
fill ~239 ~56 ~110 ~239 ~57 ~110 minecraft:blue_wool strict
fill ~238 ~56 ~111 ~238 ~56 ~114 minecraft:blue_wool strict
fill ~124 ~56 ~112 ~125 ~56 ~112 minecraft:quartz_stairs[facing=east,half=bottom,shape=straight,waterlogged=false] strict
fill ~126 ~56 ~112 ~130 ~56 ~112 minecraft:quartz_bricks strict
fill ~131 ~56 ~112 ~132 ~56 ~112 minecraft:quartz_stairs[facing=west,half=bottom,shape=straight,waterlogged=false] strict
fill ~124 ~56 ~113 ~124 ~56 ~116 minecraft:oxidized_cut_copper_stairs[facing=east,half=bottom,shape=straight,waterlogged=false] strict
fill ~127 ~56 ~113 ~127 ~56 ~116 minecraft:oxidized_cut_copper strict
fill ~129 ~56 ~113 ~130 ~56 ~114 minecraft:oxidized_cut_copper strict
fill ~131 ~56 ~113 ~132 ~56 ~114 minecraft:oxidized_cut_copper_stairs[facing=west,half=bottom,shape=straight,waterlogged=false] strict
fill ~125 ~56 ~114 ~125 ~56 ~115 minecraft:oxidized_cut_copper_stairs[facing=east,half=bottom,shape=straight,waterlogged=false] strict
setblock ~126 ~56 ~114 minecraft:oxidized_cut_copper strict
fill ~239 ~56 ~115 ~239 ~60 ~115 minecraft:blue_wool strict
fill ~129 ~56 ~116 ~130 ~56 ~116 minecraft:oxidized_cut_copper strict
setblock ~130 ~56 ~117 minecraft:oxidized_cut_copper strict
setblock ~129 ~56 ~118 minecraft:oxidized_cut_copper strict
fill ~17 ~56 ~141 ~17 ~60 ~141 minecraft:yellow_wool strict
fill ~124 ~56 ~141 ~125 ~56 ~141 minecraft:oxidized_cut_copper_stairs[facing=east,half=bottom,shape=straight,waterlogged=false] strict
fill ~18 ~56 ~142 ~18 ~56 ~145 minecraft:yellow_wool strict
fill ~125 ~56 ~142 ~125 ~56 ~143 minecraft:oxidized_cut_copper_stairs[facing=east,half=bottom,shape=straight,waterlogged=false] strict
fill ~127 ~56 ~142 ~127 ~56 ~143 minecraft:oxidized_cut_copper strict
fill ~129 ~56 ~142 ~129 ~56 ~143 minecraft:oxidized_cut_copper strict
setblock ~124 ~56 ~143 minecraft:oxidized_cut_copper_stairs[facing=east,half=bottom,shape=straight,waterlogged=false] strict
setblock ~126 ~56 ~143 minecraft:oxidized_cut_copper strict
fill ~124 ~56 ~144 ~125 ~56 ~144 minecraft:quartz_stairs[facing=east,half=bottom,shape=straight,waterlogged=false] strict
fill ~126 ~56 ~144 ~129 ~56 ~144 minecraft:quartz_bricks strict
fill ~17 ~56 ~146 ~17 ~57 ~146 minecraft:yellow_wool strict
fill ~142 ~56 ~238 ~145 ~56 ~238 minecraft:lime_wool strict
fill ~141 ~56 ~239 ~141 ~60 ~239 minecraft:lime_wool strict
fill ~146 ~56 ~239 ~146 ~57 ~239 minecraft:lime_wool strict
setblock ~109 ~57 ~17 minecraft:red_wool strict
fill ~111 ~57 ~17 ~111 ~58 ~17 minecraft:red_wool strict
fill ~112 ~57 ~18 ~114 ~58 ~18 minecraft:red_wool strict
setblock ~239 ~57 ~109 minecraft:blue_wool strict
fill ~239 ~57 ~111 ~239 ~58 ~111 minecraft:blue_wool strict
fill ~126 ~57 ~112 ~127 ~57 ~112 minecraft:quartz_stairs[facing=east,half=bottom,shape=straight,waterlogged=false] strict
setblock ~128 ~57 ~112 minecraft:quartz_bricks strict
fill ~129 ~57 ~112 ~130 ~57 ~112 minecraft:quartz_stairs[facing=west,half=bottom,shape=straight,waterlogged=false] strict
fill ~238 ~57 ~112 ~238 ~58 ~114 minecraft:blue_wool strict
fill ~127 ~57 ~113 ~127 ~57 ~116 minecraft:oxidized_cut_copper_stairs[facing=east,half=bottom,shape=straight,waterlogged=false] strict
fill ~128 ~57 ~113 ~128 ~58 ~116 minecraft:oxidized_cut_copper strict
fill ~129 ~57 ~113 ~130 ~57 ~114 minecraft:oxidized_cut_copper_stairs[facing=west,half=bottom,shape=straight,waterlogged=false] strict
setblock ~126 ~57 ~114 minecraft:oxidized_cut_copper_stairs[facing=east,half=bottom,shape=straight,waterlogged=false] strict
setblock ~131 ~57 ~114 minecraft:oxidized_cut_copper_stairs[facing=north,half=bottom,shape=straight,waterlogged=false] strict
fill ~129 ~57 ~116 ~130 ~57 ~116 minecraft:oxidized_cut_copper_stairs[facing=west,half=bottom,shape=straight,waterlogged=false] strict
setblock ~130 ~57 ~117 minecraft:oxidized_cut_copper_stairs[facing=west,half=bottom,shape=straight,waterlogged=false] strict
setblock ~129 ~57 ~118 minecraft:oxidized_cut_copper_stairs[facing=west,half=bottom,shape=straight,waterlogged=false] strict
fill ~128 ~57 ~141 ~128 ~58 ~143 minecraft:oxidized_cut_copper strict
fill ~18 ~57 ~142 ~18 ~58 ~144 minecraft:yellow_wool strict
fill ~127 ~57 ~142 ~127 ~57 ~143 minecraft:oxidized_cut_copper_stairs[facing=east,half=bottom,shape=straight,waterlogged=false] strict
fill ~129 ~57 ~142 ~129 ~57 ~143 minecraft:oxidized_cut_copper_stairs[facing=west,half=bottom,shape=straight,waterlogged=false] strict
setblock ~126 ~57 ~143 minecraft:oxidized_cut_copper_stairs[facing=east,half=bottom,shape=straight,waterlogged=false] strict
fill ~126 ~57 ~144 ~127 ~57 ~144 minecraft:quartz_stairs[facing=east,half=bottom,shape=straight,waterlogged=false] strict
setblock ~128 ~57 ~144 minecraft:quartz_bricks strict
setblock ~129 ~57 ~144 minecraft:quartz_stairs[facing=west,half=bottom,shape=straight,waterlogged=false] strict
fill ~17 ~57 ~145 ~17 ~58 ~145 minecraft:yellow_wool strict
setblock ~17 ~57 ~147 minecraft:yellow_wool strict
fill ~142 ~57 ~238 ~144 ~58 ~238 minecraft:lime_wool strict
fill ~145 ~57 ~239 ~145 ~58 ~239 minecraft:lime_wool strict
setblock ~147 ~57 ~239 minecraft:lime_wool strict
setblock ~128 ~58 ~112 minecraft:chiseled_quartz_block strict
setblock ~128 ~58 ~144 minecraft:chiseled_quartz_block strict
setblock ~112 ~59 ~17 minecraft:red_wool strict
fill ~113 ~59 ~18 ~114 ~59 ~18 minecraft:red_wool strict
setblock ~239 ~59 ~112 minecraft:blue_wool strict
fill ~238 ~59 ~113 ~238 ~59 ~114 minecraft:blue_wool strict
fill ~18 ~59 ~142 ~18 ~59 ~143 minecraft:yellow_wool strict
setblock ~17 ~59 ~144 minecraft:yellow_wool strict
fill ~142 ~59 ~238 ~143 ~59 ~238 minecraft:lime_wool strict
setblock ~144 ~59 ~239 minecraft:lime_wool strict
setblock ~117 ~61 ~17 minecraft:gold_block strict
setblock ~239 ~61 ~117 minecraft:gold_block strict
setblock ~17 ~61 ~139 minecraft:gold_block strict
setblock ~139 ~61 ~239 minecraft:gold_block strict
fill ~0 ~69 ~0 ~255 ~69 ~2 minecraft:barrier[waterlogged=false] strict
fill ~0 ~69 ~3 ~103 ~69 ~103 minecraft:barrier[waterlogged=false] strict
fill ~153 ~69 ~3 ~255 ~69 ~103 minecraft:barrier[waterlogged=false] strict
fill ~104 ~69 ~53 ~152 ~69 ~203 minecraft:barrier[waterlogged=false] strict
fill ~0 ~69 ~104 ~2 ~69 ~255 minecraft:barrier[waterlogged=false] strict
fill ~53 ~69 ~104 ~103 ~69 ~255 minecraft:barrier[waterlogged=false] strict
fill ~153 ~69 ~104 ~203 ~69 ~255 minecraft:barrier[waterlogged=false] strict
fill ~254 ~69 ~104 ~255 ~69 ~255 minecraft:barrier[waterlogged=false] strict
fill ~3 ~69 ~153 ~52 ~69 ~255 minecraft:barrier[waterlogged=false] strict
fill ~204 ~69 ~153 ~253 ~69 ~255 minecraft:barrier[waterlogged=false] strict
fill ~104 ~69 ~254 ~152 ~69 ~255 minecraft:barrier[waterlogged=false] strict
fill ~127 ~70 ~127 ~127 ~71 ~127 minecraft:deepslate_tiles strict
setblock ~128 ~70 ~128 minecraft:deepslate_tiles strict
fill ~129 ~70 ~129 ~129 ~71 ~129 minecraft:deepslate_tiles strict
fill ~126 ~71 ~126 ~126 ~72 ~126 minecraft:deepslate_tiles strict
fill ~128 ~71 ~127 ~129 ~72 ~127 minecraft:deepslate_tiles strict
fill ~127 ~71 ~128 ~127 ~72 ~128 minecraft:deepslate_tiles strict
setblock ~128 ~71 ~128 minecraft:stone strict
fill ~129 ~71 ~128 ~129 ~72 ~128 minecraft:deepslate_tiles strict
setblock ~127 ~71 ~129 minecraft:amethyst_block strict
fill ~128 ~71 ~129 ~128 ~72 ~129 minecraft:deepslate_tiles strict
setblock ~130 ~71 ~130 minecraft:amethyst_block strict
fill ~129 ~72 ~124 ~129 ~73 ~125 minecraft:deepslate_tiles strict
fill ~125 ~72 ~125 ~125 ~73 ~125 minecraft:deepslate_tiles strict
fill ~127 ~72 ~125 ~128 ~72 ~126 minecraft:deepslate_tiles strict
fill ~130 ~72 ~125 ~130 ~72 ~130 minecraft:deepslate_tiles strict
setblock ~129 ~72 ~126 minecraft:amethyst_block strict
fill ~131 ~72 ~126 ~131 ~72 ~129 minecraft:deepslate_tiles strict
fill ~125 ~72 ~127 ~126 ~72 ~127 minecraft:deepslate_tiles strict
fill ~127 ~72 ~127 ~127 ~73 ~127 minecraft:stone strict
setblock ~132 ~72 ~127 minecraft:amethyst_block strict
fill ~125 ~72 ~128 ~125 ~72 ~130 minecraft:deepslate_tiles strict
setblock ~126 ~72 ~128 minecraft:amethyst_block strict
setblock ~128 ~72 ~128 minecraft:andesite strict
fill ~124 ~72 ~129 ~124 ~73 ~129 minecraft:deepslate_tiles strict
fill ~126 ~72 ~129 ~127 ~72 ~130 minecraft:deepslate_tiles strict
setblock ~129 ~72 ~129 minecraft:amethyst_block strict
fill ~128 ~72 ~130 ~129 ~72 ~131 minecraft:deepslate_tiles strict
setblock ~126 ~72 ~131 minecraft:amethyst_block strict
fill ~127 ~72 ~131 ~127 ~73 ~132 minecraft:deepslate_tiles strict
fill ~131 ~72 ~131 ~131 ~73 ~131 minecraft:deepslate_tiles strict
fill ~127 ~73 ~122 ~127 ~74 ~122 minecraft:deepslate_tiles strict
fill ~128 ~73 ~123 ~128 ~74 ~124 minecraft:deepslate_tiles strict
fill ~124 ~73 ~124 ~124 ~74 ~124 minecraft:deepslate_tiles strict
fill ~126 ~73 ~124 ~127 ~73 ~125 minecraft:deepslate_tiles strict
fill ~130 ~73 ~124 ~130 ~73 ~129 minecraft:deepslate_tiles strict
setblock ~128 ~73 ~125 minecraft:amethyst_block strict
fill ~131 ~73 ~125 ~131 ~74 ~125 minecraft:deepslate_tiles strict
fill ~124 ~73 ~126 ~125 ~73 ~126 minecraft:deepslate_tiles strict
fill ~126 ~73 ~126 ~126 ~74 ~126 minecraft:stone strict
fill ~127 ~73 ~126 ~129 ~73 ~126 minecraft:deepslate_tiles strict
setblock ~131 ~73 ~126 minecraft:amethyst_block strict
fill ~132 ~73 ~126 ~132 ~73 ~130 minecraft:deepslate_tiles strict
fill ~122 ~73 ~127 ~122 ~74 ~127 minecraft:deepslate_tiles strict
fill ~124 ~73 ~127 ~124 ~74 ~128 minecraft:deepslate_tiles strict
