setblock ~125 ~73 ~127 minecraft:amethyst_block strict
fill ~126 ~73 ~127 ~126 ~73 ~132 minecraft:deepslate_tiles strict
fill ~128 ~73 ~127 ~129 ~74 ~127 minecraft:stone strict
fill ~131 ~73 ~127 ~131 ~73 ~128 minecraft:deepslate_tiles strict
fill ~123 ~73 ~128 ~123 ~74 ~128 minecraft:deepslate_tiles strict
fill ~125 ~73 ~128 ~125 ~73 ~129 minecraft:deepslate_tiles strict
fill ~127 ~73 ~128 ~127 ~74 ~129 minecraft:stone strict
setblock ~128 ~73 ~128 minecraft:amethyst_block strict
setblock ~129 ~73 ~128 minecraft:andesite strict
fill ~133 ~73 ~128 ~133 ~74 ~128 minecraft:deepslate_tiles strict
setblock ~128 ~73 ~129 minecraft:andesite strict
setblock ~129 ~73 ~129 minecraft:stone strict
setblock ~131 ~73 ~129 minecraft:amethyst_block strict
fill ~134 ~73 ~129 ~134 ~74 ~129 minecraft:deepslate_tiles strict
fill ~124 ~73 ~130 ~124 ~74 ~130 minecraft:deepslate_tiles strict
setblock ~125 ~73 ~130 minecraft:amethyst_block strict
fill ~127 ~73 ~130 ~129 ~73 ~130 minecraft:deepslate_tiles strict
fill ~130 ~73 ~130 ~130 ~75 ~130 minecraft:stone strict
fill ~131 ~73 ~130 ~131 ~74 ~130 minecraft:deepslate_tiles strict
fill ~125 ~73 ~131 ~125 ~74 ~131 minecraft:deepslate_tiles strict
setblock ~128 ~73 ~131 minecraft:amethyst_block strict
fill ~129 ~73 ~131 ~130 ~73 ~132 minecraft:deepslate_tiles strict
fill ~128 ~73 ~132 ~128 ~74 ~133 minecraft:deepslate_tiles strict
fill ~132 ~73 ~132 ~132 ~74 ~132 minecraft:deepslate_tiles strict
fill ~129 ~73 ~134 ~129 ~74 ~134 minecraft:deepslate_tiles strict
fill ~126 ~74 ~121 ~126 ~74 ~125 minecraft:deepslate_tiles strict
fill ~131 ~74 ~121 ~131 ~75 ~121 minecraft:deepslate_tiles strict
fill ~128 ~74 ~122 ~129 ~75 ~122 minecraft:deepslate_tiles strict
setblock ~130 ~74 ~122 minecraft:amethyst_block strict
setblock ~132 ~74 ~122 minecraft:deepslate_tiles strict
fill ~123 ~74 ~123 ~123 ~75 ~123 minecraft:deepslate_tiles strict
fill ~125 ~74 ~123 ~125 ~75 ~124 minecraft:deepslate_tiles strict
fill ~127 ~74 ~123 ~127 ~75 ~123 minecraft:deepslate_tiles strict
fill ~129 ~74 ~123 ~131 ~75 ~123 minecraft:deepslate_tiles strict
setblock ~133 ~74 ~123 minecraft:amethyst_block strict
setblock ~127 ~74 ~124 minecraft:amethyst_block strict
setblock ~129 ~74 ~124 minecraft:stone strict
fill ~130 ~74 ~124 ~132 ~74 ~124 minecraft:deepslate_tiles strict
fill ~134 ~74 ~124 ~134 ~75 ~124 minecraft:deepslate_tiles strict
fill ~123 ~74 ~125 ~124 ~74 ~125 minecraft:deepslate_tiles strict
setblock ~125 ~74 ~125 minecraft:andesite strict
fill ~127 ~74 ~125 ~128 ~75 ~125 minecraft:stone strict
setblock ~129 ~74 ~125 minecraft:andesite strict
setblock ~130 ~74 ~125 minecraft:amethyst_block strict
fill ~132 ~74 ~125 ~133 ~74 ~125 minecraft:deepslate_tiles strict
fill ~135 ~74 ~125 ~135 ~75 ~125 minecraft:deepslate_tiles strict
fill ~121 ~74 ~126 ~123 ~75 ~126 minecraft:deepslate_tiles strict
setblock ~124 ~74 ~126 minecraft:amethyst_block strict
setblock ~125 ~74 ~126 minecraft:deepslate_tiles strict
fill ~127 ~74 ~126 ~127 ~76 ~126 minecraft:stone strict
setblock ~128 ~74 ~126 minecraft:andesite strict
fill ~129 ~74 ~126 ~131 ~74 ~126 minecraft:stone strict
setblock ~132 ~74 ~126 minecraft:deepslate_tiles strict
setblock ~133 ~74 ~126 minecraft:amethyst_block strict
fill ~134 ~74 ~126 ~134 ~75 ~128 minecraft:deepslate_tiles strict
fill ~123 ~74 ~127 ~123 ~75 ~127 minecraft:deepslate_tiles strict
fill ~125 ~74 ~127 ~126 ~75 ~127 minecraft:stone strict
setblock ~127 ~74 ~127 minecraft:amethyst_block strict
fill ~130 ~74 ~127 ~130 ~76 ~127 minecraft:stone strict
setblock ~131 ~74 ~127 minecraft:andesite strict
setblock ~132 ~74 ~127 minecraft:stone strict
fill ~133 ~74 ~127 ~133 ~75 ~127 minecraft:deepslate_tiles strict
fill ~122 ~74 ~128 ~122 ~75 ~130 minecraft:deepslate_tiles strict
fill ~125 ~74 ~128 ~125 ~75 ~128 minecraft:stone strict
setblock ~126 ~74 ~128 minecraft:andesite strict
fill ~128 ~74 ~128 ~129 ~75 ~128 minecraft:stone strict
setblock ~130 ~74 ~128 minecraft:amethyst_block strict
fill ~131 ~74 ~128 ~131 ~74 ~129 minecraft:stone strict
fill ~132 ~74 ~128 ~132 ~74 ~131 minecraft:deepslate_tiles strict
fill ~123 ~74 ~129 ~123 ~74 ~131 minecraft:deepslate_tiles strict
setblock ~124 ~74 ~129 minecraft:amethyst_block strict
setblock ~125 ~74 ~129 minecraft:andesite strict
fill ~126 ~74 ~129 ~126 ~74 ~131 minecraft:stone strict
fill ~128 ~74 ~129 ~128 ~75 ~129 minecraft:stone strict
setblock ~129 ~74 ~129 minecraft:andesite strict
setblock ~130 ~74 ~129 minecraft:stone strict
setblock ~133 ~74 ~129 minecraft:amethyst_block strict
setblock ~125 ~74 ~130 minecraft:stone strict
setblock ~127 ~74 ~130 minecraft:amethyst_block strict
setblock ~128 ~74 ~130 minecraft:andesite strict
fill ~129 ~74 ~130 ~129 ~74 ~131 minecraft:stone strict
fill ~133 ~74 ~130 ~135 ~75 ~130 minecraft:deepslate_tiles strict
setblock ~121 ~74 ~131 minecraft:amethyst_block strict
fill ~124 ~74 ~131 ~124 ~75 ~131 minecraft:deepslate_tiles strict
setblock ~127 ~74 ~131 minecraft:andesite strict
setblock ~128 ~74 ~131 minecraft:stone strict
setblock ~130 ~74 ~131 minecraft:amethyst_block strict
setblock ~131 ~74 ~131 minecraft:andesite strict
fill ~133 ~74 ~131 ~133 ~75 ~131 minecraft:deepslate_tiles strict
fill ~122 ~74 ~132 ~122 ~75 ~132 minecraft:deepslate_tiles strict
setblock ~124 ~74 ~132 minecraft:amethyst_block strict
fill ~125 ~74 ~132 ~126 ~74 ~133 minecraft:deepslate_tiles strict
setblock ~127 ~74 ~132 minecraft:stone strict
fill ~129 ~74 ~132 ~131 ~74 ~133 minecraft:deepslate_tiles strict
fill ~123 ~74 ~133 ~123 ~75 ~133 minecraft:deepslate_tiles strict
setblock ~127 ~74 ~133 minecraft:amethyst_block strict
fill ~133 ~74 ~133 ~133 ~75 ~133 minecraft:deepslate_tiles strict
fill ~124 ~74 ~134 ~124 ~75 ~134 minecraft:deepslate_tiles strict
fill ~126 ~74 ~134 ~128 ~75 ~134 minecraft:deepslate_tiles strict
setblock ~130 ~74 ~134 minecraft:amethyst_block strict
fill ~125 ~74 ~135 ~125 ~75 ~135 minecraft:deepslate_tiles strict
fill ~130 ~74 ~135 ~130 ~75 ~135 minecraft:deepslate_tiles strict
fill ~129 ~75 ~119 ~129 ~76 ~119 minecraft:deepslate_tiles strict
fill ~125 ~75 ~120 ~125 ~75 ~122 minecraft:deepslate_tiles strict
fill ~130 ~75 ~120 ~130 ~75 ~122 minecraft:deepslate_tiles strict
fill ~126 ~75 ~121 ~128 ~75 ~121 minecraft:deepslate_tiles strict
setblock ~129 ~75 ~121 minecraft:amethyst_block strict
fill ~122 ~75 ~122 ~122 ~75 ~125 minecraft:deepslate_tiles strict
setblock ~123 ~75 ~122 minecraft:amethyst_block strict
fill ~124 ~75 ~122 ~124 ~76 ~123 minecraft:deepslate_tiles strict
setblock ~126 ~75 ~122 minecraft:deepslate_tiles strict
fill ~127 ~75 ~122 ~127 ~76 ~122 minecraft:stone strict
fill ~131 ~75 ~122 ~131 ~76 ~122 minecraft:deepslate_tiles strict
setblock ~132 ~75 ~122 minecraft:amethyst_block strict
fill ~133 ~75 ~122 ~133 ~75 ~126 minecraft:deepslate_tiles strict
setblock ~126 ~75 ~123 minecraft:amethyst_block strict
setblock ~128 ~75 ~123 minecraft:andesite strict
fill ~132 ~75 ~123 ~132 ~75 ~124 minecraft:deepslate_tiles strict
fill ~134 ~75 ~123 ~134 ~76 ~123 minecraft:deepslate_tiles strict
fill ~123 ~75 ~124 ~123 ~76 ~124 minecraft:deepslate_tiles strict
setblock ~124 ~75 ~124 minecraft:stone strict
fill ~126 ~75 ~124 ~126 ~77 ~124 minecraft:stone strict
setblock ~127 ~75 ~124 minecraft:andesite strict
setblock ~128 ~75 ~124 minecraft:stone strict
setblock ~129 ~75 ~124 minecraft:amethyst_block strict
fill ~130 ~75 ~124 ~130 ~77 ~124 minecraft:stone strict
setblock ~131 ~75 ~124 minecraft:deepslate_tiles strict
fill ~120 ~75 ~125 ~121 ~76 ~125 minecraft:deepslate_tiles strict
setblock ~123 ~75 ~125 minecraft:amethyst_block strict
setblock ~124 ~75 ~125 minecraft:deepslate_tiles strict
setblock ~125 ~75 ~125 minecraft:stone strict
setblock ~126 ~75 ~125 minecraft:andesite strict
fill ~129 ~75 ~125 ~129 ~77 ~125 minecraft:stone strict
setblock ~130 ~75 ~125 minecraft:andesite strict
fill ~131 ~75 ~125 ~131 ~75 ~127 minecraft:stone strict
setblock ~132 ~75 ~125 minecraft:amethyst_block strict
setblock ~134 ~75 ~125 minecraft:deepslate_tiles strict
fill ~124 ~75 ~126 ~124 ~77 ~126 minecraft:stone strict
setblock ~125 ~75 ~126 minecraft:andesite strict
setblock ~126 ~75 ~126 minecraft:amethyst_block strict
setblock ~128 ~75 ~126 minecraft:stone strict
setblock ~129 ~75 ~126 minecraft:andesite strict
setblock ~130 ~75 ~126 minecraft:stone strict
fill ~132 ~75 ~126 ~132 ~77 ~126 minecraft:stone strict
setblock ~135 ~75 ~126 minecraft:amethyst_block strict
fill ~136 ~75 ~126 ~136 ~76 ~126 minecraft:deepslate_tiles strict
fill ~121 ~75 ~127 ~121 ~75 ~131 minecraft:deepslate_tiles strict
setblock ~122 ~75 ~127 minecraft:stone strict
setblock ~124 ~75 ~127 minecraft:andesite strict
fill ~127 ~75 ~127 ~127 ~77 ~127 minecraft:stone strict
setblock ~128 ~75 ~127 minecraft:andesite strict
setblock ~129 ~75 ~127 minecraft:amethyst_block strict
setblock ~132 ~75 ~127 minecraft:andesite strict
fill ~135 ~75 ~127 ~135 ~76 ~128 minecraft:deepslate_tiles strict
fill ~137 ~75 ~127 ~137 ~76 ~127 minecraft:deepslate_tiles strict
setblock ~123 ~75 ~128 minecraft:amethyst_block strict
fill ~124 ~75 ~128 ~124 ~75 ~130 minecraft:stone strict
fill ~126 ~75 ~128 ~126 ~77 ~128 minecraft:stone strict
setblock ~127 ~75 ~128 minecraft:andesite strict
fill ~130 ~75 ~128 ~130 ~77 ~128 minecraft:stone strict
setblock ~131 ~75 ~128 minecraft:andesite strict
setblock ~132 ~75 ~128 minecraft:amethyst_block strict
fill ~133 ~75 ~128 ~133 ~76 ~128 minecraft:stone strict
setblock ~119 ~75 ~129 minecraft:deepslate_tiles strict
fill ~123 ~75 ~129 ~123 ~75 ~130 minecraft:deepslate_tiles strict
fill ~125 ~75 ~129 ~125 ~77 ~129 minecraft:stone strict
setblock ~126 ~75 ~129 minecraft:amethyst_block strict
fill ~127 ~75 ~129 ~127 ~75 ~131 minecraft:stone strict
fill ~129 ~75 ~129 ~129 ~77 ~129 minecraft:stone strict
setblock ~130 ~75 ~129 minecraft:andesite strict
fill ~131 ~75 ~129 ~132 ~75 ~130 minecraft:stone strict
setblock ~133 ~75 ~129 minecraft:deepslate_tiles strict
setblock ~134 ~75 ~129 minecraft:andesite strict
setblock ~135 ~75 ~129 minecraft:amethyst_block strict
setblock ~120 ~75 ~130 minecraft:amethyst_block strict
setblock ~125 ~75 ~130 minecraft:andesite strict
fill ~126 ~75 ~130 ~126 ~75 ~131 minecraft:stone strict
fill ~128 ~75 ~130 ~128 ~77 ~130 minecraft:stone strict
setblock ~129 ~75 ~130 minecraft:amethyst_block strict
fill ~122 ~75 ~131 ~122 ~76 ~131 minecraft:deepslate_tiles strict
setblock ~123 ~75 ~131 minecraft:amethyst_block strict
setblock ~125 ~75 ~131 minecraft:stone strict
setblock ~128 ~75 ~131 minecraft:andesite strict
fill ~129 ~75 ~131 ~131 ~75 ~131 minecraft:stone strict
setblock ~132 ~75 ~131 minecraft:amethyst_block strict
fill ~134 ~75 ~131 ~136 ~75 ~131 minecraft:deepslate_tiles strict
fill ~123 ~75 ~132 ~125 ~75 ~132 minecraft:deepslate_tiles strict
setblock ~126 ~75 ~132 minecraft:amethyst_block strict
setblock ~127 ~75 ~132 minecraft:andesite strict
fill ~128 ~75 ~132 ~130 ~75 ~132 minecraft:stone strict
fill ~131 ~75 ~132 ~131 ~75 ~136 minecraft:deepslate_tiles strict
setblock ~132 ~75 ~132 minecraft:stone strict
fill ~133 ~75 ~132 ~134 ~76 ~132 minecraft:deepslate_tiles strict
setblock ~122 ~75 ~133 minecraft:deepslate_tiles strict
fill ~124 ~75 ~133 ~127 ~75 ~133 minecraft:deepslate_tiles strict
fill ~128 ~75 ~133 ~128 ~76 ~133 minecraft:stone strict
setblock ~129 ~75 ~133 minecraft:amethyst_block strict
fill ~130 ~75 ~133 ~130 ~75 ~134 minecraft:deepslate_tiles strict
fill ~132 ~75 ~133 ~132 ~76 ~133 minecraft:deepslate_tiles strict
fill ~134 ~75 ~133 ~134 ~75 ~134 minecraft:deepslate_tiles strict
setblock ~123 ~75 ~134 minecraft:amethyst_block strict
setblock ~125 ~75 ~134 minecraft:deepslate_tiles strict
setblock ~129 ~75 ~134 minecraft:andesite strict
setblock ~132 ~75 ~134 minecraft:amethyst_block strict
fill ~133 ~75 ~134 ~133 ~76 ~134 minecraft:deepslate_tiles strict
setblock ~126 ~75 ~135 minecraft:amethyst_block strict
fill ~127 ~75 ~135 ~129 ~75 ~135 minecraft:deepslate_tiles strict
fill ~126 ~75 ~136 ~126 ~76 ~136 minecraft:deepslate_tiles strict
fill ~127 ~75 ~137 ~127 ~76 ~137 minecraft:deepslate_tiles strict
fill ~128 ~76 ~118 ~128 ~77 ~119 minecraft:deepslate_tiles strict
fill ~124 ~76 ~119 ~124 ~76 ~121 minecraft:deepslate_tiles strict
fill ~126 ~76 ~119 ~127 ~76 ~120 minecraft:deepslate_tiles strict
fill ~130 ~76 ~119 ~130 ~76 ~121 minecraft:deepslate_tiles strict
fill ~125 ~76 ~120 ~125 ~76 ~121 minecraft:deepslate_tiles strict
setblock ~128 ~76 ~120 minecraft:amethyst_block strict
fill ~129 ~76 ~120 ~129 ~76 ~121 minecraft:deepslate_tiles strict
fill ~131 ~76 ~120 ~132 ~77 ~120 minecraft:deepslate_tiles strict
fill ~135 ~76 ~120 ~135 ~77 ~120 minecraft:deepslate_tiles strict
fill ~121 ~76 ~121 ~121 ~76 ~124 minecraft:deepslate_tiles strict
setblock ~122 ~76 ~121 minecraft:amethyst_block strict
fill ~123 ~76 ~121 ~123 ~76 ~122 minecraft:deepslate_tiles strict
fill ~126 ~76 ~121 ~126 ~77 ~121 minecraft:stone strict
fill ~127 ~76 ~121 ~128 ~76 ~121 minecraft:deepslate_tiles strict
setblock ~131 ~76 ~121 minecraft:amethyst_block strict
fill ~132 ~76 ~121 ~134 ~76 ~121 minecraft:deepslate_tiles strict
fill ~136 ~76 ~121 ~136 ~77 ~121 minecraft:deepslate_tiles strict
fill ~122 ~76 ~122 ~122 ~76 ~123 minecraft:deepslate_tiles strict
setblock ~125 ~76 ~122 minecraft:amethyst_block strict
setblock ~126 ~76 ~122 minecraft:andesite strict
fill ~128 ~76 ~122 ~129 ~77 ~122 minecraft:stone strict
setblock ~130 ~76 ~122 minecraft:andesite strict
fill ~132 ~76 ~122 ~132 ~77 ~122 minecraft:stone strict
setblock ~133 ~76 ~122 minecraft:deepslate_tiles strict
setblock ~134 ~76 ~122 minecraft:amethyst_block strict
fill ~135 ~76 ~122 ~135 ~77 ~124 minecraft:deepslate_tiles strict
fill ~123 ~76 ~123 ~123 ~77 ~123 minecraft:stone strict
setblock ~125 ~76 ~123 minecraft:andesite strict
fill ~126 ~76 ~123 ~127 ~76 ~123 minecraft:stone strict
setblock ~128 ~76 ~123 minecraft:amethyst_block strict
setblock ~129 ~76 ~123 minecraft:andesite strict
fill ~130 ~76 ~123 ~131 ~76 ~123 minecraft:stone strict
setblock ~132 ~76 ~123 minecraft:deepslate_tiles strict
setblock ~133 ~76 ~123 minecraft:andesite strict
fill ~119 ~76 ~124 ~120 ~77 ~124 minecraft:deepslate_tiles strict
setblock ~122 ~76 ~124 minecraft:amethyst_block strict
setblock ~124 ~76 ~124 minecraft:andesite strict
setblock ~125 ~76 ~124 minecraft:stone strict
fill ~127 ~76 ~124 ~127 ~78 ~124 minecraft:stone strict
setblock ~128 ~76 ~124 minecraft:andesite strict
setblock ~129 ~76 ~124 minecraft:stone strict
setblock ~131 ~76 ~124 minecraft:amethyst_block strict
setblock ~132 ~76 ~124 minecraft:andesite strict
setblock ~133 ~76 ~124 minecraft:deepslate_tiles strict
fill ~134 ~76 ~124 ~134 ~77 ~124 minecraft:stone strict
fill ~136 ~76 ~124 ~136 ~76 ~125 minecraft:deepslate_tiles strict
setblock ~122 ~76 ~125 minecraft:deepslate_tiles strict
setblock ~123 ~76 ~125 minecraft:andesite strict
setblock ~124 ~76 ~125 minecraft:stone strict
setblock ~125 ~76 ~125 minecraft:amethyst_block strict
fill ~126 ~76 ~125 ~126 ~78 ~125 minecraft:stone strict
setblock ~127 ~76 ~125 minecraft:andesite strict
setblock ~128 ~76 ~125 minecraft:stone strict
fill ~130 ~76 ~125 ~130 ~78 ~125 minecraft:stone strict
setblock ~131 ~76 ~125 minecraft:andesite strict
fill ~132 ~76 ~125 ~133 ~76 ~125 minecraft:stone strict
setblock ~134 ~76 ~125 minecraft:amethyst_block strict
setblock ~135 ~76 ~125 minecraft:andesite strict
setblock ~119 ~76 ~126 minecraft:amethyst_block strict
fill ~120 ~76 ~126 ~120 ~76 ~132 minecraft:deepslate_tiles strict
setblock ~121 ~76 ~126 minecraft:stone strict
setblock ~122 ~76 ~126 minecraft:andesite strict
fill ~123 ~76 ~126 ~123 ~76 ~128 minecraft:stone strict
fill ~125 ~76 ~126 ~125 ~78 ~126 minecraft:stone strict
setblock ~126 ~76 ~126 minecraft:andesite strict
setblock ~128 ~76 ~126 minecraft:amethyst_block strict
fill ~129 ~76 ~126 ~129 ~78 ~126 minecraft:stone strict
setblock ~130 ~76 ~126 minecraft:andesite strict
setblock ~131 ~76 ~126 minecraft:stone strict
fill ~133 ~76 ~126 ~133 ~78 ~126 minecraft:stone strict
setblock ~134 ~76 ~126 minecraft:andesite strict
setblock ~135 ~76 ~126 minecraft:deepslate_tiles strict
setblock ~137 ~76 ~126 minecraft:amethyst_block strict
fill ~119 ~76 ~127 ~119 ~77 ~128 minecraft:deepslate_tiles strict
fill ~121 ~76 ~127 ~121 ~76 ~130 minecraft:deepslate_tiles strict
setblock ~122 ~76 ~127 minecraft:amethyst_block strict
setblock ~124 ~76 ~127 minecraft:stone strict
setblock ~125 ~76 ~127 minecraft:andesite strict
setblock ~126 ~76 ~127 minecraft:stone strict
fill ~128 ~76 ~127 ~128 ~78 ~127 minecraft:stone strict
setblock ~129 ~76 ~127 minecraft:andesite strict
setblock ~131 ~76 ~127 minecraft:amethyst_block strict
fill ~132 ~76 ~127 ~132 ~78 ~127 minecraft:stone strict
setblock ~133 ~76 ~127 minecraft:andesite strict
setblock ~134 ~76 ~127 minecraft:stone strict
fill ~136 ~76 ~127 ~136 ~76 ~132 minecraft:deepslate_tiles strict
setblock ~118 ~76 ~128 minecraft:deepslate_tiles strict
fill ~122 ~76 ~128 ~122 ~77 ~129 minecraft:stone strict
setblock ~124 ~76 ~128 minecraft:andesite strict
setblock ~125 ~76 ~128 minecraft:amethyst_block strict
setblock ~127 ~76 ~128 minecraft:stone strict
setblock ~128 ~76 ~128 minecraft:andesite strict
setblock ~129 ~76 ~128 minecraft:stone strict
fill ~131 ~76 ~128 ~131 ~78 ~128 minecraft:stone strict
setblock ~132 ~76 ~128 minecraft:andesite strict
setblock ~134 ~76 ~128 minecraft:amethyst_block strict
fill ~137 ~76 ~128 ~138 ~77 ~128 minecraft:deepslate_tiles strict
setblock ~119 ~76 ~129 minecraft:amethyst_block strict
setblock ~123 ~76 ~129 minecraft:andesite strict
fill ~124 ~76 ~129 ~124 ~76 ~131 minecraft:stone strict
fill ~126 ~76 ~129 ~126 ~78 ~129 minecraft:stone strict
setblock ~127 ~76 ~129 minecraft:andesite strict
setblock ~128 ~76 ~129 minecraft:amethyst_block strict
setblock ~130 ~76 ~129 minecraft:stone strict
setblock ~131 ~76 ~129 minecraft:andesite strict
fill ~132 ~76 ~129 ~134 ~76 ~129 minecraft:stone strict
setblock ~135 ~76 ~129 minecraft:deepslate_tiles strict
setblock ~137 ~76 ~129 minecraft:amethyst_block strict
fill ~119 ~76 ~130 ~119 ~77 ~130 minecraft:deepslate_tiles strict
setblock ~122 ~76 ~130 minecraft:amethyst_block strict
fill ~123 ~76 ~130 ~123 ~76 ~131 minecraft:stone strict
fill ~125 ~76 ~130 ~125 ~78 ~130 minecraft:stone strict
setblock ~126 ~76 ~130 minecraft:andesite strict
fill ~127 ~76 ~130 ~127 ~76 ~132 minecraft:stone strict
fill ~129 ~76 ~130 ~129 ~78 ~130 minecraft:stone strict
setblock ~130 ~76 ~130 minecraft:andesite strict
setblock ~131 ~76 ~130 minecraft:amethyst_block strict
fill ~132 ~76 ~130 ~133 ~76 ~130 minecraft:stone strict
setblock ~134 ~76 ~130 minecraft:andesite strict
setblock ~135 ~76 ~130 minecraft:stone strict
fill ~137 ~76 ~130 ~137 ~77 ~130 minecraft:deepslate_tiles strict
setblock ~121 ~76 ~131 minecraft:andesite strict
setblock ~125 ~76 ~131 minecraft:amethyst_block strict
fill ~126 ~76 ~131 ~126 ~76 ~133 minecraft:stone strict
fill ~128 ~76 ~131 ~128 ~78 ~131 minecraft:stone strict
setblock ~129 ~76 ~131 minecraft:andesite strict
fill ~130 ~76 ~131 ~132 ~76 ~131 minecraft:stone strict
setblock ~133 ~76 ~131 minecraft:andesite strict
setblock ~134 ~76 ~131 minecraft:amethyst_block strict
fill ~135 ~76 ~131 ~135 ~76 ~135 minecraft:deepslate_tiles strict
fill ~121 ~76 ~132 ~121 ~76 ~134 minecraft:deepslate_tiles strict
fill ~122 ~76 ~132 ~122 ~77 ~132 minecraft:stone strict
setblock ~123 ~76 ~132 minecraft:deepslate_tiles strict
setblock ~124 ~76 ~132 minecraft:andesite strict
fill ~125 ~76 ~132 ~125 ~76 ~133 minecraft:stone strict
setblock ~128 ~76 ~132 minecraft:amethyst_block strict
fill ~129 ~76 ~132 ~131 ~76 ~132 minecraft:stone strict
setblock ~132 ~76 ~132 minecraft:andesite strict
setblock ~137 ~76 ~132 minecraft:amethyst_block strict
setblock ~122 ~76 ~133 minecraft:amethyst_block strict
setblock ~123 ~76 ~133 minecraft:andesite strict
