setblock ~122 ~84 ~138 minecraft:quartz_bricks strict
setblock ~123 ~84 ~138 minecraft:smooth_quartz strict
setblock ~124 ~84 ~138 minecraft:quartz_bricks strict
setblock ~125 ~84 ~138 minecraft:smooth_quartz strict
setblock ~131 ~84 ~138 minecraft:smooth_quartz strict
setblock ~132 ~84 ~138 minecraft:quartz_bricks strict
setblock ~133 ~84 ~138 minecraft:smooth_quartz strict
setblock ~134 ~84 ~138 minecraft:quartz_bricks strict
setblock ~135 ~84 ~138 minecraft:smooth_quartz strict
setblock ~136 ~84 ~138 minecraft:quartz_bricks strict
setblock ~137 ~84 ~138 minecraft:smooth_quartz strict
setblock ~138 ~84 ~138 minecraft:quartz_bricks strict
setblock ~139 ~84 ~138 minecraft:smooth_quartz strict
fill ~140 ~84 ~138 ~140 ~84 ~139 minecraft:chiseled_quartz_block strict
setblock ~115 ~84 ~139 minecraft:polished_blackstone_bricks strict
fill ~117 ~84 ~139 ~117 ~84 ~140 minecraft:chiseled_quartz_block strict
setblock ~118 ~84 ~139 minecraft:smooth_quartz strict
setblock ~119 ~84 ~139 minecraft:quartz_bricks strict
setblock ~120 ~84 ~139 minecraft:smooth_quartz strict
setblock ~121 ~84 ~139 minecraft:quartz_bricks strict
setblock ~122 ~84 ~139 minecraft:smooth_quartz strict
setblock ~123 ~84 ~139 minecraft:quartz_bricks strict
setblock ~124 ~84 ~139 minecraft:smooth_quartz strict
setblock ~125 ~84 ~139 minecraft:quartz_bricks strict
setblock ~131 ~84 ~139 minecraft:quartz_bricks strict
setblock ~132 ~84 ~139 minecraft:smooth_quartz strict
setblock ~133 ~84 ~139 minecraft:quartz_bricks strict
setblock ~134 ~84 ~139 minecraft:smooth_quartz strict
setblock ~135 ~84 ~139 minecraft:quartz_bricks strict
setblock ~136 ~84 ~139 minecraft:smooth_quartz strict
setblock ~137 ~84 ~139 minecraft:quartz_bricks strict
setblock ~138 ~84 ~139 minecraft:smooth_quartz strict
fill ~139 ~84 ~139 ~139 ~84 ~140 minecraft:chiseled_quartz_block strict
setblock ~141 ~84 ~139 minecraft:polished_blackstone_bricks strict
setblock ~116 ~84 ~140 minecraft:polished_blackstone_bricks strict
fill ~118 ~84 ~140 ~118 ~84 ~141 minecraft:chiseled_quartz_block strict
setblock ~119 ~84 ~140 minecraft:smooth_quartz strict
setblock ~120 ~84 ~140 minecraft:quartz_bricks strict
setblock ~121 ~84 ~140 minecraft:smooth_quartz strict
setblock ~122 ~84 ~140 minecraft:quartz_bricks strict
setblock ~123 ~84 ~140 minecraft:smooth_quartz strict
setblock ~124 ~84 ~140 minecraft:quartz_bricks strict
setblock ~125 ~84 ~140 minecraft:smooth_quartz strict
fill ~127 ~84 ~140 ~129 ~84 ~140 minecraft:lime_stained_glass strict
setblock ~131 ~84 ~140 minecraft:smooth_quartz strict
setblock ~132 ~84 ~140 minecraft:quartz_bricks strict
setblock ~133 ~84 ~140 minecraft:smooth_quartz strict
setblock ~134 ~84 ~140 minecraft:quartz_bricks strict
setblock ~135 ~84 ~140 minecraft:smooth_quartz strict
setblock ~136 ~84 ~140 minecraft:quartz_bricks strict
setblock ~137 ~84 ~140 minecraft:smooth_quartz strict
fill ~138 ~84 ~140 ~138 ~84 ~141 minecraft:chiseled_quartz_block strict
setblock ~140 ~84 ~140 minecraft:polished_blackstone_bricks strict
setblock ~117 ~84 ~141 minecraft:polished_blackstone_bricks strict
setblock ~119 ~84 ~141 minecraft:chiseled_quartz_block strict
setblock ~120 ~84 ~141 minecraft:smooth_quartz strict
setblock ~121 ~84 ~141 minecraft:quartz_bricks strict
setblock ~122 ~84 ~141 minecraft:smooth_quartz strict
setblock ~123 ~84 ~141 minecraft:quartz_bricks strict
setblock ~124 ~84 ~141 minecraft:smooth_quartz strict
setblock ~125 ~84 ~141 minecraft:quartz_bricks strict
setblock ~126 ~84 ~141 minecraft:smooth_quartz strict
setblock ~127 ~84 ~141 minecraft:quartz_bricks strict
setblock ~128 ~84 ~141 minecraft:smooth_quartz strict
setblock ~129 ~84 ~141 minecraft:quartz_bricks strict
setblock ~130 ~84 ~141 minecraft:smooth_quartz strict
setblock ~131 ~84 ~141 minecraft:quartz_bricks strict
setblock ~132 ~84 ~141 minecraft:smooth_quartz strict
setblock ~133 ~84 ~141 minecraft:quartz_bricks strict
setblock ~134 ~84 ~141 minecraft:smooth_quartz strict
setblock ~135 ~84 ~141 minecraft:quartz_bricks strict
setblock ~136 ~84 ~141 minecraft:smooth_quartz strict
setblock ~137 ~84 ~141 minecraft:chiseled_quartz_block strict
setblock ~139 ~84 ~141 minecraft:polished_blackstone_bricks strict
fill ~118 ~84 ~142 ~119 ~84 ~142 minecraft:polished_blackstone_bricks strict
fill ~120 ~84 ~142 ~121 ~84 ~142 minecraft:chiseled_quartz_block strict
setblock ~122 ~84 ~142 minecraft:quartz_bricks strict
setblock ~123 ~84 ~142 minecraft:smooth_quartz strict
setblock ~124 ~84 ~142 minecraft:quartz_bricks strict
setblock ~125 ~84 ~142 minecraft:smooth_quartz strict
setblock ~126 ~84 ~142 minecraft:quartz_bricks strict
setblock ~127 ~84 ~142 minecraft:smooth_quartz strict
setblock ~128 ~84 ~142 minecraft:quartz_bricks strict
setblock ~129 ~84 ~142 minecraft:smooth_quartz strict
setblock ~130 ~84 ~142 minecraft:quartz_bricks strict
setblock ~131 ~84 ~142 minecraft:smooth_quartz strict
setblock ~132 ~84 ~142 minecraft:quartz_bricks strict
setblock ~133 ~84 ~142 minecraft:smooth_quartz strict
setblock ~134 ~84 ~142 minecraft:quartz_bricks strict
fill ~135 ~84 ~142 ~136 ~84 ~142 minecraft:chiseled_quartz_block strict
fill ~137 ~84 ~142 ~137 ~84 ~143 minecraft:polished_blackstone_bricks strict
setblock ~138 ~84 ~142 minecraft:deepslate_tiles strict
fill ~119 ~84 ~143 ~121 ~84 ~143 minecraft:polished_blackstone_bricks strict
fill ~122 ~84 ~143 ~124 ~84 ~143 minecraft:chiseled_quartz_block strict
setblock ~125 ~84 ~143 minecraft:quartz_bricks strict
setblock ~126 ~84 ~143 minecraft:smooth_quartz strict
setblock ~127 ~84 ~143 minecraft:quartz_bricks strict
setblock ~128 ~84 ~143 minecraft:smooth_quartz strict
setblock ~129 ~84 ~143 minecraft:quartz_bricks strict
setblock ~130 ~84 ~143 minecraft:smooth_quartz strict
setblock ~131 ~84 ~143 minecraft:quartz_bricks strict
fill ~132 ~84 ~143 ~134 ~84 ~143 minecraft:chiseled_quartz_block strict
fill ~135 ~84 ~143 ~136 ~84 ~143 minecraft:polished_blackstone_bricks strict
fill ~121 ~84 ~144 ~123 ~84 ~144 minecraft:polished_blackstone_bricks strict
fill ~124 ~84 ~144 ~132 ~84 ~144 minecraft:chiseled_quartz_block strict
fill ~133 ~84 ~144 ~135 ~84 ~144 minecraft:polished_blackstone_bricks strict
fill ~124 ~84 ~145 ~132 ~84 ~145 minecraft:polished_blackstone_bricks strict
setblock ~124 ~85 ~111 minecraft:polished_blackstone_brick_wall[east=low,north=none,south=none,up=true,waterlogged=false,west=none] strict
fill ~125 ~85 ~111 ~131 ~85 ~111 minecraft:polished_blackstone_brick_wall[east=low,north=none,south=none,up=false,waterlogged=false,west=low] strict
setblock ~132 ~85 ~111 minecraft:polished_blackstone_brick_wall[east=none,north=none,south=none,up=true,waterlogged=false,west=low] strict
setblock ~121 ~85 ~112 minecraft:polished_blackstone_brick_wall[east=low,north=none,south=low,up=true,waterlogged=false,west=none] strict
setblock ~122 ~85 ~112 minecraft:polished_blackstone_brick_wall[east=low,north=none,south=none,up=false,waterlogged=false,west=low] strict
setblock ~123 ~85 ~112 minecraft:polished_blackstone_brick_wall[east=none,north=none,south=none,up=true,waterlogged=false,west=low] strict
setblock ~133 ~85 ~112 minecraft:polished_blackstone_brick_wall[east=low,north=none,south=none,up=true,waterlogged=false,west=none] strict
setblock ~134 ~85 ~112 minecraft:polished_blackstone_brick_wall[east=low,north=none,south=none,up=false,waterlogged=false,west=low] strict
setblock ~135 ~85 ~112 minecraft:polished_blackstone_brick_wall[east=none,north=none,south=low,up=true,waterlogged=false,west=low] strict
setblock ~119 ~85 ~113 minecraft:polished_blackstone_brick_wall[east=low,north=none,south=low,up=true,waterlogged=false,west=none] strict
setblock ~120 ~85 ~113 minecraft:polished_blackstone_brick_wall[east=low,north=none,south=none,up=false,waterlogged=false,west=low] strict
setblock ~121 ~85 ~113 minecraft:polished_blackstone_brick_wall[east=none,north=low,south=none,up=true,waterlogged=false,west=low] strict
setblock ~135 ~85 ~113 minecraft:polished_blackstone_brick_wall[east=low,north=low,south=none,up=true,waterlogged=false,west=none] strict
setblock ~136 ~85 ~113 minecraft:polished_blackstone_brick_wall[east=low,north=none,south=none,up=false,waterlogged=false,west=low] strict
setblock ~137 ~85 ~113 minecraft:polished_blackstone_brick_wall[east=none,north=none,south=low,up=true,waterlogged=false,west=low] strict
setblock ~118 ~85 ~114 minecraft:polished_blackstone_brick_wall[east=low,north=none,south=none,up=true,waterlogged=false,west=none] strict
setblock ~119 ~85 ~114 minecraft:polished_blackstone_brick_wall[east=none,north=low,south=none,up=true,waterlogged=false,west=low] strict
setblock ~137 ~85 ~114 minecraft:polished_blackstone_brick_wall[east=low,north=low,south=none,up=true,waterlogged=false,west=none] strict
setblock ~138 ~85 ~114 minecraft:polished_blackstone_brick_wall[east=none,north=none,south=none,up=true,waterlogged=false,west=low] strict
setblock ~117 ~85 ~115 minecraft:polished_blackstone_brick_wall[east=none,north=none,south=none,up=true,waterlogged=false,west=none] strict
setblock ~123 ~85 ~115 minecraft:chiseled_quartz_block strict
fill ~128 ~85 ~115 ~128 ~87 ~115 minecraft:dark_oak_fence[east=false,north=false,south=false,waterlogged=false,west=false] strict
setblock ~133 ~85 ~115 minecraft:chiseled_quartz_block strict
setblock ~139 ~85 ~115 minecraft:polished_blackstone_brick_wall[east=none,north=none,south=none,up=true,waterlogged=false,west=none] strict
setblock ~116 ~85 ~116 minecraft:polished_blackstone_brick_wall[east=none,north=none,south=none,up=true,waterlogged=false,west=none] strict
setblock ~140 ~85 ~116 minecraft:polished_blackstone_brick_wall[east=none,north=none,south=none,up=true,waterlogged=false,west=none] strict
setblock ~115 ~85 ~117 minecraft:polished_blackstone_brick_wall[east=none,north=none,south=none,up=true,waterlogged=false,west=none] strict
setblock ~141 ~85 ~117 minecraft:polished_blackstone_brick_wall[east=none,north=none,south=none,up=true,waterlogged=false,west=none] strict
setblock ~114 ~85 ~118 minecraft:polished_blackstone_brick_wall[east=none,north=none,south=low,up=true,waterlogged=false,west=none] strict
setblock ~142 ~85 ~118 minecraft:polished_blackstone_brick_wall[east=none,north=none,south=low,up=true,waterlogged=false,west=none] strict
setblock ~113 ~85 ~119 minecraft:polished_blackstone_brick_wall[east=low,north=none,south=low,up=true,waterlogged=false,west=none] strict
setblock ~114 ~85 ~119 minecraft:polished_blackstone_brick_wall[east=none,north=low,south=none,up=true,waterlogged=false,west=low] strict
setblock ~142 ~85 ~119 minecraft:polished_blackstone_brick_wall[east=low,north=low,south=none,up=true,waterlogged=false,west=none] strict
setblock ~143 ~85 ~119 minecraft:polished_blackstone_brick_wall[east=none,north=none,south=low,up=true,waterlogged=false,west=low] strict
setblock ~113 ~85 ~120 minecraft:polished_blackstone_brick_wall[east=none,north=low,south=low,up=false,waterlogged=false,west=none] strict
setblock ~143 ~85 ~120 minecraft:polished_blackstone_brick_wall[east=none,north=low,south=low,up=false,waterlogged=false,west=none] strict
setblock ~112 ~85 ~121 minecraft:polished_blackstone_brick_wall[east=low,north=none,south=low,up=true,waterlogged=false,west=none] strict
setblock ~113 ~85 ~121 minecraft:polished_blackstone_brick_wall[east=none,north=low,south=none,up=true,waterlogged=false,west=low] strict
setblock ~143 ~85 ~121 minecraft:polished_blackstone_brick_wall[east=low,north=low,south=none,up=true,waterlogged=false,west=none] strict
setblock ~144 ~85 ~121 minecraft:polished_blackstone_brick_wall[east=none,north=none,south=low,up=true,waterlogged=false,west=low] strict
setblock ~112 ~85 ~122 minecraft:polished_blackstone_brick_wall[east=none,north=low,south=low,up=false,waterlogged=false,west=none] strict
setblock ~144 ~85 ~122 minecraft:polished_blackstone_brick_wall[east=none,north=low,south=low,up=false,waterlogged=false,west=none] strict
setblock ~112 ~85 ~123 minecraft:polished_blackstone_brick_wall[east=none,north=low,south=none,up=true,waterlogged=false,west=none] strict
setblock ~115 ~85 ~123 minecraft:chiseled_quartz_block strict
setblock ~141 ~85 ~123 minecraft:chiseled_quartz_block strict
setblock ~144 ~85 ~123 minecraft:polished_blackstone_brick_wall[east=none,north=low,south=none,up=true,waterlogged=false,west=none] strict
setblock ~111 ~85 ~124 minecraft:polished_blackstone_brick_wall[east=none,north=none,south=low,up=true,waterlogged=false,west=none] strict
setblock ~145 ~85 ~124 minecraft:polished_blackstone_brick_wall[east=none,north=none,south=low,up=true,waterlogged=false,west=none] strict
fill ~111 ~85 ~125 ~111 ~85 ~131 minecraft:polished_blackstone_brick_wall[east=none,north=low,south=low,up=false,waterlogged=false,west=none] strict
fill ~145 ~85 ~125 ~145 ~85 ~131 minecraft:polished_blackstone_brick_wall[east=none,north=low,south=low,up=false,waterlogged=false,west=none] strict
setblock ~128 ~85 ~127 minecraft:polished_blackstone_brick_wall[east=none,north=none,south=low,up=true,waterlogged=false,west=none] strict
fill ~115 ~85 ~128 ~115 ~87 ~128 minecraft:dark_oak_fence[east=false,north=false,south=false,waterlogged=false,west=false] strict
setblock ~127 ~85 ~128 minecraft:polished_blackstone_brick_wall[east=low,north=none,south=none,up=true,waterlogged=false,west=none] strict
setblock ~128 ~85 ~128 minecraft:sea_lantern strict
setblock ~129 ~85 ~128 minecraft:polished_blackstone_brick_wall[east=none,north=none,south=none,up=true,waterlogged=false,west=low] strict
fill ~141 ~85 ~128 ~141 ~87 ~128 minecraft:dark_oak_fence[east=false,north=false,south=false,waterlogged=false,west=false] strict
setblock ~128 ~85 ~129 minecraft:polished_blackstone_brick_wall[east=none,north=low,south=none,up=true,waterlogged=false,west=none] strict
setblock ~111 ~85 ~132 minecraft:polished_blackstone_brick_wall[east=none,north=low,south=none,up=true,waterlogged=false,west=none] strict
setblock ~145 ~85 ~132 minecraft:polished_blackstone_brick_wall[east=none,north=low,south=none,up=true,waterlogged=false,west=none] strict
setblock ~112 ~85 ~133 minecraft:polished_blackstone_brick_wall[east=none,north=none,south=low,up=true,waterlogged=false,west=none] strict
setblock ~115 ~85 ~133 minecraft:chiseled_quartz_block strict
setblock ~141 ~85 ~133 minecraft:chiseled_quartz_block strict
setblock ~144 ~85 ~133 minecraft:polished_blackstone_brick_wall[east=none,north=none,south=low,up=true,waterlogged=false,west=none] strict
setblock ~112 ~85 ~134 minecraft:polished_blackstone_brick_wall[east=none,north=low,south=low,up=false,waterlogged=false,west=none] strict
setblock ~144 ~85 ~134 minecraft:polished_blackstone_brick_wall[east=none,north=low,south=low,up=false,waterlogged=false,west=none] strict
setblock ~112 ~85 ~135 minecraft:polished_blackstone_brick_wall[east=low,north=low,south=none,up=true,waterlogged=false,west=none] strict
setblock ~113 ~85 ~135 minecraft:polished_blackstone_brick_wall[east=none,north=none,south=low,up=true,waterlogged=false,west=low] strict
setblock ~143 ~85 ~135 minecraft:polished_blackstone_brick_wall[east=low,north=none,south=low,up=true,waterlogged=false,west=none] strict
setblock ~144 ~85 ~135 minecraft:polished_blackstone_brick_wall[east=none,north=low,south=none,up=true,waterlogged=false,west=low] strict
setblock ~113 ~85 ~136 minecraft:polished_blackstone_brick_wall[east=none,north=low,south=low,up=false,waterlogged=false,west=none] strict
setblock ~143 ~85 ~136 minecraft:polished_blackstone_brick_wall[east=none,north=low,south=low,up=false,waterlogged=false,west=none] strict
setblock ~113 ~85 ~137 minecraft:polished_blackstone_brick_wall[east=low,north=low,south=none,up=true,waterlogged=false,west=none] strict
setblock ~114 ~85 ~137 minecraft:polished_blackstone_brick_wall[east=none,north=none,south=low,up=true,waterlogged=false,west=low] strict
setblock ~142 ~85 ~137 minecraft:polished_blackstone_brick_wall[east=low,north=none,south=low,up=true,waterlogged=false,west=none] strict
setblock ~143 ~85 ~137 minecraft:polished_blackstone_brick_wall[east=none,north=low,south=none,up=true,waterlogged=false,west=low] strict
setblock ~114 ~85 ~138 minecraft:polished_blackstone_brick_wall[east=none,north=low,south=none,up=true,waterlogged=false,west=none] strict
setblock ~142 ~85 ~138 minecraft:polished_blackstone_brick_wall[east=none,north=low,south=none,up=true,waterlogged=false,west=none] strict
setblock ~115 ~85 ~139 minecraft:polished_blackstone_brick_wall[east=none,north=none,south=none,up=true,waterlogged=false,west=none] strict
setblock ~141 ~85 ~139 minecraft:polished_blackstone_brick_wall[east=none,north=none,south=none,up=true,waterlogged=false,west=none] strict
setblock ~116 ~85 ~140 minecraft:polished_blackstone_brick_wall[east=none,north=none,south=none,up=true,waterlogged=false,west=none] strict
setblock ~140 ~85 ~140 minecraft:polished_blackstone_brick_wall[east=none,north=none,south=none,up=true,waterlogged=false,west=none] strict
setblock ~117 ~85 ~141 minecraft:polished_blackstone_brick_wall[east=none,north=none,south=none,up=true,waterlogged=false,west=none] strict
setblock ~123 ~85 ~141 minecraft:chiseled_quartz_block strict
fill ~128 ~85 ~141 ~128 ~87 ~141 minecraft:dark_oak_fence[east=false,north=false,south=false,waterlogged=false,west=false] strict
setblock ~133 ~85 ~141 minecraft:chiseled_quartz_block strict
setblock ~139 ~85 ~141 minecraft:polished_blackstone_brick_wall[east=none,north=none,south=none,up=true,waterlogged=false,west=none] strict
setblock ~118 ~85 ~142 minecraft:polished_blackstone_brick_wall[east=low,north=none,south=none,up=true,waterlogged=false,west=none] strict
setblock ~119 ~85 ~142 minecraft:polished_blackstone_brick_wall[east=none,north=none,south=low,up=true,waterlogged=false,west=low] strict
setblock ~137 ~85 ~142 minecraft:polished_blackstone_brick_wall[east=low,north=none,south=low,up=true,waterlogged=false,west=none] strict
setblock ~138 ~85 ~142 minecraft:polished_blackstone_brick_wall[east=none,north=none,south=none,up=true,waterlogged=false,west=low] strict
setblock ~119 ~85 ~143 minecraft:polished_blackstone_brick_wall[east=low,north=low,south=none,up=true,waterlogged=false,west=none] strict
setblock ~120 ~85 ~143 minecraft:polished_blackstone_brick_wall[east=low,north=none,south=none,up=false,waterlogged=false,west=low] strict
setblock ~121 ~85 ~143 minecraft:polished_blackstone_brick_wall[east=none,north=none,south=low,up=true,waterlogged=false,west=low] strict
setblock ~135 ~85 ~143 minecraft:polished_blackstone_brick_wall[east=low,north=none,south=low,up=true,waterlogged=false,west=none] strict
setblock ~136 ~85 ~143 minecraft:polished_blackstone_brick_wall[east=low,north=none,south=none,up=false,waterlogged=false,west=low] strict
setblock ~137 ~85 ~143 minecraft:polished_blackstone_brick_wall[east=none,north=low,south=none,up=true,waterlogged=false,west=low] strict
setblock ~121 ~85 ~144 minecraft:polished_blackstone_brick_wall[east=low,north=low,south=none,up=true,waterlogged=false,west=none] strict
setblock ~122 ~85 ~144 minecraft:polished_blackstone_brick_wall[east=low,north=none,south=none,up=false,waterlogged=false,west=low] strict
setblock ~123 ~85 ~144 minecraft:polished_blackstone_brick_wall[east=none,north=none,south=none,up=true,waterlogged=false,west=low] strict
setblock ~133 ~85 ~144 minecraft:polished_blackstone_brick_wall[east=low,north=none,south=none,up=true,waterlogged=false,west=none] strict
setblock ~134 ~85 ~144 minecraft:polished_blackstone_brick_wall[east=low,north=none,south=none,up=false,waterlogged=false,west=low] strict
setblock ~135 ~85 ~144 minecraft:polished_blackstone_brick_wall[east=none,north=low,south=none,up=true,waterlogged=false,west=low] strict
setblock ~124 ~85 ~145 minecraft:polished_blackstone_brick_wall[east=low,north=none,south=none,up=true,waterlogged=false,west=none] strict
fill ~125 ~85 ~145 ~131 ~85 ~145 minecraft:polished_blackstone_brick_wall[east=low,north=none,south=none,up=false,waterlogged=false,west=low] strict
setblock ~132 ~85 ~145 minecraft:polished_blackstone_brick_wall[east=none,north=none,south=none,up=true,waterlogged=false,west=low] strict
fill ~123 ~86 ~115 ~123 ~90 ~115 minecraft:quartz_pillar[axis=y] strict
fill ~133 ~86 ~115 ~133 ~90 ~115 minecraft:quartz_pillar[axis=y] strict
fill ~115 ~86 ~123 ~115 ~90 ~123 minecraft:quartz_pillar[axis=y] strict
fill ~141 ~86 ~123 ~141 ~90 ~123 minecraft:quartz_pillar[axis=y] strict
fill ~115 ~86 ~133 ~115 ~90 ~133 minecraft:quartz_pillar[axis=y] strict
fill ~141 ~86 ~133 ~141 ~90 ~133 minecraft:quartz_pillar[axis=y] strict
fill ~123 ~86 ~141 ~123 ~90 ~141 minecraft:quartz_pillar[axis=y] strict
fill ~133 ~86 ~141 ~133 ~90 ~141 minecraft:quartz_pillar[axis=y] strict
fill ~128 ~88 ~115 ~128 ~89 ~115 minecraft:dark_oak_fence[east=true,north=false,south=false,waterlogged=false,west=false] strict
fill ~129 ~88 ~115 ~129 ~89 ~115 minecraft:red_wool strict
fill ~115 ~88 ~127 ~115 ~89 ~127 minecraft:yellow_wool strict
fill ~115 ~88 ~128 ~115 ~89 ~128 minecraft:dark_oak_fence[east=false,north=true,south=false,waterlogged=false,west=false] strict
fill ~141 ~88 ~128 ~141 ~89 ~128 minecraft:dark_oak_fence[east=false,north=false,south=true,waterlogged=false,west=false] strict
fill ~141 ~88 ~129 ~141 ~89 ~129 minecraft:blue_wool strict
fill ~127 ~88 ~141 ~127 ~89 ~141 minecraft:lime_wool strict
fill ~128 ~88 ~141 ~128 ~89 ~141 minecraft:dark_oak_fence[east=false,north=false,south=false,waterlogged=false,west=true] strict
setblock ~130 ~89 ~115 minecraft:red_wool strict
setblock ~115 ~89 ~126 minecraft:yellow_wool strict
setblock ~141 ~89 ~130 minecraft:blue_wool strict
setblock ~126 ~89 ~141 minecraft:lime_wool strict
setblock ~128 ~90 ~115 minecraft:gold_block strict
setblock ~115 ~90 ~128 minecraft:gold_block strict
setblock ~141 ~90 ~128 minecraft:gold_block strict
setblock ~128 ~90 ~141 minecraft:gold_block strict
setblock ~123 ~91 ~115 minecraft:chiseled_quartz_block strict
setblock ~133 ~91 ~115 minecraft:chiseled_quartz_block strict
setblock ~115 ~91 ~123 minecraft:chiseled_quartz_block strict
setblock ~141 ~91 ~123 minecraft:chiseled_quartz_block strict
setblock ~115 ~91 ~133 minecraft:chiseled_quartz_block strict
setblock ~141 ~91 ~133 minecraft:chiseled_quartz_block strict
setblock ~123 ~91 ~141 minecraft:chiseled_quartz_block strict
setblock ~133 ~91 ~141 minecraft:chiseled_quartz_block strict
setblock ~123 ~92 ~115 minecraft:gold_block strict
setblock ~133 ~92 ~115 minecraft:gold_block strict
setblock ~115 ~92 ~123 minecraft:gold_block strict
setblock ~141 ~92 ~123 minecraft:gold_block strict
setblock ~115 ~92 ~133 minecraft:gold_block strict
setblock ~141 ~92 ~133 minecraft:gold_block strict
setblock ~123 ~92 ~141 minecraft:gold_block strict
setblock ~133 ~92 ~141 minecraft:gold_block strict
fill ~98 ~21 ~162 ~98 ~21 ~163 minecraft:stone_brick_slab[type=bottom,waterlogged=false] strict
setblock ~96 ~21 ~163 minecraft:stone_brick_slab[type=bottom,waterlogged=false] strict
setblock ~28 ~21 ~208 minecraft:stone_slab[type=bottom,waterlogged=false] strict
setblock ~20 ~21 ~224 minecraft:stone_slab[type=bottom,waterlogged=false] strict
setblock ~49 ~21 ~229 minecraft:stone_slab[type=bottom,waterlogged=false] strict
setblock ~32 ~21 ~237 minecraft:stone_slab[type=bottom,waterlogged=false] strict
fill ~77 ~22 ~52 ~77 ~22 ~53 minecraft:short_grass strict
setblock ~78 ~22 ~53 minecraft:lily_of_the_valley strict
setblock ~79 ~22 ~53 minecraft:short_grass strict
setblock ~80 ~22 ~54 minecraft:fern strict
setblock ~82 ~22 ~54 minecraft:short_grass strict
fill ~74 ~22 ~55 ~78 ~22 ~57 minecraft:wheat[age=7] strict
setblock ~80 ~22 ~56 minecraft:short_grass strict
fill ~73 ~22 ~59 ~73 ~22 ~60 minecraft:short_grass strict
fill ~75 ~22 ~60 ~75 ~22 ~61 minecraft:short_grass strict
setblock ~76 ~22 ~60 minecraft:lily_of_the_valley strict
fill ~77 ~22 ~60 ~78 ~22 ~60 minecraft:short_grass strict
setblock ~86 ~22 ~60 minecraft:lily_of_the_valley strict
fill ~64 ~22 ~61 ~65 ~22 ~61 minecraft:short_grass strict
setblock ~67 ~22 ~61 minecraft:short_grass strict
fill ~69 ~22 ~61 ~70 ~22 ~61 minecraft:short_grass strict
setblock ~72 ~22 ~61 minecraft:dandelion strict
setblock ~74 ~22 ~61 minecraft:short_grass strict
setblock ~78 ~22 ~61 minecraft:short_grass strict
setblock ~64 ~22 ~62 minecraft:short_grass strict
setblock ~83 ~22 ~62 minecraft:azure_bluet strict
setblock ~85 ~22 ~62 minecraft:short_grass strict
fill ~51 ~22 ~63 ~52 ~22 ~63 minecraft:short_grass strict
setblock ~53 ~22 ~63 minecraft:cornflower strict
setblock ~54 ~22 ~63 minecraft:short_grass strict
setblock ~76 ~22 ~63 minecraft:short_grass strict
setblock ~78 ~22 ~63 minecraft:short_grass strict
setblock ~79 ~22 ~63 minecraft:red_tulip strict
setblock ~80 ~22 ~63 minecraft:short_grass strict
setblock ~83 ~22 ~63 minecraft:fern strict
setblock ~85 ~22 ~63 minecraft:oxeye_daisy strict
fill ~50 ~22 ~64 ~50 ~22 ~65 minecraft:short_grass strict
setblock ~52 ~22 ~64 minecraft:short_grass strict
fill ~56 ~22 ~64 ~56 ~22 ~65 minecraft:short_grass strict
fill ~59 ~22 ~64 ~60 ~22 ~64 minecraft:short_grass strict
setblock ~61 ~22 ~64 minecraft:allium strict
setblock ~75 ~22 ~64 minecraft:allium strict
setblock ~76 ~22 ~64 minecraft:cornflower strict
setblock ~79 ~22 ~64 minecraft:oxeye_daisy strict
fill ~81 ~22 ~64 ~82 ~22 ~64 minecraft:short_grass strict
setblock ~85 ~22 ~64 minecraft:short_grass strict
setblock ~51 ~22 ~65 minecraft:short_grass strict
fill ~53 ~22 ~65 ~53 ~22 ~68 minecraft:short_grass strict
fill ~57 ~22 ~65 ~58 ~22 ~66 minecraft:short_grass strict
setblock ~74 ~22 ~65 minecraft:fern strict
fill ~75 ~22 ~65 ~77 ~22 ~65 minecraft:short_grass strict
setblock ~81 ~22 ~65 minecraft:short_grass strict
setblock ~82 ~22 ~65 minecraft:azure_bluet strict
fill ~83 ~22 ~65 ~83 ~22 ~69 minecraft:short_grass strict
setblock ~84 ~22 ~65 minecraft:oxeye_daisy strict
setblock ~85 ~22 ~65 minecraft:azure_bluet strict
setblock ~50 ~22 ~66 minecraft:fern strict
setblock ~51 ~22 ~66 minecraft:bush strict
setblock ~52 ~22 ~66 minecraft:oxeye_daisy strict
fill ~61 ~22 ~66 ~61 ~22 ~67 minecraft:short_grass strict
setblock ~75 ~22 ~66 minecraft:oxeye_daisy strict
fill ~77 ~22 ~66 ~78 ~22 ~66 minecraft:short_grass strict
setblock ~79 ~22 ~66 minecraft:oxeye_daisy strict
setblock ~82 ~22 ~66 minecraft:short_grass strict
fill ~87 ~22 ~66 ~87 ~22 ~67 minecraft:fern strict
setblock ~50 ~22 ~67 minecraft:short_grass strict
setblock ~52 ~22 ~67 minecraft:short_grass strict
setblock ~54 ~22 ~67 minecraft:short_grass strict
fill ~57 ~22 ~67 ~57 ~22 ~68 minecraft:short_grass strict
fill ~59 ~22 ~67 ~60 ~22 ~67 minecraft:short_grass strict
setblock ~75 ~22 ~67 minecraft:cornflower strict
setblock ~76 ~22 ~67 minecraft:allium strict
setblock ~77 ~22 ~67 minecraft:fern strict
fill ~78 ~22 ~67 ~79 ~22 ~67 minecraft:lily_of_the_valley strict
setblock ~80 ~22 ~67 minecraft:oxeye_daisy strict
setblock ~82 ~22 ~67 minecraft:cornflower strict
setblock ~85 ~22 ~67 minecraft:short_grass strict
setblock ~51 ~22 ~68 minecraft:short_grass strict
fill ~55 ~22 ~68 ~56 ~22 ~68 minecraft:short_grass strict
fill ~76 ~22 ~68 ~77 ~22 ~68 minecraft:short_grass strict
setblock ~87 ~22 ~68 minecraft:bush strict
setblock ~50 ~22 ~69 minecraft:short_grass strict
setblock ~52 ~22 ~69 minecraft:short_grass strict
setblock ~56 ~22 ~69 minecraft:short_grass strict
setblock ~76 ~22 ~69 minecraft:short_grass strict
setblock ~82 ~22 ~69 minecraft:short_grass strict
setblock ~50 ~22 ~70 minecraft:dandelion strict
fill ~53 ~22 ~70 ~53 ~22 ~71 minecraft:short_grass strict
setblock ~54 ~22 ~70 minecraft:dandelion strict
setblock ~77 ~22 ~70 minecraft:allium strict
setblock ~79 ~22 ~70 minecraft:short_grass strict
setblock ~83 ~22 ~70 minecraft:dandelion strict
fill ~50 ~22 ~71 ~52 ~22 ~71 minecraft:short_grass strict
fill ~54 ~22 ~71 ~54 ~22 ~72 minecraft:short_grass strict
fill ~74 ~22 ~71 ~74 ~22 ~72 minecraft:short_grass strict
setblock ~76 ~22 ~71 minecraft:cornflower strict
setblock ~77 ~22 ~71 minecraft:dandelion strict
fill ~78 ~22 ~71 ~78 ~22 ~72 minecraft:short_grass strict
