setblock ~67 ~51 ~253 minecraft:grass_block strict
setblock ~69 ~51 ~253 minecraft:stone strict
fill ~71 ~51 ~253 ~71 ~51 ~254 minecraft:stone strict
setblock ~72 ~51 ~253 minecraft:andesite strict
setblock ~73 ~51 ~253 minecraft:stone strict
fill ~74 ~51 ~253 ~76 ~51 ~253 minecraft:grass_block strict
fill ~77 ~51 ~253 ~78 ~51 ~253 minecraft:stone strict
setblock ~79 ~51 ~253 minecraft:coarse_dirt strict
setblock ~80 ~51 ~253 minecraft:grass_block strict
fill ~81 ~51 ~253 ~81 ~51 ~254 minecraft:stone strict
setblock ~140 ~51 ~253 minecraft:andesite strict
fill ~141 ~51 ~253 ~141 ~51 ~254 minecraft:grass_block strict
setblock ~146 ~51 ~253 minecraft:andesite strict
fill ~147 ~51 ~253 ~149 ~53 ~253 minecraft:dirt strict
fill ~153 ~51 ~253 ~154 ~51 ~253 minecraft:andesite strict
setblock ~155 ~51 ~253 minecraft:coarse_dirt strict
setblock ~229 ~51 ~253 minecraft:gravel strict
fill ~230 ~51 ~253 ~230 ~51 ~254 minecraft:grass_block strict
setblock ~231 ~51 ~253 minecraft:stone strict
setblock ~232 ~51 ~253 minecraft:andesite strict
fill ~233 ~51 ~253 ~233 ~51 ~254 minecraft:stone strict
setblock ~16 ~51 ~254 minecraft:gravel strict
setblock ~17 ~51 ~254 minecraft:coarse_dirt strict
fill ~18 ~51 ~254 ~18 ~51 ~255 minecraft:stone strict
setblock ~19 ~51 ~254 minecraft:andesite strict
fill ~20 ~51 ~254 ~20 ~51 ~255 minecraft:stone strict
setblock ~21 ~51 ~254 minecraft:andesite strict
setblock ~66 ~51 ~254 minecraft:grass_block strict
fill ~72 ~51 ~254 ~72 ~52 ~254 minecraft:stone strict
fill ~76 ~51 ~254 ~76 ~52 ~254 minecraft:stone strict
fill ~79 ~51 ~254 ~79 ~52 ~254 minecraft:stone strict
setblock ~82 ~51 ~254 minecraft:grass_block strict
setblock ~140 ~51 ~254 minecraft:grass_block strict
fill ~143 ~51 ~254 ~145 ~51 ~254 minecraft:andesite strict
fill ~146 ~51 ~254 ~147 ~53 ~254 minecraft:dirt strict
setblock ~148 ~51 ~254 minecraft:andesite strict
fill ~149 ~51 ~254 ~151 ~53 ~254 minecraft:dirt strict
fill ~154 ~51 ~254 ~154 ~51 ~255 minecraft:andesite strict
setblock ~156 ~51 ~254 minecraft:grass_block strict
fill ~228 ~51 ~254 ~229 ~51 ~254 minecraft:grass_block strict
fill ~231 ~51 ~254 ~232 ~51 ~255 minecraft:grass_block strict
fill ~234 ~51 ~254 ~235 ~51 ~254 minecraft:grass_block strict
setblock ~17 ~51 ~255 minecraft:stone strict
setblock ~19 ~51 ~255 minecraft:coarse_dirt strict
setblock ~66 ~51 ~255 minecraft:coarse_dirt strict
fill ~74 ~51 ~255 ~75 ~52 ~255 minecraft:stone strict
fill ~78 ~51 ~255 ~78 ~52 ~255 minecraft:stone strict
setblock ~82 ~51 ~255 minecraft:coarse_dirt strict
setblock ~83 ~51 ~255 minecraft:stone strict
setblock ~141 ~51 ~255 minecraft:coarse_dirt strict
setblock ~142 ~51 ~255 minecraft:grass_block strict
setblock ~146 ~51 ~255 minecraft:andesite strict
fill ~147 ~51 ~255 ~148 ~53 ~255 minecraft:dirt strict
fill ~149 ~51 ~255 ~153 ~51 ~255 minecraft:andesite strict
setblock ~155 ~51 ~255 minecraft:grass_block strict
setblock ~156 ~51 ~255 minecraft:coarse_dirt strict
fill ~154 ~52 ~0 ~158 ~52 ~1 minecraft:grass_block strict
fill ~207 ~52 ~0 ~209 ~52 ~0 minecraft:stone strict
fill ~211 ~52 ~0 ~215 ~52 ~1 minecraft:stone strict
fill ~153 ~52 ~1 ~153 ~52 ~2 minecraft:grass_block strict
fill ~206 ~52 ~1 ~208 ~52 ~1 minecraft:grass_block strict
fill ~209 ~52 ~1 ~209 ~53 ~1 minecraft:stone strict
fill ~154 ~52 ~2 ~157 ~52 ~2 minecraft:grass_block strict
setblock ~158 ~52 ~2 minecraft:stone strict
setblock ~206 ~52 ~2 minecraft:stone strict
fill ~207 ~52 ~2 ~208 ~52 ~2 minecraft:grass_block strict
fill ~210 ~52 ~2 ~210 ~52 ~3 minecraft:stone strict
fill ~212 ~52 ~2 ~212 ~53 ~3 minecraft:stone strict
fill ~214 ~52 ~2 ~215 ~52 ~2 minecraft:stone strict
setblock ~208 ~52 ~3 minecraft:stone strict
setblock ~209 ~52 ~3 minecraft:grass_block strict
fill ~211 ~52 ~3 ~211 ~53 ~3 minecraft:stone strict
setblock ~213 ~52 ~3 minecraft:stone strict
setblock ~214 ~52 ~3 minecraft:grass_block strict
setblock ~215 ~52 ~3 minecraft:stone strict
fill ~116 ~52 ~112 ~117 ~52 ~112 minecraft:quartz_stairs[facing=east,half=bottom,shape=straight,waterlogged=false] strict
fill ~118 ~52 ~112 ~138 ~52 ~112 minecraft:quartz_bricks strict
fill ~139 ~52 ~112 ~140 ~52 ~112 minecraft:quartz_stairs[facing=west,half=bottom,shape=straight,waterlogged=false] strict
fill ~116 ~52 ~113 ~117 ~52 ~115 minecraft:weathered_cut_copper_stairs[facing=east,half=bottom,shape=straight,waterlogged=false] strict
fill ~118 ~52 ~113 ~119 ~52 ~114 minecraft:weathered_cut_copper strict
fill ~137 ~52 ~113 ~138 ~52 ~113 minecraft:weathered_cut_copper strict
fill ~139 ~52 ~113 ~140 ~52 ~113 minecraft:weathered_cut_copper_stairs[facing=west,half=bottom,shape=straight,waterlogged=false] strict
fill ~137 ~52 ~114 ~137 ~52 ~116 minecraft:weathered_cut_copper strict
setblock ~140 ~52 ~114 minecraft:weathered_cut_copper_stairs[facing=west,half=bottom,shape=straight,waterlogged=false] strict
fill ~118 ~52 ~115 ~118 ~52 ~116 minecraft:weathered_cut_copper strict
setblock ~138 ~52 ~115 minecraft:weathered_cut_copper strict
setblock ~139 ~52 ~115 minecraft:weathered_cut_copper_stairs[facing=west,half=bottom,shape=straight,waterlogged=false] strict
setblock ~116 ~52 ~116 minecraft:weathered_cut_copper_stairs[facing=east,half=bottom,shape=straight,waterlogged=false] strict
fill ~140 ~52 ~116 ~140 ~52 ~117 minecraft:weathered_cut_copper_stairs[facing=west,half=bottom,shape=straight,waterlogged=false] strict
setblock ~119 ~52 ~117 minecraft:weathered_cut_copper strict
setblock ~139 ~52 ~117 minecraft:weathered_cut_copper_stairs[facing=west,half=bottom,shape=straight,waterlogged=false] strict
setblock ~116 ~52 ~118 minecraft:weathered_cut_copper_stairs[facing=east,half=bottom,shape=straight,waterlogged=false] strict
fill ~137 ~52 ~118 ~138 ~52 ~118 minecraft:weathered_cut_copper strict
setblock ~255 ~52 ~125 minecraft:stone strict
fill ~255 ~52 ~126 ~255 ~52 ~132 minecraft:cobblestone strict
fill ~255 ~52 ~133 ~255 ~53 ~133 minecraft:stone strict
fill ~254 ~52 ~134 ~254 ~52 ~137 minecraft:stone strict
fill ~255 ~52 ~137 ~255 ~52 ~139 minecraft:grass_block strict
fill ~254 ~52 ~138 ~254 ~52 ~139 minecraft:grass_block strict
fill ~116 ~52 ~141 ~117 ~52 ~143 minecraft:weathered_cut_copper_stairs[facing=east,half=bottom,shape=straight,waterlogged=false] strict
fill ~131 ~52 ~141 ~131 ~52 ~143 minecraft:weathered_cut_copper strict
fill ~119 ~52 ~142 ~119 ~52 ~143 minecraft:weathered_cut_copper strict
fill ~134 ~52 ~142 ~134 ~52 ~143 minecraft:weathered_cut_copper_stairs[facing=west,half=bottom,shape=straight,waterlogged=false] strict
setblock ~118 ~52 ~143 minecraft:weathered_cut_copper strict
fill ~116 ~52 ~144 ~117 ~52 ~144 minecraft:quartz_stairs[facing=east,half=bottom,shape=straight,waterlogged=false] strict
fill ~118 ~52 ~144 ~129 ~52 ~144 minecraft:quartz_bricks strict
setblock ~134 ~52 ~144 minecraft:quartz_stairs[facing=west,half=bottom,shape=straight,waterlogged=false] strict
setblock ~251 ~52 ~179 minecraft:spruce_leaves[distance=7,persistent=true,waterlogged=false] strict
setblock ~249 ~52 ~181 minecraft:spruce_leaves[distance=7,persistent=true,waterlogged=false] strict
setblock ~253 ~52 ~181 minecraft:spruce_leaves[distance=7,persistent=true,waterlogged=false] strict
setblock ~251 ~52 ~183 minecraft:spruce_leaves[distance=7,persistent=true,waterlogged=false] strict
fill ~0 ~52 ~209 ~1 ~52 ~211 minecraft:grass_block strict
fill ~2 ~52 ~211 ~2 ~52 ~213 minecraft:grass_block strict
setblock ~0 ~52 ~212 minecraft:grass_block strict
setblock ~3 ~52 ~213 minecraft:tuff strict
fill ~3 ~52 ~214 ~3 ~52 ~216 minecraft:grass_block strict
setblock ~3 ~52 ~217 minecraft:coarse_dirt strict
fill ~1 ~52 ~218 ~2 ~52 ~218 minecraft:tuff strict
setblock ~3 ~52 ~218 minecraft:andesite strict
fill ~2 ~52 ~219 ~2 ~52 ~220 minecraft:tuff strict
setblock ~3 ~52 ~219 minecraft:stone strict
fill ~0 ~52 ~220 ~1 ~52 ~220 minecraft:tuff strict
setblock ~3 ~52 ~220 minecraft:coarse_dirt strict
setblock ~0 ~52 ~221 minecraft:grass_block strict
fill ~1 ~52 ~221 ~1 ~52 ~222 minecraft:coarse_dirt strict
setblock ~2 ~52 ~221 minecraft:stone strict
setblock ~3 ~52 ~221 minecraft:tuff strict
setblock ~2 ~52 ~222 minecraft:grass_block strict
fill ~0 ~52 ~223 ~0 ~52 ~224 minecraft:coarse_dirt strict
setblock ~1 ~52 ~223 minecraft:stone strict
setblock ~145 ~52 ~252 minecraft:cobblestone strict
fill ~146 ~52 ~252 ~151 ~52 ~252 minecraft:stone strict
fill ~142 ~52 ~253 ~143 ~52 ~253 minecraft:grass_block strict
fill ~146 ~52 ~253 ~146 ~53 ~253 minecraft:stone strict
fill ~153 ~52 ~253 ~154 ~52 ~253 minecraft:stone strict
setblock ~68 ~52 ~254 minecraft:stone strict
fill ~69 ~52 ~254 ~70 ~52 ~255 minecraft:coarse_dirt strict
setblock ~71 ~52 ~254 minecraft:stone strict
fill ~73 ~52 ~254 ~75 ~52 ~254 minecraft:grass_block strict
fill ~77 ~52 ~254 ~78 ~52 ~254 minecraft:grass_block strict
fill ~80 ~52 ~254 ~80 ~52 ~255 minecraft:grass_block strict
setblock ~142 ~52 ~254 minecraft:grass_block strict
fill ~143 ~52 ~254 ~145 ~52 ~254 minecraft:stone strict
fill ~148 ~52 ~254 ~148 ~54 ~254 minecraft:stone strict
fill ~154 ~52 ~254 ~154 ~52 ~255 minecraft:stone strict
setblock ~155 ~52 ~254 minecraft:grass_block strict
setblock ~68 ~52 ~255 minecraft:coarse_dirt strict
fill ~72 ~52 ~255 ~73 ~52 ~255 minecraft:grass_block strict
fill ~76 ~52 ~255 ~77 ~52 ~255 minecraft:grass_block strict
setblock ~79 ~52 ~255 minecraft:grass_block strict
setblock ~81 ~52 ~255 minecraft:grass_block strict
setblock ~143 ~52 ~255 minecraft:coarse_dirt strict
fill ~146 ~52 ~255 ~146 ~53 ~255 minecraft:stone strict
fill ~149 ~52 ~255 ~153 ~52 ~255 minecraft:stone strict
setblock ~210 ~53 ~0 minecraft:coarse_dirt strict
fill ~211 ~53 ~0 ~212 ~53 ~1 minecraft:stone strict
setblock ~213 ~53 ~0 minecraft:andesite strict
setblock ~210 ~53 ~1 minecraft:grass_block strict
setblock ~213 ~53 ~1 minecraft:stone strict
setblock ~214 ~53 ~1 minecraft:andesite strict
setblock ~209 ~53 ~2 minecraft:coarse_dirt strict
setblock ~210 ~53 ~2 minecraft:stone strict
setblock ~211 ~53 ~2 minecraft:coarse_dirt strict
setblock ~213 ~53 ~2 minecraft:coarse_dirt strict
setblock ~214 ~53 ~2 minecraft:stone strict
setblock ~210 ~53 ~3 minecraft:andesite strict
setblock ~213 ~53 ~3 minecraft:andesite strict
fill ~118 ~53 ~112 ~119 ~53 ~112 minecraft:quartz_stairs[facing=east,half=bottom,shape=straight,waterlogged=false] strict
fill ~120 ~53 ~112 ~136 ~53 ~112 minecraft:quartz_bricks strict
fill ~137 ~53 ~112 ~138 ~53 ~112 minecraft:quartz_stairs[facing=west,half=bottom,shape=straight,waterlogged=false] strict
fill ~118 ~53 ~113 ~119 ~53 ~114 minecraft:weathered_cut_copper_stairs[facing=east,half=bottom,shape=straight,waterlogged=false] strict
fill ~120 ~53 ~113 ~121 ~53 ~114 minecraft:weathered_cut_copper strict
fill ~135 ~53 ~113 ~136 ~53 ~114 minecraft:weathered_cut_copper strict
fill ~137 ~53 ~113 ~138 ~53 ~113 minecraft:weathered_cut_copper_stairs[facing=west,half=bottom,shape=straight,waterlogged=false] strict
fill ~137 ~53 ~114 ~137 ~53 ~116 minecraft:weathered_cut_copper_stairs[facing=west,half=bottom,shape=straight,waterlogged=false] strict
fill ~118 ~53 ~115 ~118 ~53 ~116 minecraft:weathered_cut_copper_stairs[facing=east,half=bottom,shape=straight,waterlogged=false] strict
setblock ~121 ~53 ~115 minecraft:weathered_cut_copper strict
setblock ~135 ~53 ~115 minecraft:weathered_cut_copper strict
setblock ~138 ~53 ~115 minecraft:weathered_cut_copper_stairs[facing=west,half=bottom,shape=straight,waterlogged=false] strict
setblock ~136 ~53 ~116 minecraft:weathered_cut_copper strict
setblock ~119 ~53 ~117 minecraft:weathered_cut_copper_stairs[facing=east,half=bottom,shape=straight,waterlogged=false] strict
setblock ~139 ~53 ~117 minecraft:quartz_stairs[facing=north,half=bottom,shape=straight,waterlogged=false] strict
fill ~135 ~53 ~118 ~136 ~53 ~118 minecraft:weathered_cut_copper strict
fill ~137 ~53 ~118 ~138 ~53 ~118 minecraft:weathered_cut_copper_stairs[facing=west,half=bottom,shape=straight,waterlogged=false] strict
fill ~255 ~53 ~128 ~255 ~53 ~132 minecraft:stone strict
setblock ~255 ~53 ~134 minecraft:grass_block strict
setblock ~254 ~53 ~135 minecraft:stone strict
setblock ~255 ~53 ~135 minecraft:coarse_dirt strict
setblock ~255 ~53 ~136 minecraft:grass_block strict
fill ~131 ~53 ~141 ~131 ~53 ~143 minecraft:weathered_cut_copper_stairs[facing=west,half=bottom,shape=straight,waterlogged=false] strict
fill ~119 ~53 ~142 ~119 ~53 ~143 minecraft:weathered_cut_copper_stairs[facing=east,half=bottom,shape=straight,waterlogged=false] strict
fill ~120 ~53 ~142 ~121 ~53 ~143 minecraft:weathered_cut_copper strict
setblock ~118 ~53 ~143 minecraft:weathered_cut_copper_stairs[facing=east,half=bottom,shape=straight,waterlogged=false] strict
fill ~118 ~53 ~144 ~119 ~53 ~144 minecraft:quartz_stairs[facing=east,half=bottom,shape=straight,waterlogged=false] strict
fill ~120 ~53 ~144 ~129 ~53 ~144 minecraft:quartz_bricks strict
setblock ~131 ~53 ~144 minecraft:quartz_stairs[facing=west,half=bottom,shape=straight,waterlogged=false] strict
fill ~250 ~53 ~181 ~250 ~54 ~181 minecraft:spruce_leaves[distance=7,persistent=true,waterlogged=false] strict
fill ~252 ~53 ~181 ~252 ~54 ~181 minecraft:spruce_leaves[distance=7,persistent=true,waterlogged=false] strict
fill ~1 ~53 ~212 ~1 ~53 ~217 minecraft:grass_block strict
fill ~0 ~53 ~213 ~0 ~53 ~219 minecraft:grass_block strict
fill ~2 ~53 ~214 ~2 ~53 ~217 minecraft:grass_block strict
fill ~1 ~53 ~218 ~2 ~53 ~218 minecraft:stone strict
setblock ~1 ~53 ~219 minecraft:grass_block strict
fill ~2 ~53 ~219 ~2 ~53 ~220 minecraft:stone strict
fill ~0 ~53 ~220 ~1 ~53 ~220 minecraft:stone strict
fill ~144 ~53 ~253 ~145 ~53 ~253 minecraft:grass_block strict
fill ~150 ~53 ~253 ~152 ~53 ~253 minecraft:grass_block strict
fill ~144 ~53 ~254 ~145 ~53 ~254 minecraft:stone strict
fill ~152 ~53 ~254 ~153 ~53 ~254 minecraft:grass_block strict
fill ~144 ~53 ~255 ~145 ~53 ~255 minecraft:grass_block strict
fill ~149 ~53 ~255 ~152 ~53 ~255 minecraft:stone strict
fill ~120 ~54 ~112 ~121 ~54 ~112 minecraft:quartz_stairs[facing=east,half=bottom,shape=straight,waterlogged=false] strict
fill ~122 ~54 ~112 ~134 ~54 ~112 minecraft:quartz_bricks strict
fill ~135 ~54 ~112 ~136 ~54 ~112 minecraft:quartz_stairs[facing=west,half=bottom,shape=straight,waterlogged=false] strict
fill ~120 ~54 ~113 ~121 ~54 ~114 minecraft:weathered_cut_copper_stairs[facing=east,half=bottom,shape=straight,waterlogged=false] strict
fill ~122 ~54 ~113 ~123 ~54 ~115 minecraft:weathered_cut_copper strict
fill ~133 ~54 ~113 ~134 ~54 ~113 minecraft:weathered_cut_copper strict
fill ~135 ~54 ~113 ~136 ~54 ~114 minecraft:weathered_cut_copper_stairs[facing=west,half=bottom,shape=straight,waterlogged=false] strict
setblock ~134 ~54 ~114 minecraft:weathered_cut_copper strict
setblock ~121 ~54 ~115 minecraft:weathered_cut_copper_stairs[facing=east,half=bottom,shape=straight,waterlogged=false] strict
setblock ~135 ~54 ~115 minecraft:weathered_cut_copper_stairs[facing=west,half=bottom,shape=straight,waterlogged=false] strict
setblock ~123 ~54 ~116 minecraft:weathered_cut_copper strict
setblock ~134 ~54 ~116 minecraft:weathered_cut_copper strict
setblock ~136 ~54 ~116 minecraft:weathered_cut_copper_stairs[facing=west,half=bottom,shape=straight,waterlogged=false] strict
fill ~135 ~54 ~118 ~136 ~54 ~118 minecraft:weathered_cut_copper_stairs[facing=west,half=bottom,shape=straight,waterlogged=false] strict
fill ~120 ~54 ~142 ~121 ~54 ~143 minecraft:weathered_cut_copper_stairs[facing=east,half=bottom,shape=straight,waterlogged=false] strict
fill ~122 ~54 ~143 ~123 ~54 ~143 minecraft:weathered_cut_copper strict
fill ~120 ~54 ~144 ~121 ~54 ~144 minecraft:quartz_stairs[facing=east,half=bottom,shape=straight,waterlogged=false] strict
fill ~122 ~54 ~144 ~129 ~54 ~144 minecraft:quartz_bricks strict
setblock ~250 ~54 ~180 minecraft:spruce_leaves[distance=7,persistent=true,waterlogged=false] strict
setblock ~252 ~54 ~180 minecraft:spruce_leaves[distance=7,persistent=true,waterlogged=false] strict
setblock ~250 ~54 ~182 minecraft:spruce_leaves[distance=7,persistent=true,waterlogged=false] strict
setblock ~252 ~54 ~182 minecraft:spruce_leaves[distance=7,persistent=true,waterlogged=false] strict
fill ~147 ~54 ~253 ~149 ~54 ~253 minecraft:grass_block strict
fill ~146 ~54 ~254 ~147 ~54 ~254 minecraft:grass_block strict
fill ~149 ~54 ~254 ~151 ~54 ~254 minecraft:grass_block strict
fill ~147 ~54 ~255 ~148 ~54 ~255 minecraft:grass_block strict
fill ~149 ~54 ~255 ~150 ~54 ~255 minecraft:stone strict
fill ~122 ~55 ~112 ~123 ~55 ~112 minecraft:quartz_stairs[facing=east,half=bottom,shape=straight,waterlogged=false] strict
fill ~124 ~55 ~112 ~132 ~55 ~112 minecraft:quartz_bricks strict
fill ~133 ~55 ~112 ~134 ~55 ~112 minecraft:quartz_stairs[facing=west,half=bottom,shape=straight,waterlogged=false] strict
fill ~122 ~55 ~113 ~123 ~55 ~115 minecraft:weathered_cut_copper_stairs[facing=east,half=bottom,shape=straight,waterlogged=false] strict
fill ~124 ~55 ~113 ~125 ~55 ~113 minecraft:weathered_cut_copper strict
fill ~131 ~55 ~113 ~132 ~55 ~113 minecraft:weathered_cut_copper strict
fill ~133 ~55 ~113 ~134 ~55 ~113 minecraft:weathered_cut_copper_stairs[facing=west,half=bottom,shape=straight,waterlogged=false] strict
fill ~125 ~55 ~114 ~125 ~55 ~115 minecraft:weathered_cut_copper strict
setblock ~134 ~55 ~114 minecraft:weathered_cut_copper_stairs[facing=west,half=bottom,shape=straight,waterlogged=false] strict
fill ~124 ~55 ~115 ~124 ~55 ~116 minecraft:weathered_cut_copper strict
fill ~131 ~55 ~115 ~132 ~55 ~115 minecraft:weathered_cut_copper strict
setblock ~123 ~55 ~116 minecraft:weathered_cut_copper_stairs[facing=east,half=bottom,shape=straight,waterlogged=false] strict
setblock ~131 ~55 ~116 minecraft:weathered_cut_copper strict
setblock ~134 ~55 ~116 minecraft:weathered_cut_copper_stairs[facing=west,half=bottom,shape=straight,waterlogged=false] strict
setblock ~132 ~55 ~117 minecraft:weathered_cut_copper strict
fill ~124 ~55 ~141 ~125 ~55 ~141 minecraft:weathered_cut_copper strict
fill ~124 ~55 ~142 ~124 ~55 ~143 minecraft:weathered_cut_copper strict
fill ~122 ~55 ~143 ~123 ~55 ~143 minecraft:weathered_cut_copper_stairs[facing=east,half=bottom,shape=straight,waterlogged=false] strict
setblock ~125 ~55 ~143 minecraft:weathered_cut_copper strict
fill ~122 ~55 ~144 ~123 ~55 ~144 minecraft:quartz_stairs[facing=east,half=bottom,shape=straight,waterlogged=false] strict
fill ~124 ~55 ~144 ~129 ~55 ~144 minecraft:quartz_bricks strict
fill ~124 ~56 ~112 ~125 ~56 ~112 minecraft:quartz_stairs[facing=east,half=bottom,shape=straight,waterlogged=false] strict
fill ~126 ~56 ~112 ~130 ~56 ~112 minecraft:quartz_bricks strict
fill ~131 ~56 ~112 ~132 ~56 ~112 minecraft:quartz_stairs[facing=west,half=bottom,shape=straight,waterlogged=false] strict
fill ~124 ~56 ~113 ~125 ~56 ~113 minecraft:weathered_cut_copper_stairs[facing=east,half=bottom,shape=straight,waterlogged=false] strict
fill ~126 ~56 ~113 ~127 ~56 ~113 minecraft:weathered_cut_copper strict
fill ~129 ~56 ~113 ~130 ~56 ~113 minecraft:weathered_cut_copper strict
fill ~131 ~56 ~113 ~132 ~56 ~113 minecraft:weathered_cut_copper_stairs[facing=west,half=bottom,shape=straight,waterlogged=false] strict
fill ~125 ~56 ~114 ~125 ~56 ~115 minecraft:weathered_cut_copper_stairs[facing=east,half=bottom,shape=straight,waterlogged=false] strict
fill ~126 ~56 ~114 ~126 ~56 ~117 minecraft:weathered_cut_copper strict
fill ~130 ~56 ~114 ~130 ~56 ~115 minecraft:weathered_cut_copper strict
fill ~124 ~56 ~115 ~124 ~56 ~116 minecraft:weathered_cut_copper_stairs[facing=east,half=bottom,shape=straight,waterlogged=false] strict
fill ~131 ~56 ~115 ~132 ~56 ~115 minecraft:weathered_cut_copper_stairs[facing=west,half=bottom,shape=straight,waterlogged=false] strict
setblock ~127 ~56 ~116 minecraft:weathered_cut_copper strict
setblock ~131 ~56 ~116 minecraft:weathered_cut_copper_stairs[facing=west,half=bottom,shape=straight,waterlogged=false] strict
setblock ~132 ~56 ~117 minecraft:weathered_cut_copper_stairs[facing=west,half=bottom,shape=straight,waterlogged=false] strict
fill ~124 ~56 ~141 ~125 ~56 ~141 minecraft:weathered_cut_copper_stairs[facing=east,half=bottom,shape=straight,waterlogged=false] strict
fill ~126 ~56 ~141 ~126 ~56 ~143 minecraft:weathered_cut_copper strict
fill ~129 ~56 ~141 ~129 ~56 ~143 minecraft:weathered_cut_copper strict
fill ~124 ~56 ~142 ~124 ~56 ~143 minecraft:weathered_cut_copper_stairs[facing=east,half=bottom,shape=straight,waterlogged=false] strict
fill ~127 ~56 ~142 ~127 ~56 ~143 minecraft:weathered_cut_copper strict
setblock ~125 ~56 ~143 minecraft:weathered_cut_copper_stairs[facing=east,half=bottom,shape=straight,waterlogged=false] strict
fill ~124 ~56 ~144 ~125 ~56 ~144 minecraft:quartz_stairs[facing=east,half=bottom,shape=straight,waterlogged=false] strict
fill ~126 ~56 ~144 ~129 ~56 ~144 minecraft:quartz_bricks strict
setblock ~251 ~56 ~180 minecraft:spruce_leaves[distance=7,persistent=true,waterlogged=false] strict
setblock ~250 ~56 ~181 minecraft:spruce_leaves[distance=7,persistent=true,waterlogged=false] strict
setblock ~252 ~56 ~181 minecraft:spruce_leaves[distance=7,persistent=true,waterlogged=false] strict
setblock ~251 ~56 ~182 minecraft:spruce_leaves[distance=7,persistent=true,waterlogged=false] strict
fill ~126 ~57 ~112 ~127 ~57 ~112 minecraft:quartz_stairs[facing=east,half=bottom,shape=straight,waterlogged=false] strict
setblock ~128 ~57 ~112 minecraft:quartz_bricks strict
fill ~129 ~57 ~112 ~130 ~57 ~112 minecraft:quartz_stairs[facing=west,half=bottom,shape=straight,waterlogged=false] strict
fill ~126 ~57 ~113 ~127 ~57 ~113 minecraft:weathered_cut_copper_stairs[facing=east,half=bottom,shape=straight,waterlogged=false] strict
fill ~128 ~57 ~113 ~128 ~58 ~114 minecraft:weathered_cut_copper strict
fill ~129 ~57 ~113 ~130 ~57 ~113 minecraft:weathered_cut_copper_stairs[facing=west,half=bottom,shape=straight,waterlogged=false] strict
fill ~126 ~57 ~114 ~126 ~57 ~117 minecraft:weathered_cut_copper_stairs[facing=east,half=bottom,shape=straight,waterlogged=false] strict
fill ~130 ~57 ~114 ~130 ~57 ~115 minecraft:weathered_cut_copper_stairs[facing=west,half=bottom,shape=straight,waterlogged=false] strict
setblock ~127 ~57 ~116 minecraft:weathered_cut_copper_stairs[facing=east,half=bottom,shape=straight,waterlogged=false] strict
fill ~128 ~57 ~116 ~128 ~58 ~117 minecraft:weathered_cut_copper strict
fill ~126 ~57 ~141 ~126 ~57 ~143 minecraft:weathered_cut_copper_stairs[facing=east,half=bottom,shape=straight,waterlogged=false] strict
fill ~129 ~57 ~141 ~129 ~57 ~143 minecraft:weathered_cut_copper_stairs[facing=west,half=bottom,shape=straight,waterlogged=false] strict
fill ~127 ~57 ~142 ~127 ~57 ~143 minecraft:weathered_cut_copper_stairs[facing=east,half=bottom,shape=straight,waterlogged=false] strict
fill ~128 ~57 ~142 ~128 ~58 ~143 minecraft:weathered_cut_copper strict
fill ~126 ~57 ~144 ~127 ~57 ~144 minecraft:quartz_stairs[facing=east,half=bottom,shape=straight,waterlogged=false] strict
setblock ~128 ~57 ~144 minecraft:quartz_bricks strict
setblock ~129 ~57 ~144 minecraft:quartz_stairs[facing=west,half=bottom,shape=straight,waterlogged=false] strict
setblock ~128 ~58 ~112 minecraft:chiseled_quartz_block strict
setblock ~128 ~58 ~144 minecraft:chiseled_quartz_block strict
fill ~251 ~58 ~181 ~251 ~59 ~181 minecraft:spruce_leaves[distance=7,persistent=true,waterlogged=false] strict
fill ~63 ~22 ~50 ~64 ~22 ~50 minecraft:short_grass strict
fill ~65 ~22 ~51 ~66 ~22 ~51 minecraft:short_grass strict
setblock ~71 ~22 ~51 minecraft:short_grass strict
fill ~74 ~22 ~51 ~74 ~22 ~53 minecraft:short_grass strict
setblock ~65 ~22 ~52 minecraft:short_grass strict
setblock ~67 ~22 ~52 minecraft:short_grass strict
setblock ~70 ~22 ~53 minecraft:short_grass strict
setblock ~76 ~22 ~53 minecraft:allium strict
setblock ~77 ~22 ~53 minecraft:short_grass strict
setblock ~79 ~22 ~53 minecraft:poppy strict
setblock ~80 ~22 ~54 minecraft:fern strict
fill ~82 ~22 ~54 ~83 ~22 ~54 minecraft:short_grass strict
fill ~68 ~22 ~55 ~70 ~22 ~55 minecraft:short_grass strict
setblock ~72 ~22 ~55 minecraft:short_grass strict
fill ~74 ~22 ~55 ~78 ~22 ~57 minecraft:wheat[age=7] strict
setblock ~81 ~22 ~55 minecraft:short_grass strict
setblock ~84 ~22 ~55 minecraft:lily_of_the_valley strict
setblock ~64 ~22 ~56 minecraft:red_tulip strict
setblock ~68 ~22 ~56 minecraft:short_grass strict
setblock ~69 ~22 ~56 minecraft:azure_bluet strict
setblock ~70 ~22 ~56 minecraft:short_grass strict
setblock ~80 ~22 ~56 minecraft:short_grass strict
setblock ~69 ~22 ~57 minecraft:short_grass strict
setblock ~70 ~22 ~58 minecraft:short_grass strict
setblock ~70 ~22 ~59 minecraft:fern strict
setblock ~76 ~22 ~59 minecraft:short_grass strict
fill ~78 ~22 ~59 ~78 ~22 ~60 minecraft:short_grass strict
setblock ~79 ~22 ~59 minecraft:oxeye_daisy strict
fill ~69 ~22 ~60 ~70 ~22 ~60 minecraft:short_grass strict
fill ~73 ~22 ~60 ~74 ~22 ~60 minecraft:short_grass strict
setblock ~86 ~22 ~60 minecraft:short_grass strict
setblock ~51 ~22 ~61 minecraft:azure_bluet strict
fill ~74 ~22 ~61 ~75 ~22 ~61 minecraft:short_grass strict
setblock ~76 ~22 ~61 minecraft:allium strict
setblock ~74 ~22 ~62 minecraft:poppy strict
setblock ~76 ~22 ~62 minecraft:short_grass strict
setblock ~79 ~22 ~62 minecraft:azure_bluet strict
setblock ~51 ~22 ~63 minecraft:short_grass strict
setblock ~53 ~22 ~63 minecraft:poppy strict
setblock ~75 ~22 ~63 minecraft:short_grass strict
setblock ~77 ~22 ~63 minecraft:short_grass strict
setblock ~79 ~22 ~63 minecraft:fern strict
setblock ~81 ~22 ~63 minecraft:short_grass strict
fill ~83 ~22 ~63 ~83 ~22 ~66 minecraft:short_grass strict
