fill ~106 ~31 ~193 ~107 ~31 ~193 minecraft:short_grass strict
fill ~66 ~31 ~195 ~66 ~31 ~196 minecraft:iron_chain[axis=z,waterlogged=false] strict
fill ~70 ~31 ~195 ~70 ~31 ~196 minecraft:iron_chain[axis=z,waterlogged=false] strict
setblock ~103 ~31 ~198 minecraft:bush strict
setblock ~66 ~31 ~200 minecraft:lantern[hanging=false,waterlogged=false] strict
setblock ~70 ~31 ~200 minecraft:lantern[hanging=false,waterlogged=false] strict
fill ~66 ~31 ~204 ~66 ~31 ~205 minecraft:iron_chain[axis=z,waterlogged=false] strict
fill ~70 ~31 ~204 ~70 ~31 ~205 minecraft:iron_chain[axis=z,waterlogged=false] strict
setblock ~124 ~31 ~204 minecraft:campfire[facing=north,lit=true,signal_fire=false,waterlogged=false] strict
setblock ~132 ~31 ~204 minecraft:campfire[facing=north,lit=true,signal_fire=false,waterlogged=false] strict
setblock ~66 ~31 ~207 minecraft:iron_chain[axis=z,waterlogged=false] strict
setblock ~70 ~31 ~207 minecraft:iron_chain[axis=z,waterlogged=false] strict
fill ~99 ~31 ~210 ~99 ~31 ~211 minecraft:quartz_slab[type=bottom,waterlogged=false] strict
setblock ~107 ~31 ~216 minecraft:campfire[facing=north,lit=true,signal_fire=false,waterlogged=false] strict
setblock ~149 ~31 ~216 minecraft:campfire[facing=north,lit=true,signal_fire=false,waterlogged=false] strict
setblock ~122 ~31 ~221 minecraft:smooth_stone_slab[type=bottom,waterlogged=false] strict
setblock ~128 ~31 ~221 minecraft:smooth_stone_slab[type=bottom,waterlogged=false] strict
setblock ~134 ~31 ~221 minecraft:smooth_stone_slab[type=bottom,waterlogged=false] strict
setblock ~114 ~31 ~223 minecraft:lantern[hanging=false,waterlogged=false] strict
setblock ~140 ~31 ~223 minecraft:lantern[hanging=false,waterlogged=false] strict
setblock ~128 ~31 ~231 minecraft:lantern[hanging=false,waterlogged=false] strict
setblock ~127 ~31 ~232 minecraft:lantern[hanging=false,waterlogged=false] strict
setblock ~129 ~31 ~232 minecraft:lantern[hanging=false,waterlogged=false] strict
setblock ~128 ~31 ~233 minecraft:lantern[hanging=false,waterlogged=false] strict
setblock ~68 ~31 ~234 minecraft:fern strict
fill ~93 ~31 ~234 ~97 ~31 ~238 minecraft:smooth_quartz_slab[type=top,waterlogged=false] strict
fill ~68 ~31 ~235 ~69 ~31 ~235 minecraft:short_grass strict
setblock ~69 ~31 ~236 minecraft:short_grass strict
fill ~70 ~31 ~237 ~70 ~31 ~238 minecraft:short_grass strict
setblock ~71 ~31 ~239 minecraft:short_grass strict
setblock ~72 ~31 ~239 minecraft:fern strict
fill ~72 ~31 ~240 ~73 ~31 ~240 minecraft:short_grass strict
setblock ~63 ~31 ~242 minecraft:short_grass strict
setblock ~75 ~32 ~10 minecraft:short_grass strict
setblock ~183 ~32 ~12 minecraft:fern strict
setblock ~184 ~32 ~12 minecraft:short_grass strict
setblock ~186 ~32 ~12 minecraft:short_grass strict
setblock ~169 ~32 ~13 minecraft:fern strict
setblock ~173 ~32 ~13 minecraft:short_grass strict
fill ~177 ~32 ~13 ~178 ~32 ~13 minecraft:short_grass strict
setblock ~181 ~32 ~13 minecraft:short_grass strict
setblock ~170 ~32 ~14 minecraft:fern strict
setblock ~173 ~32 ~14 minecraft:bush strict
setblock ~174 ~32 ~14 minecraft:fern strict
setblock ~175 ~32 ~14 minecraft:short_grass strict
setblock ~177 ~32 ~15 minecraft:fern strict
fill ~175 ~32 ~16 ~177 ~32 ~16 minecraft:short_grass strict
setblock ~180 ~32 ~16 minecraft:short_grass strict
fill ~175 ~32 ~18 ~176 ~32 ~18 minecraft:short_grass strict
setblock ~178 ~32 ~18 minecraft:short_grass strict
setblock ~177 ~32 ~19 minecraft:bush strict
fill ~184 ~32 ~19 ~187 ~32 ~19 minecraft:quartz_slab[type=bottom,waterlogged=false] strict
setblock ~95 ~32 ~21 minecraft:mossy_stone_brick_slab[type=bottom,waterlogged=false] strict
setblock ~97 ~32 ~21 minecraft:stone_brick_slab[type=bottom,waterlogged=false] strict
setblock ~112 ~32 ~46 minecraft:campfire[facing=north,lit=true,signal_fire=false,waterlogged=false] strict
setblock ~144 ~32 ~46 minecraft:campfire[facing=north,lit=true,signal_fire=false,waterlogged=false] strict
fill ~153 ~32 ~58 ~153 ~32 ~60 minecraft:quartz_slab[type=bottom,waterlogged=false] strict
setblock ~105 ~32 ~61 minecraft:stone_brick_slab[type=bottom,waterlogged=false] strict
fill ~102 ~32 ~62 ~104 ~32 ~62 minecraft:quartz_slab[type=bottom,waterlogged=false] strict
setblock ~106 ~32 ~62 minecraft:quartz_slab[type=bottom,waterlogged=false] strict
fill ~102 ~32 ~64 ~104 ~32 ~64 minecraft:quartz_slab[type=bottom,waterlogged=false] strict
setblock ~106 ~32 ~64 minecraft:quartz_slab[type=bottom,waterlogged=false] strict
setblock ~102 ~32 ~65 minecraft:fern strict
setblock ~20 ~32 ~67 minecraft:short_grass strict
setblock ~154 ~32 ~67 minecraft:short_grass strict
setblock ~156 ~32 ~67 minecraft:short_grass strict
setblock ~101 ~32 ~68 minecraft:short_grass strict
setblock ~19 ~32 ~69 minecraft:short_grass strict
setblock ~100 ~32 ~69 minecraft:dandelion strict
setblock ~18 ~32 ~70 minecraft:short_grass strict
setblock ~158 ~32 ~70 minecraft:short_grass strict
setblock ~18 ~32 ~71 minecraft:fern strict
setblock ~157 ~32 ~71 minecraft:short_grass strict
setblock ~17 ~32 ~74 minecraft:short_grass strict
setblock ~12 ~32 ~78 minecraft:short_grass strict
setblock ~181 ~32 ~80 minecraft:dead_bush strict
setblock ~34 ~32 ~86 minecraft:stone_brick_slab[type=bottom,waterlogged=false] strict
fill ~16 ~32 ~94 ~17 ~32 ~94 minecraft:short_grass strict
fill ~14 ~32 ~95 ~15 ~32 ~95 minecraft:short_grass strict
setblock ~68 ~32 ~98 minecraft:fern strict
fill ~70 ~32 ~98 ~70 ~32 ~99 minecraft:short_grass strict
setblock ~64 ~32 ~99 minecraft:short_grass strict
setblock ~71 ~32 ~99 minecraft:short_grass strict
setblock ~72 ~32 ~99 minecraft:bush strict
setblock ~60 ~32 ~100 minecraft:short_grass strict
setblock ~72 ~32 ~100 minecraft:short_grass strict
setblock ~73 ~32 ~104 minecraft:mossy_stone_brick_slab[type=bottom,waterlogged=false] strict
setblock ~68 ~32 ~105 minecraft:short_grass strict
setblock ~66 ~32 ~107 minecraft:short_grass strict
setblock ~73 ~32 ~108 minecraft:stone_brick_slab[type=bottom,waterlogged=false] strict
setblock ~122 ~32 ~109 minecraft:quartz_slab[type=bottom,waterlogged=false] strict
setblock ~134 ~32 ~109 minecraft:quartz_slab[type=bottom,waterlogged=false] strict
fill ~154 ~32 ~111 ~154 ~32 ~112 minecraft:smooth_quartz_slab[type=top,waterlogged=false] strict
setblock ~46 ~32 ~112 minecraft:campfire[facing=north,lit=true,signal_fire=false,waterlogged=false] strict
setblock ~210 ~32 ~112 minecraft:campfire[facing=north,lit=true,signal_fire=false,waterlogged=false] strict
setblock ~155 ~32 ~113 minecraft:smooth_quartz_slab[type=top,waterlogged=false] strict
fill ~138 ~32 ~116 ~139 ~32 ~116 minecraft:smooth_quartz_slab[type=bottom,waterlogged=false] strict
setblock ~137 ~32 ~118 minecraft:smooth_quartz_slab[type=bottom,waterlogged=false] strict
setblock ~139 ~32 ~118 minecraft:smooth_quartz_slab[type=bottom,waterlogged=false] strict
setblock ~140 ~32 ~119 minecraft:smooth_quartz_slab[type=bottom,waterlogged=false] strict
setblock ~109 ~32 ~122 minecraft:quartz_slab[type=bottom,waterlogged=false] strict
setblock ~147 ~32 ~122 minecraft:quartz_slab[type=bottom,waterlogged=false] strict
setblock ~109 ~32 ~134 minecraft:quartz_slab[type=bottom,waterlogged=false] strict
setblock ~147 ~32 ~134 minecraft:quartz_slab[type=bottom,waterlogged=false] strict
setblock ~141 ~32 ~135 minecraft:smooth_quartz_slab[type=bottom,waterlogged=false] strict
fill ~116 ~32 ~138 ~117 ~32 ~138 minecraft:smooth_quartz_slab[type=bottom,waterlogged=false] strict
setblock ~120 ~32 ~138 minecraft:smooth_quartz_slab[type=bottom,waterlogged=false] strict
setblock ~99 ~32 ~139 minecraft:smooth_quartz_slab[type=top,waterlogged=false] strict
setblock ~116 ~32 ~139 minecraft:smooth_quartz_slab[type=bottom,waterlogged=false] strict
fill ~100 ~32 ~140 ~100 ~32 ~141 minecraft:smooth_quartz_slab[type=top,waterlogged=false] strict
setblock ~114 ~32 ~140 minecraft:smooth_quartz_slab[type=bottom,waterlogged=false] strict
fill ~187 ~32 ~142 ~191 ~32 ~146 minecraft:smooth_quartz_slab[type=top,waterlogged=false] strict
setblock ~46 ~32 ~144 minecraft:campfire[facing=north,lit=true,signal_fire=false,waterlogged=false] strict
setblock ~210 ~32 ~144 minecraft:campfire[facing=north,lit=true,signal_fire=false,waterlogged=false] strict
setblock ~122 ~32 ~147 minecraft:quartz_slab[type=bottom,waterlogged=false] strict
setblock ~134 ~32 ~147 minecraft:quartz_slab[type=bottom,waterlogged=false] strict
fill ~152 ~32 ~147 ~152 ~32 ~148 minecraft:smooth_quartz_slab[type=top,waterlogged=false] strict
setblock ~151 ~32 ~149 minecraft:smooth_quartz_slab[type=top,waterlogged=false] strict
setblock ~60 ~32 ~154 minecraft:short_grass strict
setblock ~61 ~32 ~154 minecraft:cornflower strict
setblock ~62 ~32 ~154 minecraft:short_grass strict
fill ~111 ~32 ~154 ~112 ~32 ~154 minecraft:smooth_quartz_slab[type=top,waterlogged=false] strict
fill ~144 ~32 ~154 ~145 ~32 ~154 minecraft:smooth_quartz_slab[type=top,waterlogged=false] strict
setblock ~59 ~32 ~155 minecraft:short_grass strict
fill ~67 ~32 ~155 ~67 ~32 ~157 minecraft:short_grass strict
setblock ~68 ~32 ~155 minecraft:fern strict
setblock ~113 ~32 ~155 minecraft:smooth_quartz_slab[type=top,waterlogged=false] strict
setblock ~143 ~32 ~155 minecraft:smooth_quartz_slab[type=top,waterlogged=false] strict
setblock ~65 ~32 ~156 minecraft:short_grass strict
fill ~68 ~32 ~156 ~69 ~32 ~157 minecraft:short_grass strict
setblock ~66 ~32 ~157 minecraft:short_grass strict
setblock ~61 ~32 ~159 minecraft:short_grass strict
setblock ~64 ~32 ~159 minecraft:short_grass strict
setblock ~42 ~32 ~161 minecraft:short_grass strict
setblock ~43 ~32 ~161 minecraft:fern strict
setblock ~50 ~32 ~161 minecraft:fern strict
setblock ~13 ~32 ~162 minecraft:short_grass strict
setblock ~186 ~32 ~162 minecraft:stone_brick_slab[type=bottom,waterlogged=false] strict
setblock ~210 ~32 ~162 minecraft:short_grass strict
setblock ~240 ~32 ~162 minecraft:short_grass strict
setblock ~14 ~32 ~163 minecraft:short_grass strict
setblock ~41 ~32 ~163 minecraft:short_grass strict
fill ~211 ~32 ~163 ~212 ~32 ~163 minecraft:short_grass strict
fill ~238 ~32 ~163 ~239 ~32 ~163 minecraft:short_grass strict
setblock ~17 ~32 ~164 minecraft:dandelion strict
fill ~42 ~32 ~164 ~42 ~32 ~165 minecraft:short_grass strict
setblock ~52 ~32 ~164 minecraft:short_grass strict
fill ~215 ~32 ~164 ~217 ~32 ~164 minecraft:short_grass strict
setblock ~234 ~32 ~164 minecraft:short_grass strict
setblock ~237 ~32 ~164 minecraft:short_grass strict
setblock ~17 ~32 ~165 minecraft:fern strict
setblock ~18 ~32 ~165 minecraft:short_grass strict
setblock ~47 ~32 ~165 minecraft:oxeye_daisy strict
fill ~220 ~32 ~165 ~221 ~32 ~165 minecraft:short_grass strict
fill ~225 ~32 ~165 ~226 ~32 ~165 minecraft:short_grass strict
setblock ~231 ~32 ~165 minecraft:bush strict
setblock ~232 ~32 ~165 minecraft:cornflower strict
setblock ~41 ~32 ~166 minecraft:short_grass strict
setblock ~45 ~32 ~166 minecraft:short_grass strict
fill ~19 ~32 ~167 ~19 ~32 ~169 minecraft:short_grass strict
setblock ~20 ~32 ~167 minecraft:azure_bluet strict
setblock ~18 ~32 ~168 minecraft:short_grass strict
fill ~20 ~32 ~168 ~20 ~32 ~169 minecraft:short_grass strict
setblock ~15 ~32 ~170 minecraft:short_grass strict
fill ~17 ~32 ~170 ~18 ~32 ~170 minecraft:short_grass strict
setblock ~213 ~32 ~170 minecraft:short_grass strict
setblock ~213 ~32 ~171 minecraft:fern strict
fill ~14 ~32 ~172 ~15 ~32 ~173 minecraft:short_grass strict
setblock ~66 ~32 ~172 minecraft:lantern[hanging=false,waterlogged=false] strict
setblock ~70 ~32 ~172 minecraft:lantern[hanging=false,waterlogged=false] strict
setblock ~15 ~32 ~174 minecraft:short_grass strict
setblock ~215 ~32 ~174 minecraft:dandelion strict
setblock ~14 ~32 ~175 minecraft:short_grass strict
setblock ~66 ~32 ~176 minecraft:lantern[hanging=false,waterlogged=false] strict
setblock ~70 ~32 ~176 minecraft:lantern[hanging=false,waterlogged=false] strict
setblock ~13 ~32 ~177 minecraft:fern strict
setblock ~15 ~32 ~177 minecraft:short_grass strict
setblock ~14 ~32 ~179 minecraft:short_grass strict
setblock ~13 ~32 ~180 minecraft:short_grass strict
setblock ~14 ~32 ~180 minecraft:bush strict
setblock ~66 ~32 ~180 minecraft:lantern[hanging=false,waterlogged=false] strict
setblock ~70 ~32 ~180 minecraft:lantern[hanging=false,waterlogged=false] strict
fill ~217 ~32 ~180 ~222 ~32 ~180 minecraft:quartz_slab[type=bottom,waterlogged=false] strict
setblock ~13 ~32 ~181 minecraft:fern strict
setblock ~14 ~32 ~181 minecraft:short_grass strict
fill ~13 ~32 ~183 ~13 ~32 ~185 minecraft:short_grass strict
setblock ~14 ~32 ~183 minecraft:dandelion strict
fill ~28 ~32 ~183 ~28 ~32 ~184 minecraft:stone_brick_slab[type=bottom,waterlogged=false] strict
setblock ~31 ~32 ~184 minecraft:stone_brick_slab[type=bottom,waterlogged=false] strict
setblock ~14 ~32 ~185 minecraft:azure_bluet strict
fill ~14 ~32 ~186 ~14 ~32 ~187 minecraft:short_grass strict
setblock ~48 ~32 ~186 minecraft:lantern[hanging=false,waterlogged=false] strict
setblock ~50 ~32 ~186 minecraft:lantern[hanging=false,waterlogged=false] strict
setblock ~62 ~32 ~186 minecraft:lantern[hanging=false,waterlogged=false] strict
setblock ~76 ~32 ~186 minecraft:lantern[hanging=false,waterlogged=false] strict
setblock ~80 ~32 ~186 minecraft:lantern[hanging=false,waterlogged=false] strict
setblock ~84 ~32 ~186 minecraft:lantern[hanging=false,waterlogged=false] strict
setblock ~229 ~32 ~188 minecraft:short_grass strict
fill ~14 ~32 ~190 ~15 ~32 ~191 minecraft:short_grass strict
setblock ~48 ~32 ~190 minecraft:lantern[hanging=false,waterlogged=false] strict
setblock ~50 ~32 ~190 minecraft:lantern[hanging=false,waterlogged=false] strict
setblock ~62 ~32 ~190 minecraft:lantern[hanging=false,waterlogged=false] strict
setblock ~76 ~32 ~190 minecraft:lantern[hanging=false,waterlogged=false] strict
setblock ~80 ~32 ~190 minecraft:lantern[hanging=false,waterlogged=false] strict
setblock ~84 ~32 ~190 minecraft:lantern[hanging=false,waterlogged=false] strict
setblock ~66 ~32 ~194 minecraft:lantern[hanging=false,waterlogged=false] strict
setblock ~70 ~32 ~194 minecraft:lantern[hanging=false,waterlogged=false] strict
setblock ~103 ~32 ~194 minecraft:fern strict
setblock ~105 ~32 ~194 minecraft:short_grass strict
setblock ~106 ~32 ~195 minecraft:fern strict
setblock ~102 ~32 ~197 minecraft:short_grass strict
setblock ~104 ~32 ~197 minecraft:short_grass strict
setblock ~66 ~32 ~206 minecraft:lantern[hanging=false,waterlogged=false] strict
setblock ~70 ~32 ~206 minecraft:lantern[hanging=false,waterlogged=false] strict
setblock ~187 ~32 ~207 minecraft:quartz_slab[type=bottom,waterlogged=false] strict
setblock ~66 ~32 ~208 minecraft:lantern[hanging=false,waterlogged=false] strict
setblock ~70 ~32 ~208 minecraft:lantern[hanging=false,waterlogged=false] strict
setblock ~112 ~32 ~210 minecraft:campfire[facing=north,lit=true,signal_fire=false,waterlogged=false] strict
setblock ~144 ~32 ~210 minecraft:campfire[facing=north,lit=true,signal_fire=false,waterlogged=false] strict
setblock ~66 ~32 ~237 minecraft:short_grass strict
fill ~70 ~32 ~239 ~70 ~32 ~240 minecraft:short_grass strict
setblock ~71 ~32 ~240 minecraft:short_grass strict
setblock ~64 ~32 ~242 minecraft:short_grass strict
setblock ~195 ~32 ~246 minecraft:short_grass strict
setblock ~169 ~33 ~12 minecraft:bush strict
setblock ~170 ~33 ~12 minecraft:short_grass strict
setblock ~171 ~33 ~12 minecraft:fern strict
setblock ~176 ~33 ~12 minecraft:short_grass strict
fill ~180 ~33 ~12 ~181 ~33 ~12 minecraft:short_grass strict
setblock ~134 ~33 ~25 minecraft:spruce_slab[type=bottom,waterlogged=false] strict
setblock ~135 ~33 ~26 minecraft:spruce_slab[type=bottom,waterlogged=false] strict
setblock ~136 ~33 ~27 minecraft:spruce_slab[type=bottom,waterlogged=false] strict
fill ~102 ~33 ~63 ~104 ~33 ~63 minecraft:quartz_slab[type=bottom,waterlogged=false] strict
setblock ~106 ~33 ~63 minecraft:quartz_slab[type=bottom,waterlogged=false] strict
setblock ~102 ~33 ~67 minecraft:short_grass strict
setblock ~155 ~33 ~69 minecraft:short_grass strict
setblock ~20 ~33 ~70 minecraft:short_grass strict
setblock ~18 ~33 ~74 minecraft:short_grass strict
setblock ~10 ~33 ~75 minecraft:short_grass strict
setblock ~25 ~33 ~80 minecraft:short_grass strict
fill ~30 ~33 ~81 ~30 ~33 ~82 minecraft:stone_brick_slab[type=bottom,waterlogged=false] strict
setblock ~192 ~33 ~81 minecraft:dead_bush strict
setblock ~32 ~33 ~86 minecraft:stone_brick_slab[type=bottom,waterlogged=false] strict
setblock ~23 ~33 ~90 minecraft:short_grass strict
fill ~221 ~33 ~90 ~225 ~33 ~90 minecraft:smooth_quartz_slab[type=top,waterlogged=false] strict
fill ~221 ~33 ~91 ~221 ~33 ~94 minecraft:smooth_quartz_slab[type=top,waterlogged=false] strict
fill ~225 ~33 ~91 ~225 ~33 ~94 minecraft:smooth_quartz_slab[type=top,waterlogged=false] strict
fill ~13 ~33 ~93 ~14 ~33 ~93 minecraft:short_grass strict
setblock ~16 ~33 ~93 minecraft:short_grass strict
setblock ~15 ~33 ~94 minecraft:short_grass strict
fill ~222 ~33 ~94 ~224 ~33 ~94 minecraft:smooth_quartz_slab[type=top,waterlogged=false] strict
setblock ~66 ~33 ~99 minecraft:fern strict
setblock ~61 ~33 ~100 minecraft:short_grass strict
setblock ~62 ~33 ~100 minecraft:fern strict
fill ~69 ~33 ~100 ~70 ~33 ~101 minecraft:short_grass strict
setblock ~58 ~33 ~103 minecraft:short_grass strict
fill ~68 ~33 ~103 ~69 ~33 ~103 minecraft:short_grass strict
fill ~65 ~33 ~106 ~65 ~33 ~107 minecraft:short_grass strict
setblock ~63 ~33 ~107 minecraft:fern strict
setblock ~25 ~33 ~120 minecraft:spruce_slab[type=bottom,waterlogged=false] strict
setblock ~26 ~33 ~121 minecraft:spruce_slab[type=bottom,waterlogged=false] strict
setblock ~27 ~33 ~122 minecraft:spruce_slab[type=bottom,waterlogged=false] strict
setblock ~229 ~33 ~134 minecraft:spruce_slab[type=bottom,waterlogged=false] strict
setblock ~230 ~33 ~135 minecraft:spruce_slab[type=bottom,waterlogged=false] strict
setblock ~231 ~33 ~136 minecraft:spruce_slab[type=bottom,waterlogged=false] strict
fill ~61 ~33 ~156 ~61 ~33 ~157 minecraft:short_grass strict
setblock ~60 ~33 ~158 minecraft:short_grass strict
fill ~43 ~33 ~162 ~44 ~33 ~162 minecraft:short_grass strict
setblock ~43 ~33 ~163 minecraft:short_grass strict
setblock ~44 ~33 ~163 minecraft:fern strict
setblock ~209 ~33 ~163 minecraft:short_grass strict
setblock ~13 ~33 ~164 minecraft:short_grass strict
setblock ~44 ~33 ~164 minecraft:short_grass strict
setblock ~209 ~33 ~164 minecraft:poppy strict
fill ~210 ~33 ~164 ~210 ~33 ~165 minecraft:short_grass strict
setblock ~238 ~33 ~164 minecraft:fern strict
setblock ~43 ~33 ~165 minecraft:short_grass strict
fill ~45 ~33 ~165 ~46 ~33 ~165 minecraft:short_grass strict
setblock ~209 ~33 ~165 minecraft:short_grass strict
setblock ~213 ~33 ~165 minecraft:short_grass strict
setblock ~217 ~33 ~165 minecraft:short_grass strict
fill ~236 ~33 ~165 ~238 ~33 ~165 minecraft:short_grass strict
fill ~14 ~33 ~166 ~14 ~33 ~167 minecraft:short_grass strict
setblock ~16 ~33 ~166 minecraft:short_grass strict
setblock ~219 ~33 ~166 minecraft:fern strict
setblock ~222 ~33 ~166 minecraft:short_grass strict
setblock ~224 ~33 ~166 minecraft:short_grass strict
fill ~227 ~33 ~166 ~229 ~33 ~166 minecraft:short_grass strict
fill ~231 ~33 ~166 ~234 ~33 ~166 minecraft:short_grass strict
fill ~15 ~33 ~168 ~16 ~33 ~168 minecraft:short_grass strict
fill ~211 ~33 ~168 ~212 ~33 ~168 minecraft:short_grass strict
setblock ~14 ~33 ~169 minecraft:fern strict
setblock ~15 ~33 ~169 minecraft:short_grass strict
fill ~13 ~33 ~170 ~13 ~33 ~173 minecraft:short_grass strict
setblock ~214 ~33 ~170 minecraft:short_grass strict
setblock ~14 ~33 ~171 minecraft:short_grass strict
setblock ~216 ~33 ~172 minecraft:short_grass strict
fill ~217 ~33 ~173 ~217 ~33 ~174 minecraft:short_grass strict
fill ~12 ~33 ~174 ~12 ~33 ~175 minecraft:short_grass strict
setblock ~13 ~33 ~174 minecraft:fern strict
setblock ~218 ~33 ~174 minecraft:cornflower strict
setblock ~13 ~33 ~175 minecraft:short_grass strict
setblock ~218 ~33 ~175 minecraft:short_grass strict
fill ~221 ~33 ~178 ~221 ~33 ~179 minecraft:short_grass strict
setblock ~222 ~33 ~179 minecraft:fern strict
fill ~28 ~33 ~181 ~28 ~33 ~182 minecraft:stone_brick_slab[type=bottom,waterlogged=false] strict
setblock ~222 ~33 ~181 minecraft:short_grass strict
setblock ~12 ~33 ~182 minecraft:short_grass strict
setblock ~228 ~33 ~187 minecraft:short_grass strict
setblock ~13 ~33 ~188 minecraft:short_grass strict
setblock ~231 ~33 ~188 minecraft:short_grass strict
fill ~102 ~33 ~195 ~103 ~33 ~195 minecraft:short_grass strict
setblock ~187 ~33 ~206 minecraft:quartz_slab[type=bottom,waterlogged=false] strict
setblock ~120 ~33 ~229 minecraft:spruce_slab[type=bottom,waterlogged=false] strict
setblock ~121 ~33 ~230 minecraft:spruce_slab[type=bottom,waterlogged=false] strict
setblock ~122 ~33 ~231 minecraft:spruce_slab[type=bottom,waterlogged=false] strict
setblock ~67 ~33 ~239 minecraft:dandelion strict
setblock ~65 ~33 ~241 minecraft:short_grass strict
setblock ~65 ~33 ~242 minecraft:fern strict
setblock ~71 ~33 ~242 minecraft:fern strict
fill ~66 ~33 ~243 ~67 ~33 ~243 minecraft:short_grass strict
setblock ~66 ~33 ~244 minecraft:short_grass strict
fill ~177 ~34 ~11 ~178 ~34 ~11 minecraft:short_grass strict
setblock ~182 ~34 ~11 minecraft:short_grass strict
setblock ~184 ~34 ~11 minecraft:short_grass strict
fill ~30 ~34 ~13 ~38 ~34 ~14 minecraft:smooth_quartz_slab[type=bottom,waterlogged=false] strict
fill ~27 ~34 ~14 ~29 ~34 ~14 minecraft:smooth_quartz_slab[type=bottom,waterlogged=false] strict
fill ~39 ~34 ~14 ~41 ~34 ~14 minecraft:smooth_quartz_slab[type=bottom,waterlogged=false] strict
fill ~25 ~34 ~15 ~27 ~34 ~15 minecraft:smooth_quartz_slab[type=bottom,waterlogged=false] strict
fill ~41 ~34 ~15 ~43 ~34 ~15 minecraft:smooth_quartz_slab[type=bottom,waterlogged=false] strict
fill ~23 ~34 ~16 ~25 ~34 ~16 minecraft:smooth_quartz_slab[type=bottom,waterlogged=false] strict
fill ~43 ~34 ~16 ~45 ~34 ~16 minecraft:smooth_quartz_slab[type=bottom,waterlogged=false] strict
fill ~22 ~34 ~17 ~23 ~34 ~17 minecraft:smooth_quartz_slab[type=bottom,waterlogged=false] strict
fill ~45 ~34 ~17 ~46 ~34 ~17 minecraft:smooth_quartz_slab[type=bottom,waterlogged=false] strict
fill ~20 ~34 ~18 ~22 ~34 ~18 minecraft:smooth_quartz_slab[type=bottom,waterlogged=false] strict
fill ~46 ~34 ~18 ~48 ~34 ~18 minecraft:smooth_quartz_slab[type=bottom,waterlogged=false] strict
fill ~19 ~34 ~19 ~20 ~34 ~19 minecraft:smooth_quartz_slab[type=bottom,waterlogged=false] strict
fill ~48 ~34 ~19 ~49 ~34 ~19 minecraft:smooth_quartz_slab[type=bottom,waterlogged=false] strict
fill ~18 ~34 ~20 ~19 ~34 ~20 minecraft:smooth_quartz_slab[type=bottom,waterlogged=false] strict
fill ~49 ~34 ~20 ~50 ~34 ~20 minecraft:smooth_quartz_slab[type=bottom,waterlogged=false] strict
fill ~18 ~34 ~21 ~18 ~34 ~22 minecraft:smooth_quartz_slab[type=bottom,waterlogged=false] strict
fill ~50 ~34 ~21 ~50 ~34 ~22 minecraft:smooth_quartz_slab[type=bottom,waterlogged=false] strict
fill ~17 ~34 ~22 ~17 ~34 ~23 minecraft:smooth_quartz_slab[type=bottom,waterlogged=false] strict
fill ~51 ~34 ~22 ~51 ~34 ~23 minecraft:smooth_quartz_slab[type=bottom,waterlogged=false] strict
fill ~16 ~34 ~23 ~16 ~34 ~25 minecraft:smooth_quartz_slab[type=bottom,waterlogged=false] strict
fill ~52 ~34 ~23 ~52 ~34 ~25 minecraft:smooth_quartz_slab[type=bottom,waterlogged=false] strict
fill ~15 ~34 ~25 ~15 ~34 ~27 minecraft:smooth_quartz_slab[type=bottom,waterlogged=false] strict
fill ~53 ~34 ~25 ~53 ~34 ~27 minecraft:smooth_quartz_slab[type=bottom,waterlogged=false] strict
fill ~14 ~34 ~27 ~14 ~34 ~41 minecraft:smooth_quartz_slab[type=bottom,waterlogged=false] strict
setblock ~54 ~34 ~27 minecraft:smooth_quartz_slab[type=bottom,waterlogged=false] strict
