setblock ~33 ~36 ~107 minecraft:stone_brick_slab[type=bottom,waterlogged=false] strict
setblock ~223 ~36 ~107 minecraft:stone_brick_slab[type=bottom,waterlogged=false] strict
setblock ~225 ~36 ~107 minecraft:stone_brick_slab[type=bottom,waterlogged=false] strict
setblock ~231 ~36 ~107 minecraft:stone_brick_slab[type=bottom,waterlogged=false] strict
setblock ~233 ~36 ~107 minecraft:stone_brick_slab[type=bottom,waterlogged=false] strict
setblock ~16 ~36 ~110 minecraft:stone_brick_slab[type=bottom,waterlogged=false] strict
setblock ~240 ~36 ~110 minecraft:stone_brick_slab[type=bottom,waterlogged=false] strict
setblock ~15 ~36 ~111 minecraft:stone_brick_slab[type=bottom,waterlogged=false] strict
setblock ~241 ~36 ~111 minecraft:stone_brick_slab[type=bottom,waterlogged=false] strict
setblock ~14 ~36 ~112 minecraft:stone_brick_slab[type=bottom,waterlogged=false] strict
setblock ~242 ~36 ~112 minecraft:stone_brick_slab[type=bottom,waterlogged=false] strict
setblock ~13 ~36 ~113 minecraft:stone_brick_slab[type=bottom,waterlogged=false] strict
setblock ~243 ~36 ~113 minecraft:stone_brick_slab[type=bottom,waterlogged=false] strict
setblock ~12 ~36 ~114 minecraft:stone_brick_slab[type=bottom,waterlogged=false] strict
setblock ~244 ~36 ~114 minecraft:stone_brick_slab[type=bottom,waterlogged=false] strict
setblock ~11 ~36 ~115 minecraft:stone_brick_slab[type=bottom,waterlogged=false] strict
setblock ~245 ~36 ~115 minecraft:stone_brick_slab[type=bottom,waterlogged=false] strict
setblock ~10 ~36 ~116 minecraft:stone_brick_slab[type=bottom,waterlogged=false] strict
setblock ~246 ~36 ~116 minecraft:stone_brick_slab[type=bottom,waterlogged=false] strict
setblock ~9 ~36 ~117 minecraft:stone_brick_slab[type=bottom,waterlogged=false] strict
setblock ~247 ~36 ~117 minecraft:stone_brick_slab[type=bottom,waterlogged=false] strict
setblock ~36 ~36 ~119 minecraft:lantern[hanging=false,waterlogged=false] strict
setblock ~220 ~36 ~119 minecraft:lantern[hanging=false,waterlogged=false] strict
setblock ~8 ~36 ~120 minecraft:stone_brick_slab[type=bottom,waterlogged=false] strict
setblock ~248 ~36 ~120 minecraft:stone_brick_slab[type=bottom,waterlogged=false] strict
setblock ~7 ~36 ~123 minecraft:stone_brick_slab[type=bottom,waterlogged=false] strict
setblock ~249 ~36 ~123 minecraft:stone_brick_slab[type=bottom,waterlogged=false] strict
setblock ~7 ~36 ~125 minecraft:stone_brick_slab[type=bottom,waterlogged=false] strict
setblock ~249 ~36 ~125 minecraft:stone_brick_slab[type=bottom,waterlogged=false] strict
setblock ~7 ~36 ~131 minecraft:stone_brick_slab[type=bottom,waterlogged=false] strict
setblock ~249 ~36 ~131 minecraft:stone_brick_slab[type=bottom,waterlogged=false] strict
setblock ~7 ~36 ~133 minecraft:stone_brick_slab[type=bottom,waterlogged=false] strict
setblock ~249 ~36 ~133 minecraft:stone_brick_slab[type=bottom,waterlogged=false] strict
setblock ~8 ~36 ~136 minecraft:stone_brick_slab[type=bottom,waterlogged=false] strict
setblock ~248 ~36 ~136 minecraft:stone_brick_slab[type=bottom,waterlogged=false] strict
setblock ~36 ~36 ~137 minecraft:lantern[hanging=false,waterlogged=false] strict
setblock ~220 ~36 ~137 minecraft:lantern[hanging=false,waterlogged=false] strict
fill ~142 ~36 ~138 ~143 ~36 ~138 minecraft:quartz_slab[type=bottom,waterlogged=false] strict
setblock ~9 ~36 ~139 minecraft:stone_brick_slab[type=bottom,waterlogged=false] strict
setblock ~143 ~36 ~139 minecraft:quartz_slab[type=bottom,waterlogged=false] strict
setblock ~247 ~36 ~139 minecraft:stone_brick_slab[type=bottom,waterlogged=false] strict
setblock ~10 ~36 ~140 minecraft:stone_brick_slab[type=bottom,waterlogged=false] strict
setblock ~246 ~36 ~140 minecraft:stone_brick_slab[type=bottom,waterlogged=false] strict
setblock ~11 ~36 ~141 minecraft:stone_brick_slab[type=bottom,waterlogged=false] strict
setblock ~245 ~36 ~141 minecraft:stone_brick_slab[type=bottom,waterlogged=false] strict
setblock ~12 ~36 ~142 minecraft:stone_brick_slab[type=bottom,waterlogged=false] strict
setblock ~244 ~36 ~142 minecraft:stone_brick_slab[type=bottom,waterlogged=false] strict
setblock ~13 ~36 ~143 minecraft:stone_brick_slab[type=bottom,waterlogged=false] strict
setblock ~243 ~36 ~143 minecraft:stone_brick_slab[type=bottom,waterlogged=false] strict
setblock ~14 ~36 ~144 minecraft:stone_brick_slab[type=bottom,waterlogged=false] strict
setblock ~242 ~36 ~144 minecraft:stone_brick_slab[type=bottom,waterlogged=false] strict
setblock ~15 ~36 ~145 minecraft:stone_brick_slab[type=bottom,waterlogged=false] strict
setblock ~241 ~36 ~145 minecraft:stone_brick_slab[type=bottom,waterlogged=false] strict
setblock ~16 ~36 ~146 minecraft:stone_brick_slab[type=bottom,waterlogged=false] strict
setblock ~240 ~36 ~146 minecraft:stone_brick_slab[type=bottom,waterlogged=false] strict
setblock ~23 ~36 ~149 minecraft:stone_brick_slab[type=bottom,waterlogged=false] strict
setblock ~25 ~36 ~149 minecraft:stone_brick_slab[type=bottom,waterlogged=false] strict
setblock ~31 ~36 ~149 minecraft:stone_brick_slab[type=bottom,waterlogged=false] strict
setblock ~33 ~36 ~149 minecraft:stone_brick_slab[type=bottom,waterlogged=false] strict
setblock ~223 ~36 ~149 minecraft:stone_brick_slab[type=bottom,waterlogged=false] strict
setblock ~225 ~36 ~149 minecraft:stone_brick_slab[type=bottom,waterlogged=false] strict
setblock ~231 ~36 ~149 minecraft:stone_brick_slab[type=bottom,waterlogged=false] strict
setblock ~233 ~36 ~149 minecraft:stone_brick_slab[type=bottom,waterlogged=false] strict
setblock ~245 ~36 ~164 minecraft:short_grass strict
setblock ~245 ~36 ~166 minecraft:short_grass strict
fill ~245 ~36 ~168 ~245 ~36 ~169 minecraft:short_grass strict
setblock ~226 ~36 ~170 minecraft:short_grass strict
fill ~228 ~36 ~171 ~228 ~36 ~172 minecraft:short_grass strict
setblock ~230 ~36 ~171 minecraft:fern strict
setblock ~227 ~36 ~172 minecraft:short_grass strict
setblock ~229 ~36 ~172 minecraft:short_grass strict
setblock ~231 ~36 ~172 minecraft:allium strict
setblock ~10 ~36 ~173 minecraft:short_grass strict
setblock ~230 ~36 ~173 minecraft:allium strict
fill ~231 ~36 ~173 ~232 ~36 ~173 minecraft:short_grass strict
setblock ~234 ~36 ~173 minecraft:short_grass strict
setblock ~230 ~36 ~174 minecraft:short_grass strict
setblock ~228 ~36 ~175 minecraft:short_grass strict
fill ~231 ~36 ~175 ~232 ~36 ~175 minecraft:short_grass strict
setblock ~246 ~36 ~175 minecraft:short_grass strict
fill ~232 ~36 ~176 ~234 ~36 ~176 minecraft:short_grass strict
setblock ~9 ~36 ~177 minecraft:short_grass strict
setblock ~216 ~36 ~177 minecraft:quartz_slab[type=bottom,waterlogged=false] strict
setblock ~229 ~36 ~177 minecraft:short_grass strict
setblock ~233 ~36 ~177 minecraft:short_grass strict
fill ~232 ~36 ~178 ~233 ~36 ~178 minecraft:fern strict
setblock ~234 ~36 ~178 minecraft:bush strict
fill ~232 ~36 ~179 ~233 ~36 ~179 minecraft:short_grass strict
fill ~235 ~36 ~179 ~236 ~36 ~179 minecraft:short_grass strict
setblock ~232 ~36 ~180 minecraft:short_grass strict
setblock ~234 ~36 ~180 minecraft:fern strict
fill ~235 ~36 ~180 ~235 ~36 ~181 minecraft:short_grass strict
setblock ~232 ~36 ~181 minecraft:fern strict
setblock ~234 ~36 ~181 minecraft:bush strict
setblock ~246 ~36 ~181 minecraft:short_grass strict
setblock ~232 ~36 ~182 minecraft:short_grass strict
setblock ~237 ~36 ~182 minecraft:short_grass strict
fill ~235 ~36 ~183 ~236 ~36 ~184 minecraft:short_grass strict
fill ~246 ~36 ~183 ~246 ~36 ~185 minecraft:short_grass strict
setblock ~237 ~36 ~184 minecraft:short_grass strict
fill ~235 ~36 ~186 ~236 ~36 ~186 minecraft:short_grass strict
setblock ~238 ~36 ~186 minecraft:short_grass strict
setblock ~236 ~36 ~187 minecraft:fern strict
fill ~237 ~36 ~187 ~237 ~36 ~188 minecraft:short_grass strict
setblock ~246 ~36 ~188 minecraft:short_grass strict
fill ~212 ~36 ~200 ~216 ~36 ~202 minecraft:smooth_sandstone_slab[type=bottom,waterlogged=false] strict
fill ~228 ~36 ~200 ~231 ~36 ~202 minecraft:smooth_sandstone_slab[type=bottom,waterlogged=false] strict
fill ~211 ~36 ~201 ~211 ~36 ~203 minecraft:smooth_sandstone_slab[type=bottom,waterlogged=false] strict
setblock ~210 ~36 ~202 minecraft:smooth_sandstone_slab[type=bottom,waterlogged=false] strict
fill ~212 ~36 ~203 ~213 ~36 ~203 minecraft:smooth_sandstone_slab[type=bottom,waterlogged=false] strict
setblock ~212 ~36 ~204 minecraft:smooth_sandstone_slab[type=bottom,waterlogged=false] strict
fill ~202 ~36 ~210 ~202 ~36 ~216 minecraft:smooth_sandstone_slab[type=bottom,waterlogged=false] strict
fill ~201 ~36 ~211 ~201 ~36 ~216 minecraft:smooth_sandstone_slab[type=bottom,waterlogged=false] strict
fill ~203 ~36 ~211 ~203 ~36 ~213 minecraft:smooth_sandstone_slab[type=bottom,waterlogged=false] strict
fill ~200 ~36 ~212 ~200 ~36 ~216 minecraft:smooth_sandstone_slab[type=bottom,waterlogged=false] strict
setblock ~204 ~36 ~212 minecraft:smooth_sandstone_slab[type=bottom,waterlogged=false] strict
setblock ~119 ~36 ~220 minecraft:lantern[hanging=false,waterlogged=false] strict
setblock ~137 ~36 ~220 minecraft:lantern[hanging=false,waterlogged=false] strict
setblock ~107 ~36 ~223 minecraft:stone_brick_slab[type=bottom,waterlogged=false] strict
setblock ~149 ~36 ~223 minecraft:stone_brick_slab[type=bottom,waterlogged=false] strict
setblock ~107 ~36 ~225 minecraft:stone_brick_slab[type=bottom,waterlogged=false] strict
setblock ~149 ~36 ~225 minecraft:stone_brick_slab[type=bottom,waterlogged=false] strict
fill ~200 ~36 ~228 ~202 ~36 ~231 minecraft:smooth_sandstone_slab[type=bottom,waterlogged=false] strict
setblock ~107 ~36 ~231 minecraft:stone_brick_slab[type=bottom,waterlogged=false] strict
setblock ~149 ~36 ~231 minecraft:stone_brick_slab[type=bottom,waterlogged=false] strict
setblock ~107 ~36 ~233 minecraft:stone_brick_slab[type=bottom,waterlogged=false] strict
setblock ~149 ~36 ~233 minecraft:stone_brick_slab[type=bottom,waterlogged=false] strict
setblock ~110 ~36 ~240 minecraft:stone_brick_slab[type=bottom,waterlogged=false] strict
setblock ~146 ~36 ~240 minecraft:stone_brick_slab[type=bottom,waterlogged=false] strict
setblock ~111 ~36 ~241 minecraft:stone_brick_slab[type=bottom,waterlogged=false] strict
setblock ~145 ~36 ~241 minecraft:stone_brick_slab[type=bottom,waterlogged=false] strict
setblock ~112 ~36 ~242 minecraft:stone_brick_slab[type=bottom,waterlogged=false] strict
setblock ~144 ~36 ~242 minecraft:stone_brick_slab[type=bottom,waterlogged=false] strict
setblock ~113 ~36 ~243 minecraft:stone_brick_slab[type=bottom,waterlogged=false] strict
setblock ~143 ~36 ~243 minecraft:stone_brick_slab[type=bottom,waterlogged=false] strict
setblock ~114 ~36 ~244 minecraft:stone_brick_slab[type=bottom,waterlogged=false] strict
setblock ~142 ~36 ~244 minecraft:stone_brick_slab[type=bottom,waterlogged=false] strict
setblock ~71 ~36 ~245 minecraft:short_grass strict
setblock ~115 ~36 ~245 minecraft:stone_brick_slab[type=bottom,waterlogged=false] strict
setblock ~141 ~36 ~245 minecraft:stone_brick_slab[type=bottom,waterlogged=false] strict
setblock ~116 ~36 ~246 minecraft:stone_brick_slab[type=bottom,waterlogged=false] strict
setblock ~140 ~36 ~246 minecraft:stone_brick_slab[type=bottom,waterlogged=false] strict
setblock ~117 ~36 ~247 minecraft:stone_brick_slab[type=bottom,waterlogged=false] strict
setblock ~139 ~36 ~247 minecraft:stone_brick_slab[type=bottom,waterlogged=false] strict
setblock ~120 ~36 ~248 minecraft:stone_brick_slab[type=bottom,waterlogged=false] strict
setblock ~136 ~36 ~248 minecraft:stone_brick_slab[type=bottom,waterlogged=false] strict
setblock ~179 ~36 ~248 minecraft:short_grass strict
setblock ~123 ~36 ~249 minecraft:stone_brick_slab[type=bottom,waterlogged=false] strict
setblock ~125 ~36 ~249 minecraft:stone_brick_slab[type=bottom,waterlogged=false] strict
setblock ~131 ~36 ~249 minecraft:stone_brick_slab[type=bottom,waterlogged=false] strict
setblock ~133 ~36 ~249 minecraft:stone_brick_slab[type=bottom,waterlogged=false] strict
setblock ~206 ~36 ~249 minecraft:short_grass strict
setblock ~181 ~37 ~9 minecraft:short_grass strict
fill ~18 ~37 ~75 ~18 ~37 ~76 minecraft:mossy_stone_brick_slab[type=bottom,waterlogged=false] strict
setblock ~18 ~37 ~78 minecraft:cobblestone_slab[type=bottom,waterlogged=false] strict
setblock ~18 ~37 ~79 minecraft:stone_brick_slab[type=bottom,waterlogged=false] strict
fill ~18 ~37 ~88 ~18 ~37 ~89 minecraft:short_grass strict
setblock ~61 ~37 ~104 minecraft:short_grass strict
setblock ~125 ~37 ~118 minecraft:lantern[hanging=false,waterlogged=false] strict
setblock ~131 ~37 ~118 minecraft:lantern[hanging=false,waterlogged=false] strict
setblock ~118 ~37 ~125 minecraft:lantern[hanging=false,waterlogged=false] strict
setblock ~138 ~37 ~125 minecraft:lantern[hanging=false,waterlogged=false] strict
setblock ~118 ~37 ~131 minecraft:lantern[hanging=false,waterlogged=false] strict
setblock ~138 ~37 ~131 minecraft:lantern[hanging=false,waterlogged=false] strict
setblock ~143 ~37 ~137 minecraft:quartz_slab[type=bottom,waterlogged=false] strict
setblock ~125 ~37 ~138 minecraft:lantern[hanging=false,waterlogged=false] strict
setblock ~131 ~37 ~138 minecraft:lantern[hanging=false,waterlogged=false] strict
fill ~113 ~37 ~142 ~113 ~37 ~143 minecraft:quartz_slab[type=bottom,waterlogged=false] strict
setblock ~70 ~37 ~159 minecraft:mossy_stone_brick_slab[type=bottom,waterlogged=false] strict
setblock ~246 ~37 ~168 minecraft:short_grass strict
setblock ~9 ~37 ~174 minecraft:short_grass strict
setblock ~8 ~37 ~177 minecraft:fern strict
setblock ~218 ~37 ~177 minecraft:quartz_slab[type=bottom,waterlogged=false] strict
setblock ~8 ~37 ~180 minecraft:fern strict
setblock ~9 ~37 ~183 minecraft:short_grass strict
setblock ~247 ~37 ~184 minecraft:short_grass strict
setblock ~9 ~37 ~185 minecraft:dandelion strict
setblock ~9 ~37 ~186 minecraft:short_grass strict
setblock ~247 ~37 ~187 minecraft:short_grass strict
setblock ~10 ~37 ~189 minecraft:short_grass strict
setblock ~247 ~37 ~189 minecraft:short_grass strict
setblock ~248 ~38 ~8 minecraft:short_grass strict
setblock ~170 ~38 ~9 minecraft:short_grass strict
setblock ~172 ~38 ~9 minecraft:short_grass strict
setblock ~173 ~38 ~9 minecraft:bush strict
setblock ~176 ~38 ~9 minecraft:short_grass strict
setblock ~17 ~38 ~75 minecraft:stone_brick_slab[type=bottom,waterlogged=false] strict
setblock ~188 ~38 ~77 minecraft:polished_blackstone_slab[type=bottom,waterlogged=false] strict
setblock ~9 ~38 ~170 minecraft:short_grass strict
setblock ~9 ~38 ~172 minecraft:short_grass strict
setblock ~247 ~38 ~172 minecraft:short_grass strict
setblock ~247 ~38 ~175 minecraft:fern strict
setblock ~247 ~38 ~176 minecraft:short_grass strict
setblock ~6 ~38 ~178 minecraft:short_grass strict
setblock ~6 ~38 ~180 minecraft:short_grass strict
setblock ~247 ~38 ~181 minecraft:short_grass strict
setblock ~7 ~38 ~182 minecraft:bush strict
setblock ~247 ~38 ~182 minecraft:fern strict
fill ~8 ~38 ~184 ~8 ~38 ~185 minecraft:short_grass strict
setblock ~9 ~38 ~187 minecraft:bush strict
fill ~9 ~38 ~190 ~9 ~38 ~192 minecraft:short_grass strict
fill ~74 ~38 ~246 ~76 ~38 ~246 minecraft:short_grass strict
setblock ~207 ~38 ~250 minecraft:short_grass strict
setblock ~210 ~38 ~250 minecraft:short_grass strict
setblock ~189 ~39 ~77 minecraft:polished_blackstone_slab[type=bottom,waterlogged=false] strict
setblock ~143 ~39 ~134 minecraft:quartz_slab[type=bottom,waterlogged=false] strict
setblock ~9 ~39 ~165 minecraft:short_grass strict
fill ~247 ~39 ~165 ~247 ~39 ~168 minecraft:short_grass strict
setblock ~9 ~39 ~167 minecraft:short_grass strict
setblock ~9 ~39 ~169 minecraft:short_grass strict
setblock ~8 ~39 ~173 minecraft:short_grass strict
setblock ~248 ~39 ~173 minecraft:fern strict
fill ~248 ~39 ~175 ~248 ~39 ~176 minecraft:short_grass strict
setblock ~5 ~39 ~179 minecraft:fern strict
setblock ~5 ~39 ~181 minecraft:bush strict
setblock ~6 ~39 ~183 minecraft:short_grass strict
fill ~248 ~39 ~183 ~248 ~39 ~184 minecraft:short_grass strict
setblock ~248 ~39 ~187 minecraft:short_grass strict
setblock ~248 ~39 ~188 minecraft:bush strict
setblock ~8 ~39 ~189 minecraft:fern strict
setblock ~248 ~39 ~190 minecraft:short_grass strict
fill ~248 ~39 ~192 ~248 ~39 ~193 minecraft:short_grass strict
setblock ~82 ~39 ~247 minecraft:short_grass strict
setblock ~208 ~39 ~251 minecraft:fern strict
setblock ~70 ~40 ~6 minecraft:short_grass strict
setblock ~73 ~40 ~6 minecraft:short_grass strict
setblock ~9 ~40 ~7 minecraft:short_grass strict
setblock ~172 ~40 ~8 minecraft:short_grass strict
setblock ~173 ~40 ~8 minecraft:allium strict
setblock ~176 ~40 ~8 minecraft:short_grass strict
setblock ~249 ~40 ~9 minecraft:fern strict
setblock ~7 ~40 ~78 minecraft:short_grass strict
setblock ~8 ~40 ~92 minecraft:short_grass strict
setblock ~8 ~40 ~93 minecraft:fern strict
fill ~122 ~40 ~113 ~123 ~40 ~113 minecraft:quartz_slab[type=bottom,waterlogged=false] strict
fill ~112 ~40 ~138 ~114 ~40 ~138 minecraft:quartz_slab[type=bottom,waterlogged=false] strict
setblock ~113 ~40 ~139 minecraft:quartz_slab[type=bottom,waterlogged=false] strict
setblock ~133 ~40 ~142 minecraft:quartz_slab[type=bottom,waterlogged=false] strict
setblock ~247 ~40 ~164 minecraft:short_grass strict
setblock ~8 ~40 ~169 minecraft:bush strict
fill ~248 ~40 ~169 ~248 ~40 ~170 minecraft:short_grass strict
setblock ~8 ~40 ~170 minecraft:dandelion strict
setblock ~7 ~40 ~172 minecraft:short_grass strict
setblock ~4 ~40 ~179 minecraft:short_grass strict
setblock ~4 ~40 ~181 minecraft:bush strict
setblock ~249 ~40 ~189 minecraft:allium strict
fill ~249 ~40 ~192 ~249 ~40 ~196 minecraft:short_grass strict
setblock ~249 ~40 ~200 minecraft:short_grass strict
setblock ~89 ~40 ~248 minecraft:short_grass strict
setblock ~239 ~41 ~6 minecraft:short_grass strict
setblock ~181 ~41 ~7 minecraft:bush strict
setblock ~6 ~41 ~14 minecraft:short_grass strict
setblock ~251 ~41 ~17 minecraft:short_grass strict
setblock ~6 ~41 ~45 minecraft:short_grass strict
setblock ~132 ~41 ~143 minecraft:quartz_slab[type=bottom,waterlogged=false] strict
setblock ~8 ~41 ~162 minecraft:short_grass strict
fill ~8 ~41 ~164 ~8 ~41 ~165 minecraft:short_grass strict
setblock ~7 ~41 ~171 minecraft:short_grass strict
setblock ~249 ~41 ~172 minecraft:oxeye_daisy strict
fill ~249 ~41 ~173 ~249 ~41 ~174 minecraft:short_grass strict
fill ~249 ~41 ~176 ~249 ~41 ~177 minecraft:short_grass strict
fill ~4 ~41 ~183 ~4 ~41 ~186 minecraft:short_grass strict
setblock ~249 ~41 ~183 minecraft:fern strict
setblock ~249 ~41 ~184 minecraft:short_grass strict
fill ~5 ~41 ~185 ~5 ~41 ~186 minecraft:short_grass strict
fill ~249 ~41 ~186 ~249 ~41 ~187 minecraft:short_grass strict
setblock ~6 ~41 ~191 minecraft:short_grass strict
setblock ~6 ~41 ~192 minecraft:bush strict
setblock ~250 ~41 ~196 minecraft:short_grass strict
setblock ~250 ~41 ~198 minecraft:short_grass strict
setblock ~215 ~41 ~201 minecraft:campfire[facing=north,lit=true,signal_fire=false,waterlogged=false] strict
setblock ~230 ~41 ~201 minecraft:campfire[facing=north,lit=true,signal_fire=false,waterlogged=false] strict
setblock ~213 ~41 ~202 minecraft:campfire[facing=north,lit=true,signal_fire=false,waterlogged=false] strict
setblock ~202 ~41 ~213 minecraft:campfire[facing=north,lit=true,signal_fire=false,waterlogged=false] strict
setblock ~201 ~41 ~215 minecraft:campfire[facing=north,lit=true,signal_fire=false,waterlogged=false] strict
setblock ~251 ~41 ~215 minecraft:short_grass strict
setblock ~251 ~41 ~216 minecraft:fern strict
setblock ~201 ~41 ~230 minecraft:campfire[facing=north,lit=true,signal_fire=false,waterlogged=false] strict
setblock ~89 ~41 ~249 minecraft:short_grass strict
setblock ~98 ~41 ~249 minecraft:short_grass strict
fill ~68 ~42 ~5 ~69 ~42 ~5 minecraft:short_grass strict
setblock ~71 ~42 ~5 minecraft:short_grass strict
setblock ~9 ~42 ~6 minecraft:short_grass strict
setblock ~248 ~42 ~6 minecraft:short_grass strict
setblock ~250 ~42 ~10 minecraft:short_grass strict
setblock ~6 ~42 ~13 minecraft:short_grass strict
setblock ~4 ~42 ~38 minecraft:short_grass strict
setblock ~4 ~42 ~39 minecraft:fern strict
fill ~5 ~42 ~42 ~5 ~42 ~43 minecraft:short_grass strict
fill ~119 ~42 ~119 ~131 ~42 ~119 minecraft:smooth_quartz_slab[type=bottom,waterlogged=false] strict
fill ~119 ~42 ~120 ~119 ~42 ~125 minecraft:smooth_quartz_slab[type=bottom,waterlogged=false] strict
fill ~137 ~42 ~126 ~137 ~42 ~137 minecraft:smooth_quartz_slab[type=bottom,waterlogged=false] strict
fill ~119 ~42 ~127 ~119 ~42 ~128 minecraft:smooth_quartz_slab[type=bottom,waterlogged=false] strict
fill ~119 ~42 ~130 ~119 ~42 ~132 minecraft:smooth_quartz_slab[type=bottom,waterlogged=false] strict
fill ~124 ~42 ~137 ~136 ~42 ~137 minecraft:smooth_quartz_slab[type=bottom,waterlogged=false] strict
setblock ~7 ~42 ~166 minecraft:fern strict
setblock ~7 ~42 ~167 minecraft:short_grass strict
fill ~249 ~42 ~168 ~249 ~42 ~170 minecraft:short_grass strict
setblock ~7 ~42 ~169 minecraft:short_grass strict
setblock ~6 ~42 ~171 minecraft:short_grass strict
setblock ~4 ~42 ~174 minecraft:short_grass strict
setblock ~250 ~42 ~176 minecraft:short_grass strict
setblock ~250 ~42 ~177 minecraft:bush strict
setblock ~250 ~42 ~178 minecraft:fern strict
fill ~250 ~42 ~180 ~250 ~42 ~182 minecraft:short_grass strict
setblock ~250 ~42 ~186 minecraft:short_grass strict
setblock ~5 ~42 ~192 minecraft:short_grass strict
setblock ~250 ~42 ~192 minecraft:short_grass strict
setblock ~251 ~42 ~196 minecraft:fern strict
fill ~251 ~42 ~198 ~251 ~42 ~199 minecraft:short_grass strict
setblock ~251 ~42 ~200 minecraft:fern strict
setblock ~251 ~42 ~211 minecraft:short_grass strict
setblock ~251 ~42 ~213 minecraft:short_grass strict
setblock ~249 ~42 ~247 minecraft:short_grass strict
setblock ~85 ~42 ~249 minecraft:short_grass strict
setblock ~247 ~42 ~249 minecraft:short_grass strict
setblock ~249 ~42 ~249 minecraft:short_grass strict
setblock ~90 ~42 ~250 minecraft:short_grass strict
setblock ~92 ~42 ~250 minecraft:short_grass strict
setblock ~94 ~42 ~250 minecraft:short_grass strict
fill ~51 ~42 ~251 ~52 ~42 ~251 minecraft:short_grass strict
setblock ~181 ~42 ~251 minecraft:short_grass strict
setblock ~183 ~42 ~251 minecraft:fern strict
setblock ~184 ~42 ~251 minecraft:short_grass strict
setblock ~63 ~43 ~5 minecraft:short_grass strict
setblock ~65 ~43 ~5 minecraft:short_grass strict
setblock ~75 ~43 ~5 minecraft:short_grass strict
setblock ~231 ~43 ~5 minecraft:azure_bluet strict
setblock ~233 ~43 ~5 minecraft:short_grass strict
setblock ~235 ~43 ~5 minecraft:short_grass strict
fill ~237 ~43 ~5 ~239 ~43 ~5 minecraft:short_grass strict
setblock ~4 ~43 ~6 minecraft:short_grass strict
setblock ~179 ~43 ~6 minecraft:short_grass strict
setblock ~182 ~43 ~6 minecraft:short_grass strict
setblock ~184 ~43 ~6 minecraft:short_grass strict
fill ~5 ~43 ~13 ~5 ~43 ~15 minecraft:short_grass strict
setblock ~4 ~43 ~41 minecraft:short_grass strict
setblock ~250 ~43 ~66 minecraft:short_grass strict
setblock ~7 ~43 ~162 minecraft:short_grass strict
setblock ~7 ~43 ~164 minecraft:short_grass strict
setblock ~6 ~43 ~169 minecraft:short_grass strict
fill ~250 ~43 ~171 ~250 ~43 ~172 minecraft:short_grass strict
setblock ~5 ~43 ~172 minecraft:short_grass strict
setblock ~250 ~43 ~174 minecraft:short_grass strict
setblock ~251 ~43 ~186 minecraft:short_grass strict
setblock ~251 ~43 ~190 minecraft:short_grass strict
setblock ~4 ~43 ~191 minecraft:short_grass strict
setblock ~251 ~43 ~192 minecraft:bush strict
setblock ~251 ~43 ~193 minecraft:short_grass strict
fill ~250 ~43 ~249 ~250 ~43 ~250 minecraft:short_grass strict
