setblock ~251 ~41 ~216 minecraft:fern strict
setblock ~201 ~41 ~230 minecraft:campfire[facing=north,lit=true,signal_fire=false,waterlogged=false] strict
setblock ~89 ~41 ~249 minecraft:short_grass strict
setblock ~98 ~41 ~249 minecraft:short_grass strict
fill ~68 ~42 ~5 ~69 ~42 ~5 minecraft:short_grass strict
setblock ~71 ~42 ~5 minecraft:short_grass strict
setblock ~9 ~42 ~6 minecraft:short_grass strict
setblock ~248 ~42 ~6 minecraft:short_grass strict
setblock ~250 ~42 ~10 minecraft:short_grass strict
setblock ~6 ~42 ~13 minecraft:short_grass strict
setblock ~4 ~42 ~38 minecraft:short_grass strict
setblock ~4 ~42 ~39 minecraft:fern strict
fill ~5 ~42 ~42 ~5 ~42 ~43 minecraft:short_grass strict
fill ~119 ~42 ~119 ~131 ~42 ~119 minecraft:smooth_quartz_slab[type=bottom,waterlogged=false] strict
fill ~119 ~42 ~120 ~119 ~42 ~125 minecraft:smooth_quartz_slab[type=bottom,waterlogged=false] strict
fill ~137 ~42 ~126 ~137 ~42 ~137 minecraft:smooth_quartz_slab[type=bottom,waterlogged=false] strict
fill ~119 ~42 ~127 ~119 ~42 ~128 minecraft:smooth_quartz_slab[type=bottom,waterlogged=false] strict
fill ~119 ~42 ~130 ~119 ~42 ~132 minecraft:smooth_quartz_slab[type=bottom,waterlogged=false] strict
fill ~124 ~42 ~137 ~136 ~42 ~137 minecraft:smooth_quartz_slab[type=bottom,waterlogged=false] strict
setblock ~7 ~42 ~166 minecraft:fern strict
setblock ~7 ~42 ~167 minecraft:short_grass strict
fill ~249 ~42 ~168 ~249 ~42 ~170 minecraft:short_grass strict
setblock ~7 ~42 ~169 minecraft:short_grass strict
setblock ~6 ~42 ~171 minecraft:short_grass strict
setblock ~4 ~42 ~174 minecraft:short_grass strict
setblock ~250 ~42 ~176 minecraft:short_grass strict
setblock ~250 ~42 ~177 minecraft:bush strict
setblock ~250 ~42 ~178 minecraft:fern strict
fill ~250 ~42 ~180 ~250 ~42 ~182 minecraft:short_grass strict
setblock ~250 ~42 ~186 minecraft:short_grass strict
setblock ~5 ~42 ~192 minecraft:short_grass strict
setblock ~250 ~42 ~192 minecraft:short_grass strict
setblock ~251 ~42 ~196 minecraft:fern strict
fill ~251 ~42 ~198 ~251 ~42 ~199 minecraft:short_grass strict
setblock ~251 ~42 ~200 minecraft:fern strict
setblock ~251 ~42 ~211 minecraft:short_grass strict
setblock ~251 ~42 ~213 minecraft:short_grass strict
setblock ~249 ~42 ~247 minecraft:short_grass strict
setblock ~85 ~42 ~249 minecraft:short_grass strict
setblock ~247 ~42 ~249 minecraft:short_grass strict
setblock ~249 ~42 ~249 minecraft:short_grass strict
setblock ~90 ~42 ~250 minecraft:short_grass strict
setblock ~92 ~42 ~250 minecraft:short_grass strict
setblock ~94 ~42 ~250 minecraft:short_grass strict
fill ~51 ~42 ~251 ~52 ~42 ~251 minecraft:short_grass strict
setblock ~181 ~42 ~251 minecraft:short_grass strict
setblock ~183 ~42 ~251 minecraft:fern strict
setblock ~184 ~42 ~251 minecraft:short_grass strict
setblock ~63 ~43 ~5 minecraft:short_grass strict
setblock ~65 ~43 ~5 minecraft:short_grass strict
setblock ~75 ~43 ~5 minecraft:short_grass strict
setblock ~231 ~43 ~5 minecraft:azure_bluet strict
setblock ~233 ~43 ~5 minecraft:short_grass strict
setblock ~235 ~43 ~5 minecraft:short_grass strict
fill ~237 ~43 ~5 ~239 ~43 ~5 minecraft:short_grass strict
setblock ~4 ~43 ~6 minecraft:short_grass strict
setblock ~179 ~43 ~6 minecraft:short_grass strict
setblock ~182 ~43 ~6 minecraft:short_grass strict
setblock ~184 ~43 ~6 minecraft:short_grass strict
fill ~5 ~43 ~13 ~5 ~43 ~15 minecraft:short_grass strict
setblock ~4 ~43 ~41 minecraft:short_grass strict
setblock ~250 ~43 ~66 minecraft:short_grass strict
setblock ~7 ~43 ~162 minecraft:short_grass strict
setblock ~7 ~43 ~164 minecraft:short_grass strict
setblock ~6 ~43 ~169 minecraft:short_grass strict
fill ~250 ~43 ~171 ~250 ~43 ~172 minecraft:short_grass strict
setblock ~5 ~43 ~172 minecraft:short_grass strict
setblock ~250 ~43 ~174 minecraft:short_grass strict
setblock ~251 ~43 ~186 minecraft:short_grass strict
setblock ~251 ~43 ~190 minecraft:short_grass strict
setblock ~4 ~43 ~191 minecraft:short_grass strict
setblock ~251 ~43 ~192 minecraft:bush strict
setblock ~251 ~43 ~193 minecraft:short_grass strict
fill ~250 ~43 ~249 ~250 ~43 ~250 minecraft:short_grass strict
setblock ~5 ~43 ~250 minecraft:short_grass strict
setblock ~87 ~43 ~250 minecraft:short_grass strict
setblock ~99 ~43 ~250 minecraft:short_grass strict
setblock ~43 ~43 ~251 minecraft:fern strict
setblock ~91 ~43 ~251 minecraft:short_grass strict
setblock ~66 ~44 ~4 minecraft:short_grass strict
setblock ~67 ~44 ~4 minecraft:bush strict
setblock ~70 ~44 ~4 minecraft:short_grass strict
setblock ~75 ~44 ~4 minecraft:short_grass strict
setblock ~231 ~44 ~4 minecraft:short_grass strict
setblock ~234 ~44 ~4 minecraft:fern strict
setblock ~9 ~44 ~5 minecraft:short_grass strict
setblock ~11 ~44 ~5 minecraft:short_grass strict
setblock ~180 ~44 ~5 minecraft:short_grass strict
setblock ~186 ~44 ~5 minecraft:short_grass strict
setblock ~4 ~44 ~10 minecraft:fern strict
setblock ~251 ~44 ~10 minecraft:short_grass strict
setblock ~4 ~44 ~11 minecraft:short_grass strict
setblock ~4 ~44 ~13 minecraft:fern strict
setblock ~4 ~44 ~15 minecraft:poppy strict
fill ~4 ~44 ~16 ~4 ~44 ~17 minecraft:short_grass strict
setblock ~251 ~44 ~47 minecraft:short_grass strict
setblock ~5 ~44 ~78 minecraft:short_grass strict
setblock ~6 ~44 ~92 minecraft:short_grass strict
setblock ~6 ~44 ~94 minecraft:short_grass strict
fill ~6 ~44 ~165 ~6 ~44 ~166 minecraft:short_grass strict
setblock ~250 ~44 ~169 minecraft:short_grass strict
setblock ~5 ~44 ~171 minecraft:short_grass strict
setblock ~251 ~44 ~172 minecraft:fern strict
setblock ~251 ~44 ~173 minecraft:short_grass strict
fill ~251 ~44 ~175 ~251 ~44 ~176 minecraft:short_grass strict
setblock ~251 ~44 ~178 minecraft:short_grass strict
setblock ~5 ~44 ~243 minecraft:fern strict
fill ~5 ~44 ~244 ~5 ~44 ~245 minecraft:short_grass strict
fill ~4 ~44 ~246 ~4 ~44 ~247 minecraft:short_grass strict
setblock ~4 ~44 ~250 minecraft:fern strict
setblock ~246 ~44 ~250 minecraft:short_grass strict
setblock ~249 ~44 ~250 minecraft:short_grass strict
setblock ~59 ~44 ~251 minecraft:short_grass strict
setblock ~95 ~44 ~251 minecraft:short_grass strict
setblock ~99 ~44 ~251 minecraft:azure_bluet strict
fill ~102 ~44 ~251 ~103 ~44 ~251 minecraft:short_grass strict
setblock ~170 ~44 ~251 minecraft:short_grass strict
setblock ~33 ~45 ~4 minecraft:bush strict
setblock ~34 ~45 ~4 minecraft:fern strict
setblock ~39 ~45 ~4 minecraft:short_grass strict
setblock ~42 ~45 ~4 minecraft:short_grass strict
setblock ~62 ~45 ~4 minecraft:short_grass strict
setblock ~238 ~45 ~4 minecraft:fern strict
setblock ~242 ~45 ~4 minecraft:short_grass strict
setblock ~243 ~45 ~4 minecraft:bush strict
setblock ~251 ~45 ~5 minecraft:short_grass strict
setblock ~163 ~45 ~6 minecraft:short_grass strict
setblock ~168 ~45 ~6 minecraft:fern strict
fill ~251 ~45 ~50 ~251 ~45 ~51 minecraft:short_grass strict
setblock ~251 ~45 ~54 minecraft:short_grass strict
setblock ~251 ~45 ~69 minecraft:short_grass strict
setblock ~5 ~45 ~91 minecraft:short_grass strict
fill ~251 ~45 ~154 ~251 ~45 ~155 minecraft:short_grass strict
setblock ~6 ~45 ~162 minecraft:short_grass strict
setblock ~5 ~45 ~168 minecraft:short_grass strict
setblock ~251 ~45 ~169 minecraft:short_grass strict
setblock ~4 ~45 ~243 minecraft:short_grass strict
setblock ~4 ~45 ~244 minecraft:allium strict
setblock ~251 ~45 ~249 minecraft:short_grass strict
setblock ~86 ~45 ~251 minecraft:short_grass strict
setblock ~167 ~45 ~251 minecraft:short_grass strict
setblock ~251 ~45 ~251 minecraft:short_grass strict
fill ~13 ~46 ~4 ~14 ~46 ~4 minecraft:short_grass strict
fill ~16 ~46 ~4 ~17 ~46 ~4 minecraft:short_grass strict
setblock ~30 ~46 ~4 minecraft:short_grass strict
setblock ~60 ~46 ~4 minecraft:short_grass strict
setblock ~178 ~46 ~4 minecraft:short_grass strict
setblock ~179 ~46 ~4 minecraft:bush strict
fill ~180 ~46 ~4 ~182 ~46 ~4 minecraft:short_grass strict
setblock ~183 ~46 ~4 minecraft:oxeye_daisy strict
fill ~225 ~46 ~4 ~226 ~46 ~4 minecraft:short_grass strict
setblock ~4 ~46 ~80 minecraft:dandelion strict
setblock ~4 ~46 ~81 minecraft:short_grass strict
fill ~5 ~46 ~94 ~5 ~46 ~95 minecraft:short_grass strict
setblock ~5 ~46 ~164 minecraft:short_grass strict
setblock ~4 ~46 ~168 minecraft:short_grass strict
setblock ~4 ~46 ~198 minecraft:short_grass strict
setblock ~246 ~46 ~251 minecraft:short_grass strict
setblock ~51 ~47 ~4 minecraft:short_grass strict
setblock ~176 ~47 ~4 minecraft:short_grass strict
setblock ~96 ~47 ~5 minecraft:short_grass strict
setblock ~169 ~47 ~5 minecraft:short_grass strict
setblock ~170 ~47 ~5 minecraft:fern strict
setblock ~251 ~47 ~76 minecraft:short_grass strict
setblock ~4 ~47 ~91 minecraft:short_grass strict
setblock ~4 ~47 ~92 minecraft:bush strict
setblock ~4 ~47 ~110 minecraft:short_grass strict
setblock ~119 ~47 ~141 minecraft:smooth_quartz_slab[type=bottom,waterlogged=false] strict
fill ~4 ~47 ~165 ~4 ~47 ~166 minecraft:short_grass strict
setblock ~8 ~47 ~215 minecraft:lantern[hanging=false,waterlogged=false] strict
setblock ~41 ~47 ~248 minecraft:lantern[hanging=false,waterlogged=false] strict
setblock ~22 ~48 ~4 minecraft:short_grass strict
fill ~24 ~48 ~4 ~25 ~48 ~4 minecraft:short_grass strict
setblock ~165 ~48 ~4 minecraft:short_grass strict
setblock ~169 ~48 ~4 minecraft:short_grass strict
setblock ~4 ~48 ~95 minecraft:short_grass strict
fill ~4 ~48 ~147 ~4 ~48 ~148 minecraft:short_grass strict
setblock ~4 ~48 ~164 minecraft:short_grass strict
setblock ~4 ~48 ~203 minecraft:fern strict
setblock ~95 ~49 ~4 minecraft:short_grass strict
setblock ~163 ~49 ~4 minecraft:short_grass strict
fill ~113 ~49 ~113 ~118 ~49 ~113 minecraft:smooth_quartz_slab[type=bottom,waterlogged=false] strict
fill ~133 ~49 ~113 ~143 ~49 ~113 minecraft:smooth_quartz_slab[type=bottom,waterlogged=false] strict
fill ~113 ~49 ~114 ~113 ~49 ~133 minecraft:smooth_quartz_slab[type=bottom,waterlogged=false] strict
fill ~143 ~49 ~123 ~143 ~49 ~128 minecraft:smooth_quartz_slab[type=bottom,waterlogged=false] strict
fill ~118 ~49 ~143 ~123 ~49 ~143 minecraft:smooth_quartz_slab[type=bottom,waterlogged=false] strict
fill ~138 ~49 ~143 ~143 ~49 ~143 minecraft:smooth_quartz_slab[type=bottom,waterlogged=false] strict
setblock ~4 ~49 ~150 minecraft:fern strict
setblock ~91 ~50 ~4 minecraft:short_grass strict
setblock ~94 ~50 ~4 minecraft:short_grass strict
setblock ~4 ~50 ~155 minecraft:short_grass strict
setblock ~138 ~54 ~117 minecraft:smooth_quartz_slab[type=bottom,waterlogged=false] strict
setblock ~118 ~54 ~141 minecraft:smooth_quartz_slab[type=bottom,waterlogged=false] strict
setblock ~123 ~93 ~115 minecraft:lantern[hanging=false,waterlogged=false] strict
setblock ~133 ~93 ~115 minecraft:lantern[hanging=false,waterlogged=false] strict
setblock ~115 ~93 ~123 minecraft:lantern[hanging=false,waterlogged=false] strict
setblock ~141 ~93 ~123 minecraft:lantern[hanging=false,waterlogged=false] strict
setblock ~115 ~93 ~133 minecraft:lantern[hanging=false,waterlogged=false] strict
setblock ~141 ~93 ~133 minecraft:lantern[hanging=false,waterlogged=false] strict
setblock ~123 ~93 ~141 minecraft:lantern[hanging=false,waterlogged=false] strict
setblock ~133 ~93 ~141 minecraft:lantern[hanging=false,waterlogged=false] strict
