setblock ~5 ~42 ~69 minecraft:short_grass strict
fill ~7 ~42 ~89 ~7 ~42 ~90 minecraft:short_grass strict
fill ~119 ~42 ~119 ~123 ~42 ~119 minecraft:smooth_quartz_slab[type=bottom,waterlogged=false] strict
fill ~126 ~42 ~119 ~131 ~42 ~119 minecraft:smooth_quartz_slab[type=bottom,waterlogged=false] strict
fill ~119 ~42 ~120 ~119 ~42 ~123 minecraft:smooth_quartz_slab[type=bottom,waterlogged=false] strict
fill ~119 ~42 ~125 ~119 ~42 ~127 minecraft:smooth_quartz_slab[type=bottom,waterlogged=false] strict
fill ~137 ~42 ~125 ~137 ~42 ~128 minecraft:smooth_quartz_slab[type=bottom,waterlogged=false] strict
fill ~119 ~42 ~129 ~119 ~42 ~132 minecraft:smooth_quartz_slab[type=bottom,waterlogged=false] strict
fill ~137 ~42 ~130 ~137 ~42 ~137 minecraft:smooth_quartz_slab[type=bottom,waterlogged=false] strict
fill ~124 ~42 ~137 ~136 ~42 ~137 minecraft:smooth_quartz_slab[type=bottom,waterlogged=false] strict
setblock ~6 ~42 ~171 minecraft:short_grass strict
setblock ~4 ~42 ~174 minecraft:short_grass strict
setblock ~4 ~42 ~187 minecraft:fern strict
setblock ~250 ~42 ~190 minecraft:short_grass strict
setblock ~251 ~42 ~203 minecraft:short_grass strict
setblock ~6 ~42 ~246 minecraft:short_grass strict
setblock ~249 ~42 ~247 minecraft:short_grass strict
fill ~6 ~42 ~249 ~6 ~42 ~250 minecraft:short_grass strict
setblock ~86 ~42 ~249 minecraft:short_grass strict
setblock ~88 ~42 ~250 minecraft:short_grass strict
setblock ~95 ~42 ~250 minecraft:fern strict
fill ~179 ~42 ~251 ~180 ~42 ~251 minecraft:short_grass strict
setblock ~183 ~42 ~251 minecraft:short_grass strict
fill ~190 ~42 ~251 ~191 ~42 ~251 minecraft:short_grass strict
setblock ~193 ~42 ~251 minecraft:short_grass strict
fill ~198 ~42 ~251 ~199 ~42 ~251 minecraft:short_grass strict
setblock ~192 ~43 ~5 minecraft:short_grass strict
setblock ~4 ~43 ~6 minecraft:short_grass strict
setblock ~12 ~43 ~6 minecraft:short_grass strict
setblock ~5 ~43 ~12 minecraft:short_grass strict
setblock ~251 ~43 ~25 minecraft:oxeye_daisy strict
setblock ~251 ~43 ~26 minecraft:short_grass strict
setblock ~4 ~43 ~33 minecraft:short_grass strict
setblock ~251 ~43 ~42 minecraft:short_grass strict
setblock ~5 ~43 ~47 minecraft:fern strict
setblock ~5 ~43 ~55 minecraft:short_grass strict
setblock ~5 ~43 ~74 minecraft:short_grass strict
setblock ~250 ~43 ~150 minecraft:fern strict
setblock ~249 ~43 ~165 minecraft:oxeye_daisy strict
setblock ~249 ~43 ~166 minecraft:short_grass strict
setblock ~251 ~43 ~179 minecraft:short_grass strict
setblock ~251 ~43 ~182 minecraft:short_grass strict
setblock ~251 ~43 ~205 minecraft:short_grass strict
setblock ~251 ~43 ~207 minecraft:short_grass strict
setblock ~5 ~43 ~239 minecraft:short_grass strict
setblock ~5 ~43 ~247 minecraft:short_grass strict
setblock ~5 ~44 ~4 minecraft:fern strict
setblock ~75 ~44 ~4 minecraft:short_grass strict
setblock ~107 ~44 ~5 minecraft:short_grass strict
setblock ~181 ~44 ~5 minecraft:short_grass strict
setblock ~249 ~44 ~5 minecraft:short_grass strict
setblock ~250 ~44 ~5 minecraft:bush strict
setblock ~4 ~44 ~20 minecraft:short_grass strict
fill ~4 ~44 ~22 ~4 ~44 ~23 minecraft:short_grass strict
fill ~4 ~44 ~59 ~4 ~44 ~60 minecraft:short_grass strict
setblock ~4 ~44 ~66 minecraft:short_grass strict
setblock ~4 ~44 ~74 minecraft:short_grass strict
setblock ~6 ~44 ~87 minecraft:short_grass strict
setblock ~6 ~44 ~89 minecraft:short_grass strict
setblock ~250 ~44 ~166 minecraft:short_grass strict
setblock ~6 ~44 ~167 minecraft:short_grass strict
setblock ~251 ~44 ~178 minecraft:short_grass strict
setblock ~4 ~44 ~195 minecraft:short_grass strict
setblock ~250 ~44 ~244 minecraft:short_grass strict
setblock ~4 ~44 ~246 minecraft:short_grass strict
setblock ~4 ~44 ~251 minecraft:short_grass strict
setblock ~8 ~45 ~4 minecraft:short_grass strict
setblock ~76 ~45 ~4 minecraft:short_grass strict
setblock ~238 ~45 ~4 minecraft:short_grass strict
setblock ~243 ~45 ~4 minecraft:short_grass strict
setblock ~81 ~45 ~5 minecraft:short_grass strict
setblock ~103 ~45 ~5 minecraft:short_grass strict
setblock ~178 ~45 ~5 minecraft:short_grass strict
setblock ~4 ~45 ~24 minecraft:short_grass strict
setblock ~251 ~45 ~52 minecraft:short_grass strict
setblock ~4 ~45 ~53 minecraft:short_grass strict
setblock ~4 ~45 ~55 minecraft:short_grass strict
setblock ~251 ~45 ~58 minecraft:fern strict
setblock ~5 ~45 ~81 minecraft:short_grass strict
setblock ~251 ~45 ~85 minecraft:short_grass strict
fill ~251 ~45 ~87 ~251 ~45 ~88 minecraft:short_grass strict
setblock ~251 ~45 ~90 minecraft:fern strict
setblock ~251 ~45 ~153 minecraft:short_grass strict
setblock ~250 ~45 ~161 minecraft:short_grass strict
setblock ~250 ~45 ~163 minecraft:short_grass strict
setblock ~251 ~45 ~168 minecraft:fern strict
setblock ~251 ~45 ~248 minecraft:fern strict
setblock ~249 ~45 ~251 minecraft:short_grass strict
setblock ~16 ~46 ~4 minecraft:short_grass strict
setblock ~54 ~46 ~4 minecraft:fern strict
fill ~79 ~46 ~4 ~80 ~46 ~4 minecraft:short_grass strict
setblock ~184 ~46 ~4 minecraft:bush strict
setblock ~224 ~46 ~4 minecraft:fern strict
setblock ~99 ~46 ~5 minecraft:short_grass strict
setblock ~4 ~46 ~81 minecraft:short_grass strict
setblock ~5 ~46 ~96 minecraft:short_grass strict
setblock ~5 ~46 ~100 minecraft:short_grass strict
fill ~5 ~46 ~103 ~5 ~46 ~104 minecraft:short_grass strict
setblock ~251 ~46 ~158 minecraft:short_grass strict
fill ~251 ~46 ~165 ~251 ~46 ~166 minecraft:short_grass strict
setblock ~4 ~46 ~199 minecraft:short_grass strict
setblock ~81 ~47 ~4 minecraft:short_grass strict
setblock ~83 ~47 ~4 minecraft:fern strict
setblock ~166 ~47 ~5 minecraft:short_grass strict
setblock ~169 ~47 ~5 minecraft:short_grass strict
fill ~5 ~47 ~162 ~5 ~47 ~163 minecraft:short_grass strict
setblock ~251 ~47 ~162 minecraft:short_grass strict
setblock ~4 ~47 ~167 minecraft:short_grass strict
setblock ~25 ~48 ~4 minecraft:short_grass strict
setblock ~99 ~48 ~4 minecraft:short_grass strict
setblock ~148 ~48 ~4 minecraft:short_grass strict
setblock ~168 ~48 ~4 minecraft:short_grass strict
setblock ~4 ~48 ~95 minecraft:short_grass strict
setblock ~4 ~48 ~100 minecraft:fern strict
setblock ~4 ~48 ~101 minecraft:short_grass strict
setblock ~4 ~48 ~163 minecraft:short_grass strict
setblock ~204 ~49 ~4 minecraft:fern strict
fill ~113 ~49 ~113 ~118 ~49 ~113 minecraft:smooth_quartz_slab[type=bottom,waterlogged=false] strict
fill ~123 ~49 ~113 ~143 ~49 ~113 minecraft:smooth_quartz_slab[type=bottom,waterlogged=false] strict
fill ~113 ~49 ~114 ~113 ~49 ~118 minecraft:smooth_quartz_slab[type=bottom,waterlogged=false] strict
setblock ~139 ~49 ~114 minecraft:smooth_quartz_slab[type=bottom,waterlogged=false] strict
fill ~143 ~49 ~114 ~143 ~49 ~128 minecraft:smooth_quartz_slab[type=bottom,waterlogged=false] strict
fill ~113 ~49 ~133 ~113 ~49 ~143 minecraft:smooth_quartz_slab[type=bottom,waterlogged=false] strict
setblock ~114 ~49 ~138 minecraft:smooth_quartz_slab[type=bottom,waterlogged=false] strict
fill ~114 ~49 ~143 ~143 ~49 ~143 minecraft:smooth_quartz_slab[type=bottom,waterlogged=false] strict
setblock ~4 ~49 ~154 minecraft:short_grass strict
setblock ~4 ~49 ~208 minecraft:short_grass strict
setblock ~151 ~50 ~4 minecraft:short_grass strict
setblock ~158 ~50 ~4 minecraft:fern strict
setblock ~4 ~50 ~157 minecraft:short_grass strict
setblock ~142 ~52 ~116 minecraft:smooth_quartz_slab[type=bottom,waterlogged=false] strict
setblock ~139 ~53 ~115 minecraft:smooth_quartz_slab[type=bottom,waterlogged=false] strict
fill ~140 ~53 ~117 ~140 ~54 ~117 minecraft:smooth_quartz_slab[type=bottom,waterlogged=false] strict
setblock ~117 ~53 ~142 minecraft:smooth_quartz_slab[type=bottom,waterlogged=false] strict
setblock ~138 ~54 ~115 minecraft:smooth_quartz_slab[type=bottom,waterlogged=false] strict
