fill ~224 ~48 ~64 ~255 ~63 ~95 minecraft:air strict
fill ~224 ~32 ~64 ~255 ~47 ~95 minecraft:air strict
fill ~224 ~16 ~64 ~255 ~31 ~95 minecraft:air strict
fill ~224 ~0 ~64 ~255 ~15 ~95 minecraft:air strict
fill ~224 ~80 ~96 ~255 ~95 ~127 minecraft:air strict
fill ~224 ~64 ~96 ~255 ~79 ~127 minecraft:air strict
fill ~224 ~48 ~96 ~255 ~63 ~127 minecraft:air strict
fill ~224 ~32 ~96 ~255 ~47 ~127 minecraft:air strict
fill ~224 ~16 ~96 ~255 ~31 ~127 minecraft:air strict
fill ~224 ~0 ~96 ~255 ~15 ~127 minecraft:air strict
fill ~224 ~80 ~128 ~255 ~95 ~159 minecraft:air strict
fill ~224 ~64 ~128 ~255 ~79 ~159 minecraft:air strict
fill ~224 ~48 ~128 ~255 ~63 ~159 minecraft:air strict
fill ~224 ~32 ~128 ~255 ~47 ~159 minecraft:air strict
fill ~224 ~16 ~128 ~255 ~31 ~159 minecraft:air strict
fill ~224 ~0 ~128 ~255 ~15 ~159 minecraft:air strict
fill ~224 ~80 ~160 ~255 ~95 ~191 minecraft:air strict
fill ~224 ~64 ~160 ~255 ~79 ~191 minecraft:air strict
fill ~224 ~48 ~160 ~255 ~63 ~191 minecraft:air strict
fill ~224 ~32 ~160 ~255 ~47 ~191 minecraft:air strict
fill ~224 ~16 ~160 ~255 ~31 ~191 minecraft:air strict
fill ~224 ~0 ~160 ~255 ~15 ~191 minecraft:air strict
fill ~224 ~80 ~192 ~255 ~95 ~223 minecraft:air strict
fill ~224 ~64 ~192 ~255 ~79 ~223 minecraft:air strict
fill ~224 ~48 ~192 ~255 ~63 ~223 minecraft:air strict
fill ~224 ~32 ~192 ~255 ~47 ~223 minecraft:air strict
fill ~224 ~16 ~192 ~255 ~31 ~223 minecraft:air strict
fill ~224 ~0 ~192 ~255 ~15 ~223 minecraft:air strict
fill ~224 ~80 ~224 ~255 ~95 ~255 minecraft:air strict
fill ~224 ~64 ~224 ~255 ~79 ~255 minecraft:air strict
fill ~224 ~48 ~224 ~255 ~63 ~255 minecraft:air strict
fill ~224 ~32 ~224 ~255 ~47 ~255 minecraft:air strict
fill ~224 ~16 ~224 ~255 ~31 ~255 minecraft:air strict
fill ~224 ~0 ~224 ~255 ~15 ~255 minecraft:air strict
fill ~72 ~10 ~176 ~75 ~13 ~178 minecraft:stone strict
fill ~72 ~10 ~179 ~74 ~13 ~179 minecraft:stone strict
fill ~84 ~10 ~187 ~84 ~13 ~192 minecraft:stone strict
fill ~75 ~10 ~191 ~76 ~13 ~196 minecraft:stone strict
fill ~59 ~10 ~192 ~60 ~10 ~192 minecraft:deepslate[axis=y] strict
fill ~74 ~10 ~192 ~74 ~13 ~195 minecraft:stone strict
fill ~77 ~10 ~192 ~77 ~13 ~196 minecraft:stone strict
fill ~78 ~10 ~193 ~78 ~13 ~197 minecraft:stone strict
fill ~79 ~10 ~194 ~81 ~13 ~196 minecraft:stone strict
fill ~64 ~10 ~195 ~66 ~13 ~200 minecraft:stone strict
fill ~72 ~10 ~195 ~73 ~13 ~195 minecraft:stone strict
fill ~67 ~10 ~196 ~67 ~13 ~204 minecraft:stone strict
fill ~71 ~10 ~196 ~72 ~13 ~196 minecraft:stone strict
fill ~68 ~10 ~197 ~70 ~13 ~198 minecraft:stone strict
fill ~79 ~10 ~197 ~80 ~13 ~197 minecraft:stone strict
fill ~68 ~10 ~199 ~69 ~13 ~204 minecraft:stone strict
fill ~65 ~10 ~201 ~66 ~13 ~203 minecraft:stone strict
fill ~70 ~10 ~204 ~70 ~13 ~205 minecraft:stone strict
fill ~69 ~10 ~205 ~69 ~14 ~205 minecraft:stone strict
fill ~71 ~11 ~171 ~71 ~14 ~179 minecraft:stone strict
fill ~66 ~11 ~172 ~70 ~12 ~179 minecraft:stone strict
fill ~72 ~11 ~172 ~74 ~14 ~175 minecraft:stone strict
fill ~61 ~11 ~173 ~64 ~11 ~180 minecraft:deepslate[axis=y] strict
fill ~65 ~11 ~173 ~65 ~14 ~180 minecraft:stone strict
fill ~75 ~11 ~173 ~75 ~14 ~175 minecraft:stone strict
fill ~59 ~11 ~174 ~60 ~11 ~188 minecraft:deepslate[axis=y] strict
fill ~76 ~11 ~174 ~76 ~14 ~184 minecraft:stone strict
fill ~58 ~11 ~175 ~58 ~11 ~190 minecraft:deepslate[axis=y] strict
fill ~77 ~11 ~175 ~77 ~14 ~186 minecraft:stone strict
fill ~57 ~11 ~176 ~57 ~11 ~190 minecraft:deepslate[axis=y] strict
fill ~78 ~11 ~176 ~78 ~14 ~192 minecraft:stone strict
fill ~55 ~11 ~177 ~56 ~11 ~191 minecraft:deepslate[axis=y] strict
fill ~79 ~11 ~177 ~79 ~12 ~193 minecraft:stone strict
fill ~54 ~11 ~178 ~54 ~11 ~191 minecraft:deepslate[axis=y] strict
fill ~80 ~11 ~178 ~80 ~12 ~193 minecraft:stone strict
fill ~75 ~11 ~179 ~75 ~14 ~183 minecraft:stone strict
fill ~81 ~11 ~179 ~81 ~12 ~193 minecraft:stone strict
fill ~53 ~11 ~180 ~53 ~11 ~191 minecraft:deepslate[axis=y] strict
fill ~66 ~11 ~180 ~68 ~14 ~180 minecraft:stone strict
fill ~72 ~11 ~180 ~74 ~14 ~180 minecraft:stone strict
fill ~82 ~11 ~180 ~82 ~14 ~194 minecraft:stone strict
fill ~61 ~11 ~181 ~63 ~11 ~182 minecraft:deepslate[axis=y] strict
fill ~73 ~11 ~181 ~74 ~14 ~182 minecraft:stone strict
setblock ~61 ~11 ~183 minecraft:deepslate[axis=y] strict
fill ~83 ~11 ~184 ~83 ~14 ~193 minecraft:stone strict
fill ~52 ~11 ~189 ~52 ~11 ~191 minecraft:deepslate[axis=y] strict
setblock ~59 ~11 ~189 minecraft:deepslate[axis=y] strict
fill ~59 ~11 ~190 ~59 ~14 ~201 minecraft:stone strict
fill ~77 ~11 ~190 ~77 ~14 ~191 minecraft:stone strict
fill ~57 ~11 ~191 ~58 ~14 ~200 minecraft:stone strict
fill ~52 ~11 ~192 ~56 ~14 ~193 minecraft:stone strict
fill ~60 ~11 ~192 ~60 ~13 ~201 minecraft:stone strict
fill ~61 ~11 ~193 ~61 ~14 ~201 minecraft:stone strict
fill ~53 ~11 ~194 ~56 ~14 ~194 minecraft:stone strict
fill ~54 ~11 ~195 ~56 ~14 ~196 minecraft:stone strict
fill ~62 ~11 ~195 ~63 ~14 ~202 minecraft:stone strict
fill ~73 ~11 ~196 ~74 ~14 ~203 minecraft:stone strict
fill ~55 ~11 ~197 ~56 ~14 ~198 minecraft:stone strict
fill ~71 ~11 ~197 ~72 ~14 ~204 minecraft:stone strict
fill ~75 ~11 ~197 ~77 ~14 ~201 minecraft:stone strict
fill ~78 ~11 ~198 ~80 ~14 ~198 minecraft:stone strict
fill ~56 ~11 ~199 ~56 ~15 ~199 minecraft:stone strict
fill ~70 ~11 ~199 ~70 ~14 ~203 minecraft:stone strict
fill ~78 ~11 ~199 ~79 ~14 ~200 minecraft:stone strict
fill ~58 ~11 ~201 ~58 ~14 ~201 minecraft:stone strict
fill ~64 ~11 ~201 ~64 ~15 ~202 minecraft:stone strict
fill ~75 ~11 ~202 ~76 ~14 ~202 minecraft:stone strict
fill ~73 ~11 ~204 ~73 ~14 ~204 minecraft:stone strict
fill ~61 ~12 ~173 ~64 ~14 ~180 minecraft:stone strict
fill ~59 ~12 ~174 ~60 ~14 ~188 minecraft:stone strict
fill ~58 ~12 ~175 ~58 ~14 ~190 minecraft:stone strict
fill ~57 ~12 ~176 ~57 ~14 ~190 minecraft:stone strict
fill ~55 ~12 ~177 ~56 ~14 ~191 minecraft:stone strict
fill ~54 ~12 ~178 ~54 ~14 ~191 minecraft:stone strict
fill ~53 ~12 ~180 ~53 ~14 ~191 minecraft:stone strict
fill ~61 ~12 ~181 ~63 ~14 ~182 minecraft:stone strict
fill ~61 ~12 ~183 ~61 ~14 ~183 minecraft:stone strict
fill ~52 ~12 ~189 ~52 ~14 ~191 minecraft:stone strict
fill ~59 ~12 ~189 ~59 ~14 ~189 minecraft:stone strict
fill ~66 ~13 ~172 ~70 ~14 ~174 minecraft:stone strict
fill ~66 ~13 ~175 ~66 ~28 ~175 minecraft:stone_bricks strict
fill ~67 ~13 ~175 ~67 ~28 ~175 minecraft:cracked_stone_bricks strict
fill ~68 ~13 ~175 ~70 ~28 ~175 minecraft:stone_bricks strict
fill ~66 ~13 ~176 ~66 ~28 ~177 minecraft:mossy_stone_bricks strict
fill ~67 ~13 ~176 ~67 ~29 ~176 minecraft:stone_bricks strict
fill ~68 ~13 ~176 ~68 ~28 ~176 minecraft:mossy_stone_bricks strict
fill ~69 ~13 ~176 ~69 ~29 ~176 minecraft:stone_bricks strict
fill ~70 ~13 ~176 ~70 ~28 ~176 minecraft:mossy_stone_bricks strict
fill ~67 ~13 ~177 ~67 ~28 ~177 minecraft:mossy_stone_bricks strict
fill ~68 ~13 ~177 ~68 ~29 ~177 minecraft:stone_bricks strict
fill ~69 ~13 ~177 ~69 ~28 ~177 minecraft:cracked_stone_bricks strict
fill ~70 ~13 ~177 ~70 ~28 ~177 minecraft:stone_bricks strict
fill ~79 ~13 ~177 ~79 ~14 ~185 minecraft:stone strict
fill ~66 ~13 ~178 ~70 ~14 ~179 minecraft:stone strict
fill ~80 ~13 ~178 ~80 ~14 ~185 minecraft:stone strict
fill ~81 ~13 ~179 ~81 ~14 ~185 minecraft:stone strict
fill ~71 ~13 ~180 ~71 ~15 ~180 minecraft:stone strict
fill ~79 ~13 ~186 ~79 ~28 ~188 minecraft:mossy_stone_bricks strict
fill ~80 ~13 ~186 ~80 ~28 ~186 minecraft:stone_bricks strict
fill ~81 ~13 ~186 ~81 ~28 ~186 minecraft:mossy_stone_bricks strict
fill ~84 ~13 ~186 ~85 ~14 ~186 minecraft:stone strict
fill ~80 ~13 ~187 ~80 ~28 ~188 minecraft:mossy_stone_bricks strict
fill ~81 ~13 ~187 ~81 ~29 ~189 minecraft:stone_bricks strict
fill ~85 ~13 ~187 ~85 ~14 ~193 minecraft:stone strict
fill ~79 ~13 ~189 ~80 ~28 ~190 minecraft:stone_bricks strict
fill ~74 ~13 ~190 ~76 ~14 ~190 minecraft:stone strict
fill ~81 ~13 ~190 ~81 ~28 ~190 minecraft:mossy_stone_bricks strict
fill ~60 ~13 ~191 ~61 ~16 ~191 minecraft:stone strict
fill ~73 ~13 ~191 ~74 ~15 ~191 minecraft:stone strict
fill ~79 ~13 ~191 ~81 ~14 ~193 minecraft:stone strict
fill ~61 ~13 ~192 ~61 ~16 ~192 minecraft:stone strict
fill ~73 ~13 ~192 ~73 ~15 ~194 minecraft:stone strict
fill ~84 ~13 ~193 ~84 ~14 ~193 minecraft:stone strict
fill ~63 ~13 ~194 ~67 ~15 ~194 minecraft:stone strict
fill ~71 ~13 ~194 ~72 ~15 ~194 minecraft:stone strict
fill ~67 ~13 ~195 ~68 ~15 ~195 minecraft:stone strict
fill ~70 ~13 ~195 ~71 ~15 ~195 minecraft:stone strict
fill ~82 ~13 ~195 ~82 ~14 ~197 minecraft:stone strict
fill ~68 ~13 ~196 ~70 ~15 ~196 minecraft:stone strict
fill ~81 ~13 ~197 ~81 ~14 ~198 minecraft:stone strict
fill ~64 ~13 ~203 ~64 ~14 ~204 minecraft:stone strict
fill ~65 ~13 ~204 ~66 ~14 ~204 minecraft:stone strict
fill ~66 ~13 ~205 ~68 ~14 ~205 minecraft:stone strict
fill ~71 ~13 ~205 ~71 ~14 ~206 minecraft:stone strict
fill ~68 ~13 ~206 ~70 ~14 ~206 minecraft:stone strict
fill ~59 ~14 ~69 ~63 ~15 ~75 minecraft:mossy_cobblestone strict
fill ~58 ~14 ~70 ~58 ~16 ~75 minecraft:mossy_cobblestone strict
fill ~64 ~14 ~70 ~64 ~16 ~78 minecraft:mossy_cobblestone strict
fill ~57 ~14 ~71 ~57 ~16 ~74 minecraft:mossy_cobblestone strict
fill ~65 ~14 ~71 ~65 ~16 ~77 minecraft:mossy_cobblestone strict
fill ~56 ~14 ~72 ~56 ~16 ~74 minecraft:mossy_cobblestone strict
fill ~66 ~14 ~72 ~66 ~16 ~76 minecraft:mossy_cobblestone strict
fill ~56 ~14 ~75 ~57 ~14 ~76 minecraft:stone strict
fill ~58 ~14 ~76 ~60 ~14 ~78 minecraft:stone strict
fill ~61 ~14 ~76 ~63 ~16 ~76 minecraft:mossy_cobblestone strict
setblock ~57 ~14 ~77 minecraft:stone strict
fill ~61 ~14 ~77 ~62 ~14 ~79 minecraft:stone strict
fill ~63 ~14 ~77 ~63 ~16 ~77 minecraft:mossy_cobblestone strict
fill ~63 ~14 ~78 ~63 ~14 ~79 minecraft:stone strict
fill ~59 ~14 ~79 ~60 ~14 ~79 minecraft:stone strict
fill ~70 ~14 ~170 ~72 ~15 ~170 minecraft:stone strict
fill ~65 ~14 ~171 ~70 ~16 ~171 minecraft:stone strict
fill ~72 ~14 ~171 ~75 ~15 ~171 minecraft:stone strict
fill ~60 ~14 ~172 ~65 ~16 ~172 minecraft:stone strict
fill ~75 ~14 ~172 ~76 ~15 ~172 minecraft:stone strict
fill ~58 ~14 ~173 ~60 ~17 ~173 minecraft:stone strict
fill ~76 ~14 ~173 ~77 ~15 ~173 minecraft:stone strict
fill ~57 ~14 ~174 ~58 ~17 ~174 minecraft:stone strict
fill ~77 ~14 ~174 ~78 ~14 ~174 minecraft:stone strict
fill ~56 ~14 ~175 ~57 ~17 ~175 minecraft:stone strict
fill ~78 ~14 ~175 ~79 ~14 ~175 minecraft:stone strict
fill ~54 ~14 ~176 ~56 ~17 ~176 minecraft:stone strict
setblock ~72 ~14 ~176 minecraft:andesite strict
fill ~73 ~14 ~176 ~75 ~14 ~176 minecraft:gravel strict
fill ~79 ~14 ~176 ~80 ~14 ~176 minecraft:stone strict
fill ~53 ~14 ~177 ~54 ~17 ~177 minecraft:stone strict
fill ~72 ~14 ~177 ~72 ~14 ~178 minecraft:gravel strict
setblock ~73 ~14 ~177 minecraft:stone strict
fill ~74 ~14 ~177 ~75 ~14 ~178 minecraft:gravel strict
fill ~80 ~14 ~177 ~81 ~14 ~177 minecraft:stone strict
fill ~53 ~14 ~178 ~53 ~17 ~179 minecraft:stone strict
setblock ~73 ~14 ~178 minecraft:andesite strict
fill ~81 ~14 ~178 ~82 ~14 ~178 minecraft:stone strict
fill ~52 ~14 ~179 ~52 ~17 ~188 minecraft:stone strict
setblock ~72 ~14 ~179 minecraft:andesite strict
setblock ~73 ~14 ~179 minecraft:stone strict
setblock ~74 ~14 ~179 minecraft:gravel strict
fill ~82 ~14 ~179 ~83 ~14 ~179 minecraft:stone strict
fill ~69 ~14 ~180 ~70 ~16 ~180 minecraft:stone strict
fill ~83 ~14 ~180 ~83 ~14 ~183 minecraft:stone strict
fill ~64 ~14 ~181 ~69 ~16 ~181 minecraft:stone strict
fill ~71 ~14 ~181 ~72 ~15 ~181 minecraft:stone strict
fill ~64 ~14 ~182 ~64 ~17 ~183 minecraft:stone strict
fill ~72 ~14 ~182 ~72 ~15 ~183 minecraft:stone strict
fill ~62 ~14 ~183 ~63 ~17 ~183 minecraft:stone strict
fill ~73 ~14 ~183 ~74 ~15 ~183 minecraft:stone strict
fill ~84 ~14 ~183 ~84 ~14 ~185 minecraft:stone strict
fill ~61 ~14 ~184 ~62 ~17 ~184 minecraft:stone strict
fill ~74 ~14 ~184 ~75 ~15 ~184 minecraft:stone strict
fill ~61 ~14 ~185 ~61 ~16 ~189 minecraft:stone strict
fill ~75 ~14 ~185 ~76 ~14 ~185 minecraft:stone strict
fill ~76 ~14 ~186 ~76 ~14 ~187 minecraft:stone strict
fill ~77 ~14 ~187 ~77 ~14 ~189 minecraft:stone strict
setblock ~84 ~14 ~187 minecraft:andesite strict
fill ~51 ~14 ~188 ~51 ~16 ~194 minecraft:stone strict
setblock ~84 ~14 ~188 minecraft:stone strict
fill ~60 ~14 ~189 ~60 ~16 ~190 minecraft:stone strict
setblock ~76 ~14 ~189 minecraft:stone strict
fill ~84 ~14 ~189 ~84 ~14 ~191 minecraft:gravel strict
fill ~75 ~14 ~191 ~76 ~14 ~191 minecraft:gravel strict
setblock ~60 ~14 ~192 minecraft:gravel strict
fill ~62 ~14 ~192 ~62 ~16 ~194 minecraft:stone strict
setblock ~74 ~14 ~192 minecraft:gravel strict
setblock ~75 ~14 ~192 minecraft:stone strict
setblock ~76 ~14 ~192 minecraft:andesite strict
setblock ~77 ~14 ~192 minecraft:stone strict
setblock ~84 ~14 ~192 minecraft:stone strict
fill ~60 ~14 ~193 ~60 ~14 ~202 minecraft:stone strict
fill ~74 ~14 ~193 ~75 ~14 ~193 minecraft:andesite strict
fill ~76 ~14 ~193 ~77 ~14 ~193 minecraft:gravel strict
setblock ~78 ~14 ~193 minecraft:andesite strict
fill ~52 ~14 ~194 ~52 ~16 ~195 minecraft:stone strict
fill ~74 ~14 ~194 ~74 ~14 ~195 minecraft:gravel strict
fill ~75 ~14 ~194 ~76 ~14 ~194 minecraft:stone strict
fill ~77 ~14 ~194 ~78 ~14 ~194 minecraft:gravel strict
setblock ~79 ~14 ~194 minecraft:andesite strict
fill ~80 ~14 ~194 ~80 ~14 ~195 minecraft:stone strict
fill ~81 ~14 ~194 ~81 ~14 ~196 minecraft:gravel strict
fill ~83 ~14 ~194 ~84 ~14 ~194 minecraft:stone strict
fill ~53 ~14 ~195 ~53 ~16 ~197 minecraft:stone strict
setblock ~64 ~14 ~195 minecraft:stone strict
fill ~65 ~14 ~195 ~66 ~14 ~195 minecraft:gravel strict
setblock ~72 ~14 ~195 minecraft:stone strict
setblock ~73 ~14 ~195 minecraft:andesite strict
setblock ~75 ~14 ~195 minecraft:gravel strict
setblock ~76 ~14 ~195 minecraft:stone strict
setblock ~77 ~14 ~195 minecraft:gravel strict
setblock ~78 ~14 ~195 minecraft:stone strict
setblock ~79 ~14 ~195 minecraft:gravel strict
setblock ~83 ~14 ~195 minecraft:stone strict
setblock ~64 ~14 ~196 minecraft:gravel strict
setblock ~65 ~14 ~196 minecraft:andesite strict
setblock ~66 ~14 ~196 minecraft:stone strict
setblock ~67 ~14 ~196 minecraft:andesite strict
setblock ~71 ~14 ~196 minecraft:stone strict
setblock ~72 ~14 ~196 minecraft:gravel strict
fill ~75 ~14 ~196 ~76 ~14 ~196 minecraft:andesite strict
setblock ~77 ~14 ~196 minecraft:stone strict
fill ~78 ~14 ~196 ~78 ~14 ~197 minecraft:gravel strict
setblock ~79 ~14 ~196 minecraft:andesite strict
setblock ~80 ~14 ~196 minecraft:gravel strict
fill ~54 ~14 ~197 ~54 ~15 ~199 minecraft:stone strict
setblock ~64 ~14 ~197 minecraft:stone strict
fill ~65 ~14 ~197 ~65 ~14 ~202 minecraft:gravel strict
setblock ~66 ~14 ~197 minecraft:andesite strict
fill ~67 ~14 ~197 ~67 ~14 ~198 minecraft:stone strict
fill ~68 ~14 ~197 ~68 ~14 ~199 minecraft:gravel strict
fill ~69 ~14 ~197 ~70 ~14 ~197 minecraft:stone strict
setblock ~79 ~14 ~197 minecraft:gravel strict
setblock ~80 ~14 ~197 minecraft:stone strict
setblock ~64 ~14 ~198 minecraft:andesite strict
setblock ~66 ~14 ~198 minecraft:gravel strict
setblock ~69 ~14 ~198 minecraft:andesite strict
setblock ~70 ~14 ~198 minecraft:stone strict
fill ~55 ~14 ~199 ~55 ~15 ~200 minecraft:stone strict
setblock ~64 ~14 ~199 minecraft:stone strict
setblock ~66 ~14 ~199 minecraft:stone strict
setblock ~67 ~14 ~199 minecraft:gravel strict
fill ~69 ~14 ~199 ~69 ~14 ~200 minecraft:gravel strict
fill ~80 ~14 ~199 ~81 ~14 ~199 minecraft:stone strict
fill ~56 ~14 ~200 ~56 ~15 ~201 minecraft:stone strict
setblock ~64 ~14 ~200 minecraft:andesite strict
fill ~66 ~14 ~200 ~66 ~14 ~203 minecraft:gravel strict
fill ~67 ~14 ~200 ~68 ~14 ~200 minecraft:stone strict
fill ~80 ~14 ~200 ~80 ~14 ~201 minecraft:stone strict
fill ~57 ~14 ~201 ~57 ~15 ~202 minecraft:stone strict
fill ~67 ~14 ~201 ~67 ~14 ~202 minecraft:stone strict
fill ~68 ~14 ~201 ~68 ~14 ~202 minecraft:gravel strict
setblock ~69 ~14 ~201 minecraft:stone strict
fill ~78 ~14 ~201 ~79 ~14 ~201 minecraft:stone strict
fill ~58 ~14 ~202 ~59 ~15 ~202 minecraft:stone strict
fill ~61 ~14 ~202 ~61 ~14 ~203 minecraft:stone strict
fill ~69 ~14 ~202 ~69 ~14 ~203 minecraft:gravel strict
fill ~77 ~14 ~202 ~78 ~14 ~202 minecraft:stone strict
fill ~62 ~14 ~203 ~63 ~14 ~203 minecraft:stone strict
setblock ~65 ~14 ~203 minecraft:andesite strict
setblock ~67 ~14 ~203 minecraft:andesite strict
fill ~68 ~14 ~203 ~68 ~14 ~204 minecraft:stone strict
fill ~75 ~14 ~203 ~77 ~14 ~203 minecraft:stone strict
setblock ~67 ~14 ~204 minecraft:gravel strict
setblock ~69 ~14 ~204 minecraft:andesite strict
setblock ~70 ~14 ~204 minecraft:gravel strict
fill ~74 ~14 ~204 ~75 ~14 ~204 minecraft:stone strict
setblock ~70 ~14 ~205 minecraft:andesite strict
fill ~72 ~14 ~205 ~74 ~14 ~205 minecraft:stone strict
fill ~56 ~15 ~75 ~57 ~17 ~76 minecraft:mossy_cobblestone strict
fill ~58 ~15 ~76 ~60 ~17 ~78 minecraft:mossy_cobblestone strict
fill ~57 ~15 ~77 ~57 ~17 ~77 minecraft:mossy_cobblestone strict
fill ~61 ~15 ~77 ~62 ~17 ~79 minecraft:mossy_cobblestone strict
fill ~63 ~15 ~78 ~63 ~17 ~79 minecraft:mossy_cobblestone strict
fill ~59 ~15 ~79 ~60 ~17 ~79 minecraft:mossy_cobblestone strict
fill ~71 ~15 ~171 ~71 ~15 ~174 minecraft:stone strict
setblock ~66 ~15 ~172 minecraft:gravel strict
setblock ~67 ~15 ~172 minecraft:andesite strict
fill ~68 ~15 ~172 ~70 ~15 ~173 minecraft:stone strict
fill ~72 ~15 ~172 ~72 ~15 ~174 minecraft:gravel strict
fill ~73 ~15 ~172 ~74 ~15 ~172 minecraft:stone strict
fill ~61 ~15 ~173 ~64 ~15 ~173 minecraft:gravel strict
setblock ~65 ~15 ~173 minecraft:andesite strict
fill ~66 ~15 ~173 ~67 ~15 ~173 minecraft:stone strict
fill ~73 ~15 ~173 ~73 ~15 ~174 minecraft:andesite strict
fill ~74 ~15 ~173 ~75 ~15 ~173 minecraft:stone strict
fill ~59 ~15 ~174 ~60 ~15 ~174 minecraft:gravel strict
setblock ~61 ~15 ~174 minecraft:stone strict
fill ~62 ~15 ~174 ~62 ~15 ~175 minecraft:gravel strict
fill ~63 ~15 ~174 ~64 ~15 ~174 minecraft:stone strict
setblock ~65 ~15 ~174 minecraft:gravel strict
setblock ~66 ~15 ~174 minecraft:andesite strict
setblock ~67 ~15 ~174 minecraft:stone strict
fill ~68 ~15 ~174 ~69 ~15 ~174 minecraft:gravel strict
setblock ~70 ~15 ~174 minecraft:andesite strict
setblock ~74 ~15 ~174 minecraft:stone strict
setblock ~75 ~15 ~174 minecraft:andesite strict
setblock ~76 ~15 ~174 minecraft:gravel strict
setblock ~77 ~15 ~174 minecraft:stone strict
fill ~78 ~15 ~174 ~78 ~17 ~175 minecraft:andesite strict
fill ~58 ~15 ~175 ~60 ~15 ~175 minecraft:stone strict
fill ~61 ~15 ~175 ~61 ~15 ~177 minecraft:andesite strict
fill ~63 ~15 ~175 ~64 ~15 ~176 minecraft:gravel strict
setblock ~65 ~15 ~175 minecraft:andesite strict
fill ~71 ~15 ~175 ~71 ~15 ~177 minecraft:gravel strict
setblock ~72 ~15 ~175 minecraft:andesite strict
fill ~73 ~15 ~175 ~75 ~15 ~175 minecraft:gravel strict
setblock ~76 ~15 ~175 minecraft:stone strict
setblock ~77 ~15 ~175 minecraft:andesite strict
fill ~79 ~15 ~175 ~79 ~17 ~176 minecraft:andesite strict
