fill ~1 ~58 ~95 ~2 ~58 ~96 minecraft:stone strict
fill ~3 ~58 ~95 ~3 ~61 ~96 minecraft:snow_block strict
setblock ~0 ~58 ~96 minecraft:stone strict
fill ~3 ~58 ~97 ~3 ~58 ~110 minecraft:stone strict
fill ~0 ~58 ~101 ~0 ~58 ~102 minecraft:stone strict
fill ~1 ~58 ~102 ~2 ~58 ~103 minecraft:stone strict
fill ~0 ~58 ~103 ~0 ~61 ~110 minecraft:snow_block strict
fill ~1 ~58 ~104 ~1 ~61 ~107 minecraft:snow_block strict
fill ~2 ~58 ~104 ~2 ~58 ~110 minecraft:stone strict
setblock ~1 ~58 ~108 minecraft:stone strict
fill ~1 ~58 ~109 ~1 ~61 ~111 minecraft:snow_block strict
fill ~2 ~58 ~111 ~3 ~61 ~111 minecraft:snow_block strict
fill ~4 ~58 ~111 ~4 ~60 ~111 minecraft:andesite strict
fill ~2 ~58 ~112 ~2 ~61 ~112 minecraft:snow_block strict
fill ~3 ~58 ~112 ~3 ~60 ~112 minecraft:dirt strict
setblock ~128 ~58 ~112 minecraft:chiseled_quartz_block strict
fill ~1 ~58 ~115 ~1 ~58 ~117 minecraft:grass_block[snowy=true] strict
fill ~0 ~58 ~118 ~0 ~58 ~120 minecraft:grass_block[snowy=true] strict
setblock ~128 ~58 ~144 minecraft:chiseled_quartz_block strict
fill ~254 ~58 ~170 ~255 ~61 ~170 minecraft:snow_block strict
fill ~253 ~58 ~171 ~253 ~61 ~171 minecraft:snow_block strict
fill ~254 ~58 ~171 ~255 ~58 ~171 minecraft:stone strict
fill ~253 ~58 ~172 ~254 ~58 ~172 minecraft:stone strict
setblock ~253 ~58 ~173 minecraft:stone strict
fill ~252 ~58 ~174 ~252 ~61 ~175 minecraft:snow_block strict
fill ~252 ~58 ~176 ~252 ~58 ~177 minecraft:stone strict
fill ~252 ~58 ~178 ~252 ~61 ~179 minecraft:snow_block strict
fill ~253 ~58 ~180 ~253 ~58 ~181 minecraft:stone strict
fill ~253 ~58 ~182 ~253 ~61 ~182 minecraft:snow_block strict
fill ~254 ~58 ~183 ~254 ~58 ~184 minecraft:stone strict
fill ~254 ~58 ~185 ~254 ~61 ~187 minecraft:snow_block strict
fill ~255 ~58 ~186 ~255 ~58 ~187 minecraft:stone strict
fill ~255 ~58 ~188 ~255 ~61 ~189 minecraft:snow_block strict
fill ~2 ~58 ~236 ~3 ~61 ~236 minecraft:snow_block strict
fill ~1 ~58 ~237 ~1 ~61 ~237 minecraft:snow_block strict
fill ~2 ~58 ~237 ~2 ~58 ~238 minecraft:stone strict
fill ~0 ~58 ~238 ~0 ~61 ~239 minecraft:snow_block strict
fill ~1 ~58 ~238 ~1 ~58 ~242 minecraft:stone strict
fill ~3 ~58 ~238 ~3 ~58 ~240 minecraft:stone strict
fill ~0 ~58 ~240 ~0 ~58 ~241 minecraft:stone strict
fill ~2 ~58 ~241 ~2 ~58 ~242 minecraft:stone strict
fill ~3 ~58 ~241 ~3 ~61 ~242 minecraft:snow_block strict
fill ~0 ~58 ~242 ~0 ~61 ~243 minecraft:snow_block strict
fill ~1 ~58 ~243 ~2 ~61 ~243 minecraft:snow_block strict
fill ~1 ~58 ~244 ~1 ~61 ~244 minecraft:snow_block strict
fill ~160 ~58 ~252 ~161 ~61 ~252 minecraft:snow_block strict
fill ~183 ~58 ~252 ~185 ~61 ~252 minecraft:snow_block strict
fill ~195 ~58 ~252 ~195 ~61 ~252 minecraft:snow_block strict
fill ~157 ~58 ~253 ~157 ~61 ~255 minecraft:snow_block strict
fill ~158 ~58 ~253 ~159 ~58 ~253 minecraft:andesite strict
fill ~164 ~58 ~253 ~169 ~58 ~253 minecraft:andesite strict
fill ~170 ~58 ~253 ~179 ~61 ~253 minecraft:snow_block strict
fill ~180 ~58 ~253 ~181 ~58 ~253 minecraft:stone strict
fill ~188 ~58 ~253 ~197 ~58 ~253 minecraft:stone strict
fill ~198 ~58 ~253 ~199 ~61 ~253 minecraft:snow_block strict
fill ~141 ~58 ~254 ~142 ~58 ~254 minecraft:grass_block[snowy=true] strict
fill ~158 ~58 ~254 ~158 ~58 ~255 minecraft:andesite strict
fill ~170 ~58 ~254 ~176 ~58 ~254 minecraft:stone strict
fill ~197 ~58 ~254 ~198 ~58 ~254 minecraft:stone strict
fill ~199 ~58 ~254 ~199 ~61 ~255 minecraft:snow_block strict
fill ~139 ~58 ~255 ~141 ~58 ~255 minecraft:grass_block[snowy=true] strict
setblock ~159 ~58 ~255 minecraft:andesite strict
fill ~171 ~58 ~255 ~172 ~58 ~255 minecraft:stone strict
setblock ~197 ~58 ~255 minecraft:stone strict
fill ~198 ~58 ~255 ~198 ~61 ~255 minecraft:snow_block strict
fill ~11 ~59 ~0 ~11 ~59 ~2 minecraft:stone strict
fill ~12 ~59 ~0 ~12 ~62 ~2 minecraft:snow_block strict
fill ~45 ~59 ~0 ~45 ~62 ~0 minecraft:snow_block strict
setblock ~46 ~59 ~0 minecraft:stone strict
fill ~82 ~59 ~0 ~83 ~59 ~0 minecraft:andesite strict
fill ~84 ~59 ~0 ~85 ~62 ~0 minecraft:snow_block strict
fill ~95 ~59 ~0 ~95 ~62 ~1 minecraft:snow_block strict
fill ~96 ~59 ~0 ~96 ~59 ~1 minecraft:stone strict
setblock ~119 ~59 ~0 minecraft:stone strict
fill ~120 ~59 ~0 ~120 ~61 ~0 minecraft:dirt strict
fill ~137 ~59 ~0 ~138 ~59 ~0 minecraft:snow_block strict
fill ~10 ~59 ~1 ~10 ~59 ~2 minecraft:stone strict
fill ~13 ~59 ~1 ~13 ~62 ~2 minecraft:snow_block strict
fill ~46 ~59 ~1 ~46 ~62 ~2 minecraft:snow_block strict
fill ~47 ~59 ~1 ~47 ~59 ~2 minecraft:deepslate[axis=y] strict
fill ~83 ~59 ~1 ~84 ~59 ~3 minecraft:andesite strict
fill ~85 ~59 ~1 ~85 ~62 ~3 minecraft:snow_block strict
setblock ~139 ~59 ~1 minecraft:snow_block strict
fill ~7 ~59 ~2 ~9 ~59 ~2 minecraft:stone strict
fill ~86 ~59 ~2 ~86 ~62 ~3 minecraft:snow_block strict
fill ~94 ~59 ~2 ~94 ~62 ~3 minecraft:snow_block strict
setblock ~95 ~59 ~2 minecraft:stone strict
fill ~4 ~59 ~3 ~5 ~59 ~3 minecraft:stone strict
fill ~6 ~59 ~3 ~10 ~62 ~3 minecraft:snow_block strict
fill ~48 ~59 ~3 ~49 ~59 ~3 minecraft:deepslate[axis=y] strict
fill ~59 ~59 ~3 ~61 ~59 ~3 minecraft:stone strict
setblock ~82 ~59 ~3 minecraft:andesite strict
fill ~95 ~59 ~3 ~95 ~62 ~3 minecraft:snow_block strict
setblock ~96 ~59 ~3 minecraft:stone strict
fill ~3 ~59 ~4 ~3 ~59 ~6 minecraft:stone strict
fill ~50 ~59 ~4 ~50 ~62 ~4 minecraft:snow_block strict
fill ~51 ~59 ~4 ~57 ~59 ~4 minecraft:deepslate[axis=y] strict
fill ~58 ~59 ~4 ~62 ~62 ~4 minecraft:snow_block strict
setblock ~63 ~59 ~4 minecraft:stone strict
fill ~78 ~59 ~4 ~80 ~59 ~4 minecraft:andesite strict
fill ~81 ~59 ~4 ~82 ~62 ~4 minecraft:snow_block strict
fill ~97 ~59 ~4 ~97 ~62 ~4 minecraft:snow_block strict
fill ~98 ~59 ~4 ~102 ~59 ~4 minecraft:stone strict
fill ~65 ~59 ~5 ~65 ~62 ~5 minecraft:snow_block strict
fill ~66 ~59 ~5 ~68 ~59 ~5 minecraft:stone strict
fill ~70 ~59 ~5 ~73 ~59 ~5 minecraft:stone strict
fill ~74 ~59 ~5 ~76 ~62 ~5 minecraft:snow_block strict
fill ~105 ~59 ~5 ~108 ~62 ~5 minecraft:snow_block strict
fill ~2 ~59 ~7 ~2 ~59 ~8 minecraft:stone strict
fill ~3 ~59 ~7 ~3 ~62 ~7 minecraft:snow_block strict
fill ~0 ~59 ~8 ~1 ~59 ~8 minecraft:stone strict
fill ~0 ~59 ~9 ~2 ~62 ~9 minecraft:snow_block strict
setblock ~112 ~59 ~17 minecraft:red_wool strict
fill ~113 ~59 ~18 ~114 ~59 ~18 minecraft:red_wool strict
fill ~1 ~59 ~95 ~2 ~62 ~96 minecraft:snow_block strict
fill ~0 ~59 ~96 ~0 ~62 ~96 minecraft:snow_block strict
fill ~0 ~59 ~97 ~2 ~59 ~100 minecraft:stone strict
fill ~3 ~59 ~97 ~3 ~62 ~110 minecraft:snow_block strict
fill ~0 ~59 ~101 ~0 ~62 ~102 minecraft:snow_block strict
fill ~1 ~59 ~101 ~2 ~59 ~101 minecraft:stone strict
fill ~1 ~59 ~102 ~2 ~62 ~103 minecraft:snow_block strict
fill ~2 ~59 ~104 ~2 ~62 ~110 minecraft:snow_block strict
fill ~1 ~59 ~108 ~1 ~62 ~108 minecraft:snow_block strict
setblock ~239 ~59 ~112 minecraft:blue_wool strict
fill ~238 ~59 ~113 ~238 ~59 ~114 minecraft:blue_wool strict
setblock ~2 ~59 ~115 minecraft:grass_block[snowy=true] strict
setblock ~126 ~59 ~116 minecraft:weathered_cut_copper strict
fill ~18 ~59 ~142 ~18 ~59 ~143 minecraft:yellow_wool strict
setblock ~17 ~59 ~144 minecraft:yellow_wool strict
fill ~254 ~59 ~171 ~255 ~62 ~171 minecraft:snow_block strict
fill ~253 ~59 ~172 ~254 ~62 ~172 minecraft:snow_block strict
setblock ~255 ~59 ~172 minecraft:deepslate[axis=y] strict
fill ~253 ~59 ~173 ~253 ~62 ~173 minecraft:snow_block strict
fill ~254 ~59 ~173 ~255 ~59 ~173 minecraft:stone strict
setblock ~253 ~59 ~174 minecraft:stone strict
fill ~252 ~59 ~176 ~252 ~62 ~177 minecraft:snow_block strict
fill ~253 ~59 ~179 ~253 ~59 ~180 minecraft:stone strict
fill ~253 ~59 ~181 ~253 ~62 ~181 minecraft:snow_block strict
setblock ~254 ~59 ~182 minecraft:stone strict
fill ~254 ~59 ~183 ~254 ~62 ~184 minecraft:snow_block strict
fill ~255 ~59 ~184 ~255 ~59 ~185 minecraft:stone strict
fill ~255 ~59 ~186 ~255 ~62 ~187 minecraft:snow_block strict
fill ~2 ~59 ~237 ~3 ~62 ~238 minecraft:snow_block strict
fill ~1 ~59 ~238 ~1 ~62 ~242 minecraft:snow_block strict
fill ~142 ~59 ~238 ~143 ~59 ~238 minecraft:lime_wool strict
fill ~2 ~59 ~239 ~2 ~59 ~240 minecraft:stone strict
fill ~3 ~59 ~239 ~3 ~62 ~240 minecraft:snow_block strict
setblock ~144 ~59 ~239 minecraft:lime_wool strict
fill ~0 ~59 ~240 ~0 ~62 ~241 minecraft:snow_block strict
fill ~2 ~59 ~241 ~2 ~62 ~242 minecraft:snow_block strict
fill ~158 ~59 ~253 ~159 ~62 ~253 minecraft:snow_block strict
fill ~160 ~59 ~253 ~160 ~59 ~255 minecraft:andesite strict
fill ~161 ~59 ~253 ~163 ~59 ~253 minecraft:stone strict
fill ~164 ~59 ~253 ~169 ~62 ~253 minecraft:snow_block strict
fill ~180 ~59 ~253 ~181 ~62 ~253 minecraft:snow_block strict
fill ~182 ~59 ~253 ~185 ~59 ~253 minecraft:stone strict
fill ~186 ~59 ~253 ~187 ~59 ~253 minecraft:deepslate[axis=y] strict
fill ~188 ~59 ~253 ~197 ~62 ~253 minecraft:snow_block strict
fill ~158 ~59 ~254 ~158 ~62 ~255 minecraft:snow_block strict
setblock ~159 ~59 ~254 minecraft:andesite strict
fill ~166 ~59 ~254 ~169 ~59 ~254 minecraft:stone strict
fill ~170 ~59 ~254 ~176 ~62 ~254 minecraft:snow_block strict
fill ~177 ~59 ~254 ~181 ~59 ~254 minecraft:stone strict
fill ~195 ~59 ~254 ~196 ~59 ~255 minecraft:deepslate[axis=y] strict
fill ~197 ~59 ~254 ~198 ~62 ~254 minecraft:snow_block strict
fill ~159 ~59 ~255 ~159 ~62 ~255 minecraft:snow_block strict
fill ~168 ~59 ~255 ~170 ~59 ~255 minecraft:stone strict
fill ~171 ~59 ~255 ~172 ~62 ~255 minecraft:snow_block strict
fill ~173 ~59 ~255 ~175 ~59 ~255 minecraft:stone strict
fill ~197 ~59 ~255 ~197 ~62 ~255 minecraft:snow_block strict
fill ~8 ~60 ~0 ~10 ~60 ~0 minecraft:deepslate[axis=y] strict
fill ~11 ~60 ~0 ~11 ~63 ~2 minecraft:snow_block strict
fill ~46 ~60 ~0 ~46 ~63 ~0 minecraft:snow_block strict
fill ~47 ~60 ~0 ~48 ~60 ~0 minecraft:deepslate[axis=y] strict
fill ~54 ~60 ~0 ~63 ~60 ~0 minecraft:deepslate[axis=y] strict
fill ~80 ~60 ~0 ~81 ~60 ~0 minecraft:stone strict
fill ~82 ~60 ~0 ~83 ~63 ~0 minecraft:snow_block strict
fill ~96 ~60 ~0 ~96 ~63 ~1 minecraft:snow_block strict
setblock ~97 ~60 ~0 minecraft:stone strict
setblock ~118 ~60 ~0 minecraft:stone strict
fill ~119 ~60 ~0 ~119 ~62 ~0 minecraft:dirt strict
fill ~6 ~60 ~1 ~9 ~60 ~1 minecraft:deepslate[axis=y] strict
fill ~10 ~60 ~1 ~10 ~63 ~2 minecraft:snow_block strict
fill ~47 ~60 ~1 ~47 ~63 ~2 minecraft:snow_block strict
fill ~48 ~60 ~1 ~48 ~60 ~2 minecraft:deepslate[axis=y] strict
fill ~55 ~60 ~1 ~62 ~60 ~1 minecraft:deepslate[axis=y] strict
fill ~81 ~60 ~1 ~82 ~60 ~2 minecraft:stone strict
fill ~83 ~60 ~1 ~84 ~63 ~3 minecraft:snow_block strict
fill ~5 ~60 ~2 ~6 ~60 ~2 minecraft:deepslate[axis=y] strict
fill ~7 ~60 ~2 ~9 ~63 ~2 minecraft:snow_block strict
setblock ~49 ~60 ~2 minecraft:deepslate[axis=y] strict
fill ~57 ~60 ~2 ~62 ~60 ~2 minecraft:deepslate[axis=y] strict
fill ~95 ~60 ~2 ~95 ~63 ~2 minecraft:snow_block strict
setblock ~96 ~60 ~2 minecraft:stone strict
fill ~3 ~60 ~3 ~3 ~60 ~4 minecraft:deepslate[axis=y] strict
fill ~4 ~60 ~3 ~5 ~63 ~3 minecraft:snow_block strict
fill ~48 ~60 ~3 ~49 ~63 ~3 minecraft:snow_block strict
setblock ~50 ~60 ~3 minecraft:deepslate[axis=y] strict
fill ~56 ~60 ~3 ~58 ~60 ~3 minecraft:deepslate[axis=y] strict
fill ~59 ~60 ~3 ~61 ~63 ~3 minecraft:snow_block strict
fill ~62 ~60 ~3 ~63 ~60 ~3 minecraft:deepslate[axis=y] strict
fill ~80 ~60 ~3 ~81 ~60 ~3 minecraft:stone strict
fill ~82 ~60 ~3 ~82 ~63 ~3 minecraft:snow_block strict
fill ~96 ~60 ~3 ~96 ~63 ~3 minecraft:snow_block strict
setblock ~97 ~60 ~3 minecraft:stone strict
fill ~51 ~60 ~4 ~57 ~63 ~4 minecraft:snow_block strict
fill ~63 ~60 ~4 ~63 ~63 ~4 minecraft:snow_block strict
fill ~64 ~60 ~4 ~65 ~60 ~4 minecraft:stone strict
fill ~75 ~60 ~4 ~77 ~60 ~4 minecraft:stone strict
fill ~78 ~60 ~4 ~80 ~63 ~4 minecraft:snow_block strict
fill ~98 ~60 ~4 ~99 ~63 ~4 minecraft:snow_block strict
fill ~100 ~60 ~4 ~105 ~60 ~4 minecraft:stone strict
fill ~110 ~60 ~4 ~110 ~61 ~4 minecraft:deepslate[axis=y] strict
fill ~111 ~60 ~4 ~111 ~62 ~4 minecraft:stone strict
fill ~3 ~60 ~5 ~3 ~63 ~6 minecraft:snow_block strict
fill ~66 ~60 ~5 ~67 ~63 ~5 minecraft:snow_block strict
fill ~68 ~60 ~5 ~70 ~60 ~5 minecraft:stone strict
fill ~71 ~60 ~5 ~73 ~63 ~5 minecraft:snow_block strict
fill ~109 ~60 ~5 ~110 ~62 ~5 minecraft:stone strict
setblock ~2 ~60 ~6 minecraft:deepslate[axis=y] strict
fill ~0 ~60 ~7 ~1 ~60 ~7 minecraft:deepslate[axis=y] strict
fill ~2 ~60 ~7 ~2 ~63 ~8 minecraft:snow_block strict
fill ~0 ~60 ~8 ~1 ~63 ~8 minecraft:snow_block strict
fill ~0 ~60 ~97 ~2 ~63 ~100 minecraft:snow_block strict
fill ~1 ~60 ~101 ~2 ~63 ~101 minecraft:snow_block strict
setblock ~3 ~60 ~113 minecraft:grass_block[snowy=true] strict
setblock ~2 ~60 ~114 minecraft:grass_block[snowy=true] strict
fill ~255 ~60 ~172 ~255 ~63 ~173 minecraft:snow_block strict
fill ~254 ~60 ~173 ~254 ~63 ~173 minecraft:snow_block strict
fill ~253 ~60 ~174 ~253 ~63 ~174 minecraft:snow_block strict
fill ~254 ~60 ~174 ~255 ~60 ~174 minecraft:deepslate[axis=y] strict
fill ~253 ~60 ~175 ~253 ~60 ~178 minecraft:deepslate[axis=y] strict
fill ~253 ~60 ~179 ~253 ~63 ~180 minecraft:snow_block strict
setblock ~254 ~60 ~180 minecraft:deepslate[axis=y] strict
setblock ~254 ~60 ~181 minecraft:stone strict
fill ~254 ~60 ~182 ~254 ~63 ~182 minecraft:snow_block strict
setblock ~255 ~60 ~182 minecraft:deepslate[axis=y] strict
setblock ~255 ~60 ~183 minecraft:stone strict
fill ~255 ~60 ~184 ~255 ~63 ~185 minecraft:snow_block strict
fill ~2 ~60 ~239 ~2 ~63 ~240 minecraft:snow_block strict
fill ~216 ~60 ~251 ~216 ~62 ~251 minecraft:spruce_log[axis=y] strict
fill ~160 ~60 ~253 ~163 ~63 ~253 minecraft:snow_block strict
fill ~182 ~60 ~253 ~187 ~63 ~253 minecraft:snow_block strict
fill ~159 ~60 ~254 ~160 ~63 ~254 minecraft:snow_block strict
fill ~161 ~60 ~254 ~165 ~60 ~255 minecraft:stone strict
fill ~166 ~60 ~254 ~169 ~63 ~254 minecraft:snow_block strict
fill ~177 ~60 ~254 ~181 ~63 ~254 minecraft:snow_block strict
fill ~182 ~60 ~254 ~194 ~60 ~254 minecraft:deepslate[axis=y] strict
fill ~195 ~60 ~254 ~196 ~63 ~255 minecraft:snow_block strict
fill ~160 ~60 ~255 ~160 ~63 ~255 minecraft:snow_block strict
fill ~166 ~60 ~255 ~167 ~60 ~255 minecraft:stone strict
fill ~168 ~60 ~255 ~170 ~63 ~255 minecraft:snow_block strict
fill ~173 ~60 ~255 ~175 ~63 ~255 minecraft:snow_block strict
fill ~176 ~60 ~255 ~184 ~60 ~255 minecraft:deepslate[axis=y] strict
setblock ~194 ~60 ~255 minecraft:deepslate[axis=y] strict
fill ~0 ~61 ~0 ~0 ~61 ~1 minecraft:deepslate[axis=y] strict
fill ~3 ~61 ~0 ~7 ~61 ~0 minecraft:deepslate[axis=y] strict
fill ~8 ~61 ~0 ~10 ~64 ~0 minecraft:snow_block strict
fill ~47 ~61 ~0 ~48 ~64 ~0 minecraft:snow_block strict
fill ~49 ~61 ~0 ~53 ~61 ~1 minecraft:deepslate[axis=y] strict
fill ~54 ~61 ~0 ~63 ~64 ~0 minecraft:snow_block strict
fill ~64 ~61 ~0 ~67 ~61 ~0 minecraft:deepslate[axis=y] strict
setblock ~69 ~61 ~0 minecraft:deepslate[axis=y] strict
fill ~70 ~61 ~0 ~79 ~61 ~0 minecraft:stone strict
fill ~80 ~61 ~0 ~81 ~64 ~0 minecraft:snow_block strict
fill ~97 ~61 ~0 ~97 ~64 ~0 minecraft:snow_block strict
fill ~116 ~61 ~0 ~117 ~61 ~0 minecraft:deepslate[axis=y] strict
fill ~118 ~61 ~0 ~118 ~63 ~0 minecraft:dirt strict
fill ~3 ~61 ~1 ~5 ~61 ~1 minecraft:deepslate[axis=y] strict
fill ~6 ~61 ~1 ~9 ~64 ~1 minecraft:snow_block strict
fill ~48 ~61 ~1 ~48 ~64 ~2 minecraft:snow_block strict
fill ~54 ~61 ~1 ~54 ~61 ~3 minecraft:deepslate[axis=y] strict
fill ~55 ~61 ~1 ~62 ~64 ~1 minecraft:snow_block strict
fill ~63 ~61 ~1 ~65 ~61 ~1 minecraft:deepslate[axis=y] strict
fill ~73 ~61 ~1 ~80 ~61 ~1 minecraft:stone strict
fill ~81 ~61 ~1 ~82 ~64 ~2 minecraft:snow_block strict
fill ~97 ~61 ~1 ~97 ~61 ~2 minecraft:stone strict
setblock ~117 ~61 ~1 minecraft:stone strict
fill ~2 ~61 ~2 ~4 ~61 ~2 minecraft:deepslate[axis=y] strict
fill ~5 ~61 ~2 ~6 ~64 ~2 minecraft:snow_block strict
fill ~49 ~61 ~2 ~49 ~64 ~2 minecraft:snow_block strict
fill ~50 ~61 ~2 ~53 ~61 ~2 minecraft:deepslate[axis=y] strict
fill ~55 ~61 ~2 ~56 ~61 ~2 minecraft:deepslate[axis=y] strict
fill ~57 ~61 ~2 ~62 ~64 ~2 minecraft:snow_block strict
fill ~63 ~61 ~2 ~64 ~61 ~2 minecraft:deepslate[axis=y] strict
fill ~77 ~61 ~2 ~80 ~61 ~2 minecraft:stone strict
fill ~96 ~61 ~2 ~96 ~64 ~2 minecraft:snow_block strict
fill ~2 ~61 ~3 ~2 ~61 ~5 minecraft:deepslate[axis=y] strict
fill ~3 ~61 ~3 ~3 ~64 ~4 minecraft:snow_block strict
fill ~50 ~61 ~3 ~50 ~64 ~3 minecraft:snow_block strict
fill ~51 ~61 ~3 ~53 ~61 ~3 minecraft:deepslate[axis=y] strict
setblock ~55 ~61 ~3 minecraft:deepslate[axis=y] strict
fill ~56 ~61 ~3 ~58 ~64 ~3 minecraft:snow_block strict
fill ~62 ~61 ~3 ~63 ~64 ~3 minecraft:snow_block strict
setblock ~64 ~61 ~3 minecraft:deepslate[axis=y] strict
fill ~76 ~61 ~3 ~79 ~61 ~3 minecraft:stone strict
fill ~80 ~61 ~3 ~81 ~64 ~3 minecraft:snow_block strict
fill ~97 ~61 ~3 ~97 ~64 ~3 minecraft:snow_block strict
setblock ~98 ~61 ~3 minecraft:stone strict
fill ~1 ~61 ~4 ~1 ~61 ~6 minecraft:deepslate[axis=y] strict
fill ~64 ~61 ~4 ~65 ~64 ~4 minecraft:snow_block strict
fill ~66 ~61 ~4 ~67 ~61 ~4 minecraft:deepslate[axis=y] strict
fill ~72 ~61 ~4 ~74 ~61 ~4 minecraft:stone strict
fill ~75 ~61 ~4 ~77 ~64 ~4 minecraft:snow_block strict
fill ~100 ~61 ~4 ~100 ~64 ~4 minecraft:snow_block strict
fill ~101 ~61 ~4 ~109 ~61 ~4 minecraft:deepslate[axis=y] strict
fill ~0 ~61 ~5 ~0 ~61 ~6 minecraft:deepslate[axis=y] strict
fill ~68 ~61 ~5 ~70 ~64 ~5 minecraft:snow_block strict
fill ~2 ~61 ~6 ~2 ~64 ~6 minecraft:snow_block strict
fill ~0 ~61 ~7 ~1 ~64 ~7 minecraft:snow_block strict
setblock ~117 ~61 ~17 minecraft:gold_block strict
setblock ~3 ~61 ~112 minecraft:grass_block[snowy=true] strict
setblock ~239 ~61 ~117 minecraft:gold_block strict
setblock ~17 ~61 ~139 minecraft:gold_block strict
fill ~254 ~61 ~174 ~255 ~64 ~174 minecraft:snow_block strict
fill ~253 ~61 ~175 ~253 ~64 ~178 minecraft:snow_block strict
fill ~254 ~61 ~175 ~255 ~61 ~179 minecraft:deepslate[axis=y] strict
fill ~254 ~61 ~180 ~254 ~64 ~181 minecraft:snow_block strict
fill ~255 ~61 ~180 ~255 ~61 ~181 minecraft:deepslate[axis=y] strict
fill ~255 ~61 ~182 ~255 ~64 ~183 minecraft:snow_block strict
setblock ~139 ~61 ~239 minecraft:gold_block strict
fill ~161 ~61 ~254 ~165 ~64 ~255 minecraft:snow_block strict
fill ~182 ~61 ~254 ~194 ~64 ~254 minecraft:snow_block strict
fill ~166 ~61 ~255 ~167 ~64 ~255 minecraft:snow_block strict
fill ~176 ~61 ~255 ~184 ~64 ~255 minecraft:snow_block strict
fill ~185 ~61 ~255 ~187 ~61 ~255 minecraft:deepslate[axis=y] strict
fill ~192 ~61 ~255 ~193 ~61 ~255 minecraft:deepslate[axis=y] strict
fill ~194 ~61 ~255 ~194 ~64 ~255 minecraft:snow_block strict
fill ~0 ~62 ~0 ~0 ~65 ~1 minecraft:snow_block strict
fill ~1 ~62 ~0 ~2 ~62 ~0 minecraft:stone strict
fill ~3 ~62 ~0 ~7 ~65 ~0 minecraft:snow_block strict
fill ~49 ~62 ~0 ~53 ~65 ~1 minecraft:snow_block strict
fill ~64 ~62 ~0 ~67 ~65 ~0 minecraft:snow_block strict
fill ~68 ~62 ~0 ~68 ~62 ~1 minecraft:deepslate[axis=y] strict
fill ~69 ~62 ~0 ~79 ~65 ~0 minecraft:snow_block strict
fill ~98 ~62 ~0 ~98 ~62 ~2 minecraft:deepslate[axis=y] strict
fill ~113 ~62 ~0 ~115 ~62 ~0 minecraft:deepslate[axis=y] strict
fill ~116 ~62 ~0 ~117 ~65 ~0 minecraft:snow_block strict
setblock ~120 ~62 ~0 minecraft:grass_block[snowy=true] strict
fill ~1 ~62 ~1 ~2 ~62 ~1 minecraft:deepslate[axis=y] strict
fill ~3 ~62 ~1 ~5 ~65 ~1 minecraft:snow_block strict
fill ~54 ~62 ~1 ~54 ~65 ~3 minecraft:snow_block strict
fill ~63 ~62 ~1 ~65 ~65 ~1 minecraft:snow_block strict
fill ~66 ~62 ~1 ~67 ~62 ~1 minecraft:deepslate[axis=y] strict
fill ~69 ~62 ~1 ~72 ~62 ~1 minecraft:deepslate[axis=y] strict
fill ~73 ~62 ~1 ~80 ~65 ~1 minecraft:snow_block strict
fill ~97 ~62 ~1 ~97 ~65 ~2 minecraft:snow_block strict
fill ~115 ~62 ~1 ~116 ~62 ~1 minecraft:stone strict
fill ~117 ~62 ~1 ~117 ~64 ~1 minecraft:dirt strict
fill ~0 ~62 ~2 ~1 ~62 ~3 minecraft:deepslate[axis=y] strict
