fill ~249 ~46 ~232 ~249 ~46 ~234 minecraft:snow[layers=1] strict
setblock ~194 ~46 ~247 minecraft:snow[layers=2] strict
fill ~7 ~46 ~248 ~7 ~46 ~249 minecraft:snow[layers=1] strict
setblock ~70 ~46 ~248 minecraft:snow[layers=2] strict
fill ~75 ~46 ~248 ~77 ~46 ~248 minecraft:snow[layers=2] strict
fill ~188 ~46 ~248 ~190 ~46 ~248 minecraft:snow[layers=2] strict
setblock ~199 ~46 ~248 minecraft:snow[layers=2] strict
fill ~8 ~46 ~249 ~9 ~46 ~249 minecraft:snow[layers=1] strict
fill ~67 ~46 ~249 ~68 ~46 ~249 minecraft:snow[layers=1] strict
fill ~81 ~46 ~249 ~82 ~46 ~249 minecraft:snow[layers=1] strict
fill ~149 ~46 ~249 ~150 ~46 ~249 minecraft:snow[layers=1] strict
fill ~205 ~46 ~249 ~211 ~46 ~249 minecraft:snow[layers=1] strict
setblock ~232 ~46 ~249 minecraft:snow[layers=2] strict
fill ~243 ~46 ~249 ~246 ~46 ~249 minecraft:snow[layers=1] strict
fill ~51 ~46 ~250 ~58 ~46 ~250 minecraft:snow[layers=2] strict
fill ~59 ~46 ~250 ~64 ~46 ~250 minecraft:snow[layers=1] strict
fill ~85 ~46 ~250 ~86 ~46 ~250 minecraft:snow[layers=1] strict
fill ~87 ~46 ~250 ~93 ~46 ~250 minecraft:snow[layers=2] strict
fill ~222 ~46 ~250 ~223 ~46 ~250 minecraft:snow[layers=1] strict
fill ~224 ~46 ~250 ~226 ~46 ~250 minecraft:snow[layers=2] strict
fill ~114 ~46 ~252 ~114 ~46 ~253 minecraft:snow[layers=1] strict
setblock ~118 ~46 ~253 minecraft:snow[layers=1] strict
setblock ~133 ~46 ~253 minecraft:snow[layers=2] strict
fill ~138 ~46 ~253 ~140 ~46 ~253 minecraft:snow[layers=1] strict
fill ~159 ~47 ~1 ~161 ~47 ~2 minecraft:snow[layers=1] strict
fill ~162 ~47 ~2 ~162 ~47 ~4 minecraft:snow[layers=1] strict
setblock ~138 ~47 ~3 minecraft:snow[layers=2] strict
fill ~142 ~47 ~3 ~142 ~47 ~4 minecraft:snow[layers=1] strict
fill ~158 ~47 ~3 ~159 ~47 ~3 minecraft:snow[layers=1] strict
setblock ~161 ~47 ~3 minecraft:snow[layers=1] strict
fill ~139 ~47 ~4 ~140 ~47 ~4 minecraft:snow[layers=2] strict
setblock ~143 ~47 ~4 minecraft:snow[layers=1] strict
fill ~156 ~47 ~4 ~157 ~47 ~4 minecraft:snow[layers=1] strict
fill ~25 ~47 ~5 ~29 ~47 ~5 minecraft:snow[layers=1] strict
fill ~154 ~47 ~5 ~155 ~47 ~5 minecraft:snow[layers=1] strict
setblock ~163 ~47 ~5 minecraft:snow[layers=1] strict
setblock ~21 ~47 ~6 minecraft:snow[layers=1] strict
fill ~41 ~47 ~6 ~42 ~47 ~6 minecraft:snow[layers=2] strict
setblock ~164 ~47 ~6 minecraft:snow[layers=1] strict
fill ~194 ~47 ~6 ~201 ~47 ~6 minecraft:snow[layers=1] strict
setblock ~211 ~47 ~6 minecraft:snow[layers=1] strict
setblock ~212 ~47 ~6 minecraft:snow[layers=2] strict
fill ~215 ~47 ~6 ~218 ~47 ~6 minecraft:snow[layers=2] strict
fill ~226 ~47 ~6 ~228 ~47 ~6 minecraft:snow[layers=1] strict
fill ~235 ~47 ~6 ~241 ~47 ~6 minecraft:snow[layers=1] strict
fill ~14 ~47 ~7 ~16 ~47 ~7 minecraft:snow[layers=1] strict
setblock ~47 ~47 ~7 minecraft:snow[layers=1] strict
fill ~166 ~47 ~7 ~167 ~47 ~7 minecraft:snow[layers=1] strict
setblock ~184 ~47 ~7 minecraft:snow[layers=1] strict
setblock ~245 ~47 ~7 minecraft:snow[layers=1] strict
setblock ~53 ~47 ~8 minecraft:snow[layers=1] strict
fill ~86 ~47 ~8 ~89 ~47 ~8 minecraft:snow[layers=1] strict
fill ~170 ~47 ~8 ~171 ~47 ~8 minecraft:snow[layers=1] strict
setblock ~181 ~47 ~8 minecraft:snow[layers=2] strict
fill ~7 ~47 ~9 ~7 ~47 ~11 minecraft:snow[layers=1] strict
fill ~59 ~47 ~9 ~60 ~47 ~9 minecraft:snow[layers=1] strict
fill ~176 ~47 ~9 ~177 ~47 ~9 minecraft:snow[layers=2] strict
setblock ~67 ~47 ~10 minecraft:snow[layers=1] strict
fill ~72 ~47 ~10 ~73 ~47 ~10 minecraft:snow[layers=1] strict
fill ~249 ~47 ~10 ~249 ~47 ~13 minecraft:snow[layers=2] strict
setblock ~64 ~47 ~11 minecraft:snow[layers=1] strict
setblock ~66 ~47 ~11 minecraft:snow[layers=1] strict
setblock ~61 ~47 ~12 minecraft:snow[layers=1] strict
setblock ~64 ~47 ~13 minecraft:snow[layers=1] strict
setblock ~66 ~47 ~13 minecraft:snow[layers=1] strict
setblock ~250 ~47 ~22 minecraft:snow[layers=1] strict
setblock ~7 ~47 ~25 minecraft:snow[layers=1] strict
fill ~6 ~47 ~32 ~6 ~47 ~34 minecraft:snow[layers=1] strict
fill ~6 ~47 ~36 ~6 ~47 ~37 minecraft:snow[layers=1] strict
fill ~250 ~47 ~37 ~250 ~47 ~38 minecraft:snow[layers=1] strict
setblock ~7 ~47 ~52 minecraft:snow[layers=2] strict
setblock ~249 ~47 ~52 minecraft:snow[layers=1] strict
setblock ~8 ~47 ~57 minecraft:snow[layers=2] strict
fill ~248 ~47 ~58 ~248 ~47 ~67 minecraft:snow[layers=1] strict
setblock ~9 ~47 ~61 minecraft:snow[layers=2] strict
fill ~9 ~47 ~65 ~9 ~47 ~66 minecraft:snow[layers=1] strict
fill ~8 ~47 ~70 ~8 ~47 ~71 minecraft:snow[layers=1] strict
fill ~32 ~47 ~75 ~34 ~47 ~76 minecraft:snow[layers=1] strict
setblock ~249 ~47 ~75 minecraft:snow[layers=1] strict
fill ~31 ~47 ~76 ~31 ~47 ~77 minecraft:snow[layers=1] strict
fill ~35 ~47 ~76 ~35 ~47 ~78 minecraft:snow[layers=1] strict
fill ~28 ~47 ~77 ~30 ~47 ~77 minecraft:snow[layers=1] strict
setblock ~33 ~47 ~77 minecraft:snow[layers=1] strict
fill ~27 ~47 ~78 ~28 ~47 ~78 minecraft:snow[layers=1] strict
setblock ~30 ~47 ~78 minecraft:snow[layers=1] strict
setblock ~34 ~47 ~78 minecraft:snow[layers=1] strict
setblock ~250 ~47 ~78 minecraft:snow[layers=1] strict
fill ~27 ~47 ~79 ~27 ~47 ~80 minecraft:snow[layers=1] strict
setblock ~33 ~47 ~79 minecraft:snow[layers=1] strict
fill ~28 ~47 ~80 ~30 ~47 ~80 minecraft:snow[layers=1] strict
setblock ~32 ~47 ~80 minecraft:snow[layers=1] strict
setblock ~34 ~47 ~80 minecraft:snow[layers=1] strict
setblock ~35 ~47 ~80 minecraft:snow[layers=2] strict
fill ~251 ~47 ~80 ~251 ~47 ~81 minecraft:snow[layers=1] strict
fill ~28 ~47 ~81 ~29 ~47 ~81 minecraft:snow[layers=1] strict
fill ~30 ~47 ~81 ~34 ~47 ~81 minecraft:snow[layers=2] strict
setblock ~31 ~47 ~82 minecraft:snow[layers=2] strict
setblock ~33 ~47 ~82 minecraft:snow[layers=2] strict
setblock ~36 ~47 ~85 minecraft:snow[layers=2] strict
setblock ~38 ~47 ~85 minecraft:snow[layers=2] strict
setblock ~35 ~47 ~86 minecraft:snow[layers=2] strict
setblock ~37 ~47 ~86 minecraft:snow[layers=2] strict
setblock ~40 ~47 ~86 minecraft:snow[layers=2] strict
setblock ~34 ~47 ~87 minecraft:snow[layers=2] strict
setblock ~36 ~47 ~87 minecraft:snow[layers=2] strict
setblock ~41 ~47 ~87 minecraft:snow[layers=2] strict
setblock ~35 ~47 ~88 minecraft:snow[layers=2] strict
fill ~38 ~47 ~88 ~39 ~47 ~88 minecraft:snow[layers=2] strict
fill ~41 ~47 ~88 ~41 ~47 ~89 minecraft:snow[layers=1] strict
setblock ~44 ~47 ~88 minecraft:snow[layers=1] strict
fill ~251 ~47 ~88 ~251 ~47 ~89 minecraft:snow[layers=1] strict
fill ~39 ~47 ~89 ~40 ~47 ~89 minecraft:snow[layers=1] strict
fill ~250 ~47 ~91 ~250 ~47 ~92 minecraft:snow[layers=1] strict
fill ~249 ~47 ~96 ~249 ~47 ~97 minecraft:snow[layers=1] strict
fill ~253 ~47 ~116 ~253 ~47 ~117 minecraft:snow[layers=1] strict
fill ~253 ~47 ~135 ~253 ~47 ~136 minecraft:snow[layers=1] strict
fill ~4 ~47 ~140 ~4 ~47 ~142 minecraft:snow[layers=2] strict
setblock ~119 ~47 ~141 minecraft:smooth_quartz_slab[type=bottom,waterlogged=false] strict
setblock ~5 ~47 ~145 minecraft:snow[layers=1] strict
fill ~250 ~47 ~149 ~250 ~47 ~150 minecraft:snow[layers=2] strict
fill ~6 ~47 ~151 ~6 ~47 ~152 minecraft:snow[layers=1] strict
fill ~7 ~47 ~158 ~7 ~47 ~167 minecraft:snow[layers=2] strict
fill ~249 ~47 ~161 ~249 ~47 ~163 minecraft:snow[layers=1] strict
fill ~7 ~47 ~177 ~7 ~47 ~186 minecraft:snow[layers=1] strict
fill ~249 ~47 ~182 ~249 ~47 ~188 minecraft:snow[layers=1] strict
fill ~7 ~47 ~187 ~7 ~47 ~190 minecraft:snow[layers=2] strict
fill ~6 ~47 ~196 ~6 ~47 ~197 minecraft:snow[layers=2] strict
fill ~248 ~47 ~197 ~248 ~47 ~200 minecraft:snow[layers=1] strict
fill ~6 ~47 ~198 ~6 ~47 ~199 minecraft:snow[layers=1] strict
setblock ~249 ~47 ~206 minecraft:snow[layers=1] strict
setblock ~250 ~47 ~211 minecraft:snow[layers=1] strict
setblock ~8 ~47 ~215 minecraft:lantern[hanging=false,waterlogged=false] strict
setblock ~250 ~47 ~217 minecraft:snow[layers=2] strict
setblock ~6 ~47 ~228 minecraft:snow[layers=1] strict
setblock ~7 ~47 ~232 minecraft:snow[layers=1] strict
fill ~249 ~47 ~235 ~249 ~47 ~238 minecraft:snow[layers=1] strict
fill ~249 ~47 ~240 ~249 ~47 ~248 minecraft:snow[layers=2] strict
fill ~7 ~47 ~244 ~7 ~47 ~247 minecraft:snow[layers=1] strict
setblock ~41 ~47 ~248 minecraft:lantern[hanging=false,waterlogged=false] strict
fill ~71 ~47 ~248 ~74 ~47 ~248 minecraft:snow[layers=2] strict
setblock ~191 ~47 ~248 minecraft:snow[layers=2] strict
fill ~197 ~47 ~248 ~198 ~47 ~248 minecraft:snow[layers=2] strict
setblock ~69 ~47 ~249 minecraft:snow[layers=2] strict
fill ~79 ~47 ~249 ~80 ~47 ~249 minecraft:snow[layers=2] strict
fill ~151 ~47 ~249 ~153 ~47 ~249 minecraft:snow[layers=1] strict
fill ~174 ~47 ~249 ~176 ~47 ~249 minecraft:snow[layers=2] strict
fill ~203 ~47 ~249 ~204 ~47 ~249 minecraft:snow[layers=1] strict
fill ~233 ~47 ~249 ~235 ~47 ~249 minecraft:snow[layers=1] strict
fill ~239 ~47 ~249 ~242 ~47 ~249 minecraft:snow[layers=1] strict
fill ~247 ~47 ~249 ~248 ~47 ~249 minecraft:snow[layers=2] strict
fill ~11 ~47 ~250 ~13 ~47 ~250 minecraft:snow[layers=1] strict
fill ~14 ~47 ~250 ~16 ~47 ~250 minecraft:snow[layers=2] strict
fill ~47 ~47 ~250 ~50 ~47 ~250 minecraft:snow[layers=2] strict
fill ~65 ~47 ~250 ~67 ~47 ~250 minecraft:snow[layers=1] strict
fill ~83 ~47 ~250 ~84 ~47 ~250 minecraft:snow[layers=1] strict
fill ~94 ~47 ~250 ~95 ~47 ~250 minecraft:snow[layers=2] strict
fill ~105 ~47 ~250 ~109 ~47 ~250 minecraft:snow[layers=1] strict
fill ~220 ~47 ~250 ~221 ~47 ~250 minecraft:snow[layers=1] strict
setblock ~227 ~47 ~250 minecraft:snow[layers=2] strict
fill ~61 ~47 ~251 ~62 ~47 ~251 minecraft:snow[layers=1] strict
fill ~142 ~47 ~252 ~143 ~47 ~252 minecraft:snow[layers=1] strict
setblock ~115 ~47 ~253 minecraft:snow[layers=1] strict
setblock ~117 ~47 ~253 minecraft:snow[layers=1] strict
setblock ~137 ~47 ~253 minecraft:snow[layers=1] strict
setblock ~158 ~48 ~0 minecraft:snow[layers=2] strict
fill ~159 ~48 ~0 ~163 ~48 ~0 minecraft:snow[layers=1] strict
fill ~158 ~48 ~1 ~158 ~48 ~2 minecraft:snow[layers=1] strict
fill ~162 ~48 ~1 ~163 ~48 ~1 minecraft:snow[layers=1] strict
fill ~157 ~48 ~2 ~157 ~48 ~3 minecraft:snow[layers=1] strict
fill ~163 ~48 ~2 ~163 ~48 ~4 minecraft:snow[layers=1] strict
fill ~139 ~48 ~3 ~140 ~48 ~3 minecraft:snow[layers=2] strict
setblock ~141 ~48 ~3 minecraft:snow[layers=1] strict
setblock ~141 ~48 ~4 minecraft:snow[layers=2] strict
setblock ~155 ~48 ~4 minecraft:snow[layers=1] strict
fill ~23 ~48 ~5 ~24 ~48 ~5 minecraft:snow[layers=1] strict
fill ~30 ~48 ~5 ~32 ~48 ~5 minecraft:snow[layers=1] strict
fill ~33 ~48 ~5 ~35 ~48 ~5 minecraft:snow[layers=2] strict
fill ~152 ~48 ~5 ~153 ~48 ~5 minecraft:snow[layers=1] strict
setblock ~164 ~48 ~5 minecraft:snow[layers=1] strict
setblock ~20 ~48 ~6 minecraft:snow[layers=1] strict
setblock ~43 ~48 ~6 minecraft:snow[layers=2] strict
fill ~165 ~48 ~6 ~166 ~48 ~6 minecraft:snow[layers=1] strict
fill ~186 ~48 ~6 ~193 ~48 ~6 minecraft:snow[layers=1] strict
fill ~202 ~48 ~6 ~210 ~48 ~6 minecraft:snow[layers=1] strict
fill ~229 ~48 ~6 ~234 ~48 ~6 minecraft:snow[layers=1] strict
setblock ~242 ~48 ~6 minecraft:snow[layers=1] strict
fill ~7 ~48 ~7 ~13 ~48 ~7 minecraft:snow[layers=1] strict
setblock ~48 ~48 ~7 minecraft:snow[layers=1] strict
fill ~168 ~48 ~7 ~169 ~48 ~7 minecraft:snow[layers=1] strict
setblock ~182 ~48 ~7 minecraft:snow[layers=2] strict
setblock ~183 ~48 ~7 minecraft:snow[layers=1] strict
setblock ~246 ~48 ~7 minecraft:snow[layers=1] strict
fill ~247 ~48 ~7 ~249 ~48 ~7 minecraft:snow[layers=2] strict
setblock ~7 ~48 ~8 minecraft:snow[layers=1] strict
setblock ~54 ~48 ~8 minecraft:snow[layers=1] strict
fill ~84 ~48 ~8 ~85 ~48 ~8 minecraft:snow[layers=1] strict
setblock ~172 ~48 ~8 minecraft:snow[layers=1] strict
setblock ~173 ~48 ~8 minecraft:snow[layers=2] strict
fill ~179 ~48 ~8 ~180 ~48 ~8 minecraft:snow[layers=2] strict
fill ~249 ~48 ~8 ~249 ~48 ~9 minecraft:snow[layers=2] strict
fill ~61 ~48 ~9 ~63 ~48 ~9 minecraft:snow[layers=1] strict
fill ~68 ~48 ~10 ~71 ~48 ~10 minecraft:snow[layers=1] strict
fill ~7 ~48 ~12 ~7 ~48 ~20 minecraft:snow[layers=1] strict
fill ~250 ~48 ~20 ~250 ~48 ~21 minecraft:snow[layers=1] strict
setblock ~7 ~48 ~24 minecraft:snow[layers=1] strict
setblock ~6 ~48 ~31 minecraft:snow[layers=1] strict
setblock ~6 ~48 ~38 minecraft:snow[layers=1] strict
setblock ~250 ~48 ~39 minecraft:snow[layers=1] strict
setblock ~250 ~48 ~47 minecraft:snow[layers=1] strict
fill ~7 ~48 ~53 ~7 ~48 ~54 minecraft:snow[layers=2] strict
fill ~249 ~48 ~53 ~249 ~48 ~54 minecraft:snow[layers=1] strict
fill ~8 ~48 ~58 ~8 ~48 ~59 minecraft:snow[layers=2] strict
setblock ~9 ~48 ~62 minecraft:snow[layers=2] strict
setblock ~9 ~48 ~64 minecraft:snow[layers=1] strict
setblock ~8 ~48 ~69 minecraft:snow[layers=1] strict
fill ~7 ~48 ~73 ~7 ~48 ~79 minecraft:snow[layers=1] strict
setblock ~249 ~48 ~74 minecraft:snow[layers=1] strict
fill ~32 ~48 ~77 ~32 ~48 ~79 minecraft:snow[layers=1] strict
setblock ~34 ~48 ~77 minecraft:snow[layers=1] strict
setblock ~250 ~48 ~77 minecraft:snow[layers=1] strict
fill ~29 ~48 ~78 ~29 ~48 ~79 minecraft:snow[layers=1] strict
fill ~31 ~48 ~78 ~31 ~48 ~80 minecraft:snow[layers=1] strict
setblock ~33 ~48 ~78 minecraft:snow[layers=1] strict
setblock ~28 ~48 ~79 minecraft:snow[layers=1] strict
setblock ~30 ~48 ~79 minecraft:snow[layers=1] strict
setblock ~34 ~48 ~79 minecraft:snow[layers=1] strict
setblock ~251 ~48 ~79 minecraft:snow[layers=1] strict
fill ~7 ~48 ~80 ~7 ~48 ~82 minecraft:snow[layers=2] strict
setblock ~33 ~48 ~80 minecraft:snow[layers=1] strict
fill ~36 ~48 ~81 ~38 ~48 ~81 minecraft:snow[layers=2] strict
fill ~36 ~48 ~82 ~36 ~48 ~83 minecraft:snow[layers=2] strict
fill ~38 ~48 ~82 ~38 ~48 ~83 minecraft:snow[layers=2] strict
fill ~252 ~48 ~82 ~252 ~48 ~88 minecraft:snow[layers=1] strict
setblock ~37 ~48 ~83 minecraft:snow[layers=2] strict
setblock ~251 ~48 ~90 minecraft:snow[layers=1] strict
setblock ~250 ~48 ~93 minecraft:snow[layers=1] strict
fill ~249 ~48 ~98 ~249 ~48 ~99 minecraft:snow[layers=2] strict
fill ~249 ~48 ~106 ~249 ~48 ~107 minecraft:snow[layers=2] strict
setblock ~64 ~48 ~109 minecraft:snow[layers=2] strict
setblock ~4 ~48 ~139 minecraft:snow[layers=2] strict
setblock ~117 ~48 ~141 minecraft:smooth_quartz_slab[type=bottom,waterlogged=false] strict
fill ~5 ~48 ~146 ~5 ~48 ~148 minecraft:snow[layers=1] strict
setblock ~251 ~48 ~146 minecraft:snow[layers=2] strict
setblock ~250 ~48 ~151 minecraft:snow[layers=2] strict
setblock ~250 ~48 ~152 minecraft:snow[layers=1] strict
setblock ~6 ~48 ~153 minecraft:snow[layers=1] strict
fill ~249 ~48 ~164 ~249 ~48 ~165 minecraft:snow[layers=1] strict
fill ~7 ~48 ~168 ~7 ~48 ~170 minecraft:snow[layers=2] strict
setblock ~7 ~48 ~171 minecraft:snow[layers=1] strict
fill ~7 ~48 ~175 ~7 ~48 ~176 minecraft:snow[layers=1] strict
fill ~249 ~48 ~180 ~249 ~48 ~181 minecraft:snow[layers=1] strict
fill ~249 ~48 ~189 ~249 ~48 ~191 minecraft:snow[layers=1] strict
fill ~6 ~48 ~194 ~6 ~48 ~195 minecraft:snow[layers=2] strict
fill ~6 ~48 ~200 ~6 ~48 ~202 minecraft:snow[layers=1] strict
fill ~249 ~48 ~204 ~249 ~48 ~205 minecraft:snow[layers=1] strict
setblock ~250 ~48 ~210 minecraft:snow[layers=1] strict
setblock ~6 ~48 ~216 minecraft:snow[layers=1] strict
fill ~250 ~48 ~218 ~250 ~48 ~222 minecraft:snow[layers=2] strict
setblock ~6 ~48 ~229 minecraft:snow[layers=1] strict
setblock ~7 ~48 ~233 minecraft:snow[layers=1] strict
setblock ~249 ~48 ~239 minecraft:snow[layers=1] strict
fill ~7 ~48 ~242 ~7 ~48 ~243 minecraft:snow[layers=2] strict
setblock ~192 ~48 ~248 minecraft:snow[layers=2] strict
fill ~195 ~48 ~248 ~196 ~48 ~248 minecraft:snow[layers=2] strict
fill ~70 ~48 ~249 ~71 ~48 ~249 minecraft:snow[layers=2] strict
fill ~77 ~48 ~249 ~78 ~48 ~249 minecraft:snow[layers=2] strict
fill ~154 ~48 ~249 ~155 ~48 ~249 minecraft:snow[layers=2] strict
fill ~164 ~48 ~249 ~173 ~48 ~249 minecraft:snow[layers=1] strict
fill ~177 ~48 ~249 ~179 ~48 ~249 minecraft:snow[layers=2] strict
setblock ~202 ~48 ~249 minecraft:snow[layers=1] strict
fill ~236 ~48 ~249 ~238 ~48 ~249 minecraft:snow[layers=1] strict
setblock ~249 ~48 ~249 minecraft:snow[layers=2] strict
fill ~9 ~48 ~250 ~10 ~48 ~250 minecraft:snow[layers=1] strict
fill ~17 ~48 ~250 ~22 ~48 ~250 minecraft:snow[layers=2] strict
fill ~23 ~48 ~250 ~28 ~48 ~250 minecraft:snow[layers=1] strict
fill ~44 ~48 ~250 ~45 ~48 ~250 minecraft:snow[layers=1] strict
setblock ~46 ~48 ~250 minecraft:snow[layers=2] strict
setblock ~68 ~48 ~250 minecraft:snow[layers=1] strict
setblock ~81 ~48 ~250 minecraft:snow[layers=2] strict
setblock ~82 ~48 ~250 minecraft:snow[layers=1] strict
fill ~96 ~48 ~250 ~98 ~48 ~250 minecraft:snow[layers=2] strict
fill ~99 ~48 ~250 ~104 ~48 ~250 minecraft:snow[layers=1] strict
setblock ~228 ~48 ~250 minecraft:snow[layers=2] strict
fill ~56 ~48 ~251 ~59 ~48 ~251 minecraft:snow[layers=2] strict
setblock ~60 ~48 ~251 minecraft:snow[layers=1] strict
fill ~63 ~48 ~251 ~66 ~48 ~251 minecraft:snow[layers=1] strict
setblock ~85 ~48 ~251 minecraft:snow[layers=1] strict
fill ~86 ~48 ~251 ~91 ~48 ~251 minecraft:snow[layers=2] strict
fill ~61 ~48 ~252 ~62 ~48 ~252 minecraft:snow[layers=1] strict
setblock ~136 ~48 ~253 minecraft:snow[layers=1] strict
fill ~141 ~48 ~253 ~142 ~48 ~253 minecraft:snow[layers=1] strict
fill ~60 ~48 ~255 ~61 ~48 ~255 minecraft:snow[layers=2] strict
setblock ~62 ~48 ~255 minecraft:snow[layers=1] strict
fill ~156 ~49 ~0 ~157 ~49 ~0 minecraft:snow[layers=2] strict
fill ~164 ~49 ~0 ~164 ~49 ~4 minecraft:snow[layers=1] strict
fill ~156 ~49 ~1 ~157 ~49 ~1 minecraft:snow[layers=1] strict
fill ~156 ~49 ~2 ~156 ~49 ~3 minecraft:snow[layers=1] strict
setblock ~155 ~49 ~3 minecraft:snow[layers=1] strict
setblock ~144 ~49 ~4 minecraft:snow[layers=1] strict
setblock ~154 ~49 ~4 minecraft:snow[layers=1] strict
setblock ~22 ~49 ~5 minecraft:snow[layers=1] strict
fill ~36 ~49 ~5 ~39 ~49 ~5 minecraft:snow[layers=2] strict
fill ~146 ~49 ~5 ~151 ~49 ~5 minecraft:snow[layers=1] strict
setblock ~165 ~49 ~5 minecraft:snow[layers=1] strict
setblock ~212 ~49 ~5 minecraft:snow[layers=1] strict
fill ~213 ~49 ~5 ~215 ~49 ~5 minecraft:snow[layers=2] strict
setblock ~19 ~49 ~6 minecraft:snow[layers=1] strict
setblock ~44 ~49 ~6 minecraft:snow[layers=2] strict
setblock ~167 ~49 ~6 minecraft:snow[layers=1] strict
fill ~184 ~49 ~6 ~185 ~49 ~6 minecraft:snow[layers=1] strict
fill ~243 ~49 ~6 ~244 ~49 ~6 minecraft:snow[layers=1] strict
setblock ~49 ~49 ~7 minecraft:snow[layers=1] strict
fill ~170 ~49 ~7 ~171 ~49 ~7 minecraft:snow[layers=1] strict
setblock ~181 ~49 ~7 minecraft:snow[layers=2] strict
fill ~55 ~49 ~8 ~56 ~49 ~8 minecraft:snow[layers=1] strict
fill ~81 ~49 ~8 ~83 ~49 ~8 minecraft:snow[layers=1] strict
fill ~174 ~49 ~8 ~178 ~49 ~8 minecraft:snow[layers=2] strict
fill ~64 ~49 ~9 ~65 ~49 ~9 minecraft:snow[layers=1] strict
fill ~74 ~49 ~9 ~75 ~49 ~9 minecraft:snow[layers=2] strict
setblock ~67 ~49 ~12 minecraft:snow[layers=1] strict
fill ~250 ~49 ~18 ~250 ~49 ~19 minecraft:snow[layers=1] strict
fill ~7 ~49 ~21 ~7 ~49 ~23 minecraft:snow[layers=1] strict
fill ~251 ~49 ~24 ~251 ~49 ~26 minecraft:snow[layers=1] strict
setblock ~6 ~49 ~30 minecraft:snow[layers=1] strict
setblock ~6 ~49 ~39 minecraft:snow[layers=1] strict
fill ~250 ~49 ~40 ~250 ~49 ~46 minecraft:snow[layers=1] strict
fill ~250 ~49 ~48 ~250 ~49 ~50 minecraft:snow[layers=1] strict
setblock ~7 ~49 ~55 minecraft:snow[layers=2] strict
fill ~249 ~49 ~55 ~249 ~49 ~56 minecraft:snow[layers=1] strict
setblock ~8 ~49 ~60 minecraft:snow[layers=2] strict
setblock ~9 ~49 ~63 minecraft:snow[layers=2] strict
fill ~8 ~49 ~67 ~8 ~49 ~68 minecraft:snow[layers=1] strict
fill ~7 ~49 ~71 ~7 ~49 ~72 minecraft:snow[layers=1] strict
fill ~249 ~49 ~71 ~249 ~49 ~73 minecraft:snow[layers=1] strict
setblock ~250 ~49 ~76 minecraft:snow[layers=1] strict
setblock ~251 ~49 ~78 minecraft:snow[layers=1] strict
fill ~252 ~49 ~80 ~252 ~49 ~81 minecraft:snow[layers=1] strict
fill ~253 ~49 ~82 ~253 ~49 ~88 minecraft:snow[layers=1] strict
fill ~7 ~49 ~83 ~7 ~49 ~92 minecraft:snow[layers=2] strict
fill ~254 ~49 ~84 ~255 ~49 ~87 minecraft:snow[layers=1] strict
setblock ~255 ~49 ~88 minecraft:snow[layers=1] strict
setblock ~252 ~49 ~89 minecraft:snow[layers=1] strict
setblock ~251 ~49 ~91 minecraft:snow[layers=1] strict
setblock ~250 ~49 ~94 minecraft:snow[layers=1] strict
fill ~249 ~49 ~100 ~249 ~49 ~105 minecraft:snow[layers=2] strict
fill ~123 ~49 ~113 ~133 ~49 ~113 minecraft:smooth_quartz_slab[type=bottom,waterlogged=false] strict
fill ~138 ~49 ~113 ~143 ~49 ~113 minecraft:smooth_quartz_slab[type=bottom,waterlogged=false] strict
fill ~143 ~49 ~114 ~143 ~49 ~143 minecraft:smooth_quartz_slab[type=bottom,waterlogged=false] strict
setblock ~142 ~49 ~118 minecraft:smooth_quartz_slab[type=bottom,waterlogged=false] strict
fill ~113 ~49 ~123 ~113 ~49 ~128 minecraft:smooth_quartz_slab[type=bottom,waterlogged=false] strict
